Workbook

Sheet Pays
A1: Pays | B1: Code | C1: Zone | D1: TVA | E1: Gazole | G1: Surcharge carburant : | I1: US : 1,50€/kg
A2: ALLEMAGNE | B2: DE | C2: 1 | D2: 0.2 | I2: Canada : 1,50€/kg
A3: ARABIE SAOUDITE | B3: SA | C3: 2 | D3: 0 | I3: Australie : 1,50€/kg
A4: AUSTRALIE | B4: AU | C4: 2 | D4: 0 | E4: 1.5 | I4: Nouvelle Zélande : 1,50€/kg
A5: AUTRICHE | B5: AT | C5: 1 | D5: 0.2 | I5: Japon :1,50€/kg
A6: BELGIQUE | B6: BE | C6: 1_BE | D6: 0.2
A7: BOSNIE-HERZÉGOVINE | B7: BA | C7: 2 | D7: 0
A8: BRÉSIL | B8: BR | C8: 2 | D8: 0
A9: BULGARIE | B9: BG | C9: 1 | D9: 0.2
A10: CAMBODGE | B10: KH | C10: 2 | D10: 0
A11: CANADA | B11: CA | C11: 2 | D11: 0 | E11: 1.5
A12: CHILI | B12: CL | C12: 2 | D12: 0
A13: CHINE | B13: CN | C13: 2 | D13: 0
A14: CHYPRE | B14: CY | C14: 2 | D14: 0
A15: COLOMBIE | B15: CO | C15: 2 | D15: 0
A16: CROATIE | B16: HR | C16: 1 | D16: 0.2
A17: DANEMARK | B17: DK | C17: 1 | D17: 0.2
A18: ÉMIRATS ARABES UNIS | B18: UAE | C18: 2 | D18: 0
A19: ESPAGNE | B19: ES | C19: 1 | D19: 0.2
A20: ESTONIE | B20: EE | C20: 1 | D20: 0.2
A21: ETATS-UNIS | B21: US | C21: 2_US | D21: 0 | E21: 1.5
A22: ÉTATS-UNIS | B22: US | C22: 2_US | D22: 0 | E22: 1.5
A23: FINLANDE | B23: FI | C23: 1 | D23: 0.2
A24: GÉORGIE | B24: GE | C24: 1 | D24: 0.2
A25: GRECE | B25: GR | C25: 1 | D25: 0.2
A26: GRÈCE | B26: GR | C26: 1 | D26: 0.2
A27: GUATEMALA | B27: GT | C27: 2 | D27: 0
A28: HONG KONG | B28: HK | C28: 2 | D28: 0
A29: HONGRIE | B29: HU | C29: 1 | D29: 0.2
A30: INDE | B30: IN | C30: 2 | D30: 0
A31: INDONÉSIE | B31: ID | C31: 2 | D31: 0
A32: IRLANDE | B32: IE | C32: 1 | D32: 0.2
A33: ISLANDE | B33: IS | C33: 2 | D33: 0
A34: ISRAËL | B34: IL | C34: 2 | D34: 0
A35: ITALIE | B35: IT | C35: 1 | D35: 0.2
A36: JAPON | B36: JP | C36: 2 | D36: 0 | E36: 1.5
A37: KAZAKHSTAN | B37: KZ | C37: 2 | D37: 0
A38: KOWEIT | B38: KW | C38: 2 | D38: 0
A39: LAO, REPUBLIQUE DEMOCRATIQUE POPULAIRE | B39: LA | C39: 2 | D39: 0
A40: LETTONIE | B40: LV | C40: 1 | D40: 0.2
...

Sheet Fichier import
A1: Date remise | B1: Transporteur | C1: Date validité tarif | D1: Réf.1 | E1: Réf. 2 | F1: Statut Général | G1: Numéro de suivi | H1: Destinataire nom | I1: E / P | J1: Pays | K1: Zone | L1: Nbr Colis | M1: Poids | N1: mode envoi | O1: TVA | P1: Droits et taxes | Q1: Assurance | R1: Zones éloignées | S1: Colis volumineux | T1: Adresses | U1: Frêt | V1: plus-value BtoC | W1: Taxe Gasoil | X1: Pays
A2: 01/06/2026 | B2: DELIVENGO-LPPQ | C2: 46174 | F2: Distribué | G2: LD248499501FR | H2: HAYWARD ANDY | I2: P | J2: =IF(COUNTIF(Pays!A:A,X2)=0,"Pays inconnu",_xlfn.XLOOKUP(X2,Pays!A:A,Pays!B:B)) -> GB | K2: =IF(COUNTIF(Pays!A:A,X2)=0,"Pays inconnu",_xlfn.XLOOKUP(X2,Pays!A:A,Pays!C:C)) -> 1_GB | L2: 1 | M2: =ROUND(MAX(P2:Q2),2) -> 0.15 | N2: avecsuivi | O2: =LOOKUP(X2,Pays!A:A,Pays!D:D) -> 0 | P2: 0.15 | Q2: 0.12 | U2: 1 | W2: =IF(COUNTIF(Pays!A:A,X2)=0,"",LOOKUP(X2,Pays!A:A,Pays!E:E)) -> 0 | X2: ROYAUME-UNI
A3: 01/06/2026 | B3: DELIVENGO-LPPQ | C3: =C2 -> 46174 | F3: Distribué | G3: LD248499696FR | H3: MORGAN SALLY | I3: P | J3: =IF(COUNTIF(Pays!A:A,X3)=0,"Pays inconnu",_xlfn.XLOOKUP(X3,Pays!A:A,Pays!B:B)) -> GB | K3: =IF(COUNTIF(Pays!A:A,X3)=0,"Pays inconnu",_xlfn.XLOOKUP(X3,Pays!A:A,Pays!C:C)) -> 1_GB | L3: 1 | M3: =ROUND(MAX(P3:Q3),2) -> 0.21 | N3: avecsuivi | O3: =LOOKUP(X3,Pays!A:A,Pays!D:D) -> 0 | P3: 0.15 | Q3: 0.21 | U3: 1 | W3: =IF(COUNTIF(Pays!A:A,X3)=0,"",LOOKUP(X3,Pays!A:A,Pays!E:E)) -> 0 | X3: ROYAUME-UNI
A4: 01/06/2026 | B4: DELIVENGO-LPPQ | C4: =C3 -> 46174 | F4: Distribué | G4: LD248499767FR | H4: SPAHN MICHELLE | I4: P | J4: =IF(COUNTIF(Pays!A:A,X4)=0,"Pays inconnu",_xlfn.XLOOKUP(X4,Pays!A:A,Pays!B:B)) -> CH | K4: =IF(COUNTIF(Pays!A:A,X4)=0,"Pays inconnu",_xlfn.XLOOKUP(X4,Pays!A:A,Pays!C:C)) -> 1_CH | L4: 1 | M4: =ROUND(MAX(P4:Q4),2) -> 0.58 | N4: avecsuivi | O4: =LOOKUP(X4,Pays!A:A,Pays!D:D) -> 0 | P4: 0.15 | Q4: 0.58 | U4: 1 | W4: =IF(COUNTIF(Pays!A:A,X4)=0,"",LOOKUP(X4,Pays!A:A,Pays!E:E)) -> 0 | X4: SUISSE
A5: 01/06/2026 | B5: DELIVENGO-LPPQ | C5: =C4 -> 46174 | F5: Distribué | G5: LD248500814FR | H5: BARHAM YVONNE | I5: P | J5: =IF(COUNTIF(Pays!A:A,X5)=0,"Pays inconnu",_xlfn.XLOOKUP(X5,Pays!A:A,Pays!B:B)) -> GB | K5: =IF(COUNTIF(Pays!A:A,X5)=0,"Pays inconnu",_xlfn.XLOOKUP(X5,Pays!A:A,Pays!C:C)) -> 1_GB | L5: 1 | M5: =ROUND(MAX(P5:Q5),2) -> 0.15 | N5: avecsuivi | O5: =LOOKUP(X5,Pays!A:A,Pays!D:D) -> 0 | P5: 0.15 | Q5: 0.04 | U5: 1 | W5: =IF(COUNTIF(Pays!A:A,X5)=0,"",LOOKUP(X5,Pays!A:A,Pays!E:E)) -> 0 | X5: ROYAUME-UNI
A6: 01/06/2026 | B6: DELIVENGO-LPPQ | C6: =C5 -> 46174 | F6: Déposé | G6: LD248604139FR | H6: WENGER ANDREA | I6: P | J6: =IF(COUNTIF(Pays!A:A,X6)=0,"Pays inconnu",_xlfn.XLOOKUP(X6,Pays!A:A,Pays!B:B)) -> CH | K6: =IF(COUNTIF(Pays!A:A,X6)=0,"Pays inconnu",_xlfn.XLOOKUP(X6,Pays!A:A,Pays!C:C)) -> 1_CH | L6: 1 | M6: =ROUND(MAX(P6:Q6),2) -> 0.15 | N6: avecsuivi | O6: =LOOKUP(X6,Pays!A:A,Pays!D:D) -> 0 | P6: 0.15 | U6: 1 | W6: =IF(COUNTIF(Pays!A:A,X6)=0,"",LOOKUP(X6,Pays!A:A,Pays!E:E)) -> 0 | X6: SUISSE
A7: 01/06/2026 | B7: DELIVENGO-LPPQ | C7: =C6 -> 46174 | F7: Déposé | G7: LD248602345FR | H7: COOPER JILL | I7: P | J7: =IF(COUNTIF(Pays!A:A,X7)=0,"Pays inconnu",_xlfn.XLOOKUP(X7,Pays!A:A,Pays!B:B)) -> GB | K7: =IF(COUNTIF(Pays!A:A,X7)=0,"Pays inconnu",_xlfn.XLOOKUP(X7,Pays!A:A,Pays!C:C)) -> 1_GB | L7: 1 | M7: =ROUND(MAX(P7:Q7),2) -> 0.15 | N7: avecsuivi | O7: =LOOKUP(X7,Pays!A:A,Pays!D:D) -> 0 | P7: 0.15 | U7: 1 | W7: =IF(COUNTIF(Pays!A:A,X7)=0,"",LOOKUP(X7,Pays!A:A,Pays!E:E)) -> 0 | X7: ROYAUME-UNI
A8: 01/06/2026 | B8: DELIVENGO-LPPQ | C8: =C7 -> 46174 | F8: Distribué | G8: LD248607064FR | H8: FEX HANNA | I8: P | J8: =IF(COUNTIF(Pays!A:A,X8)=0,"Pays inconnu",_xlfn.XLOOKUP(X8,Pays!A:A,Pays!B:B)) -> CH | K8: =IF(COUNTIF(Pays!A:A,X8)=0,"Pays inconnu",_xlfn.XLOOKUP(X8,Pays!A:A,Pays!C:C)) -> 1_CH | L8: 1 | M8: =ROUND(MAX(P8:Q8),2) -> 1 | N8: avecsuivi | O8: =LOOKUP(X8,Pays!A:A,Pays!D:D) -> 0 | P8: 0.15 | Q8: 1 | U8: 1 | W8: =IF(COUNTIF(Pays!A:A,X8)=0,"",LOOKUP(X8,Pays!A:A,Pays!E:E)) -> 0 | X8: SUISSE
A9: 01/06/2026 | B9: DELIVENGO-LPPQ | C9: =C8 -> 46174 | F9: Distribué | G9: LD248608538FR | H9: WAHL RITA | I9: P | J9: =IF(COUNTIF(Pays!A:A,X9)=0,"Pays inconnu",_xlfn.XLOOKUP(X9,Pays!A:A,Pays!B:B)) -> CH | K9: =IF(COUNTIF(Pays!A:A,X9)=0,"Pays inconnu",_xlfn.XLOOKUP(X9,Pays!A:A,Pays!C:C)) -> 1_CH | L9: 1 | M9: =ROUND(MAX(P9:Q9),2) -> 1 | N9: avecsuivi | O9: =LOOKUP(X9,Pays!A:A,Pays!D:D) -> 0 | P9: 0.15 | Q9: 1 | U9: 1 | W9: =IF(COUNTIF(Pays!A:A,X9)=0,"",LOOKUP(X9,Pays!A:A,Pays!E:E)) -> 0 | X9: SUISSE
A10: 01/06/2026 | B10: DELIVENGO-LPPQ | C10: =C9 -> 46174 | F10: En cours | G10: LD248609533FR | H10: COOPER JILL | I10: P | J10: =IF(COUNTIF(Pays!A:A,X10)=0,"Pays inconnu",_xlfn.XLOOKUP(X10,Pays!A:A,Pays!B:B)) -> GB | K10: =IF(COUNTIF(Pays!A:A,X10)=0,"Pays inconnu",_xlfn.XLOOKUP(X10,Pays!A:A,Pays!C:C)) -> 1_GB | L10: 1 | M10: =ROUND(MAX(P10:Q10),2) -> 1 | N10: avecsuivi | O10: =LOOKUP(X10,Pays!A:A,Pays!D:D) -> 0 | P10: 0.15 | Q10: 1 | U10: 1 | W10: =IF(COUNTIF(Pays!A:A,X10)=0,"",LOOKUP(X10,Pays!A:A,Pays!E:E)) -> 0 | X10: ROYAUME-UNI
A11: 01/06/2026 | B11: DELIVENGO-LPPQ | C11: =C10 -> 46174 | F11: Distribué | G11: LD248611510FR | H11: EDES ZSUZSANNA | I11: P | J11: =IF(COUNTIF(Pays!A:A,X11)=0,"Pays inconnu",_xlfn.XLOOKUP(X11,Pays!A:A,Pays!B:B)) -> CH | K11: =IF(COUNTIF(Pays!A:A,X11)=0,"Pays inconnu",_xlfn.XLOOKUP(X11,Pays!A:A,Pays!C:C)) -> 1_CH | L11: 1 | M11: =ROUND(MAX(P11:Q11),2) -> 1 | N11: avecsuivi | O11: =LOOKUP(X11,Pays!A:A,Pays!D:D) -> 0 | P11: 0.15 | Q11: 1 | U11: 1 | W11: =IF(COUNTIF(Pays!A:A,X11)=0,"",LOOKUP(X11,Pays!A:A,Pays!E:E)) -> 0 | X11: SUISSE
A12: 01/06/2026 | B12: DELIVENGO-LPPQ | C12: =C11 -> 46174 | F12: Distribué | G12: LD248614140FR | H12: WENGER ANDREA | I12: P | J12: =IF(COUNTIF(Pays!A:A,X12)=0,"Pays inconnu",_xlfn.XLOOKUP(X12,Pays!A:A,Pays!B:B)) -> CH | K12: =IF(COUNTIF(Pays!A:A,X12)=0,"Pays inconnu",_xlfn.XLOOKUP(X12,Pays!A:A,Pays!C:C)) -> 1_CH | L12: 1 | M12: =ROUND(MAX(P12:Q12),2) -> 1 | N12: avecsuivi | O12: =LOOKUP(X12,Pays!A:A,Pays!D:D) -> 0 | P12: 0.15 | Q12: 1 | U12: 1 | W12: =IF(COUNTIF(Pays!A:A,X12)=0,"",LOOKUP(X12,Pays!A:A,Pays!E:E)) -> 0 | X12: SUISSE
A13: 01/06/2026 | B13: DELIVENGO-LPPQ | C13: =C12 -> 46174 | F13: Distribué | G13: LD248617530FR | H13: BUCKNER KATRINA | I13: P | J13: =IF(COUNTIF(Pays!A:A,X13)=0,"Pays inconnu",_xlfn.XLOOKUP(X13,Pays!A:A,Pays!B:B)) -> GB | K13: =IF(COUNTIF(Pays!A:A,X13)=0,"Pays inconnu",_xlfn.XLOOKUP(X13,Pays!A:A,Pays!C:C)) -> 1_GB | L13: 1 | M13: =ROUND(MAX(P13:Q13),2) -> 0.15 | N13: avecsuivi | O13: =LOOKUP(X13,Pays!A:A,Pays!D:D) -> 0 | P13: 0.15 | U13: 1 | W13: =IF(COUNTIF(Pays!A:A,X13)=0,"",LOOKUP(X13,Pays!A:A,Pays!E:E)) -> 0 | X13: ROYAUME-UNI
A14: 01/06/2026 | B14: DELIVENGO-LPPQ | C14: =C13 -> 46174 | F14: Distribué | G14: LD248622614FR | H14: PRVULOVIC MILENA | I14: P | J14: =IF(COUNTIF(Pays!A:A,X14)=0,"Pays inconnu",_xlfn.XLOOKUP(X14,Pays!A:A,Pays!B:B)) -> CH | K14: =IF(COUNTIF(Pays!A:A,X14)=0,"Pays inconnu",_xlfn.XLOOKUP(X14,Pays!A:A,Pays!C:C)) -> 1_CH | L14: 1 | M14: =ROUND(MAX(P14:Q14),2) -> 0.15 | N14: avecsuivi | O14: =LOOKUP(X14,Pays!A:A,Pays!D:D) -> 0 | P14: 0.15 | U14: 1 | W14: =IF(COUNTIF(Pays!A:A,X14)=0,"",LOOKUP(X14,Pays!A:A,Pays!E:E)) -> 0 | X14: SUISSE
A15: 01/06/2026 | B15: DELIVENGO-LPPQ | C15: =C14 -> 46174 | F15: Distribué | G15: LD248623668FR | H15: LAIDOUNI HOUDA | I15: P | J15: =IF(COUNTIF(Pays!A:A,X15)=0,"Pays inconnu",_xlfn.XLOOKUP(X15,Pays!A:A,Pays!B:B)) -> CH | K15: =IF(COUNTIF(Pays!A:A,X15)=0,"Pays inconnu",_xlfn.XLOOKUP(X15,Pays!A:A,Pays!C:C)) -> 1_CH | L15: 1 | M15: =ROUND(MAX(P15:Q15),2) -> 0.15 | N15: avecsuivi | O15: =LOOKUP(X15,Pays!A:A,Pays!D:D) -> 0 | P15: 0.15 | U15: 1 | W15: =IF(COUNTIF(Pays!A:A,X15)=0,"",LOOKUP(X15,Pays!A:A,Pays!E:E)) -> 0 | X15: SUISSE
A16: 01/06/2026 | B16: DELIVENGO-LPPQ | C16: =C15 -> 46174 | F16: Distribué | G16: LD248625730FR | H16: VON ZEFFMAN DAVID | I16: P | J16: =IF(COUNTIF(Pays!A:A,X16)=0,"Pays inconnu",_xlfn.XLOOKUP(X16,Pays!A:A,Pays!B:B)) -> GB | K16: =IF(COUNTIF(Pays!A:A,X16)=0,"Pays inconnu",_xlfn.XLOOKUP(X16,Pays!A:A,Pays!C:C)) -> 1_GB | L16: 1 | M16: =ROUND(MAX(P16:Q16),2) -> 0.15 | N16: avecsuivi | O16: =LOOKUP(X16,Pays!A:A,Pays!D:D) -> 0 | P16: 0.15 | U16: 1 | W16: =IF(COUNTIF(Pays!A:A,X16)=0,"",LOOKUP(X16,Pays!A:A,Pays!E:E)) -> 0 | X16: ROYAUME-UNI
A17: 01/06/2026 | B17: DELIVENGO-LPPQ | C17: =C16 -> 46174 | F17: Distribué | G17: LD248628183FR | H17: KING ALFIE | I17: P | J17: =IF(COUNTIF(Pays!A:A,X17)=0,"Pays inconnu",_xlfn.XLOOKUP(X17,Pays!A:A,Pays!B:B)) -> GB | K17: =IF(COUNTIF(Pays!A:A,X17)=0,"Pays inconnu",_xlfn.XLOOKUP(X17,Pays!A:A,Pays!C:C)) -> 1_GB | L17: 1 | M17: =ROUND(MAX(P17:Q17),2) -> 0.15 | N17: avecsuivi | O17: =LOOKUP(X17,Pays!A:A,Pays!D:D) -> 0 | P17: 0.15 | U17: 1 | W17: =IF(COUNTIF(Pays!A:A,X17)=0,"",LOOKUP(X17,Pays!A:A,Pays!E:E)) -> 0 | X17: ROYAUME-UNI
A18: 01/06/2026 | B18: DELIVENGO-LPPQ | C18: =C17 -> 46174 | F18: Distribué | G18: LD248632302FR | H18: SCHLINK PHILIPPE | I18: P | J18: =IF(COUNTIF(Pays!A:A,X18)=0,"Pays inconnu",_xlfn.XLOOKUP(X18,Pays!A:A,Pays!B:B)) -> CH | K18: =IF(COUNTIF(Pays!A:A,X18)=0,"Pays inconnu",_xlfn.XLOOKUP(X18,Pays!A:A,Pays!C:C)) -> 1_CH | L18: 1 | M18: =ROUND(MAX(P18:Q18),2) -> 0.15 | N18: avecsuivi | O18: =LOOKUP(X18,Pays!A:A,Pays!D:D) -> 0 | P18: 0.15 | U18: 1 | W18: =IF(COUNTIF(Pays!A:A,X18)=0,"",LOOKUP(X18,Pays!A:A,Pays!E:E)) -> 0 | X18: SUISSE
A19: 01/06/2026 | B19: DELIVENGO-LPPQ | C19: =C18 -> 46174 | F19: Distribué | G19: LD248633121FR | H19: VUILLE JENNIFER | I19: P | J19: =IF(COUNTIF(Pays!A:A,X19)=0,"Pays inconnu",_xlfn.XLOOKUP(X19,Pays!A:A,Pays!B:B)) -> CH | K19: =IF(COUNTIF(Pays!A:A,X19)=0,"Pays inconnu",_xlfn.XLOOKUP(X19,Pays!A:A,Pays!C:C)) -> 1_CH | L19: 1 | M19: =ROUND(MAX(P19:Q19),2) -> 0.15 | N19: avecsuivi | O19: =LOOKUP(X19,Pays!A:A,Pays!D:D) -> 0 | P19: 0.15 | U19: 1 | W19: =IF(COUNTIF(Pays!A:A,X19)=0,"",LOOKUP(X19,Pays!A:A,Pays!E:E)) -> 0 | X19: SUISSE
A20: 01/06/2026 | B20: DELIVENGO-LPPQ | C20: =C19 -> 46174 | F20: Distribué | G20: LD248640309FR | H20: BERINGER SYLVIA | I20: P | J20: =IF(COUNTIF(Pays!A:A,X20)=0,"Pays inconnu",_xlfn.XLOOKUP(X20,Pays!A:A,Pays!B:B)) -> CH | K20: =IF(COUNTIF(Pays!A:A,X20)=0,"Pays inconnu",_xlfn.XLOOKUP(X20,Pays!A:A,Pays!C:C)) -> 1_CH | L20: 1 | M20: =ROUND(MAX(P20:Q20),2) -> 0.15 | N20: avecsuivi | O20: =LOOKUP(X20,Pays!A:A,Pays!D:D) -> 0 | P20: 0.15 | U20: 1 | W20: =IF(COUNTIF(Pays!A:A,X20)=0,"",LOOKUP(X20,Pays!A:A,Pays!E:E)) -> 0 | X20: SUISSE
A21: 01/06/2026 | B21: DELIVENGO-LPPQ | C21: =C20 -> 46174 | F21: Distribué | G21: LD248644359FR | H21: AGNAOU ZINEB | I21: P | J21: =IF(COUNTIF(Pays!A:A,X21)=0,"Pays inconnu",_xlfn.XLOOKUP(X21,Pays!A:A,Pays!B:B)) -> CH | K21: =IF(COUNTIF(Pays!A:A,X21)=0,"Pays inconnu",_xlfn.XLOOKUP(X21,Pays!A:A,Pays!C:C)) -> 1_CH | L21: 1 | M21: =ROUND(MAX(P21:Q21),2) -> 0.15 | N21: avecsuivi | O21: =LOOKUP(X21,Pays!A:A,Pays!D:D) -> 0 | P21: 0.15 | U21: 1 | W21: =IF(COUNTIF(Pays!A:A,X21)=0,"",LOOKUP(X21,Pays!A:A,Pays!E:E)) -> 0 | X21: SUISSE
A22: 01/06/2026 | B22: DELIVENGO-LPPQ | C22: =C21 -> 46174 | F22: Distribué | G22: LD248649095FR | H22: SICCARDI MICHELE | I22: P | J22: =IF(COUNTIF(Pays!A:A,X22)=0,"Pays inconnu",_xlfn.XLOOKUP(X22,Pays!A:A,Pays!B:B)) -> CH | K22: =IF(COUNTIF(Pays!A:A,X22)=0,"Pays inconnu",_xlfn.XLOOKUP(X22,Pays!A:A,Pays!C:C)) -> 1_CH | L22: 1 | M22: =ROUND(MAX(P22:Q22),2) -> 0.15 | N22: avecsuivi | O22: =LOOKUP(X22,Pays!A:A,Pays!D:D) -> 0 | P22: 0.15 | U22: 1 | W22: =IF(COUNTIF(Pays!A:A,X22)=0,"",LOOKUP(X22,Pays!A:A,Pays!E:E)) -> 0 | X22: SUISSE
A23: 01/06/2026 | B23: DELIVENGO-LPPQ | C23: =C22 -> 46174 | F23: Distribué | G23: LD248649489FR | H23: METZ SAMUEL | I23: P | J23: =IF(COUNTIF(Pays!A:A,X23)=0,"Pays inconnu",_xlfn.XLOOKUP(X23,Pays!A:A,Pays!B:B)) -> CH | K23: =IF(COUNTIF(Pays!A:A,X23)=0,"Pays inconnu",_xlfn.XLOOKUP(X23,Pays!A:A,Pays!C:C)) -> 1_CH | L23: 1 | M23: =ROUND(MAX(P23:Q23),2) -> 0.15 | N23: avecsuivi | O23: =LOOKUP(X23,Pays!A:A,Pays!D:D) -> 0 | P23: 0.15 | U23: 1 | W23: =IF(COUNTIF(Pays!A:A,X23)=0,"",LOOKUP(X23,Pays!A:A,Pays!E:E)) -> 0 | X23: SUISSE
A24: 01/06/2026 | B24: DELIVENGO-LPPQ | C24: =C23 -> 46174 | F24: Déposé | G24: LD248649585FR | H24: PIPER JOAN | I24: P | J24: =IF(COUNTIF(Pays!A:A,X24)=0,"Pays inconnu",_xlfn.XLOOKUP(X24,Pays!A:A,Pays!B:B)) -> GB | K24: =IF(COUNTIF(Pays!A:A,X24)=0,"Pays inconnu",_xlfn.XLOOKUP(X24,Pays!A:A,Pays!C:C)) -> 1_GB | L24: 1 | M24: =ROUND(MAX(P24:Q24),2) -> 0.15 | N24: avecsuivi | O24: =LOOKUP(X24,Pays!A:A,Pays!D:D) -> 0 | P24: 0.15 | U24: 1 | W24: =IF(COUNTIF(Pays!A:A,X24)=0,"",LOOKUP(X24,Pays!A:A,Pays!E:E)) -> 0 | X24: ROYAUME-UNI
... A36: 01/06/2026 | B36: DELIVENGO-LPPQ | C36: =C35 -> 46174 | F36: Distribué | G36: LD248694695FR | H36: TOSOLINI PAOLA | I36: P | J36: =IF(COUNTIF(Pays!A:A,X36)=0,"Pays inconnu",_xlfn.XLOOKUP(X36,Pays!A:A,Pays!B:B)) -> CH | K36: =IF(COUNTIF(Pays!A:A,X36)=0,"Pays inconnu",_xlfn.XLOOKUP(X36,Pays!A:A,Pays!C:C)) -> 1_CH | L36: 1 | M36: =ROUND(MAX(P36:Q36),2) -> 0.15 | N36: avecsuivi | O36: =LOOKUP(X36,Pays!A:A,Pays!D:D) -> 0 | P36: 0.15 | U36: 1 | W36: =IF(COUNTIF(Pays!A:A,X36)=0,"",LOOKUP(X36,Pays!A:A,Pays!E:E)) -> 0 | X36: SUISSE
A37: 01/06/2026 | B37: DELIVENGO-LPPQ | C37: =C36 -> 46174 | F37: Distribué | G37: LD248703162FR | H37: TOSOLINI PAOLA | I37: P | J37: =IF(COUNTIF(Pays!A:A,X37)=0,"Pays inconnu",_xlfn.XLOOKUP(X37,Pays!A:A,Pays!B:B)) -> CH | K37: =IF(COUNTIF(Pays!A:A,X37)=0,"Pays inconnu",_xlfn.XLOOKUP(X37,Pays!A:A,Pays!C:C)) -> 1_CH | L37: 1 | M37: =ROUND(MAX(P37:Q37),2) -> 0.15 | N37: avecsuivi | O37: =LOOKUP(X37,Pays!A:A,Pays!D:D) -> 0 | P37: 0.15 | Q37: 0.01 | U37: 1 | W37: =IF(COUNTIF(Pays!A:A,X37)=0,"",LOOKUP(X37,Pays!A:A,Pays!E:E)) -> 0 | X37: SUISSE
A38: 01/06/2026 | B38: DELIVENGO-LPPQ | C38: =C37 -> 46174 | F38: Distribué | G38: LD248703321FR | H38: STEINER RAFFAEL | I38: P | J38: =IF(COUNTIF(Pays!A:A,X38)=0,"Pays inconnu",_xlfn.XLOOKUP(X38,Pays!A:A,Pays!B:B)) -> CH | K38: =IF(COUNTIF(Pays!A:A,X38)=0,"Pays inconnu",_xlfn.XLOOKUP(X38,Pays!A:A,Pays!C:C)) -> 1_CH | L38: 1 | M38: =ROUND(MAX(P38:Q38),2) -> 0.27 | N38: avecsuivi | O38: =LOOKUP(X38,Pays!A:A,Pays!D:D) -> 0 | P38: 0.15 | Q38: 0.27 | U38: 1 | W38: =IF(COUNTIF(Pays!A:A,X38)=0,"",LOOKUP(X38,Pays!A:A,Pays!E:E)) -> 0 | X38: SUISSE
A39: 01/06/2026 | B39: DELIVENGO-LPPQ | C39: =C38 -> 46174 | F39: Distribué | G39: LD248704826FR | H39: TATE HELEN | I39: P | J39: =IF(COUNTIF(Pays!A:A,X39)=0,"Pays inconnu",_xlfn.XLOOKUP(X39,Pays!A:A,Pays!B:B)) -> GB | K39: =IF(COUNTIF(Pays!A:A,X39)=0,"Pays inconnu",_xlfn.XLOOKUP(X39,Pays!A:A,Pays!C:C)) -> 1_GB | L39: 1 | M39: =ROUND(MAX(P39:Q39),2) -> 0.15 | N39: avecsuivi | O39: =LOOKUP(X39,Pays!A:A,Pays!D:D) -> 0 | P39: 0.15 | Q39: 0.11 | U39: 1 | W39: =IF(COUNTIF(Pays!A:A,X39)=0,"",LOOKUP(X39,Pays!A:A,Pays!E:E)) -> 0 | X39: ROYAUME-UNI
A40: 01/06/2026 | B40: DELIVENGO-LPPQ | C40: =C39 -> 46174 | F40: Distribué | G40: LD248718555FR | H40: ALDERBASS SHOUQ H | I40: P | J40: =IF(COUNTIF(Pays!A:A,X40)=0,"Pays inconnu",_xlfn.XLOOKUP(X40,Pays!A:A,Pays!B:B)) -> GB | K40: =IF(COUNTIF(Pays!A:A,X40)=0,"Pays inconnu",_xlfn.XLOOKUP(X40,Pays!A:A,Pays!C:C)) -> 1_GB | L40: 1 | M40: =ROUND(MAX(P40:Q40),2) -> 0.25 | N40: avecsuivi | O40: =LOOKUP(X40,Pays!A:A,Pays!D:D) -> 0 | P40: 0.15 | Q40: 0.25 | U40: 1 | W40: =IF(COUNTIF(Pays!A:A,X40)=0,"",LOOKUP(X40,Pays!A:A,Pays!E:E)) -> 0 | X40: ROYAUME-UNI
A41: 01/06/2026 | B41: DELIVENGO-LPPQ | C41: =C40 -> 46174 | F41: Distribué | G41: LD248718900FR | H41: SETTELEN CHRISTINA | I41: P | J41: =IF(COUNTIF(Pays!A:A,X41)=0,"Pays inconnu",_xlfn.XLOOKUP(X41,Pays!A:A,Pays!B:B)) -> CH | K41: =IF(COUNTIF(Pays!A:A,X41)=0,"Pays inconnu",_xlfn.XLOOKUP(X41,Pays!A:A,Pays!C:C)) -> 1_CH | L41: 1 | M41: =ROUND(MAX(P41:Q41),2) -> 0.42 | N41: avecsuivi | O41: =LOOKUP(X41,Pays!A:A,Pays!D:D) -> 0 | P41: 0.15 | Q41: 0.42 | U41: 1 | W41: =IF(COUNTIF(Pays!A:A,X41)=0,"",LOOKUP(X41,Pays!A:A,Pays!E:E)) -> 0 | X41: SUISSE
A42: 01/06/2026 | B42: DELIVENGO-LPPQ | C42: =C41 -> 46174 | F42: Distribué | G42: LD248719953FR | H42: KARSENTI SOPHIE | I42: P | J42: =IF(COUNTIF(Pays!A:A,X42)=0,"Pays inconnu",_xlfn.XLOOKUP(X42,Pays!A:A,Pays!B:B)) -> ES | K42: =IF(COUNTIF(Pays!A:A,X42)=0,"Pays inconnu",_xlfn.XLOOKUP(X42,Pays!A:A,Pays!C:C)) -> 1 | L42: 1 | M42: =ROUND(MAX(P42:Q42),2) -> 0.15 | N42: avecsuivi | O42: =LOOKUP(X42,Pays!A:A,Pays!D:D) -> 0.2 | P42: 0.15 | U42: 1 | W42: =IF(COUNTIF(Pays!A:A,X42)=0,"",LOOKUP(X42,Pays!A:A,Pays!E:E)) -> 0 | X42: ESPAGNE
A43: 01/06/2026 | B43: DELIVENGO-LPPQ | C43: =C42 -> 46174 | F43: En cours | G43: LD248721081FR | H43: GRIFFITHS STEPHEN | I43: P | J43: =IF(COUNTIF(Pays!A:A,X43)=0,"Pays inconnu",_xlfn.XLOOKUP(X43,Pays!A:A,Pays!B:B)) -> GB | K43: =IF(COUNTIF(Pays!A:A,X43)=0,"Pays inconnu",_xlfn.XLOOKUP(X43,Pays!A:A,Pays!C:C)) -> 1_GB | L43: 1 | M43: =ROUND(MAX(P43:Q43),2) -> 0.5 | N43: avecsuivi | O43: =LOOKUP(X43,Pays!A:A,Pays!D:D) -> 0 | P43: 0.15 | Q43: 0.5 | U43: 1 | W43: =IF(COUNTIF(Pays!A:A,X43)=0,"",LOOKUP(X43,Pays!A:A,Pays!E:E)) -> 0 | X43: ROYAUME-UNI
A44: 01/06/2026 | B44: DELIVENGO-LPPQ | C44: =C43 -> 46174 | F44: Distribué | G44: LD248722609FR | H44: CHORNY JO | I44: P | J44: =IF(COUNTIF(Pays!A:A,X44)=0,"Pays inconnu",_xlfn.XLOOKUP(X44,Pays!A:A,Pays!B:B)) -> DE | K44: =IF(COUNTIF(Pays!A:A,X44)=0,"Pays inconnu",_xlfn.XLOOKUP(X44,Pays!A:A,Pays!C:C)) -> 1 | L44: 1 | M44: =ROUND(MAX(P44:Q44),2) -> 0.2 | N44: avecsuivi | O44: =LOOKUP(X44,Pays!A:A,Pays!D:D) -> 0.2 | P44: 0.15 | Q44: 0.2 | U44: 1 | W44: =IF(COUNTIF(Pays!A:A,X44)=0,"",LOOKUP(X44,Pays!A:A,Pays!E:E)) -> 0 | X44: ALLEMAGNE
A45: 01/06/2026 | B45: DELIVENGO-LPPQ | C45: =C44 -> 46174 | F45: Distribué | G45: LD248722921FR | H45: CALUORI DENNIS | I45: P | J45: =IF(COUNTIF(Pays!A:A,X45)=0,"Pays inconnu",_xlfn.XLOOKUP(X45,Pays!A:A,Pays!B:B)) -> CH | K45: =IF(COUNTIF(Pays!A:A,X45)=0,"Pays inconnu",_xlfn.XLOOKUP(X45,Pays!A:A,Pays!C:C)) -> 1_CH | L45: 1 | M45: =ROUND(MAX(P45:Q45),2) -> 0.48 | N45: avecsuivi | O45: =LOOKUP(X45,Pays!A:A,Pays!D:D) -> 0 | P45: 0.15 | Q45: 0.48 | U45: 1 | W45: =IF(COUNTIF(Pays!A:A,X45)=0,"",LOOKUP(X45,Pays!A:A,Pays!E:E)) -> 0 | X45: SUISSE
A46: 01/06/2026 | B46: DELIVENGO-LPPQ | C46: =C45 -> 46174 | F46: Distribué | G46: LD248723618FR | H46: MEISTER CATERINA | I46: P | J46: =IF(COUNTIF(Pays!A:A,X46)=0,"Pays inconnu",_xlfn.XLOOKUP(X46,Pays!A:A,Pays!B:B)) -> CH | K46: =IF(COUNTIF(Pays!A:A,X46)=0,"Pays inconnu",_xlfn.XLOOKUP(X46,Pays!A:A,Pays!C:C)) -> 1_CH | L46: 1 | M46: =ROUND(MAX(P46:Q46),2) -> 0.82 | N46: avecsuivi | O46: =LOOKUP(X46,Pays!A:A,Pays!D:D) -> 0 | P46: 0.15 | Q46: 0.82 | U46: 1 | W46: =IF(COUNTIF(Pays!A:A,X46)=0,"",LOOKUP(X46,Pays!A:A,Pays!E:E)) -> 0 | X46: SUISSE
A47: 01/06/2026 | B47: DELIVENGO-LPPQ | C47: =C46 -> 46174 | F47: Distribué | G47: LD248723666FR | H47: SCHUHLE IRIS | I47: P | J47: =IF(COUNTIF(Pays!A:A,X47)=0,"Pays inconnu",_xlfn.XLOOKUP(X47,Pays!A:A,Pays!B:B)) -> CH | K47: =IF(COUNTIF(Pays!A:A,X47)=0,"Pays inconnu",_xlfn.XLOOKUP(X47,Pays!A:A,Pays!C:C)) -> 1_CH | L47: 1 | M47: =ROUND(MAX(P47:Q47),2) -> 0.23 | N47: avecsuivi | O47: =LOOKUP(X47,Pays!A:A,Pays!D:D) -> 0 | P47: 0.15 | Q47: 0.23 | U47: 1 | W47: =IF(COUNTIF(Pays!A:A,X47)=0,"",LOOKUP(X47,Pays!A:A,Pays!E:E)) -> 0 | X47: SUISSE
A48: 01/06/2026 | B48: DELIVENGO-LPPQ | C48: =C47 -> 46174 | F48: Distribué | G48: LD248724689FR | H48: RAUCH KARIN | I48: P | J48: =IF(COUNTIF(Pays!A:A,X48)=0,"Pays inconnu",_xlfn.XLOOKUP(X48,Pays!A:A,Pays!B:B)) -> CH | K48: =IF(COUNTIF(Pays!A:A,X48)=0,"Pays inconnu",_xlfn.XLOOKUP(X48,Pays!A:A,Pays!C:C)) -> 1_CH | L48: 1 | M48: =ROUND(MAX(P48:Q48),2) -> 0.2 | N48: avecsuivi | O48: =LOOKUP(X48,Pays!A:A,Pays!D:D) -> 0 | P48: 0.15 | Q48: 0.2 | U48: 1 | W48: =IF(COUNTIF(Pays!A:A,X48)=0,"",LOOKUP(X48,Pays!A:A,Pays!E:E)) -> 0 | X48: SUISSE
A49: 01/06/2026 | B49: DELIVENGO-LPPQ | C49: =C48 -> 46174 | F49: Distribué | G49: LD248725066FR | H49: CHEN KUO KAI IN | I49: P | J49: =IF(COUNTIF(Pays!A:A,X49)=0,"Pays inconnu",_xlfn.XLOOKUP(X49,Pays!A:A,Pays!B:B)) -> GB | K49: =IF(COUNTIF(Pays!A:A,X49)=0,"Pays inconnu",_xlfn.XLOOKUP(X49,Pays!A:A,Pays!C:C)) -> 1_GB | L49: 1 | M49: =ROUND(MAX(P49:Q49),2) -> 0.15 | N49: avecsuivi | O49: =LOOKUP(X49,Pays!A:A,Pays!D:D) -> 0 | P49: 0.15 | Q49: 0.11 | U49: 1 | W49: =IF(COUNTIF(Pays!A:A,X49)=0,"",LOOKUP(X49,Pays!A:A,Pays!E:E)) -> 0 | X49: ROYAUME-UNI
A50: 01/06/2026 | B50: DELIVENGO-LPPQ | C50: =C49 -> 46174 | F50: Distribué | G50: LD248725636FR | H50: DABERER CORINA | I50: P | J50: =IF(COUNTIF(Pays!A:A,X50)=0,"Pays inconnu",_xlfn.XLOOKUP(X50,Pays!A:A,Pays!B:B)) -> AT | K50: =IF(COUNTIF(Pays!A:A,X50)=0,"Pays inconnu",_xlfn.XLOOKUP(X50,Pays!A:A,Pays!C:C)) -> 1 | L50: 1 | M50: =ROUND(MAX(P50:Q50),2) -> 1.16 | N50: avecsuivi | O50: =LOOKUP(X50,Pays!A:A,Pays!D:D) -> 0.2 | P50: 0.15 | Q50: 1.16 | U50: 1 | W50: =IF(COUNTIF(Pays!A:A,X50)=0,"",LOOKUP(X50,Pays!A:A,Pays!E:E)) -> 0 | X50: AUTRICHE
A51: 01/06/2026 | B51: DELIVENGO-LPPQ | C51: =C50 -> 46174 | F51: Distribué | G51: LD248726469FR | H51: PORTENIER POLYA | I51: P | J51: =IF(COUNTIF(Pays!A:A,X51)=0,"Pays inconnu",_xlfn.XLOOKUP(X51,Pays!A:A,Pays!B:B)) -> CH | K51: =IF(COUNTIF(Pays!A:A,X51)=0,"Pays inconnu",_xlfn.XLOOKUP(X51,Pays!A:A,Pays!C:C)) -> 1_CH | L51: 1 | M51: =ROUND(MAX(P51:Q51),2) -> 0.27 | N51: avecsuivi | O51: =LOOKUP(X51,Pays!A:A,Pays!D:D) -> 0 | P51: 0.15 | Q51: 0.27 | U51: 1 | W51: =IF(COUNTIF(Pays!A:A,X51)=0,"",LOOKUP(X51,Pays!A:A,Pays!E:E)) -> 0 | X51: SUISSE
...
