Workbook

Sheet Bareme gazole
A1: De | B1: A | C1: Messagerie
A2: 0.7 | B2: 0.74 | C2: 0.008
A3: 0.75 | B3: 0.79 | C3: 0.0115
A4: 0.8 | B4: 0.84 | C4: 0.016
A5: 0.85 | B5: 0.89 | C5: 0.02
A6: 0.9 | B6: 0.94 | C6: 0.0245
A7: 0.95 | B7: 0.99 | C7: 0.0295
A8: 1 | B8: 1.04 | C8: 0.0355
A9: 1.05 | B9: 1.09 | C9: 0.04
A10: 1.1 | B10: 1.14 | C10: 0.0445
A11: 1.15 | B11: 1.19 | C11: 0.056
A12: 1.2 | B12: 1.24 | C12: 0.0615
A13: 1.25 | B13: 1.29 | C13: 0.069
... A40: 2.6 | B40: 2.64 | C40: 0.1695

Sheet Fichier Kuehne
A1: ID Client | B1: Tracking | C1: Total hors GO | D1: Total + GO | E1: Droits et taxes | F1: Assurance | G1: Zones éloignées | H1: Colis volumineux | I1: Adresses | J1: Frêt | K1: Plus value B2C | L1: Gazole | M1: No facture | N1: Date facture | O1: Payeur | P1: Ref pay | Q1: Année | R1: Expedition | S1: Ref EDI | T1: ComRefExpedition | U1: Incoterm | V1: Sens | W1: Perimetre | X1: Zip Code | Y1: Métier | Z1: Origine expédition | AA1: Km | AB1: EmissionCO2 | AC1: Date sais/Chg | AD1: Agence Saisie/Chgt | AE1: Expéditeur | AF1: Ref exp | AG1: Pays exp | AH1: Dept exp | AI1: Commune exp | AJ1: Date livraison | AK1: Destinataire | AL1: Ref dest | AM1: Pays dest | AN1: Dept dest | AO1: Commune dest | AP1: Type dest | AQ1: Contraintes livr dest | AR1: Nb colis | AS1: Nb UM | AT1: Poids | AU1: Poids taxable | AV1: Volume | AW1: Unité Taxe | AX1: Nb unité taxe | AY1: Mètres linéaires | AZ1: MD | BA1: MD(QT) | BB1: MD(QL) | BC1: MD(QE) | BD1: MD(BL) | BE1: Mode Port | BF1: Produit | BG1: Devise | BH1: Nb PAL EUR | BI1: Mt ASSIGNE | BJ1: Mt CR | BK1: Mt VD | BL1: Exonération TVA | BM1: Mt HT (hors frais) | BN1: Mt HT (avec frais) | BO1: PLTFM_LOGISTIQUE | BP1: NdS_Enlevement | BQ1: NdS_Livraison | BR1: Code_Gde_Longueur | BS1: Préavis_Téléphone | BT1: Préavis_SMS-Mail | BU1: Is_Douane | BV1: Is_Douane_Export_ST | BW1: Is_Douane_Import_ST | BX1: T_ADMC | BY1: T_ADMIN_ARRIVEE | BZ1: T_ADMIN_DEPART | CA1: T_ADMIN_FOURNISSEUR | CB1: T_ADM | CC1: T_APPROCHE_ENLEVEMENT | CD1: T_APPROCHE_LIVRAISON | CE1: T_ASSIGNE | CF1: T_CDE_MANU | CG1: T_CONTRE_REMBOUR | CH1: T_DOUANE_ANDORRE | CI1: T_DOUANE_CANARIES | CJ1: T_DOUANE_EXPORT | CK1: T_DOUANE_IMPORT | CL1: T_FRAIS_DOSSIER | CM1: T_FRET_SENSIBLE | CN1: T_GENERIQUE | CO1: T_HAYON | CP1: T_ILE | CQ1: T_MD_QL | CR1: T_MD_QT | CS1: T_PALETTE_EUR | CT1: T_PAQ_ARRIVEE | CU1: T_PAQC | CV1: T_PAQ_DEPART | CW1: T_PAQ_HUB_ENTREE | CX1: T_PAQ_HUB_SORTIE | CY1: T_PAQ | CZ1: T_PAQ_PORTE_ENTREE | DA1: T_PAQ_PORTE_SORTIE | DB1: T_PAQ_TRANSIT | DC1: T_PORTDU_APPRO | DD1: T_PORTEUR | DE1: T_PORTE_ENTREE | DF1: T_PORTE_SORTIE | DG1: T_PORT_PAYE | DH1: T_PRS | DI1: T_SAISO | DJ1: T_SAISO_2013 | DK1: T_SECU | DL1: T_SURCOUT_LIV_EXPRESS | DM1: T_LIV_SUPERMARCHE | DN1: T_LIV_URBAINE | DO1: T_T0 | DP1: T_T1 | DQ1: T_T2 | DR1: T_T3 | DS1: T_T4 | DT1: T_T5 | DU1: T_VALEUR_DECLARE | DV1: T_VD_VD | DW1: T_CORR_POIDS | DX1: T_EMBALLAGE | DY1: T_ENLEVEMENT_VIDE | DZ1: T_GESTION_PARTICULIER | EA1: T_LIV_ETAGE | EB1: T_LIV_HORS_CRENEAU | EC1: T_MD_APPROCHE_QL | ED1: T_MD_APPROCHE_QT | EE1: T_LIV_AEROPORT | EF1: T_LIV_PORTUAIRE | EG1: T_SOUFFRANCE | EH1: T_ANNULATION | EI1: T_ATTENTE_CHRGT | EJ1: T_ATTENTE_DECHRGT | EK1: T_CROSS_DOCK | EL1: T_EKAER | EM1: T_IMMO_CHRGT | EN1: T_IMMO_DECHRGT | EO1: T_MAUT | EP1: T_STOP | EQ1: T_GAZOLE | ER1: T_PDT_FIRST | ES1: T_PDT_FIX | ET1: T_AUTOROUTE | EU1: T_CONTROLE_TEMP | EV1: T_DOUBLE_DECK | EW1: T_ESCORTE | EX1: T_FERRY | EY1: T_GENERATRICE | EZ1: T_MANUTENTION | FA1: T_KM_SUPPL | FB1: T_BELGE | FC1: T_FRAIS_TUNNEL | FD1: T_GEST_EMBAL | FE1: T_LIV_WEST | FF1: T_ENTREE | FG1: T_SORTIE | FH1: T_GRUE | FI1: T_INSTAL | FJ1: T_ASSUR | FK1: T_GEST_STOCK | FL1: T_IMMO_JOURF | FM1: T_PARK_SEC | FN1: T_IMP_TICKET | FO1: T_DOUANE_INSPECT | FP1: T_DOUB_CHAUF | FQ1: T_ANNUL_PARTIEL | FR1: T_PACKLIST | FS1: T_ATTENTE_DOUANE | FT1: T_IMMO_DOUANE | FU1: T_LIV_PLTFM_LOGISTIQUE | FV1: T_01_RDV | FW1: T_02_AVIS_TEL | FX1: T_501_LG_LIGHT | FY1: T_502_AVIS_SMS | FZ1: T_503_LIV_PM | GA1: T_504_LIV_SOIR | GB1: T_505_LIV_FIXE | GC1: T_511_AVT_10 | GD1: T_512_AVT_12 | GE1: T_70_ENLEV_RDV | GF1: T_755_RDV_4H | GG1: T_88_LG_HEAVY | GH1: T_EVT_EXCEP | GI1: T_UIT | GJ1: T_BAT_LIT | GK1: T_CHR_AVT_11 | GL1: T_ENS | GM1: T_ENERGIE
B2: =IF(S2<>"",S2,T2) -> 5001334 | C2: =SUM(E2:K2) -> 29.38 | D2: =SUM(E2:L2) -> 29.38 | E2: =IF(BU2+BV2+BW2+CH2+CI2+CJ2+CK2+FO2+FS2+FT2=0,"",BU2+BV2+BW2+CH2+CI2+CJ2+CK2+FO2+FS2+FT2) | F2: =IF(FJ2=0,"",FJ2) | G2: =IF(CP2+DM2+DN2+EE2+EX2+EF2=0,"",CP2+DM2+DN2+EE2+EX2+EF2) | H2: =IF(DW2=0,"",DW2) | I2: =IF(DZ2+EA2+EG2=0,"",DZ2+EA2+EG2) | J2: =IF(BM2+BS2+BT2+BY2+BZ2+CA2+CB2+CC2+CD2+CE2+CF2+CG2+CL2+CM2+CN2+CO2+CQ2+CR2+CT2+CU2+CV2+CW2+CX2+CY2+CZ2+DA2+DB2+DC2+DD2+DE2+DF2+DG2+DH2+DI2+DJ2+DK2+DL2+DO2+DP2+DQ2+DR2+DS2+DT2+DY2+EB2+EC2+ED2+EH2+EI2+EJ2+EK2+EL2+EM2+EN2+EO2+EP2+ER2+ES2+ET2+EU2+EV2+EW2+EY2+EZ2+FA2+FB2+FC2+FD2+FE2+FF2+FG2+FH2+FI2+FK2+FL2+FM2+FN2+FP2+FQ2+FR2+FU2+FV2+FW2+FX2+FY2+FZ2+GA2+GB2+GC2+GD2+GE2+GF2+GG2+GH2+GI2+GJ2+GK2+GL2+GM2=0,"",BM2+BS2+BT2+BY2+BZ2+CA2+CB2+CC2+CD2+CE2+CF2+CG2+CL2+CM2+CN2+CO2+CQ2+CR2+CT2+CU2+CV2+CW2+CX2+CY2+CZ2+DA2+DB2+DC2+DD2+DE2+DF2+DG2+DH2+DI2+DJ2+DK2+DL2+DO2+DP2+DQ2+DR2+DS2+DT2+DY2+EB2+EC2+ED2+EH2+EI2+EJ2+EK2+EL2+EM2+EN2+EO2+EP2+ER2+ES2+ET2+EU2+EV2+EW2+EY2+EZ2+FA2+FB2+FC2+FD2+FE2+FF2+FG2+FH2+FI2+FK2+FL2+FM2+FN2+FP2+FQ2+FR2+FU2+FV2+FW2+FX2+FY2+FZ2+GA2+GB2+GC2+GD2+GE2+GF2+GG2+GH2+GI2+GJ2+GK2+GL2+GM2) -> 29.38 | K2: =DX2+CS2 -> 0 | L2: =BN2-C2 -> 0 | M2: F2606017122 | N2: 46203 | O2: 9505289-C01 | P2: 5001334 | Q2: 2026 | R2: 26-05-0838077 | S2: 5001334 | T2: 26A050838077 | U2: DAP | V2: DOMESTIC | W2: DOMESTIC | X2: 34570 | Y2: MESS | Z2: EDI | AA2: 560 | AC2: 46171 | AD2: 21 | AE2: LA RUCHE LOGISTIQUE | AF2: 5001334 | AG2: FR | AH2: 21 | AI2: CREANCEY | AJ2: 46178 | AK2: HASARD Françoise (ENTREPRISE) | AL2: 5001334 | AM2: FR | AN2: 34 | AO2: MURVIEL LES MONTPELLIER | AR2: 1 | AS2: 1 | AT2: 1 | AU2: 5 | AV2: 0.02 | AW2: KG | AX2: 1 | AY2: 0 | BE2: PORTPAYE | BF2: STANDARD | BG2: EUR | BM2: 21.78 | BN2: 29.38 | BQ2: LSTANDARD | DI2: 5.45 | DK2: 2 | GM2: 0.15
B3: =IF(S3<>"",S3,T3) -> 5001333 | C3: =SUM(E3:K3) -> 25.14 | D3: =SUM(E3:L3) -> 25.14 | E3: =IF(BU3+BV3+BW3+CH3+CI3+CJ3+CK3+FO3+FS3+FT3=0,"",BU3+BV3+BW3+CH3+CI3+CJ3+CK3+FO3+FS3+FT3) | F3: =IF(FJ3=0,"",FJ3) | G3: =IF(CP3+DM3+DN3+EE3+EX3+EF3=0,"",CP3+DM3+DN3+EE3+EX3+EF3) | H3: =IF(DW3=0,"",DW3) | I3: =IF(DZ3+EA3+EG3=0,"",DZ3+EA3+EG3) | J3: =IF(BM3+BS3+BT3+BY3+BZ3+CA3+CB3+CC3+CD3+CE3+CF3+CG3+CL3+CM3+CN3+CO3+CQ3+CR3+CT3+CU3+CV3+CW3+CX3+CY3+CZ3+DA3+DB3+DC3+DD3+DE3+DF3+DG3+DH3+DI3+DJ3+DK3+DL3+DO3+DP3+DQ3+DR3+DS3+DT3+DY3+EB3+EC3+ED3+EH3+EI3+EJ3+EK3+EL3+EM3+EN3+EO3+EP3+ER3+ES3+ET3+EU3+EV3+EW3+EY3+EZ3+FA3+FB3+FC3+FD3+FE3+FF3+FG3+FH3+FI3+FK3+FL3+FM3+FN3+FP3+FQ3+FR3+FU3+FV3+FW3+FX3+FY3+FZ3+GA3+GB3+GC3+GD3+GE3+GF3+GG3+GH3+GI3+GJ3+GK3+GL3+GM3=0,"",BM3+BS3+BT3+BY3+BZ3+CA3+CB3+CC3+CD3+CE3+CF3+CG3+CL3+CM3+CN3+CO3+CQ3+CR3+CT3+CU3+CV3+CW3+CX3+CY3+CZ3+DA3+DB3+DC3+DD3+DE3+DF3+DG3+DH3+DI3+DJ3+DK3+DL3+DO3+DP3+DQ3+DR3+DS3+DT3+DY3+EB3+EC3+ED3+EH3+EI3+EJ3+EK3+EL3+EM3+EN3+EO3+EP3+ER3+ES3+ET3+EU3+EV3+EW3+EY3+EZ3+FA3+FB3+FC3+FD3+FE3+FF3+FG3+FH3+FI3+FK3+FL3+FM3+FN3+FP3+FQ3+FR3+FU3+FV3+FW3+FX3+FY3+FZ3+GA3+GB3+GC3+GD3+GE3+GF3+GG3+GH3+GI3+GJ3+GK3+GL3+GM3) -> 25.14 | K3: =DX3+CS3 -> 0 | L3: =BN3-C3 -> 0 | M3: F2606017122 | N3: 46203 | O3: 9505289-C01 | P3: 5001333 | Q3: 2026 | R3: 26-05-0838106 | S3: 5001333 | T3: 26A050838106 | U3: DAP | V3: DOMESTIC | W3: DOMESTIC | X3: 78140 | Y3: MESS | Z3: EDI | AA3: 467 | AC3: 46171 | AD3: 21 | AE3: LA RUCHE LOGISTIQUE | AF3: 5001333 | AG3: FR | AH3: 21 | AI3: CREANCEY | AJ3: 46177 | AK3: LACHAUX Guillaume (ENTREPRISE) | AL3: 5001333 | AM3: FR | AN3: 78 | AO3: VELIZY VILLACOUBLAY | AR3: 1 | AS3: 1 | AT3: 6 | AU3: 13 | AV3: 0.05 | AW3: KG | AX3: 6 | AY3: 0 | BE3: PORTPAYE | BF3: STANDARD | BG3: EUR | BM3: 22.99 | BN3: 25.14 | BQ3: LSTANDARD | DK3: 2 | GM3: 0.15
B4: =IF(S4<>"",S4,T4) -> 26A060014947 | C4: =SUM(E4:K4) -> 300 | D4: =SUM(E4:L4) -> 300 | E4: =IF(BU4+BV4+BW4+CH4+CI4+CJ4+CK4+FO4+FS4+FT4=0,"",BU4+BV4+BW4+CH4+CI4+CJ4+CK4+FO4+FS4+FT4) | F4: =IF(FJ4=0,"",FJ4) | G4: =IF(CP4+DM4+DN4+EE4+EX4+EF4=0,"",CP4+DM4+DN4+EE4+EX4+EF4) | H4: =IF(DW4=0,"",DW4) | I4: =IF(DZ4+EA4+EG4=0,"",DZ4+EA4+EG4) | J4: =IF(BM4+BS4+BT4+BY4+BZ4+CA4+CB4+CC4+CD4+CE4+CF4+CG4+CL4+CM4+CN4+CO4+CQ4+CR4+CT4+CU4+CV4+CW4+CX4+CY4+CZ4+DA4+DB4+DC4+DD4+DE4+DF4+DG4+DH4+DI4+DJ4+DK4+DL4+DO4+DP4+DQ4+DR4+DS4+DT4+DY4+EB4+EC4+ED4+EH4+EI4+EJ4+EK4+EL4+EM4+EN4+EO4+EP4+ER4+ES4+ET4+EU4+EV4+EW4+EY4+EZ4+FA4+FB4+FC4+FD4+FE4+FF4+FG4+FH4+FI4+FK4+FL4+FM4+FN4+FP4+FQ4+FR4+FU4+FV4+FW4+FX4+FY4+FZ4+GA4+GB4+GC4+GD4+GE4+GF4+GG4+GH4+GI4+GJ4+GK4+GL4+GM4=0,"",BM4+BS4+BT4+BY4+BZ4+CA4+CB4+CC4+CD4+CE4+CF4+CG4+CL4+CM4+CN4+CO4+CQ4+CR4+CT4+CU4+CV4+CW4+CX4+CY4+CZ4+DA4+DB4+DC4+DD4+DE4+DF4+DG4+DH4+DI4+DJ4+DK4+DL4+DO4+DP4+DQ4+DR4+DS4+DT4+DY4+EB4+EC4+ED4+EH4+EI4+EJ4+EK4+EL4+EM4+EN4+EO4+EP4+ER4+ES4+ET4+EU4+EV4+EW4+EY4+EZ4+FA4+FB4+FC4+FD4+FE4+FF4+FG4+FH4+FI4+FK4+FL4+FM4+FN4+FP4+FQ4+FR4+FU4+FV4+FW4+FX4+FY4+FZ4+GA4+GB4+GC4+GD4+GE4+GF4+GG4+GH4+GI4+GJ4+GK4+GL4+GM4) -> 300 | K4: =DX4+CS4 -> 0 | L4: =BN4-C4 -> 0 | M4: F2606017122 | N4: 46203 | O4: 9505289-C01 | Q4: 2026 | R4: 26-06-0014947 | T4: 26A060014947 | U4: EXW | V4: DOMESTIC | W4: DOMESTIC | X4: 21320 | Y4: AFFR | AA4: 60 | AC4: 46176 | AD4: 21 | AE4: STG | AG4: FR | AH4: 21 | AI4: LONGVIC | AJ4: 46177 | AK4: LA RUCHE LOGISTIQUE | AM4: FR | AN4: 21 | AO4: CREANCEY | AR4: 33 | AS4: 33 | AT4: 25000 | AU4: 0 | AV4: 0 | AW4: Pal | AX4: 33 | AY4: 13.4 | BE4: APPRO | BF4: AFFRET | BG4: EUR | BM4: 300 | BN4: 300
B5: =IF(S5<>"",S5,T5) -> 5001336 | C5: =SUM(E5:K5) -> 32.9 | D5: =SUM(E5:L5) -> 32.9 | E5: =IF(BU5+BV5+BW5+CH5+CI5+CJ5+CK5+FO5+FS5+FT5=0,"",BU5+BV5+BW5+CH5+CI5+CJ5+CK5+FO5+FS5+FT5) | F5: =IF(FJ5=0,"",FJ5) | G5: =IF(CP5+DM5+DN5+EE5+EX5+EF5=0,"",CP5+DM5+DN5+EE5+EX5+EF5) | H5: =IF(DW5=0,"",DW5) | I5: =IF(DZ5+EA5+EG5=0,"",DZ5+EA5+EG5) | J5: =IF(BM5+BS5+BT5+BY5+BZ5+CA5+CB5+CC5+CD5+CE5+CF5+CG5+CL5+CM5+CN5+CO5+CQ5+CR5+CT5+CU5+CV5+CW5+CX5+CY5+CZ5+DA5+DB5+DC5+DD5+DE5+DF5+DG5+DH5+DI5+DJ5+DK5+DL5+DO5+DP5+DQ5+DR5+DS5+DT5+DY5+EB5+EC5+ED5+EH5+EI5+EJ5+EK5+EL5+EM5+EN5+EO5+EP5+ER5+ES5+ET5+EU5+EV5+EW5+EY5+EZ5+FA5+FB5+FC5+FD5+FE5+FF5+FG5+FH5+FI5+FK5+FL5+FM5+FN5+FP5+FQ5+FR5+FU5+FV5+FW5+FX5+FY5+FZ5+GA5+GB5+GC5+GD5+GE5+GF5+GG5+GH5+GI5+GJ5+GK5+GL5+GM5=0,"",BM5+BS5+BT5+BY5+BZ5+CA5+CB5+CC5+CD5+CE5+CF5+CG5+CL5+CM5+CN5+CO5+CQ5+CR5+CT5+CU5+CV5+CW5+CX5+CY5+CZ5+DA5+DB5+DC5+DD5+DE5+DF5+DG5+DH5+DI5+DJ5+DK5+DL5+DO5+DP5+DQ5+DR5+DS5+DT5+DY5+EB5+EC5+ED5+EH5+EI5+EJ5+EK5+EL5+EM5+EN5+EO5+EP5+ER5+ES5+ET5+EU5+EV5+EW5+EY5+EZ5+FA5+FB5+FC5+FD5+FE5+FF5+FG5+FH5+FI5+FK5+FL5+FM5+FN5+FP5+FQ5+FR5+FU5+FV5+FW5+FX5+FY5+FZ5+GA5+GB5+GC5+GD5+GE5+GF5+GG5+GH5+GI5+GJ5+GK5+GL5+GM5) -> 32.9 | K5: =DX5+CS5 -> 0 | L5: =BN5-C5 -> 0 | M5: F2606017122 | N5: 46203 | O5: 9505289-C01 | P5: 5001336 | Q5: 2026 | R5: 26-06-0049541 | S5: 5001336 | T5: 26A060049541 | U5: DAP | V5: DOMESTIC | W5: DOMESTIC | X5: 30800 | Y5: MESS | Z5: EDI | AA5: 540 | AC5: 46174 | AD5: 21 | AE5: LA RUCHE LOGISTIQUE | AF5: 5001336 | AG5: FR | AH5: 21 | AI5: CREANCEY | AJ5: 46183 | AK5: Gregory TUDELA (ENTREPRISE) | AL5: 5001336 | AM5: FR | AN5: 30 | AO5: ST GILLES | AR5: 1 | AS5: 1 | AT5: 10 | AU5: 40 | AV5: 0.16 | AW5: KG | AX5: 10 | AY5: 0 | BE5: PORTPAYE | BF5: STANDARD | BG5: EUR | BM5: 24.6 | BN5: 32.9 | BQ5: LSTANDARD | DI5: 6.15 | DK5: 2 | GM5: 0.15
B6: =IF(S6<>"",S6,T6) -> EXP20260529-2770114 | C6: =SUM(E6:K6) -> 76.66 | D6: =SUM(E6:L6) -> 76.66 | E6: =IF(BU6+BV6+BW6+CH6+CI6+CJ6+CK6+FO6+FS6+FT6=0,"",BU6+BV6+BW6+CH6+CI6+CJ6+CK6+FO6+FS6+FT6) | F6: =IF(FJ6=0,"",FJ6) | G6: =IF(CP6+DM6+DN6+EE6+EX6+EF6=0,"",CP6+DM6+DN6+EE6+EX6+EF6) | H6: =IF(DW6=0,"",DW6) | I6: =IF(DZ6+EA6+EG6=0,"",DZ6+EA6+EG6) | J6: =IF(BM6+BS6+BT6+BY6+BZ6+CA6+CB6+CC6+CD6+CE6+CF6+CG6+CL6+CM6+CN6+CO6+CQ6+CR6+CT6+CU6+CV6+CW6+CX6+CY6+CZ6+DA6+DB6+DC6+DD6+DE6+DF6+DG6+DH6+DI6+DJ6+DK6+DL6+DO6+DP6+DQ6+DR6+DS6+DT6+DY6+EB6+EC6+ED6+EH6+EI6+EJ6+EK6+EL6+EM6+EN6+EO6+EP6+ER6+ES6+ET6+EU6+EV6+EW6+EY6+EZ6+FA6+FB6+FC6+FD6+FE6+FF6+FG6+FH6+FI6+FK6+FL6+FM6+FN6+FP6+FQ6+FR6+FU6+FV6+FW6+FX6+FY6+FZ6+GA6+GB6+GC6+GD6+GE6+GF6+GG6+GH6+GI6+GJ6+GK6+GL6+GM6=0,"",BM6+BS6+BT6+BY6+BZ6+CA6+CB6+CC6+CD6+CE6+CF6+CG6+CL6+CM6+CN6+CO6+CQ6+CR6+CT6+CU6+CV6+CW6+CX6+CY6+CZ6+DA6+DB6+DC6+DD6+DE6+DF6+DG6+DH6+DI6+DJ6+DK6+DL6+DO6+DP6+DQ6+DR6+DS6+DT6+DY6+EB6+EC6+ED6+EH6+EI6+EJ6+EK6+EL6+EM6+EN6+EO6+EP6+ER6+ES6+ET6+EU6+EV6+EW6+EY6+EZ6+FA6+FB6+FC6+FD6+FE6+FF6+FG6+FH6+FI6+FK6+FL6+FM6+FN6+FP6+FQ6+FR6+FU6+FV6+FW6+FX6+FY6+FZ6+GA6+GB6+GC6+GD6+GE6+GF6+GG6+GH6+GI6+GJ6+GK6+GL6+GM6) -> 76.66 | K6: =DX6+CS6 -> 0 | L6: =BN6-C6 -> 0 | M6: F2606017122 | N6: 46203 | O6: 9505289-C01 | P6: EXP20260529-2770114 | Q6: 2026 | R6: 26-06-0049547 | S6: EXP20260529-2770114 | T6: 26A060049547 | U6: DAP | V6: DOMESTIC | W6: DOMESTIC | X6: 83920 | Y6: MESS | Z6: EDI | AA6: 599 | AC6: 46174 | AD6: 21 | AE6: LA RUCHE LOGISTIQUE | AF6: EXP20260529-2770114 | AG6: FR | AH6: 21 | AI6: CREANCEY | AJ6: 46176 | AK6: GAEC Terres d'Esclans RAYMOND Fabri (ENTREPRISE) | AL6: EXP20260529-2770114 | AM6: FR | AN6: 83 | AO6: LA MOTTE | AR6: 1 | AS6: 1 | AT6: 134 | AU6: 134 | AV6: 0 | AW6: KG | AX6: 134 | AY6: 0 | BE6: PORTPAYE | BF6: STANDARD | BG6: EUR | BM6: 59.61 | BN6: 76.66 | BQ6: LSTANDARD | DI6: 14.9 | DK6: 2 | GM6: 0.15
B7: =IF(S7<>"",S7,T7) -> EXP20260601-2772380 | C7: =SUM(E7:K7) -> 33.85 | D7: =SUM(E7:L7) -> 33.85 | E7: =IF(BU7+BV7+BW7+CH7+CI7+CJ7+CK7+FO7+FS7+FT7=0,"",BU7+BV7+BW7+CH7+CI7+CJ7+CK7+FO7+FS7+FT7) | F7: =IF(FJ7=0,"",FJ7) | G7: =IF(CP7+DM7+DN7+EE7+EX7+EF7=0,"",CP7+DM7+DN7+EE7+EX7+EF7) | H7: =IF(DW7=0,"",DW7) | I7: =IF(DZ7+EA7+EG7=0,"",DZ7+EA7+EG7) | J7: =IF(BM7+BS7+BT7+BY7+BZ7+CA7+CB7+CC7+CD7+CE7+CF7+CG7+CL7+CM7+CN7+CO7+CQ7+CR7+CT7+CU7+CV7+CW7+CX7+CY7+CZ7+DA7+DB7+DC7+DD7+DE7+DF7+DG7+DH7+DI7+DJ7+DK7+DL7+DO7+DP7+DQ7+DR7+DS7+DT7+DY7+EB7+EC7+ED7+EH7+EI7+EJ7+EK7+EL7+EM7+EN7+EO7+EP7+ER7+ES7+ET7+EU7+EV7+EW7+EY7+EZ7+FA7+FB7+FC7+FD7+FE7+FF7+FG7+FH7+FI7+FK7+FL7+FM7+FN7+FP7+FQ7+FR7+FU7+FV7+FW7+FX7+FY7+FZ7+GA7+GB7+GC7+GD7+GE7+GF7+GG7+GH7+GI7+GJ7+GK7+GL7+GM7=0,"",BM7+BS7+BT7+BY7+BZ7+CA7+CB7+CC7+CD7+CE7+CF7+CG7+CL7+CM7+CN7+CO7+CQ7+CR7+CT7+CU7+CV7+CW7+CX7+CY7+CZ7+DA7+DB7+DC7+DD7+DE7+DF7+DG7+DH7+DI7+DJ7+DK7+DL7+DO7+DP7+DQ7+DR7+DS7+DT7+DY7+EB7+EC7+ED7+EH7+EI7+EJ7+EK7+EL7+EM7+EN7+EO7+EP7+ER7+ES7+ET7+EU7+EV7+EW7+EY7+EZ7+FA7+FB7+FC7+FD7+FE7+FF7+FG7+FH7+FI7+FK7+FL7+FM7+FN7+FP7+FQ7+FR7+FU7+FV7+FW7+FX7+FY7+FZ7+GA7+GB7+GC7+GD7+GE7+GF7+GG7+GH7+GI7+GJ7+GK7+GL7+GM7) -> 33.85 | K7: =DX7+CS7 -> 0 | L7: =BN7-C7 -> 0 | M7: F2606017122 | N7: 46203 | O7: 9505289-C01 | P7: EXP20260601-2772380 | Q7: 2026 | R7: 26-06-0049550 | S7: EXP20260601-2772380 | T7: 26A060049550 | U7: DAP | V7: DOMESTIC | W7: DOMESTIC | X7: 34290 | Y7: MESS | Z7: EDI | AA7: 695 | AC7: 46174 | AD7: 21 | AE7: LA RUCHE LOGISTIQUE | AF7: EXP20260601-2772380 | AG7: FR | AH7: 21 | AI7: CREANCEY | AJ7: 46176 | AK7: GAEC LAROSE LAROSE JOEL (ENTREPRISE) | AL7: EXP20260601-2772380 | AM7: FR | AN7: 34 | AO7: ALIGNAN DU VENT | AR7: 1 | AS7: 1 | AT7: 13 | AU7: 13 | AV7: 0 | AW7: KG | AX7: 13 | AY7: 0 | BE7: PORTPAYE | BF7: STANDARD | BG7: EUR | BM7: 25.36 | BN7: 33.85 | BQ7: LSTANDARD | DI7: 6.34 | DK7: 2 | GM7: 0.15
B8: =IF(S8<>"",S8,T8) -> EXP20260601-2772379 | C8: =SUM(E8:K8) -> 55.86 | D8: =SUM(E8:L8) -> 55.86 | E8: =IF(BU8+BV8+BW8+CH8+CI8+CJ8+CK8+FO8+FS8+FT8=0,"",BU8+BV8+BW8+CH8+CI8+CJ8+CK8+FO8+FS8+FT8) | F8: =IF(FJ8=0,"",FJ8) | G8: =IF(CP8+DM8+DN8+EE8+EX8+EF8=0,"",CP8+DM8+DN8+EE8+EX8+EF8) | H8: =IF(DW8=0,"",DW8) | I8: =IF(DZ8+EA8+EG8=0,"",DZ8+EA8+EG8) | J8: =IF(BM8+BS8+BT8+BY8+BZ8+CA8+CB8+CC8+CD8+CE8+CF8+CG8+CL8+CM8+CN8+CO8+CQ8+CR8+CT8+CU8+CV8+CW8+CX8+CY8+CZ8+DA8+DB8+DC8+DD8+DE8+DF8+DG8+DH8+DI8+DJ8+DK8+DL8+DO8+DP8+DQ8+DR8+DS8+DT8+DY8+EB8+EC8+ED8+EH8+EI8+EJ8+EK8+EL8+EM8+EN8+EO8+EP8+ER8+ES8+ET8+EU8+EV8+EW8+EY8+EZ8+FA8+FB8+FC8+FD8+FE8+FF8+FG8+FH8+FI8+FK8+FL8+FM8+FN8+FP8+FQ8+FR8+FU8+FV8+FW8+FX8+FY8+FZ8+GA8+GB8+GC8+GD8+GE8+GF8+GG8+GH8+GI8+GJ8+GK8+GL8+GM8=0,"",BM8+BS8+BT8+BY8+BZ8+CA8+CB8+CC8+CD8+CE8+CF8+CG8+CL8+CM8+CN8+CO8+CQ8+CR8+CT8+CU8+CV8+CW8+CX8+CY8+CZ8+DA8+DB8+DC8+DD8+DE8+DF8+DG8+DH8+DI8+DJ8+DK8+DL8+DO8+DP8+DQ8+DR8+DS8+DT8+DY8+EB8+EC8+ED8+EH8+EI8+EJ8+EK8+EL8+EM8+EN8+EO8+EP8+ER8+ES8+ET8+EU8+EV8+EW8+EY8+EZ8+FA8+FB8+FC8+FD8+FE8+FF8+FG8+FH8+FI8+FK8+FL8+FM8+FN8+FP8+FQ8+FR8+FU8+FV8+FW8+FX8+FY8+FZ8+GA8+GB8+GC8+GD8+GE8+GF8+GG8+GH8+GI8+GJ8+GK8+GL8+GM8) -> 55.86 | K8: =DX8+CS8 -> 0 | L8: =BN8-C8 -> 0 | M8: F2606017122 | N8: 46203 | O8: 9505289-C01 | P8: EXP20260601-2772379 | Q8: 2026 | R8: 26-06-0049553 | S8: EXP20260601-2772379 | T8: 26A060049553 | U8: DAP | V8: DOMESTIC | W8: DOMESTIC | X8: 11300 | Y8: MESS | Z8: EDI | AA8: 847 | AC8: 46174 | AD8: 21 | AE8: LA RUCHE LOGISTIQUE | AF8: EXP20260601-2772379 | AG8: FR | AH8: 21 | AI8: CREANCEY | AJ8: 46178 | AK8: SAS La Martine Brune CLAEYS (ENTREPRISE) | AL8: EXP20260601-2772379 | AM8: FR | AN8: 11 | AO8: CASTELRENG | AR8: 1 | AS8: 1 | AT8: 72 | AU8: 72 | AV8: 0 | AW8: KG | AX8: 72 | AY8: 0 | BE8: PORTPAYE | BF8: STANDARD | BG8: EUR | BM8: 42.97 | BN8: 55.86 | BQ8: LSTANDARD | DI8: 10.74 | DK8: 2 | GM8: 0.15
B9: =IF(S9<>"",S9,T9) -> EXP20260528-2768110 | C9: =SUM(E9:K9) -> 42.96 | D9: =SUM(E9:L9) -> 42.96 | E9: =IF(BU9+BV9+BW9+CH9+CI9+CJ9+CK9+FO9+FS9+FT9=0,"",BU9+BV9+BW9+CH9+CI9+CJ9+CK9+FO9+FS9+FT9) | F9: =IF(FJ9=0,"",FJ9) | G9: =IF(CP9+DM9+DN9+EE9+EX9+EF9=0,"",CP9+DM9+DN9+EE9+EX9+EF9) -> 7 | H9: =IF(DW9=0,"",DW9) | I9: =IF(DZ9+EA9+EG9=0,"",DZ9+EA9+EG9) | J9: =IF(BM9+BS9+BT9+BY9+BZ9+CA9+CB9+CC9+CD9+CE9+CF9+CG9+CL9+CM9+CN9+CO9+CQ9+CR9+CT9+CU9+CV9+CW9+CX9+CY9+CZ9+DA9+DB9+DC9+DD9+DE9+DF9+DG9+DH9+DI9+DJ9+DK9+DL9+DO9+DP9+DQ9+DR9+DS9+DT9+DY9+EB9+EC9+ED9+EH9+EI9+EJ9+EK9+EL9+EM9+EN9+EO9+EP9+ER9+ES9+ET9+EU9+EV9+EW9+EY9+EZ9+FA9+FB9+FC9+FD9+FE9+FF9+FG9+FH9+FI9+FK9+FL9+FM9+FN9+FP9+FQ9+FR9+FU9+FV9+FW9+FX9+FY9+FZ9+GA9+GB9+GC9+GD9+GE9+GF9+GG9+GH9+GI9+GJ9+GK9+GL9+GM9=0,"",BM9+BS9+BT9+BY9+BZ9+CA9+CB9+CC9+CD9+CE9+CF9+CG9+CL9+CM9+CN9+CO9+CQ9+CR9+CT9+CU9+CV9+CW9+CX9+CY9+CZ9+DA9+DB9+DC9+DD9+DE9+DF9+DG9+DH9+DI9+DJ9+DK9+DL9+DO9+DP9+DQ9+DR9+DS9+DT9+DY9+EB9+EC9+ED9+EH9+EI9+EJ9+EK9+EL9+EM9+EN9+EO9+EP9+ER9+ES9+ET9+EU9+EV9+EW9+EY9+EZ9+FA9+FB9+FC9+FD9+FE9+FF9+FG9+FH9+FI9+FK9+FL9+FM9+FN9+FP9+FQ9+FR9+FU9+FV9+FW9+FX9+FY9+FZ9+GA9+GB9+GC9+GD9+GE9+GF9+GG9+GH9+GI9+GJ9+GK9+GL9+GM9) -> 35.96 | K9: =DX9+CS9 -> 0 | L9: =BN9-C9 -> 0 | M9: F2606017122 | N9: 46203 | O9: 9505289-C01 | P9: EXP20260528-2768110 | Q9: 2026 | R9: 26-06-0049556 | S9: EXP20260528-2768110 | T9: 26A060049556 | U9: DAP | V9: DOMESTIC | W9: DOMESTIC | X9: 93200 | Y9: MESS | Z9: EDI | AA9: 413 | AC9: 46174 | AD9: 21 | AE9: LA RUCHE LOGISTIQUE | AF9: EXP20260528-2768110 | AG9: FR | AH9: 21 | AI9: CREANCEY | AJ9: 46178 | AK9: LA GRANDE PHARMACIE DE ST DENIS Sab (ENTREPRISE) | AL9: EXP20260528-2768110 | AM9: FR | AN9: 93 | AO9: ST DENIS | AR9: 1 | AS9: 1 | AT9: 38 | AU9: 38 | AV9: 0 | AW9: KG | AX9: 38 | AY9: 0 | BE9: PORTPAYE | BF9: STANDARD | BG9: EUR | BM9: 33.81 | BN9: 42.96 | BQ9: LSTANDARD | DK9: 2 | DN9: 7 | GM9: 0.15
B10: =IF(S10<>"",S10,T10) -> EXP20260601-2772378 | C10: =SUM(E10:K10) -> 55.09 | D10: =SUM(E10:L10) -> 55.09 | E10: =IF(BU10+BV10+BW10+CH10+CI10+CJ10+CK10+FO10+FS10+FT10=0,"",BU10+BV10+BW10+CH10+CI10+CJ10+CK10+FO10+FS10+FT10) | F10: =IF(FJ10=0,"",FJ10) | G10: =IF(CP10+DM10+DN10+EE10+EX10+EF10=0,"",CP10+DM10+DN10+EE10+EX10+EF10) | H10: =IF(DW10=0,"",DW10) | I10: =IF(DZ10+EA10+EG10=0,"",DZ10+EA10+EG10) | J10: =IF(BM10+BS10+BT10+BY10+BZ10+CA10+CB10+CC10+CD10+CE10+CF10+CG10+CL10+CM10+CN10+CO10+CQ10+CR10+CT10+CU10+CV10+CW10+CX10+CY10+CZ10+DA10+DB10+DC10+DD10+DE10+DF10+DG10+DH10+DI10+DJ10+DK10+DL10+DO10+DP10+DQ10+DR10+DS10+DT10+DY10+EB10+EC10+ED10+EH10+EI10+EJ10+EK10+EL10+EM10+EN10+EO10+EP10+ER10+ES10+ET10+EU10+EV10+EW10+EY10+EZ10+FA10+FB10+FC10+FD10+FE10+FF10+FG10+FH10+FI10+FK10+FL10+FM10+FN10+FP10+FQ10+FR10+FU10+FV10+FW10+FX10+FY10+FZ10+GA10+GB10+GC10+GD10+GE10+GF10+GG10+GH10+GI10+GJ10+GK10+GL10+GM10=0,"",BM10+BS10+BT10+BY10+BZ10+CA10+CB10+CC10+CD10+CE10+CF10+CG10+CL10+CM10+CN10+CO10+CQ10+CR10+CT10+CU10+CV10+CW10+CX10+CY10+CZ10+DA10+DB10+DC10+DD10+DE10+DF10+DG10+DH10+DI10+DJ10+DK10+DL10+DO10+DP10+DQ10+DR10+DS10+DT10+DY10+EB10+EC10+ED10+EH10+EI10+EJ10+EK10+EL10+EM10+EN10+EO10+EP10+ER10+ES10+ET10+EU10+EV10+EW10+EY10+EZ10+FA10+FB10+FC10+FD10+FE10+FF10+FG10+FH10+FI10+FK10+FL10+FM10+FN10+FP10+FQ10+FR10+FU10+FV10+FW10+FX10+FY10+FZ10+GA10+GB10+GC10+GD10+GE10+GF10+GG10+GH10+GI10+GJ10+GK10+GL10+GM10) -> 55.09 | K10: =DX10+CS10 -> 0 | L10: =BN10-C10 -> 0 | M10: F2606017122 | N10: 46203 | O10: 9505289-C01 | P10: EXP20260601-2772378 | Q10: 2026 | R10: 26-06-0049560 | S10: EXP20260601-2772378 | T10: 26A060049560 | U10: DAP | V10: DOMESTIC | W10: DOMESTIC | X10: 34490 | Y10: MESS | Z10: EDI | AA10: 695 | AC10: 46174 | AD10: 21 | AE10: LA RUCHE LOGISTIQUE | AF10: EXP20260601-2772378 | AG10: FR | AH10: 21 | AI10: CREANCEY | AJ10: 46185 | AK10: GAEC LANYE BARRAC - 2 Bernhard BACK (ENTREPRISE) | AL10: EXP20260601-2772378 | AM10: FR | AN10: 34 | AO10: MURVIEL LES BEZIERS | AR10: 1 | AS10: 1 | AT10: 100 | AU10: 100 | AV10: 0 | AW10: KG | AX10: 100 | AY10: 0 | BE10: PORTPAYE | BF10: STANDARD | BG10: EUR | BM10: 42.35 | BN10: 55.09 | BQ10: LSTANDARD | DI10: 10.59 | DK10: 2 | GM10: 0.15
B11: =IF(S11<>"",S11,T11) -> EXP20260601-2774918 | C11: =SUM(E11:K11) -> 43.19 | D11: =SUM(E11:L11) -> 43.19 | E11: =IF(BU11+BV11+BW11+CH11+CI11+CJ11+CK11+FO11+FS11+FT11=0,"",BU11+BV11+BW11+CH11+CI11+CJ11+CK11+FO11+FS11+FT11) | F11: =IF(FJ11=0,"",FJ11) | G11: =IF(CP11+DM11+DN11+EE11+EX11+EF11=0,"",CP11+DM11+DN11+EE11+EX11+EF11) | H11: =IF(DW11=0,"",DW11) | I11: =IF(DZ11+EA11+EG11=0,"",DZ11+EA11+EG11) | J11: =IF(BM11+BS11+BT11+BY11+BZ11+CA11+CB11+CC11+CD11+CE11+CF11+CG11+CL11+CM11+CN11+CO11+CQ11+CR11+CT11+CU11+CV11+CW11+CX11+CY11+CZ11+DA11+DB11+DC11+DD11+DE11+DF11+DG11+DH11+DI11+DJ11+DK11+DL11+DO11+DP11+DQ11+DR11+DS11+DT11+DY11+EB11+EC11+ED11+EH11+EI11+EJ11+EK11+EL11+EM11+EN11+EO11+EP11+ER11+ES11+ET11+EU11+EV11+EW11+EY11+EZ11+FA11+FB11+FC11+FD11+FE11+FF11+FG11+FH11+FI11+FK11+FL11+FM11+FN11+FP11+FQ11+FR11+FU11+FV11+FW11+FX11+FY11+FZ11+GA11+GB11+GC11+GD11+GE11+GF11+GG11+GH11+GI11+GJ11+GK11+GL11+GM11=0,"",BM11+BS11+BT11+BY11+BZ11+CA11+CB11+CC11+CD11+CE11+CF11+CG11+CL11+CM11+CN11+CO11+CQ11+CR11+CT11+CU11+CV11+CW11+CX11+CY11+CZ11+DA11+DB11+DC11+DD11+DE11+DF11+DG11+DH11+DI11+DJ11+DK11+DL11+DO11+DP11+DQ11+DR11+DS11+DT11+DY11+EB11+EC11+ED11+EH11+EI11+EJ11+EK11+EL11+EM11+EN11+EO11+EP11+ER11+ES11+ET11+EU11+EV11+EW11+EY11+EZ11+FA11+FB11+FC11+FD11+FE11+FF11+FG11+FH11+FI11+FK11+FL11+FM11+FN11+FP11+FQ11+FR11+FU11+FV11+FW11+FX11+FY11+FZ11+GA11+GB11+GC11+GD11+GE11+GF11+GG11+GH11+GI11+GJ11+GK11+GL11+GM11) -> 43.19 | K11: =DX11+CS11 -> 0 | L11: =BN11-C11 -> 0 | M11: F2606017122 | N11: 46203 | O11: 9505289-C01 | P11: EXP20260601-2774918 | Q11: 2026 | R11: 26-06-0092699 | S11: EXP20260601-2774918 | T11: 26A060092699 | U11: DAP | V11: DOMESTIC | W11: DOMESTIC | X11: 84190 | Y11: MESS | Z11: EDI | AA11: 468 | AC11: 46175 | AD11: 21 | AE11: LA RUCHE LOGISTIQUE | AF11: EXP20260601-2774918 | AG11: FR | AH11: 21 | AI11: CREANCEY | AJ11: 46178 | AK11: DOMAINE DE LA TETE NOIRE DE MARIA W (ENTREPRISE) | AL11: EXP20260601-2774918 | AM11: FR | AN11: 84 | AO11: GIGONDAS | AR11: 1 | AS11: 1 | AT11: 59 | AU11: 59 | AV11: 0 | AW11: KG | AX11: 59 | AY11: 0 | BE11: PORTPAYE | BF11: STANDARD | BG11: EUR | BM11: 32.83 | BN11: 43.19 | BQ11: LSTANDARD | DI11: 8.21 | DK11: 2 | GM11: 0.15
B12: =IF(S12<>"",S12,T12) -> EXP20260601-2774442 | C12: =SUM(E12:K12) -> 48.37 | D12: =SUM(E12:L12) -> 48.37 | E12: =IF(BU12+BV12+BW12+CH12+CI12+CJ12+CK12+FO12+FS12+FT12=0,"",BU12+BV12+BW12+CH12+CI12+CJ12+CK12+FO12+FS12+FT12) | F12: =IF(FJ12=0,"",FJ12) | G12: =IF(CP12+DM12+DN12+EE12+EX12+EF12=0,"",CP12+DM12+DN12+EE12+EX12+EF12) | H12: =IF(DW12=0,"",DW12) | I12: =IF(DZ12+EA12+EG12=0,"",DZ12+EA12+EG12) | J12: =IF(BM12+BS12+BT12+BY12+BZ12+CA12+CB12+CC12+CD12+CE12+CF12+CG12+CL12+CM12+CN12+CO12+CQ12+CR12+CT12+CU12+CV12+CW12+CX12+CY12+CZ12+DA12+DB12+DC12+DD12+DE12+DF12+DG12+DH12+DI12+DJ12+DK12+DL12+DO12+DP12+DQ12+DR12+DS12+DT12+DY12+EB12+EC12+ED12+EH12+EI12+EJ12+EK12+EL12+EM12+EN12+EO12+EP12+ER12+ES12+ET12+EU12+EV12+EW12+EY12+EZ12+FA12+FB12+FC12+FD12+FE12+FF12+FG12+FH12+FI12+FK12+FL12+FM12+FN12+FP12+FQ12+FR12+FU12+FV12+FW12+FX12+FY12+FZ12+GA12+GB12+GC12+GD12+GE12+GF12+GG12+GH12+GI12+GJ12+GK12+GL12+GM12=0,"",BM12+BS12+BT12+BY12+BZ12+CA12+CB12+CC12+CD12+CE12+CF12+CG12+CL12+CM12+CN12+CO12+CQ12+CR12+CT12+CU12+CV12+CW12+CX12+CY12+CZ12+DA12+DB12+DC12+DD12+DE12+DF12+DG12+DH12+DI12+DJ12+DK12+DL12+DO12+DP12+DQ12+DR12+DS12+DT12+DY12+EB12+EC12+ED12+EH12+EI12+EJ12+EK12+EL12+EM12+EN12+EO12+EP12+ER12+ES12+ET12+EU12+EV12+EW12+EY12+EZ12+FA12+FB12+FC12+FD12+FE12+FF12+FG12+FH12+FI12+FK12+FL12+FM12+FN12+FP12+FQ12+FR12+FU12+FV12+FW12+FX12+FY12+FZ12+GA12+GB12+GC12+GD12+GE12+GF12+GG12+GH12+GI12+GJ12+GK12+GL12+GM12) -> 48.37 | K12: =DX12+CS12 -> 0 | L12: =BN12-C12 -> 0 | M12: F2606017122 | N12: 46203 | O12: 9505289-C01 | P12: EXP20260601-2774442 | Q12: 2026 | R12: 26-06-0092703 | S12: EXP20260601-2774442 | T12: 26A060092703 | U12: DAP | V12: DOMESTIC | W12: DOMESTIC | X12: 95310 | Y12: MESS | Z12: EDI | AA12: 472 | AC12: 46175 | AD12: 21 | AE12: LA RUCHE LOGISTIQUE | AF12: EXP20260601-2774442 | AG12: FR | AH12: 21 | AI12: CREANCEY | AJ12: 46181 | AK12: PHARMACIE DU FOUR-BONAPARTE PHARMAC (ENTREPRISE) | AL12: EXP20260601-2774442 | AM12: FR | AN12: 95 | AO12: ST OUEN L AUMONE | AR12: 1 | AS12: 1 | AT12: 104 | AU12: 104 | AV12: 0 | AW12: KG | AX12: 104 | AY12: 0 | BE12: PORTPAYE | BF12: STANDARD | BG12: EUR | BM12: 46.22 | BN12: 48.37 | BQ12: LSTANDARD | DK12: 2 | GM12: 0.15
B13: =IF(S13<>"",S13,T13) -> EXP20260601-2774095 | C13: =SUM(E13:K13) -> 80.78 | D13: =SUM(E13:L13) -> 80.78 | E13: =IF(BU13+BV13+BW13+CH13+CI13+CJ13+CK13+FO13+FS13+FT13=0,"",BU13+BV13+BW13+CH13+CI13+CJ13+CK13+FO13+FS13+FT13) | F13: =IF(FJ13=0,"",FJ13) | G13: =IF(CP13+DM13+DN13+EE13+EX13+EF13=0,"",CP13+DM13+DN13+EE13+EX13+EF13) | H13: =IF(DW13=0,"",DW13) | I13: =IF(DZ13+EA13+EG13=0,"",DZ13+EA13+EG13) | J13: =IF(BM13+BS13+BT13+BY13+BZ13+CA13+CB13+CC13+CD13+CE13+CF13+CG13+CL13+CM13+CN13+CO13+CQ13+CR13+CT13+CU13+CV13+CW13+CX13+CY13+CZ13+DA13+DB13+DC13+DD13+DE13+DF13+DG13+DH13+DI13+DJ13+DK13+DL13+DO13+DP13+DQ13+DR13+DS13+DT13+DY13+EB13+EC13+ED13+EH13+EI13+EJ13+EK13+EL13+EM13+EN13+EO13+EP13+ER13+ES13+ET13+EU13+EV13+EW13+EY13+EZ13+FA13+FB13+FC13+FD13+FE13+FF13+FG13+FH13+FI13+FK13+FL13+FM13+FN13+FP13+FQ13+FR13+FU13+FV13+FW13+FX13+FY13+FZ13+GA13+GB13+GC13+GD13+GE13+GF13+GG13+GH13+GI13+GJ13+GK13+GL13+GM13=0,"",BM13+BS13+BT13+BY13+BZ13+CA13+CB13+CC13+CD13+CE13+CF13+CG13+CL13+CM13+CN13+CO13+CQ13+CR13+CT13+CU13+CV13+CW13+CX13+CY13+CZ13+DA13+DB13+DC13+DD13+DE13+DF13+DG13+DH13+DI13+DJ13+DK13+DL13+DO13+DP13+DQ13+DR13+DS13+DT13+DY13+EB13+EC13+ED13+EH13+EI13+EJ13+EK13+EL13+EM13+EN13+EO13+EP13+ER13+ES13+ET13+EU13+EV13+EW13+EY13+EZ13+FA13+FB13+FC13+FD13+FE13+FF13+FG13+FH13+FI13+FK13+FL13+FM13+FN13+FP13+FQ13+FR13+FU13+FV13+FW13+FX13+FY13+FZ13+GA13+GB13+GC13+GD13+GE13+GF13+GG13+GH13+GI13+GJ13+GK13+GL13+GM13) -> 80.78 | K13: =DX13+CS13 -> 0 | L13: =BN13-C13 -> 0 | M13: F2606017122 | N13: 46203 | O13: 9505289-C01 | P13: EXP20260601-2774095 | Q13: 2026 | R13: 26-06-0092706 | S13: EXP20260601-2774095 | T13: 26A060092706 | U13: DAP | V13: DOMESTIC | W13: DOMESTIC | X13: 29620 | Y13: MESS | Z13: EDI | AA13: 897 | AC13: 46175 | AD13: 21 | AE13: LA RUCHE LOGISTIQUE | AF13: EXP20260601-2774095 | AG13: FR | AH13: 21 | AI13: CREANCEY | AJ13: 46178 | AK13: Kerveguen Baron Eric (ENTREPRISE) | AL13: EXP20260601-2774095 | AM13: FR | AN13: 29 | AO13: GUIMAEC | AR13: 1 | AS13: 1 | AT13: 115 | AU13: 115 | AV13: 0 | AW13: KG | AX13: 115 | AY13: 0 | BE13: PORTPAYE | BF13: STANDARD | BG13: EUR | BM13: 62.9 | BN13: 80.78 | BQ13: LSTANDARD | DI13: 15.73 | DK13: 2 | GM13: 0.15
B14: =IF(S14<>"",S14,T14) -> EXP20260601-2774686 | C14: =SUM(E14:K14) -> 37.31 | D14: =SUM(E14:L14) -> 37.31 | E14: =IF(BU14+BV14+BW14+CH14+CI14+CJ14+CK14+FO14+FS14+FT14=0,"",BU14+BV14+BW14+CH14+CI14+CJ14+CK14+FO14+FS14+FT14) | F14: =IF(FJ14=0,"",FJ14) | G14: =IF(CP14+DM14+DN14+EE14+EX14+EF14=0,"",CP14+DM14+DN14+EE14+EX14+EF14) | H14: =IF(DW14=0,"",DW14) | I14: =IF(DZ14+EA14+EG14=0,"",DZ14+EA14+EG14) | J14: =IF(BM14+BS14+BT14+BY14+BZ14+CA14+CB14+CC14+CD14+CE14+CF14+CG14+CL14+CM14+CN14+CO14+CQ14+CR14+CT14+CU14+CV14+CW14+CX14+CY14+CZ14+DA14+DB14+DC14+DD14+DE14+DF14+DG14+DH14+DI14+DJ14+DK14+DL14+DO14+DP14+DQ14+DR14+DS14+DT14+DY14+EB14+EC14+ED14+EH14+EI14+EJ14+EK14+EL14+EM14+EN14+EO14+EP14+ER14+ES14+ET14+EU14+EV14+EW14+EY14+EZ14+FA14+FB14+FC14+FD14+FE14+FF14+FG14+FH14+FI14+FK14+FL14+FM14+FN14+FP14+FQ14+FR14+FU14+FV14+FW14+FX14+FY14+FZ14+GA14+GB14+GC14+GD14+GE14+GF14+GG14+GH14+GI14+GJ14+GK14+GL14+GM14=0,"",BM14+BS14+BT14+BY14+BZ14+CA14+CB14+CC14+CD14+CE14+CF14+CG14+CL14+CM14+CN14+CO14+CQ14+CR14+CT14+CU14+CV14+CW14+CX14+CY14+CZ14+DA14+DB14+DC14+DD14+DE14+DF14+DG14+DH14+DI14+DJ14+DK14+DL14+DO14+DP14+DQ14+DR14+DS14+DT14+DY14+EB14+EC14+ED14+EH14+EI14+EJ14+EK14+EL14+EM14+EN14+EO14+EP14+ER14+ES14+ET14+EU14+EV14+EW14+EY14+EZ14+FA14+FB14+FC14+FD14+FE14+FF14+FG14+FH14+FI14+FK14+FL14+FM14+FN14+FP14+FQ14+FR14+FU14+FV14+FW14+FX14+FY14+FZ14+GA14+GB14+GC14+GD14+GE14+GF14+GG14+GH14+GI14+GJ14+GK14+GL14+GM14) -> 37.31 | K14: =DX14+CS14 -> 0 | L14: =BN14-C14 -> 0 | M14: F2606017122 | N14: 46203 | O14: 9505289-C01 | P14: EXP20260601-2774686 | Q14: 2026 | R14: 26-06-0092708 | S14: EXP20260601-2774686 | T14: 26A060092708 | U14: DAP | V14: DOMESTIC | W14: DOMESTIC | X14: 33330 | Y14: MESS | Z14: EDI | AA14: 713 | AC14: 46175 | AD14: 21 | AE14: LA RUCHE LOGISTIQUE | AF14: EXP20260601-2774686 | AG14: FR | AH14: 21 | AI14: CREANCEY | AJ14: 46177 | AK14: CHATEAU LA SABLIERE AVEZOU SYLVIE (ENTREPRISE) | AL14: EXP20260601-2774686 | AM14: FR | AN14: 33 | AO14: ST EMILION | AR14: 1 | AS14: 1 | AT14: 10 | AU14: 10 | AV14: 0 | AW14: KG | AX14: 10 | AY14: 0 | BE14: PORTPAYE | BF14: STANDARD | BG14: EUR | BM14: 28.13 | BN14: 37.31 | BQ14: LSTANDARD | DI14: 7.03 | DK14: 2 | GM14: 0.15
B15: =IF(S15<>"",S15,T15) -> EXP20260601-2774625 | C15: =SUM(E15:K15) -> 32.31 | D15: =SUM(E15:L15) -> 32.31 | E15: =IF(BU15+BV15+BW15+CH15+CI15+CJ15+CK15+FO15+FS15+FT15=0,"",BU15+BV15+BW15+CH15+CI15+CJ15+CK15+FO15+FS15+FT15) | F15: =IF(FJ15=0,"",FJ15) | G15: =IF(CP15+DM15+DN15+EE15+EX15+EF15=0,"",CP15+DM15+DN15+EE15+EX15+EF15) | H15: =IF(DW15=0,"",DW15) | I15: =IF(DZ15+EA15+EG15=0,"",DZ15+EA15+EG15) | J15: =IF(BM15+BS15+BT15+BY15+BZ15+CA15+CB15+CC15+CD15+CE15+CF15+CG15+CL15+CM15+CN15+CO15+CQ15+CR15+CT15+CU15+CV15+CW15+CX15+CY15+CZ15+DA15+DB15+DC15+DD15+DE15+DF15+DG15+DH15+DI15+DJ15+DK15+DL15+DO15+DP15+DQ15+DR15+DS15+DT15+DY15+EB15+EC15+ED15+EH15+EI15+EJ15+EK15+EL15+EM15+EN15+EO15+EP15+ER15+ES15+ET15+EU15+EV15+EW15+EY15+EZ15+FA15+FB15+FC15+FD15+FE15+FF15+FG15+FH15+FI15+FK15+FL15+FM15+FN15+FP15+FQ15+FR15+FU15+FV15+FW15+FX15+FY15+FZ15+GA15+GB15+GC15+GD15+GE15+GF15+GG15+GH15+GI15+GJ15+GK15+GL15+GM15=0,"",BM15+BS15+BT15+BY15+BZ15+CA15+CB15+CC15+CD15+CE15+CF15+CG15+CL15+CM15+CN15+CO15+CQ15+CR15+CT15+CU15+CV15+CW15+CX15+CY15+CZ15+DA15+DB15+DC15+DD15+DE15+DF15+DG15+DH15+DI15+DJ15+DK15+DL15+DO15+DP15+DQ15+DR15+DS15+DT15+DY15+EB15+EC15+ED15+EH15+EI15+EJ15+EK15+EL15+EM15+EN15+EO15+EP15+ER15+ES15+ET15+EU15+EV15+EW15+EY15+EZ15+FA15+FB15+FC15+FD15+FE15+FF15+FG15+FH15+FI15+FK15+FL15+FM15+FN15+FP15+FQ15+FR15+FU15+FV15+FW15+FX15+FY15+FZ15+GA15+GB15+GC15+GD15+GE15+GF15+GG15+GH15+GI15+GJ15+GK15+GL15+GM15) -> 32.31 | K15: =DX15+CS15 -> 0 | L15: =BN15-C15 -> 0 | M15: F2606017122 | N15: 46203 | O15: 9505289-C01 | P15: EXP20260601-2774625 | Q15: 2026 | R15: 26-06-0147565 | S15: EXP20260601-2774625 | T15: 26A060147565 | U15: DAP | V15: DOMESTIC | W15: DOMESTIC | X15: 58150 | Y15: MESS | Z15: EDI | AA15: 356 | AC15: 46176 | AD15: 21 | AE15: LA RUCHE LOGISTIQUE | AF15: EXP20260601-2774625 | AG15: FR | AH15: 21 | AI15: CREANCEY | AJ15: 46178 | AK15: SAGET | AL15: EXP20260601-2774625 | AM15: FR | AN15: 58 | AO15: POUILLY SUR LOIRE | AP15: Magasin / Commerce | AQ15: O | AR15: 1 | AS15: 1 | AT15: 66 | AU15: 66 | AV15: 0 | AW15: KG | AX15: 66 | AY15: 0 | BE15: PORTPAYE | BF15: STANDARD | BG15: EUR | BM15: 30.16 | BN15: 32.31 | BQ15: LSTANDARD | DK15: 2 | GM15: 0.15
B16: =IF(S16<>"",S16,T16) -> EXP20260601-2774279 | C16: =SUM(E16:K16) -> 48.98 | D16: =SUM(E16:L16) -> 48.98 | E16: =IF(BU16+BV16+BW16+CH16+CI16+CJ16+CK16+FO16+FS16+FT16=0,"",BU16+BV16+BW16+CH16+CI16+CJ16+CK16+FO16+FS16+FT16) | F16: =IF(FJ16=0,"",FJ16) | G16: =IF(CP16+DM16+DN16+EE16+EX16+EF16=0,"",CP16+DM16+DN16+EE16+EX16+EF16) | H16: =IF(DW16=0,"",DW16) | I16: =IF(DZ16+EA16+EG16=0,"",DZ16+EA16+EG16) | J16: =IF(BM16+BS16+BT16+BY16+BZ16+CA16+CB16+CC16+CD16+CE16+CF16+CG16+CL16+CM16+CN16+CO16+CQ16+CR16+CT16+CU16+CV16+CW16+CX16+CY16+CZ16+DA16+DB16+DC16+DD16+DE16+DF16+DG16+DH16+DI16+DJ16+DK16+DL16+DO16+DP16+DQ16+DR16+DS16+DT16+DY16+EB16+EC16+ED16+EH16+EI16+EJ16+EK16+EL16+EM16+EN16+EO16+EP16+ER16+ES16+ET16+EU16+EV16+EW16+EY16+EZ16+FA16+FB16+FC16+FD16+FE16+FF16+FG16+FH16+FI16+FK16+FL16+FM16+FN16+FP16+FQ16+FR16+FU16+FV16+FW16+FX16+FY16+FZ16+GA16+GB16+GC16+GD16+GE16+GF16+GG16+GH16+GI16+GJ16+GK16+GL16+GM16=0,"",BM16+BS16+BT16+BY16+BZ16+CA16+CB16+CC16+CD16+CE16+CF16+CG16+CL16+CM16+CN16+CO16+CQ16+CR16+CT16+CU16+CV16+CW16+CX16+CY16+CZ16+DA16+DB16+DC16+DD16+DE16+DF16+DG16+DH16+DI16+DJ16+DK16+DL16+DO16+DP16+DQ16+DR16+DS16+DT16+DY16+EB16+EC16+ED16+EH16+EI16+EJ16+EK16+EL16+EM16+EN16+EO16+EP16+ER16+ES16+ET16+EU16+EV16+EW16+EY16+EZ16+FA16+FB16+FC16+FD16+FE16+FF16+FG16+FH16+FI16+FK16+FL16+FM16+FN16+FP16+FQ16+FR16+FU16+FV16+FW16+FX16+FY16+FZ16+GA16+GB16+GC16+GD16+GE16+GF16+GG16+GH16+GI16+GJ16+GK16+GL16+GM16) -> 48.98 | K16: =DX16+CS16 -> 0 | L16: =BN16-C16 -> 0 | M16: F2606017122 | N16: 46203 | O16: 9505289-C01 | P16: EXP20260601-2774279 | Q16: 2026 | R16: 26-06-0147570 | S16: EXP20260601-2774279 | T16: 26A060147570 | U16: DAP | V16: DOMESTIC | W16: DOMESTIC | X16: 13210 | Y16: MESS | Z16: EDI | AA16: 448 | AC16: 46176 | AD16: 21 | AE16: LA RUCHE LOGISTIQUE | AF16: EXP20260601-2774279 | AG16: FR | AH16: 21 | AI16: CREANCEY | AJ16: 46182 | AK16: CHATEAU ROMANIN | AL16: EXP20260601-2774279 | AM16: FR | AN16: 13 | AO16: ST REMY DE PROVENCE | AP16: Magasin / Commerce | AQ16: O | AR16: 1 | AS16: 1 | AT16: 68 | AU16: 68 | AV16: 0 | AW16: KG | AX16: 68 | AY16: 0 | BE16: PORTPAYE | BF16: STANDARD | BG16: EUR | BM16: 37.46 | BN16: 48.98 | BQ16: LSTANDARD | DI16: 9.37 | DK16: 2 | GM16: 0.15
B17: =IF(S17<>"",S17,T17) -> EXP20260601-2774815 | C17: =SUM(E17:K17) -> 53.36 | D17: =SUM(E17:L17) -> 53.36 | E17: =IF(BU17+BV17+BW17+CH17+CI17+CJ17+CK17+FO17+FS17+FT17=0,"",BU17+BV17+BW17+CH17+CI17+CJ17+CK17+FO17+FS17+FT17) | F17: =IF(FJ17=0,"",FJ17) | G17: =IF(CP17+DM17+DN17+EE17+EX17+EF17=0,"",CP17+DM17+DN17+EE17+EX17+EF17) | H17: =IF(DW17=0,"",DW17) | I17: =IF(DZ17+EA17+EG17=0,"",DZ17+EA17+EG17) | J17: =IF(BM17+BS17+BT17+BY17+BZ17+CA17+CB17+CC17+CD17+CE17+CF17+CG17+CL17+CM17+CN17+CO17+CQ17+CR17+CT17+CU17+CV17+CW17+CX17+CY17+CZ17+DA17+DB17+DC17+DD17+DE17+DF17+DG17+DH17+DI17+DJ17+DK17+DL17+DO17+DP17+DQ17+DR17+DS17+DT17+DY17+EB17+EC17+ED17+EH17+EI17+EJ17+EK17+EL17+EM17+EN17+EO17+EP17+ER17+ES17+ET17+EU17+EV17+EW17+EY17+EZ17+FA17+FB17+FC17+FD17+FE17+FF17+FG17+FH17+FI17+FK17+FL17+FM17+FN17+FP17+FQ17+FR17+FU17+FV17+FW17+FX17+FY17+FZ17+GA17+GB17+GC17+GD17+GE17+GF17+GG17+GH17+GI17+GJ17+GK17+GL17+GM17=0,"",BM17+BS17+BT17+BY17+BZ17+CA17+CB17+CC17+CD17+CE17+CF17+CG17+CL17+CM17+CN17+CO17+CQ17+CR17+CT17+CU17+CV17+CW17+CX17+CY17+CZ17+DA17+DB17+DC17+DD17+DE17+DF17+DG17+DH17+DI17+DJ17+DK17+DL17+DO17+DP17+DQ17+DR17+DS17+DT17+DY17+EB17+EC17+ED17+EH17+EI17+EJ17+EK17+EL17+EM17+EN17+EO17+EP17+ER17+ES17+ET17+EU17+EV17+EW17+EY17+EZ17+FA17+FB17+FC17+FD17+FE17+FF17+FG17+FH17+FI17+FK17+FL17+FM17+FN17+FP17+FQ17+FR17+FU17+FV17+FW17+FX17+FY17+FZ17+GA17+GB17+GC17+GD17+GE17+GF17+GG17+GH17+GI17+GJ17+GK17+GL17+GM17) -> 53.36 | K17: =DX17+CS17 -> 0 | L17: =BN17-C17 -> 0 | M17: F2606017122 | N17: 46203 | O17: 9505289-C01 | P17: EXP20260601-2774815 | Q17: 2026 | R17: 26-06-0147574 | S17: EXP20260601-2774815 | T17: 26A060147574 | U17: DAP | V17: DOMESTIC | W17: DOMESTIC | X17: 34210 | Y17: MESS | Z17: EDI | AA17: 695 | AC17: 46176 | AD17: 21 | AE17: LA RUCHE LOGISTIQUE | AF17: EXP20260601-2774815 | AG17: FR | AH17: 21 | AI17: CREANCEY | AJ17: 46181 | AK17: Grands Vignobles en Mediterranee Ch (ENTREPRISE) | AL17: EXP20260601-2774815 | AM17: FR | AN17: 34 | AO17: FELINES MINERVOIS | AR17: 1 | AS17: 1 | AT17: 83 | AU17: 83 | AV17: 0 | AW17: KG | AX17: 83 | AY17: 0 | BE17: PORTPAYE | BF17: STANDARD | BG17: EUR | BM17: 40.97 | BN17: 53.36 | BQ17: LSTANDARD | DI17: 10.24 | DK17: 2 | GM17: 0.15
B18: =IF(S18<>"",S18,T18) -> EXP20260603-2778100 | C18: =SUM(E18:K18) -> 27.38 | D18: =SUM(E18:L18) -> 27.38 | E18: =IF(BU18+BV18+BW18+CH18+CI18+CJ18+CK18+FO18+FS18+FT18=0,"",BU18+BV18+BW18+CH18+CI18+CJ18+CK18+FO18+FS18+FT18) | F18: =IF(FJ18=0,"",FJ18) | G18: =IF(CP18+DM18+DN18+EE18+EX18+EF18=0,"",CP18+DM18+DN18+EE18+EX18+EF18) | H18: =IF(DW18=0,"",DW18) | I18: =IF(DZ18+EA18+EG18=0,"",DZ18+EA18+EG18) | J18: =IF(BM18+BS18+BT18+BY18+BZ18+CA18+CB18+CC18+CD18+CE18+CF18+CG18+CL18+CM18+CN18+CO18+CQ18+CR18+CT18+CU18+CV18+CW18+CX18+CY18+CZ18+DA18+DB18+DC18+DD18+DE18+DF18+DG18+DH18+DI18+DJ18+DK18+DL18+DO18+DP18+DQ18+DR18+DS18+DT18+DY18+EB18+EC18+ED18+EH18+EI18+EJ18+EK18+EL18+EM18+EN18+EO18+EP18+ER18+ES18+ET18+EU18+EV18+EW18+EY18+EZ18+FA18+FB18+FC18+FD18+FE18+FF18+FG18+FH18+FI18+FK18+FL18+FM18+FN18+FP18+FQ18+FR18+FU18+FV18+FW18+FX18+FY18+FZ18+GA18+GB18+GC18+GD18+GE18+GF18+GG18+GH18+GI18+GJ18+GK18+GL18+GM18=0,"",BM18+BS18+BT18+BY18+BZ18+CA18+CB18+CC18+CD18+CE18+CF18+CG18+CL18+CM18+CN18+CO18+CQ18+CR18+CT18+CU18+CV18+CW18+CX18+CY18+CZ18+DA18+DB18+DC18+DD18+DE18+DF18+DG18+DH18+DI18+DJ18+DK18+DL18+DO18+DP18+DQ18+DR18+DS18+DT18+DY18+EB18+EC18+ED18+EH18+EI18+EJ18+EK18+EL18+EM18+EN18+EO18+EP18+ER18+ES18+ET18+EU18+EV18+EW18+EY18+EZ18+FA18+FB18+FC18+FD18+FE18+FF18+FG18+FH18+FI18+FK18+FL18+FM18+FN18+FP18+FQ18+FR18+FU18+FV18+FW18+FX18+FY18+FZ18+GA18+GB18+GC18+GD18+GE18+GF18+GG18+GH18+GI18+GJ18+GK18+GL18+GM18) -> 27.38 | K18: =DX18+CS18 -> 0 | L18: =BN18-C18 -> 0 | M18: F2606017122 | N18: 46203 | O18: 9505289-C01 | P18: EXP20260603-2778100 | Q18: 2026 | R18: 26-06-0188565 | S18: EXP20260603-2778100 | T18: 26A060188565 | U18: DAP | V18: DOMESTIC | W18: DOMESTIC | X18: 69640 | Y18: MESS | Z18: EDI | AA18: 187 | AC18: 46177 | AD18: 21 | AE18: LA RUCHE LOGISTIQUE | AF18: EXP20260603-2778100 | AG18: FR | AH18: 21 | AI18: CREANCEY | AJ18: 46185 | AK18: DOMAINE FOND MOIROUX | AL18: EXP20260603-2778100 | AM18: FR | AN18: 69 | AO18: COGNY | AR18: 1 | AS18: 1 | AT18: 45 | AU18: 45 | AV18: 0 | AW18: KG | AX18: 45 | AY18: 0 | BE18: PORTPAYE | BF18: STANDARD | BG18: EUR | BM18: 25.23 | BN18: 27.38 | BQ18: LSTANDARD | DK18: 2 | GM18: 0.15
B19: =IF(S19<>"",S19,T19) -> EXP20260604-2780722 | C19: =SUM(E19:K19) -> 81.95 | D19: =SUM(E19:L19) -> 81.95 | E19: =IF(BU19+BV19+BW19+CH19+CI19+CJ19+CK19+FO19+FS19+FT19=0,"",BU19+BV19+BW19+CH19+CI19+CJ19+CK19+FO19+FS19+FT19) | F19: =IF(FJ19=0,"",FJ19) | G19: =IF(CP19+DM19+DN19+EE19+EX19+EF19=0,"",CP19+DM19+DN19+EE19+EX19+EF19) | H19: =IF(DW19=0,"",DW19) | I19: =IF(DZ19+EA19+EG19=0,"",DZ19+EA19+EG19) | J19: =IF(BM19+BS19+BT19+BY19+BZ19+CA19+CB19+CC19+CD19+CE19+CF19+CG19+CL19+CM19+CN19+CO19+CQ19+CR19+CT19+CU19+CV19+CW19+CX19+CY19+CZ19+DA19+DB19+DC19+DD19+DE19+DF19+DG19+DH19+DI19+DJ19+DK19+DL19+DO19+DP19+DQ19+DR19+DS19+DT19+DY19+EB19+EC19+ED19+EH19+EI19+EJ19+EK19+EL19+EM19+EN19+EO19+EP19+ER19+ES19+ET19+EU19+EV19+EW19+EY19+EZ19+FA19+FB19+FC19+FD19+FE19+FF19+FG19+FH19+FI19+FK19+FL19+FM19+FN19+FP19+FQ19+FR19+FU19+FV19+FW19+FX19+FY19+FZ19+GA19+GB19+GC19+GD19+GE19+GF19+GG19+GH19+GI19+GJ19+GK19+GL19+GM19=0,"",BM19+BS19+BT19+BY19+BZ19+CA19+CB19+CC19+CD19+CE19+CF19+CG19+CL19+CM19+CN19+CO19+CQ19+CR19+CT19+CU19+CV19+CW19+CX19+CY19+CZ19+DA19+DB19+DC19+DD19+DE19+DF19+DG19+DH19+DI19+DJ19+DK19+DL19+DO19+DP19+DQ19+DR19+DS19+DT19+DY19+EB19+EC19+ED19+EH19+EI19+EJ19+EK19+EL19+EM19+EN19+EO19+EP19+ER19+ES19+ET19+EU19+EV19+EW19+EY19+EZ19+FA19+FB19+FC19+FD19+FE19+FF19+FG19+FH19+FI19+FK19+FL19+FM19+FN19+FP19+FQ19+FR19+FU19+FV19+FW19+FX19+FY19+FZ19+GA19+GB19+GC19+GD19+GE19+GF19+GG19+GH19+GI19+GJ19+GK19+GL19+GM19) -> 81.95 | K19: =DX19+CS19 -> 0 | L19: =BN19-C19 -> 0 | M19: F2606017122 | N19: 46203 | O19: 9505289-C01 | P19: EXP20260604-2780722 | Q19: 2026 | R19: 26-06-0188569 | S19: EXP20260604-2780722 | T19: 26A060188569 | U19: DAP | V19: DOMESTIC | W19: DOMESTIC | X19: 33330 | Y19: MESS | Z19: EDI | AA19: 713 | AC19: 46177 | AD19: 21 | AE19: LA RUCHE LOGISTIQUE | AF19: EXP20260604-2780722 | AG19: FR | AH19: 21 | AI19: CREANCEY | AJ19: 46181 | AK19: CHATEAUX ET VINS DE BORDEAUX BALLAN (ENTREPRISE) | AL19: EXP20260604-2780722 | AM19: FR | AN19: 33 | AO19: ST SULPICE DE FALEYRENS | AR19: 1 | AS19: 1 | AT19: 153 | AU19: 153 | AV19: 0 | AW19: Pal | AX19: 1 | AY19: 0 | BE19: PORTPAYE | BF19: STANDARD | BG19: EUR | BM19: 63.84 | BN19: 81.95 | BQ19: LSTANDARD | DI19: 15.96 | DK19: 2 | GM19: 0.15
B20: =IF(S20<>"",S20,T20) -> EXP20260602-2776631 | C20: =SUM(E20:K20) -> 59.49 | D20: =SUM(E20:L20) -> 59.49 | E20: =IF(BU20+BV20+BW20+CH20+CI20+CJ20+CK20+FO20+FS20+FT20=0,"",BU20+BV20+BW20+CH20+CI20+CJ20+CK20+FO20+FS20+FT20) | F20: =IF(FJ20=0,"",FJ20) | G20: =IF(CP20+DM20+DN20+EE20+EX20+EF20=0,"",CP20+DM20+DN20+EE20+EX20+EF20) | H20: =IF(DW20=0,"",DW20) | I20: =IF(DZ20+EA20+EG20=0,"",DZ20+EA20+EG20) | J20: =IF(BM20+BS20+BT20+BY20+BZ20+CA20+CB20+CC20+CD20+CE20+CF20+CG20+CL20+CM20+CN20+CO20+CQ20+CR20+CT20+CU20+CV20+CW20+CX20+CY20+CZ20+DA20+DB20+DC20+DD20+DE20+DF20+DG20+DH20+DI20+DJ20+DK20+DL20+DO20+DP20+DQ20+DR20+DS20+DT20+DY20+EB20+EC20+ED20+EH20+EI20+EJ20+EK20+EL20+EM20+EN20+EO20+EP20+ER20+ES20+ET20+EU20+EV20+EW20+EY20+EZ20+FA20+FB20+FC20+FD20+FE20+FF20+FG20+FH20+FI20+FK20+FL20+FM20+FN20+FP20+FQ20+FR20+FU20+FV20+FW20+FX20+FY20+FZ20+GA20+GB20+GC20+GD20+GE20+GF20+GG20+GH20+GI20+GJ20+GK20+GL20+GM20=0,"",BM20+BS20+BT20+BY20+BZ20+CA20+CB20+CC20+CD20+CE20+CF20+CG20+CL20+CM20+CN20+CO20+CQ20+CR20+CT20+CU20+CV20+CW20+CX20+CY20+CZ20+DA20+DB20+DC20+DD20+DE20+DF20+DG20+DH20+DI20+DJ20+DK20+DL20+DO20+DP20+DQ20+DR20+DS20+DT20+DY20+EB20+EC20+ED20+EH20+EI20+EJ20+EK20+EL20+EM20+EN20+EO20+EP20+ER20+ES20+ET20+EU20+EV20+EW20+EY20+EZ20+FA20+FB20+FC20+FD20+FE20+FF20+FG20+FH20+FI20+FK20+FL20+FM20+FN20+FP20+FQ20+FR20+FU20+FV20+FW20+FX20+FY20+FZ20+GA20+GB20+GC20+GD20+GE20+GF20+GG20+GH20+GI20+GJ20+GK20+GL20+GM20) -> 59.49 | K20: =DX20+CS20 -> 0 | L20: =BN20-C20 -> 0 | M20: F2606017122 | N20: 46203 | O20: 9505289-C01 | P20: EXP20260602-2776631 | Q20: 2026 | R20: 26-06-0188571 | S20: EXP20260602-2776631 | T20: 26A060188571 | U20: DAP | V20: DOMESTIC | W20: DOMESTIC | X20: 33330 | Y20: MESS | Z20: EDI | AA20: 713 | AC20: 46177 | AD20: 21 | AE20: LA RUCHE LOGISTIQUE | AF20: EXP20260602-2776631 | AG20: FR | AH20: 21 | AI20: CREANCEY | AJ20: 46182 | AK20: CHATEAU GESSAN GONZALES PATRICK (ENTREPRISE) | AL20: EXP20260602-2776631 | AM20: FR | AN20: 33 | AO20: ST SULPICE DE FALEYRENS | AR20: 1 | AS20: 1 | AT20: 81 | AU20: 81 | AV20: 0 | AW20: KG | AX20: 81 | AY20: 0 | BE20: PORTPAYE | BF20: STANDARD | BG20: EUR | BM20: 45.87 | BN20: 59.49 | BQ20: LSTANDARD | DI20: 11.47 | DK20: 2 | GM20: 0.15
B21: =IF(S21<>"",S21,T21) -> EXP20260602-2777383 | C21: =SUM(E21:K21) -> 32.4 | D21: =SUM(E21:L21) -> 32.4 | E21: =IF(BU21+BV21+BW21+CH21+CI21+CJ21+CK21+FO21+FS21+FT21=0,"",BU21+BV21+BW21+CH21+CI21+CJ21+CK21+FO21+FS21+FT21) | F21: =IF(FJ21=0,"",FJ21) | G21: =IF(CP21+DM21+DN21+EE21+EX21+EF21=0,"",CP21+DM21+DN21+EE21+EX21+EF21) | H21: =IF(DW21=0,"",DW21) | I21: =IF(DZ21+EA21+EG21=0,"",DZ21+EA21+EG21) | J21: =IF(BM21+BS21+BT21+BY21+BZ21+CA21+CB21+CC21+CD21+CE21+CF21+CG21+CL21+CM21+CN21+CO21+CQ21+CR21+CT21+CU21+CV21+CW21+CX21+CY21+CZ21+DA21+DB21+DC21+DD21+DE21+DF21+DG21+DH21+DI21+DJ21+DK21+DL21+DO21+DP21+DQ21+DR21+DS21+DT21+DY21+EB21+EC21+ED21+EH21+EI21+EJ21+EK21+EL21+EM21+EN21+EO21+EP21+ER21+ES21+ET21+EU21+EV21+EW21+EY21+EZ21+FA21+FB21+FC21+FD21+FE21+FF21+FG21+FH21+FI21+FK21+FL21+FM21+FN21+FP21+FQ21+FR21+FU21+FV21+FW21+FX21+FY21+FZ21+GA21+GB21+GC21+GD21+GE21+GF21+GG21+GH21+GI21+GJ21+GK21+GL21+GM21=0,"",BM21+BS21+BT21+BY21+BZ21+CA21+CB21+CC21+CD21+CE21+CF21+CG21+CL21+CM21+CN21+CO21+CQ21+CR21+CT21+CU21+CV21+CW21+CX21+CY21+CZ21+DA21+DB21+DC21+DD21+DE21+DF21+DG21+DH21+DI21+DJ21+DK21+DL21+DO21+DP21+DQ21+DR21+DS21+DT21+DY21+EB21+EC21+ED21+EH21+EI21+EJ21+EK21+EL21+EM21+EN21+EO21+EP21+ER21+ES21+ET21+EU21+EV21+EW21+EY21+EZ21+FA21+FB21+FC21+FD21+FE21+FF21+FG21+FH21+FI21+FK21+FL21+FM21+FN21+FP21+FQ21+FR21+FU21+FV21+FW21+FX21+FY21+FZ21+GA21+GB21+GC21+GD21+GE21+GF21+GG21+GH21+GI21+GJ21+GK21+GL21+GM21) -> 32.4 | K21: =DX21+CS21 -> 0 | L21: =BN21-C21 -> 0 | M21: F2606017122 | N21: 46203 | O21: 9505289-C01 | P21: EXP20260602-2777383 | Q21: 2026 | R21: 26-06-0188573 | S21: EXP20260602-2777383 | T21: 26A060188573 | U21: DAP | V21: DOMESTIC | W21: DOMESTIC | X21: 79100 | Y21: MESS | Z21: EDI | AA21: 782 | AC21: 46177 | AD21: 21 | AE21: LA RUCHE LOGISTIQUE | AF21: EXP20260602-2777383 | AG21: FR | AH21: 21 | AI21: CREANCEY | AJ21: 46182 | AK21: Jardins de Fleury Kohler Carole (ENTREPRISE) | AL21: EXP20260602-2777383 | AM21: FR | AN21: 79 | AO21: THOUARS | AR21: 1 | AS21: 1 | AT21: 25 | AU21: 25 | AV21: 0 | AW21: KG | AX21: 25 | AY21: 0 | BE21: PORTPAYE | BF21: STANDARD | BG21: EUR | BM21: 30.25 | BN21: 32.4 | BQ21: LSTANDARD | DK21: 2 | GM21: 0.15
B22: =IF(S22<>"",S22,T22) -> EXP20260602-2776061 | C22: =SUM(E22:K22) -> 49.95 | D22: =SUM(E22:L22) -> 49.95 | E22: =IF(BU22+BV22+BW22+CH22+CI22+CJ22+CK22+FO22+FS22+FT22=0,"",BU22+BV22+BW22+CH22+CI22+CJ22+CK22+FO22+FS22+FT22) | F22: =IF(FJ22=0,"",FJ22) | G22: =IF(CP22+DM22+DN22+EE22+EX22+EF22=0,"",CP22+DM22+DN22+EE22+EX22+EF22) | H22: =IF(DW22=0,"",DW22) | I22: =IF(DZ22+EA22+EG22=0,"",DZ22+EA22+EG22) | J22: =IF(BM22+BS22+BT22+BY22+BZ22+CA22+CB22+CC22+CD22+CE22+CF22+CG22+CL22+CM22+CN22+CO22+CQ22+CR22+CT22+CU22+CV22+CW22+CX22+CY22+CZ22+DA22+DB22+DC22+DD22+DE22+DF22+DG22+DH22+DI22+DJ22+DK22+DL22+DO22+DP22+DQ22+DR22+DS22+DT22+DY22+EB22+EC22+ED22+EH22+EI22+EJ22+EK22+EL22+EM22+EN22+EO22+EP22+ER22+ES22+ET22+EU22+EV22+EW22+EY22+EZ22+FA22+FB22+FC22+FD22+FE22+FF22+FG22+FH22+FI22+FK22+FL22+FM22+FN22+FP22+FQ22+FR22+FU22+FV22+FW22+FX22+FY22+FZ22+GA22+GB22+GC22+GD22+GE22+GF22+GG22+GH22+GI22+GJ22+GK22+GL22+GM22=0,"",BM22+BS22+BT22+BY22+BZ22+CA22+CB22+CC22+CD22+CE22+CF22+CG22+CL22+CM22+CN22+CO22+CQ22+CR22+CT22+CU22+CV22+CW22+CX22+CY22+CZ22+DA22+DB22+DC22+DD22+DE22+DF22+DG22+DH22+DI22+DJ22+DK22+DL22+DO22+DP22+DQ22+DR22+DS22+DT22+DY22+EB22+EC22+ED22+EH22+EI22+EJ22+EK22+EL22+EM22+EN22+EO22+EP22+ER22+ES22+ET22+EU22+EV22+EW22+EY22+EZ22+FA22+FB22+FC22+FD22+FE22+FF22+FG22+FH22+FI22+FK22+FL22+FM22+FN22+FP22+FQ22+FR22+FU22+FV22+FW22+FX22+FY22+FZ22+GA22+GB22+GC22+GD22+GE22+GF22+GG22+GH22+GI22+GJ22+GK22+GL22+GM22) -> 49.95 | K22: =DX22+CS22 -> 0 | L22: =BN22-C22 -> 0 | M22: F2606017122 | N22: 46203 | O22: 9505289-C01 | P22: EXP20260602-2776061 | Q22: 2026 | R22: 26-06-0188575 | S22: EXP20260602-2776061 | T22: 26A060188575 | U22: DAP | V22: DOMESTIC | W22: DOMESTIC | X22: 34150 | Y22: MESS | Z22: EDI | AA22: 560 | AC22: 46177 | AD22: 21 | AE22: LA RUCHE LOGISTIQUE | AF22: EXP20260602-2776061 | AG22: FR | AH22: 21 | AI22: CREANCEY | AJ22: 46183 | AK22: Domaine de la grande sieste Leticia (ENTREPRISE) | AL22: EXP20260602-2776061 | AM22: FR | AN22: 34 | AO22: ANIANE | AR22: 1 | AS22: 1 | AT22: 67 | AU22: 67 | AV22: 0 | AW22: KG | AX22: 67 | AY22: 0 | BE22: PORTPAYE | BF22: STANDARD | BG22: EUR | BM22: 38.24 | BN22: 49.95 | BQ22: LSTANDARD | DI22: 9.56 | DK22: 2 | GM22: 0.15
B23: =IF(S23<>"",S23,T23) -> EXP20260603-2779296 | C23: =SUM(E23:K23) -> 140.23 | D23: =SUM(E23:L23) -> 140.23 | E23: =IF(BU23+BV23+BW23+CH23+CI23+CJ23+CK23+FO23+FS23+FT23=0,"",BU23+BV23+BW23+CH23+CI23+CJ23+CK23+FO23+FS23+FT23) | F23: =IF(FJ23=0,"",FJ23) | G23: =IF(CP23+DM23+DN23+EE23+EX23+EF23=0,"",CP23+DM23+DN23+EE23+EX23+EF23) | H23: =IF(DW23=0,"",DW23) | I23: =IF(DZ23+EA23+EG23=0,"",DZ23+EA23+EG23) | J23: =IF(BM23+BS23+BT23+BY23+BZ23+CA23+CB23+CC23+CD23+CE23+CF23+CG23+CL23+CM23+CN23+CO23+CQ23+CR23+CT23+CU23+CV23+CW23+CX23+CY23+CZ23+DA23+DB23+DC23+DD23+DE23+DF23+DG23+DH23+DI23+DJ23+DK23+DL23+DO23+DP23+DQ23+DR23+DS23+DT23+DY23+EB23+EC23+ED23+EH23+EI23+EJ23+EK23+EL23+EM23+EN23+EO23+EP23+ER23+ES23+ET23+EU23+EV23+EW23+EY23+EZ23+FA23+FB23+FC23+FD23+FE23+FF23+FG23+FH23+FI23+FK23+FL23+FM23+FN23+FP23+FQ23+FR23+FU23+FV23+FW23+FX23+FY23+FZ23+GA23+GB23+GC23+GD23+GE23+GF23+GG23+GH23+GI23+GJ23+GK23+GL23+GM23=0,"",BM23+BS23+BT23+BY23+BZ23+CA23+CB23+CC23+CD23+CE23+CF23+CG23+CL23+CM23+CN23+CO23+CQ23+CR23+CT23+CU23+CV23+CW23+CX23+CY23+CZ23+DA23+DB23+DC23+DD23+DE23+DF23+DG23+DH23+DI23+DJ23+DK23+DL23+DO23+DP23+DQ23+DR23+DS23+DT23+DY23+EB23+EC23+ED23+EH23+EI23+EJ23+EK23+EL23+EM23+EN23+EO23+EP23+ER23+ES23+ET23+EU23+EV23+EW23+EY23+EZ23+FA23+FB23+FC23+FD23+FE23+FF23+FG23+FH23+FI23+FK23+FL23+FM23+FN23+FP23+FQ23+FR23+FU23+FV23+FW23+FX23+FY23+FZ23+GA23+GB23+GC23+GD23+GE23+GF23+GG23+GH23+GI23+GJ23+GK23+GL23+GM23) -> 140.23 | K23: =DX23+CS23 -> 0 | L23: =BN23-C23 -> 0 | M23: F2606017122 | N23: 46203 | O23: 9505289-C01 | P23: EXP20260603-2779296 | Q23: 2026 | R23: 26-06-0188578 | S23: EXP20260603-2779296 | T23: 26A060188578 | U23: DAP | V23: DOMESTIC | W23: DOMESTIC | X23: 30127 | Y23: MESS | Z23: EDI | AA23: 540 | AC23: 46177 | AD23: 21 | AE23: LA RUCHE LOGISTIQUE | AF23: EXP20260603-2779296 | AG23: FR | AH23: 21 | AI23: CREANCEY | AJ23: 46181 | AK23: CHATEAU ST LOUIS LA PERDRIX CASTAN (ENTREPRISE) | AL23: EXP20260603-2779296 | AM23: FR | AN23: 30 | AO23: BELLEGARDE | AR23: 2 | AS23: 2 | AT23: 207 | AU23: 207 | AV23: 0 | AW23: Pal | AX23: 2 | AY23: 0 | BE23: PORTPAYE | BF23: STANDARD | BG23: EUR | BM23: 110.46 | BN23: 140.23 | BQ23: LSTANDARD | DI23: 27.62 | DK23: 2 | GM23: 0.15
B24: =IF(S24<>"",S24,T24) -> EXP20260602-2776687 | C24: =SUM(E24:K24) -> 40.14 | D24: =SUM(E24:L24) -> 40.14 | E24: =IF(BU24+BV24+BW24+CH24+CI24+CJ24+CK24+FO24+FS24+FT24=0,"",BU24+BV24+BW24+CH24+CI24+CJ24+CK24+FO24+FS24+FT24) | F24: =IF(FJ24=0,"",FJ24) | G24: =IF(CP24+DM24+DN24+EE24+EX24+EF24=0,"",CP24+DM24+DN24+EE24+EX24+EF24) | H24: =IF(DW24=0,"",DW24) | I24: =IF(DZ24+EA24+EG24=0,"",DZ24+EA24+EG24) | J24: =IF(BM24+BS24+BT24+BY24+BZ24+CA24+CB24+CC24+CD24+CE24+CF24+CG24+CL24+CM24+CN24+CO24+CQ24+CR24+CT24+CU24+CV24+CW24+CX24+CY24+CZ24+DA24+DB24+DC24+DD24+DE24+DF24+DG24+DH24+DI24+DJ24+DK24+DL24+DO24+DP24+DQ24+DR24+DS24+DT24+DY24+EB24+EC24+ED24+EH24+EI24+EJ24+EK24+EL24+EM24+EN24+EO24+EP24+ER24+ES24+ET24+EU24+EV24+EW24+EY24+EZ24+FA24+FB24+FC24+FD24+FE24+FF24+FG24+FH24+FI24+FK24+FL24+FM24+FN24+FP24+FQ24+FR24+FU24+FV24+FW24+FX24+FY24+FZ24+GA24+GB24+GC24+GD24+GE24+GF24+GG24+GH24+GI24+GJ24+GK24+GL24+GM24=0,"",BM24+BS24+BT24+BY24+BZ24+CA24+CB24+CC24+CD24+CE24+CF24+CG24+CL24+CM24+CN24+CO24+CQ24+CR24+CT24+CU24+CV24+CW24+CX24+CY24+CZ24+DA24+DB24+DC24+DD24+DE24+DF24+DG24+DH24+DI24+DJ24+DK24+DL24+DO24+DP24+DQ24+DR24+DS24+DT24+DY24+EB24+EC24+ED24+EH24+EI24+EJ24+EK24+EL24+EM24+EN24+EO24+EP24+ER24+ES24+ET24+EU24+EV24+EW24+EY24+EZ24+FA24+FB24+FC24+FD24+FE24+FF24+FG24+FH24+FI24+FK24+FL24+FM24+FN24+FP24+FQ24+FR24+FU24+FV24+FW24+FX24+FY24+FZ24+GA24+GB24+GC24+GD24+GE24+GF24+GG24+GH24+GI24+GJ24+GK24+GL24+GM24) -> 40.14 | K24: =DX24+CS24 -> 0 | L24: =BN24-C24 -> 0 | M24: F2606017122 | N24: 46203 | O24: 9505289-C01 | P24: EXP20260602-2776687 | Q24: 2026 | R24: 26-06-0188581 | S24: EXP20260602-2776687 | T24: 26A060188581 | U24: DAP | V24: DOMESTIC | W24: DOMESTIC | X24: 84350 | Y24: MESS | Z24: EDI | AA24: 468 | AC24: 46177 | AD24: 21 | AE24: LA RUCHE LOGISTIQUE | AF24: EXP20260602-2776687 | AG24: FR | AH24: 21 | AI24: CREANCEY | AJ24: 46181 | AK24: EARL LE CLOS BONVIN JEAN CLAUDE (ENTREPRISE) | AL24: EXP20260602-2776687 | AM24: FR | AN24: 84 | AO24: COURTHEZON | AR24: 1 | AS24: 1 | AT24: 32 | AU24: 32 | AV24: 0 | AW24: KG | AX24: 32 | AY24: 0 | BE24: PORTPAYE | BF24: STANDARD | BG24: EUR | BM24: 30.39 | BN24: 40.14 | BQ24: LSTANDARD | DI24: 7.6 | DK24: 2 | GM24: 0.15
B25: =IF(S25<>"",S25,T25) -> EXP20260602-2775732 | C25: =SUM(E25:K25) -> 48.75 | D25: =SUM(E25:L25) -> 48.75 | E25: =IF(BU25+BV25+BW25+CH25+CI25+CJ25+CK25+FO25+FS25+FT25=0,"",BU25+BV25+BW25+CH25+CI25+CJ25+CK25+FO25+FS25+FT25) | F25: =IF(FJ25=0,"",FJ25) | G25: =IF(CP25+DM25+DN25+EE25+EX25+EF25=0,"",CP25+DM25+DN25+EE25+EX25+EF25) | H25: =IF(DW25=0,"",DW25) | I25: =IF(DZ25+EA25+EG25=0,"",DZ25+EA25+EG25) | J25: =IF(BM25+BS25+BT25+BY25+BZ25+CA25+CB25+CC25+CD25+CE25+CF25+CG25+CL25+CM25+CN25+CO25+CQ25+CR25+CT25+CU25+CV25+CW25+CX25+CY25+CZ25+DA25+DB25+DC25+DD25+DE25+DF25+DG25+DH25+DI25+DJ25+DK25+DL25+DO25+DP25+DQ25+DR25+DS25+DT25+DY25+EB25+EC25+ED25+EH25+EI25+EJ25+EK25+EL25+EM25+EN25+EO25+EP25+ER25+ES25+ET25+EU25+EV25+EW25+EY25+EZ25+FA25+FB25+FC25+FD25+FE25+FF25+FG25+FH25+FI25+FK25+FL25+FM25+FN25+FP25+FQ25+FR25+FU25+FV25+FW25+FX25+FY25+FZ25+GA25+GB25+GC25+GD25+GE25+GF25+GG25+GH25+GI25+GJ25+GK25+GL25+GM25=0,"",BM25+BS25+BT25+BY25+BZ25+CA25+CB25+CC25+CD25+CE25+CF25+CG25+CL25+CM25+CN25+CO25+CQ25+CR25+CT25+CU25+CV25+CW25+CX25+CY25+CZ25+DA25+DB25+DC25+DD25+DE25+DF25+DG25+DH25+DI25+DJ25+DK25+DL25+DO25+DP25+DQ25+DR25+DS25+DT25+DY25+EB25+EC25+ED25+EH25+EI25+EJ25+EK25+EL25+EM25+EN25+EO25+EP25+ER25+ES25+ET25+EU25+EV25+EW25+EY25+EZ25+FA25+FB25+FC25+FD25+FE25+FF25+FG25+FH25+FI25+FK25+FL25+FM25+FN25+FP25+FQ25+FR25+FU25+FV25+FW25+FX25+FY25+FZ25+GA25+GB25+GC25+GD25+GE25+GF25+GG25+GH25+GI25+GJ25+GK25+GL25+GM25) -> 48.75 | K25: =DX25+CS25 -> 0 | L25: =BN25-C25 -> 0 | M25: F2606017122 | N25: 46203 | O25: 9505289-C01 | P25: EXP20260602-2775732 | Q25: 2026 | R25: 26-06-0188583 | S25: EXP20260602-2775732 | T25: 26A060188583 | U25: DAP | V25: DOMESTIC | W25: DOMESTIC | X25: 66310 | Y25: MESS | Z25: EDI | AA25: 725 | AC25: 46177 | AD25: 21 | AE25: LA RUCHE LOGISTIQUE | AF25: EXP20260602-2775732 | AG25: FR | AH25: 21 | AI25: CREANCEY | AJ25: 46182 | AK25: GAEC DOMAINE DEVEZA JORDAN DEVEZA (ENTREPRISE) | AL25: EXP20260602-2775732 | AM25: FR | AN25: 66 | AO25: ESTAGEL | AR25: 1 | AS25: 1 | AT25: 46 | AU25: 46 | AV25: 0 | AW25: KG | AX25: 46 | AY25: 0 | BE25: PORTPAYE | BF25: STANDARD | BG25: EUR | BM25: 37.28 | BN25: 48.75 | BQ25: LSTANDARD | DI25: 9.32 | DK25: 2 | GM25: 0.15
B26: =IF(S26<>"",S26,T26) -> EXP20260602-2776126 | C26: =SUM(E26:K26) -> 62.48 | D26: =SUM(E26:L26) -> 62.48 | E26: =IF(BU26+BV26+BW26+CH26+CI26+CJ26+CK26+FO26+FS26+FT26=0,"",BU26+BV26+BW26+CH26+CI26+CJ26+CK26+FO26+FS26+FT26) | F26: =IF(FJ26=0,"",FJ26) | G26: =IF(CP26+DM26+DN26+EE26+EX26+EF26=0,"",CP26+DM26+DN26+EE26+EX26+EF26) | H26: =IF(DW26=0,"",DW26) | I26: =IF(DZ26+EA26+EG26=0,"",DZ26+EA26+EG26) | J26: =IF(BM26+BS26+BT26+BY26+BZ26+CA26+CB26+CC26+CD26+CE26+CF26+CG26+CL26+CM26+CN26+CO26+CQ26+CR26+CT26+CU26+CV26+CW26+CX26+CY26+CZ26+DA26+DB26+DC26+DD26+DE26+DF26+DG26+DH26+DI26+DJ26+DK26+DL26+DO26+DP26+DQ26+DR26+DS26+DT26+DY26+EB26+EC26+ED26+EH26+EI26+EJ26+EK26+EL26+EM26+EN26+EO26+EP26+ER26+ES26+ET26+EU26+EV26+EW26+EY26+EZ26+FA26+FB26+FC26+FD26+FE26+FF26+FG26+FH26+FI26+FK26+FL26+FM26+FN26+FP26+FQ26+FR26+FU26+FV26+FW26+FX26+FY26+FZ26+GA26+GB26+GC26+GD26+GE26+GF26+GG26+GH26+GI26+GJ26+GK26+GL26+GM26=0,"",BM26+BS26+BT26+BY26+BZ26+CA26+CB26+CC26+CD26+CE26+CF26+CG26+CL26+CM26+CN26+CO26+CQ26+CR26+CT26+CU26+CV26+CW26+CX26+CY26+CZ26+DA26+DB26+DC26+DD26+DE26+DF26+DG26+DH26+DI26+DJ26+DK26+DL26+DO26+DP26+DQ26+DR26+DS26+DT26+DY26+EB26+EC26+ED26+EH26+EI26+EJ26+EK26+EL26+EM26+EN26+EO26+EP26+ER26+ES26+ET26+EU26+EV26+EW26+EY26+EZ26+FA26+FB26+FC26+FD26+FE26+FF26+FG26+FH26+FI26+FK26+FL26+FM26+FN26+FP26+FQ26+FR26+FU26+FV26+FW26+FX26+FY26+FZ26+GA26+GB26+GC26+GD26+GE26+GF26+GG26+GH26+GI26+GJ26+GK26+GL26+GM26) -> 62.48 | K26: =DX26+CS26 -> 0 | L26: =BN26-C26 -> 0 | M26: F2606017122 | N26: 46203 | O26: 9505289-C01 | P26: EXP20260602-2776126 | Q26: 2026 | R26: 26-06-0188587 | S26: EXP20260602-2776126 | T26: 26A060188587 | U26: DAP | V26: DOMESTIC | W26: DOMESTIC | X26: 34290 | Y26: MESS | Z26: EDI | AA26: 695 | AC26: 46177 | AD26: 21 | AE26: LA RUCHE LOGISTIQUE | AF26: EXP20260602-2776126 | AG26: FR | AH26: 21 | AI26: CREANCEY | AJ26: 46182 | AK26: BRUNO ANDREU | AL26: EXP20260602-2776126 | AM26: FR | AN26: 34 | AO26: MONTBLANC | AR26: 1 | AS26: 1 | AT26: 112 | AU26: 112 | AV26: 0 | AW26: KG | AX26: 112 | AY26: 0 | BE26: PORTPAYE | BF26: STANDARD | BG26: EUR | BM26: 48.26 | BN26: 62.48 | BQ26: LSTANDARD | DI26: 12.07 | DK26: 2 | GM26: 0.15
B27: =IF(S27<>"",S27,T27) -> EXP20260602-2777127 | C27: =SUM(E27:K27) -> 43.15 | D27: =SUM(E27:L27) -> 43.15 | E27: =IF(BU27+BV27+BW27+CH27+CI27+CJ27+CK27+FO27+FS27+FT27=0,"",BU27+BV27+BW27+CH27+CI27+CJ27+CK27+FO27+FS27+FT27) | F27: =IF(FJ27=0,"",FJ27) | G27: =IF(CP27+DM27+DN27+EE27+EX27+EF27=0,"",CP27+DM27+DN27+EE27+EX27+EF27) | H27: =IF(DW27=0,"",DW27) | I27: =IF(DZ27+EA27+EG27=0,"",DZ27+EA27+EG27) | J27: =IF(BM27+BS27+BT27+BY27+BZ27+CA27+CB27+CC27+CD27+CE27+CF27+CG27+CL27+CM27+CN27+CO27+CQ27+CR27+CT27+CU27+CV27+CW27+CX27+CY27+CZ27+DA27+DB27+DC27+DD27+DE27+DF27+DG27+DH27+DI27+DJ27+DK27+DL27+DO27+DP27+DQ27+DR27+DS27+DT27+DY27+EB27+EC27+ED27+EH27+EI27+EJ27+EK27+EL27+EM27+EN27+EO27+EP27+ER27+ES27+ET27+EU27+EV27+EW27+EY27+EZ27+FA27+FB27+FC27+FD27+FE27+FF27+FG27+FH27+FI27+FK27+FL27+FM27+FN27+FP27+FQ27+FR27+FU27+FV27+FW27+FX27+FY27+FZ27+GA27+GB27+GC27+GD27+GE27+GF27+GG27+GH27+GI27+GJ27+GK27+GL27+GM27=0,"",BM27+BS27+BT27+BY27+BZ27+CA27+CB27+CC27+CD27+CE27+CF27+CG27+CL27+CM27+CN27+CO27+CQ27+CR27+CT27+CU27+CV27+CW27+CX27+CY27+CZ27+DA27+DB27+DC27+DD27+DE27+DF27+DG27+DH27+DI27+DJ27+DK27+DL27+DO27+DP27+DQ27+DR27+DS27+DT27+DY27+EB27+EC27+ED27+EH27+EI27+EJ27+EK27+EL27+EM27+EN27+EO27+EP27+ER27+ES27+ET27+EU27+EV27+EW27+EY27+EZ27+FA27+FB27+FC27+FD27+FE27+FF27+FG27+FH27+FI27+FK27+FL27+FM27+FN27+FP27+FQ27+FR27+FU27+FV27+FW27+FX27+FY27+FZ27+GA27+GB27+GC27+GD27+GE27+GF27+GG27+GH27+GI27+GJ27+GK27+GL27+GM27) -> 43.15 | K27: =DX27+CS27 -> 0 | L27: =BN27-C27 -> 0 | M27: F2606017122 | N27: 46203 | O27: 9505289-C01 | P27: EXP20260602-2777127 | Q27: 2026 | R27: 26-06-0188590 | S27: EXP20260602-2777127 | T27: 26A060188590 | U27: DAP | V27: DOMESTIC | W27: DOMESTIC | X27: 30610 | Y27: MESS | Z27: EDI | AA27: 540 | AC27: 46177 | AD27: 21 | AE27: LA RUCHE LOGISTIQUE | AF27: EXP20260602-2777127 | AG27: FR | AH27: 21 | AI27: CREANCEY | AJ27: 46188 | AK27: SAS CHATEAU PUECH LONG FRIZON Lione (ENTREPRISE) | AL27: EXP20260602-2777127 | AM27: FR | AN27: 30 | AO27: ST NAZAIRE DES GARDIES | AR27: 1 | AS27: 1 | AT27: 45 | AU27: 45 | AV27: 0 | AW27: KG | AX27: 45 | AY27: 0 | BE27: PORTPAYE | BF27: STANDARD | BG27: EUR | BM27: 32.8 | BN27: 43.15 | BQ27: LSTANDARD | DI27: 8.2 | DK27: 2 | GM27: 0.15
