Workbook

Sheet Pays TVA
A1: AT | B1: 0.2
A2: BE | B2: 0.2
A3: CH | B3: 0
A4: DE | B4: 0.2
A5: ES | B5: 0.2
A6: GB | B6: 0
A7: GR | B7: 0.2
A8: IT | B8: 0.2
A9: LU | B9: 0.2
A10: NL | B10: 0.2
A11: PF | B11: 0

Sheet Sous-comptes
A1: 0 | B1: La Ruche
A2: 1 | B2: Ker Sun
A3: 2 | B3: Foutas
A4: 5
A5: 6

Sheet Bibliothèque transporteurs
A1: mode envoi ERP | B1: zone ERP | C1: produit chrono | D1: zone Chrono | E1: Transporteur
A2: 16 | B2: 16 | C2: 1 | E2: CHRONOPOST
A3: 2 | B3: 2 | C3: 2 | E3: CHRONOPOST
A4: 17 | B4: 17 | C4: 17 | E4: CHRONOPOST
A5: 44 | B5: 44 | C5: 44 | E5: CHRONOPOST
A6: 86 | B6: 86 | C6: 86 | E6: CHRONOPOST
A7: 16 | B7: 16 | C7: 2L | E7: CHRONOPOST
A8: 16 | B8: 16 | C8: 3Z | E8: CHRONOPOST
A9: 5X | B9: 5X | C9: 5X | E9: CHRONO_2SHOP
A10: 5Y | B10: 5Y | C10: 5Y | E10: CHRONO_2SHOP
A11: 6B | B11: 6B | C11: 6B | E11: CHRONO_2SHOP
A12: 6C | B12: 6C | C12: 6C | E12: CHRONO_2SHOP
A13: 1S | B13: 1S | C13: 1S | E13: CHRONOPOST
A14: 16 | B14: 16 | C14: 16 | E14: CHRONOPOST
A15: 5X | B15: 5X | C15: 5XK | E15: CHRONO_2SHOP_KERSUN
A16: 5Y | B16: 5Y | C16: 5YK | E16: CHRONO_2SHOP_KERSUN
A17: 6B | B17: 6B | C17: 6BK | E17: CHRONO_2SHOP_KERSUN
A18: 6C | B18: 6C | C18: 6CK | E18: CHRONO_2SHOP_KERSUN

Sheet Catégories
A1: Assurance | B1: Assurance
A2: CAP RouteCAP ROUTE | B2: Gazole
A3: Correction d'adresse | B3: Adresse
A4: Eco responsablePar | B4: Frêt
A5: ESD | B5: Gazole
A6: Frais de gestion | B6: Frais facturation
A7: Participation Eco-Responsable | B7: Frêt
A8: Supp Retour Expediteur Europe | B8: Frêt
A9: Supp Retour Expediteur Inter | B9: Frêt
A10: Supp Zone Internationale Eloignee | B10: Zones éloignées
A11: Supplement Annonce incomplète | B11: Adresse | G11: Adresse
A12: Supplement Corse | B12: Zones éloignées | G12: Gazole
A13: Supplement Corse 18h | B13: Corse | G13: Frais facturation
A14: Supplement domicile prive | B14: Zones éloignées | G14: Frêt
A15: Supplement Douane Zone C2 | B15: Droits et taxes | G15: Zones éloignées
A16: Supplement Douane Zone C4 | B16: Droits et taxes
A17: Supplement Etiquette Non Conforme | B17: Frêt | G17: Corse
A18: Supplement Forfait Expedition | B18: Frêt
A19: Supplement GT | B19: Frêt | G19: Droits et taxes
A20: Supplement Hors Norme | B20: Colis volumineux | G20: Colis volumineux
A21: Supplement Manutention | B21: Colis volumineux
A22: Supplement Retour Expediteur | B22: Frêt
A23: Supplement Retrait Bureau | B23: Zones éloignées
A24: Surcharge Carburant Aérien | B24: Gazole
A25: Surcharge Carburant Routier | B25: Gazole
A26: Surcharge Facture Papier | B26: Frais facturation
A27: Sûreté colis | B27: Frêt
A28: Traitement Réacheminement | B28: Frêt
A29: Traitement SAV complémentaire | B29: Adresse
A30: Transport | B30: Frêt
A31: Transport encompte | B31: Frêt
A32: Sûreté étendue | B32: Frêt
A33: Zones Difficiles d'accès | B33: Zones éloignées

Sheet TARIFS
C3: Tarifs LA RUCHE LOGISTIQUE
C4: C18 BAL | F4: C18 IR | I4: RELAIS
C7: OFFRE | F7: OFFRE | I7: OFFRE
C8: NAT | D8: REG/DEP | F8: NAT | G8: REG/DEP | I8: NAT | J8: REG/DEP
A10: 1er kg | C10: 6.5 | D10: =C10 | F10: 6.9 | G10: 6.9 | I10: 3.9 | J10: 3.9
A11: kg sup 1-2 | C11: 0.9 | D11: 0.9 | F11: 0.9 | G11: 0.9 | I11: 0.8 | J11: 0.8
A12: kg sup 2-3 | C12: 0.4 | D12: 0.4 | F12: 0.45 | G12: 0.45 | I12: 0.35 | J12: 0.35
A13: kg sup 3-5 | C13: 0.4 | D13: 0.4 | F13: 0.45 | G13: 0.45 | I13: 0.43 | J13: 0.43
A14: kg sup 5-10 | C14: 0.4 | D14: 0.4 | F14: 0.5 | G14: 0.5 | I14: 0.47 | J14: 0.47
A15: kg sup 10-15 | C15: 0.4 | D15: 0.4 | F15: 0.5 | G15: 0.5 | I15: 0.78 | J15: 0.78
A16: kg sup 15-20 | C16: 0.4 | D16: 0.4 | F16: 0.5 | G16: 0.5 | I16: 0.78 | J16: 0.78
A17: kg sup 20-30 | C17: 0.4 | D17: 0.4 | F17: 0.5 | G17: 0.5 | I17: 0.78 | J17: 0.78
A18: kg sup 30-999 | C18: 0.4 | D18: 0.4 | F18: 0.5 | G18: 0.5
A20: 1 | C20: =C10 | D20: =D10 | F20: =F10 | G20: =G10 | I20: =I10 | J20: =J10
A21: 2 | C21: =C20+C11 | D21: =D20+D11 | F21: =F20+F11 | G21: =G20+G11 | I21: =I20+I11 | J21: =J20+J11
A22: =+A21+1 | C22: =C21+C12 | D22: =D21+D12 | F22: =F21+F12 | G22: =G21+G12 | I22: =I21+I12 | J22: =J21+J12
A23: =+A22+1 | C23: =C22+C13 | D23: =D22+D13 | F23: =F22+F13 | G23: =G22+G13 | I23: =I22+I13 | J23: =J22+J13
A24: =+A23+1 | C24: =C23+C13 | D24: =D23+D13 | F24: =F23+F13 | G24: =G23+G13 | I24: =I23+I13 | J24: =J23+J13
A25: =+A24+1 | C25: =C24+$C$14 | D25: =D24+$D$14 | F25: =F24+$F$14 | G25: =G24+$G$14 | I25: =I24+$I$14 | J25: =J24+$J$14
A26: =+A25+1 | C26: =C25+$C$14 | D26: =D25+$D$14 | F26: =F25+$F$14 | G26: =G25+$G$14 | I26: =I25+$I$14 | J26: =J25+$J$14
A27: =+A26+1 | C27: =C26+$C$14 | D27: =D26+$D$14 | F27: =F26+$F$14 | G27: =G26+$G$14 | I27: =I26+$I$14 | J27: =J26+$J$14
A28: =+A27+1 | C28: =C27+$C$14 | D28: =D27+$D$14 | F28: =F27+$F$14 | G28: =G27+$G$14 | I28: =I27+$I$14 | J28: =J27+$J$14
A29: =+A28+1 | C29: =C28+$C$14 | D29: =D28+$D$14 | F29: =F28+$F$14 | G29: =G28+$G$14 | I29: =I28+$I$14 | J29: =J28+$J$14
A30: =+A29+1 | C30: =C29+$C$15 | D30: =D29+$D$15 | F30: =F29+$F$15 | G30: =G29+$G$15 | I30: =I29+$I$15 | J30: =J29+$J$15
A31: =+A30+1 | C31: =C30+$C$15 | D31: =D30+$D$15 | F31: =F30+$F$15 | G31: =G30+$G$15 | I31: =I30+$I$15 | J31: =J30+$J$15
A32: =+A31+1 | C32: =C31+$C$15 | D32: =D31+$D$15 | F32: =F31+$F$15 | G32: =G31+$G$15 | I32: =I31+$I$15 | J32: =J31+$J$15
A33: =+A32+1 | C33: =C32+$C$15 | D33: =D32+$D$15 | F33: =F32+$F$15 | G33: =G32+$G$15 | I33: =I32+$I$15 | J33: =J32+$J$15
A34: =+A33+1 | C34: =C33+$C$15 | D34: =D33+$D$15 | F34: =F33+$F$15 | G34: =G33+$G$15 | I34: =I33+$I$15 | J34: =J33+$J$15
A35: =+A34+1 | C35: =C34+$C$16 | D35: =D34+$D$16 | F35: =F34+$F$16 | G35: =G34+$G$16 | I35: =I34+$I$16 | J35: =J34+$J$16
A36: =+A35+1 | C36: =C35+$C$16 | D36: =D35+$D$16 | F36: =F35+$F$16 | G36: =G35+$G$16 | I36: =I35+$I$16 | J36: =J35+$J$16
A37: =+A36+1 | C37: =C36+$C$16 | D37: =D36+$D$16 | F37: =F36+$F$16 | G37: =G36+$G$16 | I37: =I36+$I$16 | J37: =J36+$J$16
A38: =+A37+1 | C38: =C37+$C$16 | D38: =D37+$D$16 | F38: =F37+$F$16 | G38: =G37+$G$16 | I38: =I37+$I$16 | J38: =J37+$J$16
A39: =+A38+1 | C39: =C38+$C$16 | D39: =D38+$D$16 | F39: =F38+$F$16 | G39: =G38+$G$16 | I39: =I38+$I$16 | J39: =J38+$J$16
A40: =+A39+1 | C40: =C39+$C$17 | D40: =D39+$D$17 | F40: =F39+$F$17 | G40: =G39+$G$17 | I40: =I39+$I$17 | J40: =J39+$J$17
A41: =+A40+1 | C41: =C40+$C$17 | D41: =D40+$D$17 | F41: =F40+$F$17 | G41: =G40+$G$17 | I41: =I40+$I$17 | J41: =J40+$J$17
A42: =+A41+1 | C42: =C41+$C$17 | D42: =D41+$D$17 | F42: =F41+$F$17 | G42: =G41+$G$17 | I42: =I41+$I$17 | J42: =J41+$J$17
A43: =+A42+1 | C43: =C42+$C$17 | D43: =D42+$D$17 | F43: =F42+$F$17 | G43: =G42+$G$17 | I43: =I42+$I$17 | J43: =J42+$J$17
A44: =+A43+1 | C44: =C43+$C$17 | D44: =D43+$D$17 | F44: =F43+$F$17 | G44: =G43+$G$17 | I44: =I43+$I$17 | J44: =J43+$J$17
A45: =+A44+1 | C45: =C44+$C$17 | D45: =D44+$D$17 | F45: =F44+$F$17 | G45: =G44+$G$17 | I45: =I44+$I$17 | J45: =J44+$J$17
A46: =+A45+1 | C46: =C45+$C$17 | D46: =D45+$D$17 | F46: =F45+$F$17 | G46: =G45+$G$17 | I46: =I45+$I$17 | J46: =J45+$J$17
...

Sheet cap à 5%
A1: Pour intégration dans Outil Surcharge carburant :
A3: Date indice référence : | C3: 44166
A4: Pas de chaque tranche d'indice : | C4: 0.025
A5: Surcote ou sous cote départ : | C5: 0.05
A6: Surcote ou sous cote tranche : | C6: 0.0025
A13: Pour intégration dans le contrat :
A15: type surcharge | B15: Routier
A16: type indice | B16: Pompe CNR moyenne mensuelle
A17: périodicité | B17: Mensuelle
A18: date indice référence | B18: 44166
A20: Litre de Gazole strictement supérieur à | B20: Litre de Gazole inférieur ou égal à | C20: % de surcharge applicable
A21: 0 | B21: 1.0475 | C21: 0.05
A22: 1.0475 | B22: 1.0725 | C22: 0.0525
A23: 1.0725 | B23: 1.0975 | C23: 0.055
A24: 1.0975 | B24: 1.1225 | C24: 0.0575
A25: 1.1225 | B25: 1.1475 | C25: 0.06
A26: 1.1475 | B26: 1.1725 | C26: 0.0625
A27: 1.1725 | B27: 1.1975 | C27: 0.065
A28: 1.1975 | B28: 1.2225 | C28: 0.0675
A29: 1.2225 | B29: 1.2475 | C29: 0.07
A30: 1.2475 | B30: 1.2725 | C30: 0.0725
A31: 1.2725 | B31: 1.2975 | C31: 0.075
A32: 1.2975 | B32: 1.3225 | C32: 0.0775
... A57: 1.9225 | B57: 1.9475 | C57: 0.14
A59: Par tranche supp | B59: 0.025 | C59: 0.0025

Sheet Contrôle pdf
A3: Étiquettes de lignes | B3: Somme de Montant HT | C3: pdf | D3: écarts
A4: 13617721 | B4: 4555.12 | C4: 4555.12 | D4: =B4-C4
A5: 13617722 | B5: 21.68 | C5: 21.68 | D5: =B5-C5
A6: 13617723 | B6: 6688.75 | C6: 6688.75 | D6: =B6-C6
A7: 13624019 | B7: 1487.32 | C7: 1487.32 | D7: =B7-C7
A8: 13624020 | B8: 142.46 | C8: 142.46 | D8: =B8-C8
A9: 13624021 | B9: 8246.49 | C9: 8246.49 | D9: =B9-C9
A10: (vide) | D10: =B10-C10
A11: Total général | B11: 21141.82 | C11: =SUM(C4:C10) | D11: =B11-C11
D12: =B12-C12

Sheet Zoning 2shop
A1: 6B | C1: 6C
A2: AT | B2: 1 | C2: AT | D2: 25
A3: BE | B3: 2 | C3: BE | D3: 26
A4: BG | B4: 3 | C4: BG | D4: 27
A5: CH | B5: 4 | C5: CH | D5: 28
A6: CZ | B6: 5 | C6: CZ | D6: 29
A7: DE | B7: 6 | C7: DE | D7: 30
A8: DK | B8: 7 | C8: DK | D8: 25
A9: EE | B9: 8 | C9: EE | D9: 27
A10: ES | B10: 9 | C10: ES | D10: 33
A11: FI | B11: 8 | C11: FI | D11: 27
A12: HR | B12: 8 | C12: HR | D12: 27
A13: HU | B13: 8 | C13: HU | D13: 28
... A25: SK | B25: 24 | C25: SK | D25: 25

Sheet Facture Chronopost
A1: ID Clients | B1: No Facture | C1: Sous-compte | D1: Date LT | E1: Code postal depart | F1: Code postal arrivee | G1: Pays depart | H1: Pays arrivee | I1: Ref Destinataire | J1: Ref Expediteur | K1: No Groupage tarifaire | L1: Numero LT | M1: Groupage | N1: Type prestation | O1: TVA | P1: Observations | Q1: Zone Tarifaire | R1: Poids | S1: Produit | T1: Montant HT | U1: Raison sociale | V1: Raison sociale 2 | W1: Code produit modifié | X1: Zoning 2shop | Y1: Gazole % | Z1: frêt | AA1: sureté + eco | AB1: gazole | AC1: hors gazole | AD1: Catégories | AE1: Total avec GO | AF1: Total | AG1: =SUM(AG2:AG6) | AI1: Passer la colonne S en "nombre"
B2: 13617723 | C2: 0 | D2: 46173 | K2: 0 | L2: CAPI1 | M2: X | N2: Surcharge Carburant Aérien | O2: I | P2: 0.4375 | Q2: XX | R2: 0 | S2: X | T2: 42.11 | U2: LA RUCHE LOGISTIQUE | W2: =IF(C2<>2,"",IF(S2="5X","5XK",IF(S2="5Y","5YK",IF(S2="6B","6BK",IF(S2="6C","6CK",""))))) | X2: =IF(S2="6B",_xlfn.XLOOKUP(H2,'Zoning 2shop'!A:A,'Zoning 2shop'!B:B),IF(S2="6C",_xlfn.XLOOKUP(G2,'Zoning 2shop'!C:C,'Zoning 2shop'!D:D),"")) | Y2: =AB2/Z2 | Z2: =T2 | AA2: =IF(OR(S2="6C",S2="6B",S2="5X",S2="5Y"),0.08,0.5) | AB2: =$AG$5/$AG$2*Z2 | AC2: =Z2+AA2 | AD2: =IF(COUNTIF(Catégories!A:A,N2)=0,"catégorie inconnue",LOOKUP(N2,Catégories!A:A,Catégories!B:B)) | AE2: =SUM(Z2:AB2) | AF2: Frêt | AG2: =SUM(T28:T3000)
B3: 13617723 | C3: 0 | D3: 46173 | K3: 0 | L3: CAPI2 | M3: X | N3: Surcharge Carburant Routier | O3: I | P3: 0.1425 | Q3: XX | R3: 0 | S3: X | T3: 55.57 | U3: LA RUCHE LOGISTIQUE | W3: =IF(C3<>2,"",IF(S3="5X","5XK",IF(S3="5Y","5YK",IF(S3="6B","6BK",IF(S3="6C","6CK",""))))) | X3: =IF(S3="6B",_xlfn.XLOOKUP(H3,'Zoning 2shop'!A:A,'Zoning 2shop'!B:B),IF(S3="6C",_xlfn.XLOOKUP(G3,'Zoning 2shop'!C:C,'Zoning 2shop'!D:D),"")) | Y3: =AB3/Z3 | Z3: =T3 | AA3: =IF(OR(S3="6C",S3="6B",S3="5X",S3="5Y"),0.08,0.5) | AB3: =$AG$5/$AG$2*Z3 | AC3: =Z3+AA3 | AD3: =IF(COUNTIF(Catégories!A:A,N3)=0,"catégorie inconnue",LOOKUP(N3,Catégories!A:A,Catégories!B:B)) | AE3: =SUM(Z3:AB3) | AF3: eco | AG3: =SUM(T12:T19)
B4: 13617723 | C4: 0 | D4: 46173 | K4: 0 | L4: CAPN1 | M4: X | N4: Surcharge Carburant Aérien | O4: N | P4: 0.4375 | Q4: XX | R4: 0 | S4: X | T4: 1534.86 | U4: LA RUCHE LOGISTIQUE | W4: =IF(C4<>2,"",IF(S4="5X","5XK",IF(S4="5Y","5YK",IF(S4="6B","6BK",IF(S4="6C","6CK",""))))) | X4: =IF(S4="6B",_xlfn.XLOOKUP(H4,'Zoning 2shop'!A:A,'Zoning 2shop'!B:B),IF(S4="6C",_xlfn.XLOOKUP(G4,'Zoning 2shop'!C:C,'Zoning 2shop'!D:D),"")) | Y4: =AB4/Z4 | Z4: =T4 | AA4: =IF(OR(S4="6C",S4="6B",S4="5X",S4="5Y"),0.08,0.5) | AB4: =$AG$5/$AG$2*Z4 | AC4: =Z4+AA4 | AD4: =IF(COUNTIF(Catégories!A:A,N4)=0,"catégorie inconnue",LOOKUP(N4,Catégories!A:A,Catégories!B:B)) | AE4: =SUM(Z4:AB4) | AF4: sureté | AG4: =SUM(T20:T27)
B5: 13624019 | C5: 2 | D5: 46173 | K5: 0 | L5: CAPN2 | M5: X | N5: Surcharge Carburant Routier | O5: N | P5: 0.0475 | Q5: XX | R5: 0 | S5: X | T5: 66.13 | U5: LA RUCHE LOGISTIQUE | W5: =IF(C5<>2,"",IF(S5="5X","5XK",IF(S5="5Y","5YK",IF(S5="6B","6BK",IF(S5="6C","6CK",""))))) | X5: =IF(S5="6B",_xlfn.XLOOKUP(H5,'Zoning 2shop'!A:A,'Zoning 2shop'!B:B),IF(S5="6C",_xlfn.XLOOKUP(G5,'Zoning 2shop'!C:C,'Zoning 2shop'!D:D),"")) | Y5: =AB5/Z5 | Z5: =T5 | AA5: =IF(OR(S5="6C",S5="6B",S5="5X",S5="5Y"),0.08,0.5) | AB5: =$AG$5/$AG$2*Z5 | AC5: =Z5+AA5 | AD5: =IF(COUNTIF(Catégories!A:A,N5)=0,"catégorie inconnue",LOOKUP(N5,Catégories!A:A,Catégories!B:B)) | AE5: =SUM(Z5:AB5) | AF5: Gazole | AG5: =SUM(T2:T11) | AH5: =AG5/AG2
B6: 13624020 | C6: 0 | D6: 46173 | K6: 0 | L6: CAPN2 | M6: X | N6: Surcharge Carburant Routier | O6: N | P6: 0.0475 | Q6: XX | R6: 0 | S6: X | T6: 6.43 | U6: LA RUCHE LOGISTIQUE | W6: =IF(C6<>2,"",IF(S6="5X","5XK",IF(S6="5Y","5YK",IF(S6="6B","6BK",IF(S6="6C","6CK",""))))) | X6: =IF(S6="6B",_xlfn.XLOOKUP(H6,'Zoning 2shop'!A:A,'Zoning 2shop'!B:B),IF(S6="6C",_xlfn.XLOOKUP(G6,'Zoning 2shop'!C:C,'Zoning 2shop'!D:D),"")) | Y6: =AB6/Z6 | Z6: =T6 | AA6: =IF(OR(S6="6C",S6="6B",S6="5X",S6="5Y"),0.08,0.5) | AB6: =$AG$5/$AG$2*Z6 | AC6: =Z6+AA6 | AD6: =IF(COUNTIF(Catégories!A:A,N6)=0,"catégorie inconnue",LOOKUP(N6,Catégories!A:A,Catégories!B:B)) | AE6: =SUM(Z6:AB6) | AF6: Gestion
B7: 13624021 | C7: 2 | D7: 46173 | K7: 0 | L7: CAPN2 | M7: X | N7: Surcharge Carburant Routier | O7: N | P7: 0.0475 | Q7: XX | R7: 0 | S7: X | T7: 371.42 | U7: LA RUCHE LOGISTIQUE | W7: =IF(C7<>2,"",IF(S7="5X","5XK",IF(S7="5Y","5YK",IF(S7="6B","6BK",IF(S7="6C","6CK",""))))) | X7: =IF(S7="6B",_xlfn.XLOOKUP(H7,'Zoning 2shop'!A:A,'Zoning 2shop'!B:B),IF(S7="6C",_xlfn.XLOOKUP(G7,'Zoning 2shop'!C:C,'Zoning 2shop'!D:D),"")) | Y7: =AB7/Z7 | Z7: =T7 | AA7: =IF(OR(S7="6C",S7="6B",S7="5X",S7="5Y"),0.08,0.5) | AB7: =$AG$5/$AG$2*Z7 | AC7: =Z7+AA7 | AD7: =IF(COUNTIF(Catégories!A:A,N7)=0,"catégorie inconnue",LOOKUP(N7,Catégories!A:A,Catégories!B:B)) | AE7: =SUM(Z7:AB7)
B8: 13617721 | C8: 0 | D8: 46173 | K8: 0 | L8: CAPN2 | M8: X | N8: Surcharge Carburant Routier | O8: N | P8: 0.1425 | Q8: XX | R8: 0 | S8: X | T8: 560.45 | U8: LA RUCHE LOGISTIQUE | W8: =IF(C8<>2,"",IF(S8="5X","5XK",IF(S8="5Y","5YK",IF(S8="6B","6BK",IF(S8="6C","6CK",""))))) | X8: =IF(S8="6B",_xlfn.XLOOKUP(H8,'Zoning 2shop'!A:A,'Zoning 2shop'!B:B),IF(S8="6C",_xlfn.XLOOKUP(G8,'Zoning 2shop'!C:C,'Zoning 2shop'!D:D),"")) | Y8: =AB8/Z8 | Z8: =T8 | AA8: =IF(OR(S8="6C",S8="6B",S8="5X",S8="5Y"),0.08,0.5) | AB8: =$AG$5/$AG$2*Z8 | AC8: =Z8+AA8 | AD8: =IF(COUNTIF(Catégories!A:A,N8)=0,"catégorie inconnue",LOOKUP(N8,Catégories!A:A,Catégories!B:B)) | AE8: =SUM(Z8:AB8) | AF8: Gazole réel | AH8: 0.2315 | AI8: routier
B9: 13617722 | C9: 2 | D9: 46173 | K9: 0 | L9: CAPN2 | M9: X | N9: Surcharge Carburant Routier | O9: N | P9: 0.1425 | Q9: XX | R9: 0 | S9: X | T9: 2.68 | U9: LA RUCHE LOGISTIQUE | W9: =IF(C9<>2,"",IF(S9="5X","5XK",IF(S9="5Y","5YK",IF(S9="6B","6BK",IF(S9="6C","6CK",""))))) | X9: =IF(S9="6B",_xlfn.XLOOKUP(H9,'Zoning 2shop'!A:A,'Zoning 2shop'!B:B),IF(S9="6C",_xlfn.XLOOKUP(G9,'Zoning 2shop'!C:C,'Zoning 2shop'!D:D),"")) | Y9: =AB9/Z9 | Z9: =T9 | AA9: =IF(OR(S9="6C",S9="6B",S9="5X",S9="5Y"),0.08,0.5) | AB9: =$AG$5/$AG$2*Z9 | AC9: =Z9+AA9 | AD9: =IF(COUNTIF(Catégories!A:A,N9)=0,"catégorie inconnue",LOOKUP(N9,Catégories!A:A,Catégories!B:B)) | AE9: =SUM(Z9:AB9) | AF9: (avant remise) | AH9: 0.4375 | AI9: aérien
B10: 13617723 | C10: 0 | D10: 46173 | K10: 0 | L10: CAPN2 | M10: X | N10: Surcharge Carburant Routier | O10: N | P10: 0.1425 | Q10: XX | R10: 0 | S10: X | T10: 18.56 | U10: LA RUCHE LOGISTIQUE | W10: =IF(C10<>2,"",IF(S10="5X","5XK",IF(S10="5Y","5YK",IF(S10="6B","6BK",IF(S10="6C","6CK",""))))) | X10: =IF(S10="6B",_xlfn.XLOOKUP(H10,'Zoning 2shop'!A:A,'Zoning 2shop'!B:B),IF(S10="6C",_xlfn.XLOOKUP(G10,'Zoning 2shop'!C:C,'Zoning 2shop'!D:D),"")) | Y10: =AB10/Z10 | Z10: =T10 | AA10: =IF(OR(S10="6C",S10="6B",S10="5X",S10="5Y"),0.08,0.5) | AB10: =$AG$5/$AG$2*Z10 | AC10: =Z10+AA10 | AD10: =IF(COUNTIF(Catégories!A:A,N10)=0,"catégorie inconnue",LOOKUP(N10,Catégories!A:A,Catégories!B:B)) | AE10: =SUM(Z10:AB10)
B11: 13617723 | C11: 0 | D11: 46173 | K11: 0 | L11: CAPO1 | M11: X | N11: Surcharge Carburant Aérien | O11: O | P11: 0.4375 | Q11: XX | R11: 0 | S11: X | T11: 18.19 | U11: LA RUCHE LOGISTIQUE | W11: =IF(C11<>2,"",IF(S11="5X","5XK",IF(S11="5Y","5YK",IF(S11="6B","6BK",IF(S11="6C","6CK",""))))) | X11: =IF(S11="6B",_xlfn.XLOOKUP(H11,'Zoning 2shop'!A:A,'Zoning 2shop'!B:B),IF(S11="6C",_xlfn.XLOOKUP(G11,'Zoning 2shop'!C:C,'Zoning 2shop'!D:D),"")) | Y11: =AB11/Z11 | Z11: =T11 | AA11: =IF(OR(S11="6C",S11="6B",S11="5X",S11="5Y"),0.08,0.5) | AB11: =$AG$5/$AG$2*Z11 | AC11: =Z11+AA11 | AD11: =IF(COUNTIF(Catégories!A:A,N11)=0,"catégorie inconnue",LOOKUP(N11,Catégories!A:A,Catégories!B:B)) | AE11: =SUM(Z11:AB11)
B12: 13617723 | C12: 0 | D12: 46173 | K12: 0 | L12: ECORI | M12: X | N12: Participation Eco-Responsable | O12: I | Q12: XX | R12: 0 | S12: X | T12: 3.7 | U12: LA RUCHE LOGISTIQUE | W12: =IF(C12<>2,"",IF(S12="5X","5XK",IF(S12="5Y","5YK",IF(S12="6B","6BK",IF(S12="6C","6CK",""))))) | X12: =IF(S12="6B",_xlfn.XLOOKUP(H12,'Zoning 2shop'!A:A,'Zoning 2shop'!B:B),IF(S12="6C",_xlfn.XLOOKUP(G12,'Zoning 2shop'!C:C,'Zoning 2shop'!D:D),"")) | Y12: =AB12/Z12 | Z12: =T12 | AA12: =IF(OR(S12="6C",S12="6B",S12="5X",S12="5Y"),0.08,0.5) | AB12: =$AG$5/$AG$2*Z12 | AC12: =Z12+AA12 | AD12: =IF(COUNTIF(Catégories!A:A,N12)=0,"catégorie inconnue",LOOKUP(N12,Catégories!A:A,Catégories!B:B)) | AE12: =SUM(Z12:AB12)
B13: 13624019 | C13: 2 | D13: 46173 | K13: 0 | L13: ECORN | M13: X | N13: Participation Eco-Responsable | O13: N | Q13: XX | R13: 0 | S13: X | T13: 12.99 | U13: LA RUCHE LOGISTIQUE | W13: =IF(C13<>2,"",IF(S13="5X","5XK",IF(S13="5Y","5YK",IF(S13="6B","6BK",IF(S13="6C","6CK",""))))) | X13: =IF(S13="6B",_xlfn.XLOOKUP(H13,'Zoning 2shop'!A:A,'Zoning 2shop'!B:B),IF(S13="6C",_xlfn.XLOOKUP(G13,'Zoning 2shop'!C:C,'Zoning 2shop'!D:D),"")) | Y13: =AB13/Z13 | Z13: =T13 | AA13: =IF(OR(S13="6C",S13="6B",S13="5X",S13="5Y"),0.08,0.5) | AB13: =$AG$5/$AG$2*Z13 | AC13: =Z13+AA13 | AD13: =IF(COUNTIF(Catégories!A:A,N13)=0,"catégorie inconnue",LOOKUP(N13,Catégories!A:A,Catégories!B:B)) | AE13: =SUM(Z13:AB13)
B14: 13624020 | C14: 0 | D14: 46173 | K14: 0 | L14: ECORN | M14: X | N14: Participation Eco-Responsable | O14: N | Q14: XX | R14: 0 | S14: X | T14: 0.63 | U14: LA RUCHE LOGISTIQUE | W14: =IF(C14<>2,"",IF(S14="5X","5XK",IF(S14="5Y","5YK",IF(S14="6B","6BK",IF(S14="6C","6CK",""))))) | X14: =IF(S14="6B",_xlfn.XLOOKUP(H14,'Zoning 2shop'!A:A,'Zoning 2shop'!B:B),IF(S14="6C",_xlfn.XLOOKUP(G14,'Zoning 2shop'!C:C,'Zoning 2shop'!D:D),"")) | Y14: =AB14/Z14 | Z14: =T14 | AA14: =IF(OR(S14="6C",S14="6B",S14="5X",S14="5Y"),0.08,0.5) | AB14: =$AG$5/$AG$2*Z14 | AC14: =Z14+AA14 | AD14: =IF(COUNTIF(Catégories!A:A,N14)=0,"catégorie inconnue",LOOKUP(N14,Catégories!A:A,Catégories!B:B)) | AE14: =SUM(Z14:AB14)
B15: 13624021 | C15: 2 | D15: 46173 | K15: 0 | L15: ECORN | M15: X | N15: Participation Eco-Responsable | O15: N | Q15: XX | R15: 0 | S15: X | T15: 27.78 | U15: LA RUCHE LOGISTIQUE | W15: =IF(C15<>2,"",IF(S15="5X","5XK",IF(S15="5Y","5YK",IF(S15="6B","6BK",IF(S15="6C","6CK",""))))) | X15: =IF(S15="6B",_xlfn.XLOOKUP(H15,'Zoning 2shop'!A:A,'Zoning 2shop'!B:B),IF(S15="6C",_xlfn.XLOOKUP(G15,'Zoning 2shop'!C:C,'Zoning 2shop'!D:D),"")) | Y15: =AB15/Z15 | Z15: =T15 | AA15: =IF(OR(S15="6C",S15="6B",S15="5X",S15="5Y"),0.08,0.5) | AB15: =$AG$5/$AG$2*Z15 | AC15: =Z15+AA15 | AD15: =IF(COUNTIF(Catégories!A:A,N15)=0,"catégorie inconnue",LOOKUP(N15,Catégories!A:A,Catégories!B:B)) | AE15: =SUM(Z15:AB15)
B16: 13617721 | C16: 0 | D16: 46173 | K16: 0 | L16: ECORN | M16: X | N16: Participation Eco-Responsable | O16: N | Q16: XX | R16: 0 | S16: X | T16: 53.7 | U16: LA RUCHE LOGISTIQUE | W16: =IF(C16<>2,"",IF(S16="5X","5XK",IF(S16="5Y","5YK",IF(S16="6B","6BK",IF(S16="6C","6CK",""))))) | X16: =IF(S16="6B",_xlfn.XLOOKUP(H16,'Zoning 2shop'!A:A,'Zoning 2shop'!B:B),IF(S16="6C",_xlfn.XLOOKUP(G16,'Zoning 2shop'!C:C,'Zoning 2shop'!D:D),"")) | Y16: =AB16/Z16 | Z16: =T16 | AA16: =IF(OR(S16="6C",S16="6B",S16="5X",S16="5Y"),0.08,0.5) | AB16: =$AG$5/$AG$2*Z16 | AC16: =Z16+AA16 | AD16: =IF(COUNTIF(Catégories!A:A,N16)=0,"catégorie inconnue",LOOKUP(N16,Catégories!A:A,Catégories!B:B)) | AE16: =SUM(Z16:AB16)
B17: 13617722 | C17: 2 | D17: 46173 | K17: 0 | L17: ECORN | M17: X | N17: Participation Eco-Responsable | O17: N | Q17: XX | R17: 0 | S17: X | T17: 0.2 | U17: LA RUCHE LOGISTIQUE | W17: =IF(C17<>2,"",IF(S17="5X","5XK",IF(S17="5Y","5YK",IF(S17="6B","6BK",IF(S17="6C","6CK",""))))) | X17: =IF(S17="6B",_xlfn.XLOOKUP(H17,'Zoning 2shop'!A:A,'Zoning 2shop'!B:B),IF(S17="6C",_xlfn.XLOOKUP(G17,'Zoning 2shop'!C:C,'Zoning 2shop'!D:D),"")) | Y17: =AB17/Z17 | Z17: =T17 | AA17: =IF(OR(S17="6C",S17="6B",S17="5X",S17="5Y"),0.08,0.5) | AB17: =$AG$5/$AG$2*Z17 | AC17: =Z17+AA17 | AD17: =IF(COUNTIF(Catégories!A:A,N17)=0,"catégorie inconnue",LOOKUP(N17,Catégories!A:A,Catégories!B:B)) | AE17: =SUM(Z17:AB17)
B18: 13617723 | C18: 0 | D18: 46173 | K18: 0 | L18: ECORN | M18: X | N18: Participation Eco-Responsable | O18: N | Q18: XX | R18: 0 | S18: X | T18: 23.4 | U18: LA RUCHE LOGISTIQUE | W18: =IF(C18<>2,"",IF(S18="5X","5XK",IF(S18="5Y","5YK",IF(S18="6B","6BK",IF(S18="6C","6CK",""))))) | X18: =IF(S18="6B",_xlfn.XLOOKUP(H18,'Zoning 2shop'!A:A,'Zoning 2shop'!B:B),IF(S18="6C",_xlfn.XLOOKUP(G18,'Zoning 2shop'!C:C,'Zoning 2shop'!D:D),"")) | Y18: =AB18/Z18 | Z18: =T18 | AA18: =IF(OR(S18="6C",S18="6B",S18="5X",S18="5Y"),0.08,0.5) | AB18: =$AG$5/$AG$2*Z18 | AC18: =Z18+AA18 | AD18: =IF(COUNTIF(Catégories!A:A,N18)=0,"catégorie inconnue",LOOKUP(N18,Catégories!A:A,Catégories!B:B)) | AE18: =SUM(Z18:AB18)
B19: 13617723 | C19: 0 | D19: 46173 | K19: 0 | L19: ECORO | M19: X | N19: Participation Eco-Responsable | O19: O | Q19: XX | R19: 0 | S19: X | T19: 0.1 | U19: LA RUCHE LOGISTIQUE | W19: =IF(C19<>2,"",IF(S19="5X","5XK",IF(S19="5Y","5YK",IF(S19="6B","6BK",IF(S19="6C","6CK",""))))) | X19: =IF(S19="6B",_xlfn.XLOOKUP(H19,'Zoning 2shop'!A:A,'Zoning 2shop'!B:B),IF(S19="6C",_xlfn.XLOOKUP(G19,'Zoning 2shop'!C:C,'Zoning 2shop'!D:D),"")) | Y19: =AB19/Z19 | Z19: =T19 | AA19: =IF(OR(S19="6C",S19="6B",S19="5X",S19="5Y"),0.08,0.5) | AB19: =$AG$5/$AG$2*Z19 | AC19: =Z19+AA19 | AD19: =IF(COUNTIF(Catégories!A:A,N19)=0,"catégorie inconnue",LOOKUP(N19,Catégories!A:A,Catégories!B:B)) | AE19: =SUM(Z19:AB19)
B20: 13617723 | C20: 0 | D20: 46173 | K20: 0 | L20: SURTI | M20: X | N20: Sûreté colis | O20: I | Q20: XX | R20: 0 | S20: X | T20: 14.8 | U20: LA RUCHE LOGISTIQUE | W20: =IF(C20<>2,"",IF(S20="5X","5XK",IF(S20="5Y","5YK",IF(S20="6B","6BK",IF(S20="6C","6CK",""))))) | X20: =IF(S20="6B",_xlfn.XLOOKUP(H20,'Zoning 2shop'!A:A,'Zoning 2shop'!B:B),IF(S20="6C",_xlfn.XLOOKUP(G20,'Zoning 2shop'!C:C,'Zoning 2shop'!D:D),"")) | Y20: =AB20/Z20 | Z20: =T20 | AA20: =IF(OR(S20="6C",S20="6B",S20="5X",S20="5Y"),0.08,0.5) | AB20: =$AG$5/$AG$2*Z20 | AC20: =Z20+AA20 | AD20: =IF(COUNTIF(Catégories!A:A,N20)=0,"catégorie inconnue",LOOKUP(N20,Catégories!A:A,Catégories!B:B)) | AE20: =SUM(Z20:AB20)
B21: 13624019 | C21: 2 | D21: 46173 | K21: 0 | L21: SURTN | M21: X | N21: Sûreté colis | O21: N | Q21: XX | R21: 0 | S21: X | T21: 21.65 | U21: LA RUCHE LOGISTIQUE | W21: =IF(C21<>2,"",IF(S21="5X","5XK",IF(S21="5Y","5YK",IF(S21="6B","6BK",IF(S21="6C","6CK",""))))) | X21: =IF(S21="6B",_xlfn.XLOOKUP(H21,'Zoning 2shop'!A:A,'Zoning 2shop'!B:B),IF(S21="6C",_xlfn.XLOOKUP(G21,'Zoning 2shop'!C:C,'Zoning 2shop'!D:D),"")) | Y21: =AB21/Z21 | Z21: =T21 | AA21: =IF(OR(S21="6C",S21="6B",S21="5X",S21="5Y"),0.08,0.5) | AB21: =$AG$5/$AG$2*Z21 | AC21: =Z21+AA21 | AD21: =IF(COUNTIF(Catégories!A:A,N21)=0,"catégorie inconnue",LOOKUP(N21,Catégories!A:A,Catégories!B:B)) | AE21: =SUM(Z21:AB21)
B22: 13624020 | C22: 0 | D22: 46173 | K22: 0 | L22: SURTN | M22: X | N22: Sûreté colis | O22: N | Q22: XX | R22: 0 | S22: X | T22: 1.05 | U22: LA RUCHE LOGISTIQUE | W22: =IF(C22<>2,"",IF(S22="5X","5XK",IF(S22="5Y","5YK",IF(S22="6B","6BK",IF(S22="6C","6CK",""))))) | X22: =IF(S22="6B",_xlfn.XLOOKUP(H22,'Zoning 2shop'!A:A,'Zoning 2shop'!B:B),IF(S22="6C",_xlfn.XLOOKUP(G22,'Zoning 2shop'!C:C,'Zoning 2shop'!D:D),"")) | Y22: =AB22/Z22 | Z22: =T22 | AA22: =IF(OR(S22="6C",S22="6B",S22="5X",S22="5Y"),0.08,0.5) | AB22: =$AG$5/$AG$2*Z22 | AC22: =Z22+AA22 | AD22: =IF(COUNTIF(Catégories!A:A,N22)=0,"catégorie inconnue",LOOKUP(N22,Catégories!A:A,Catégories!B:B)) | AE22: =SUM(Z22:AB22)
B23: 13624021 | C23: 2 | D23: 46173 | K23: 0 | L23: SURTN | M23: X | N23: Sûreté colis | O23: N | Q23: XX | R23: 0 | S23: X | T23: 46.3 | U23: LA RUCHE LOGISTIQUE | W23: =IF(C23<>2,"",IF(S23="5X","5XK",IF(S23="5Y","5YK",IF(S23="6B","6BK",IF(S23="6C","6CK",""))))) | X23: =IF(S23="6B",_xlfn.XLOOKUP(H23,'Zoning 2shop'!A:A,'Zoning 2shop'!B:B),IF(S23="6C",_xlfn.XLOOKUP(G23,'Zoning 2shop'!C:C,'Zoning 2shop'!D:D),"")) | Y23: =AB23/Z23 | Z23: =T23 | AA23: =IF(OR(S23="6C",S23="6B",S23="5X",S23="5Y"),0.08,0.5) | AB23: =$AG$5/$AG$2*Z23 | AC23: =Z23+AA23 | AD23: =IF(COUNTIF(Catégories!A:A,N23)=0,"catégorie inconnue",LOOKUP(N23,Catégories!A:A,Catégories!B:B)) | AE23: =SUM(Z23:AB23)
... B27: 13617723 | C27: 0 | D27: 46173 | K27: 0 | L27: SURTO | M27: X | N27: Sûreté colis | O27: O | Q27: XX | R27: 0 | S27: X | T27: 0.4 | U27: LA RUCHE LOGISTIQUE | W27: =IF(C27<>2,"",IF(S27="5X","5XK",IF(S27="5Y","5YK",IF(S27="6B","6BK",IF(S27="6C","6CK",""))))) | X27: =IF(S27="6B",_xlfn.XLOOKUP(H27,'Zoning 2shop'!A:A,'Zoning 2shop'!B:B),IF(S27="6C",_xlfn.XLOOKUP(G27,'Zoning 2shop'!C:C,'Zoning 2shop'!D:D),"")) | Y27: =AB27/Z27 | Z27: =T27 | AA27: =IF(OR(S27="6C",S27="6B",S27="5X",S27="5Y"),0.08,0.5) | AB27: =$AG$5/$AG$2*Z27 | AC27: =Z27+AA27 | AD27: =IF(COUNTIF(Catégories!A:A,N27)=0,"catégorie inconnue",LOOKUP(N27,Catégories!A:A,Catégories!B:B)) | AE27: =SUM(Z27:AB27)
B28: 13617723 | C28: 0 | D28: 46146 | E28: 21320 | F28: 13088 | G28: FR | H28: DE | I28: Martinez Cruz Daniela | J28: Laruche | K28: 999999 | L28: XF142220606FR | M28: N | N28: Transport | O28: N | P28: S | Q28: Z1 | R28: 0.783 | S28: 17 | T28: 9.94 | U28: LA RUCHE LOGISTIQUE | W28: =IF(C28<>2,"",IF(S28="5X","5XK",IF(S28="5Y","5YK",IF(S28="6B","6BK",IF(S28="6C","6CK",""))))) | X28: =IF(S28="6B",_xlfn.XLOOKUP(H28,'Zoning 2shop'!A:A,'Zoning 2shop'!B:B),IF(S28="6C",_xlfn.XLOOKUP(G28,'Zoning 2shop'!C:C,'Zoning 2shop'!D:D),"")) | Y28: =AB28/Z28 | Z28: =T28 | AA28: =IF(OR(S28="6C",S28="6B",S28="5X",S28="5Y"),0.08,0.5) | AB28: =$AG$5/$AG$2*Z28 | AC28: =Z28+AA28 | AD28: =IF(COUNTIF(Catégories!A:A,N28)=0,"catégorie inconnue",LOOKUP(N28,Catégories!A:A,Catégories!B:B)) | AE28: =SUM(Z28:AB28)
B29: 13617723 | C29: 0 | D29: 46146 | E29: 21320 | F29: 14542 | G29: FR | H29: DE | I29: Fettig Herbert | J29: Laruche | K29: 999999 | L29: XF142220708FR | M29: N | N29: Transport | O29: N | P29: S | Q29: Z1 | R29: 4.532 | S29: 17 | T29: 19.47 | U29: LA RUCHE LOGISTIQUE | W29: =IF(C29<>2,"",IF(S29="5X","5XK",IF(S29="5Y","5YK",IF(S29="6B","6BK",IF(S29="6C","6CK",""))))) | X29: =IF(S29="6B",_xlfn.XLOOKUP(H29,'Zoning 2shop'!A:A,'Zoning 2shop'!B:B),IF(S29="6C",_xlfn.XLOOKUP(G29,'Zoning 2shop'!C:C,'Zoning 2shop'!D:D),"")) | Y29: =AB29/Z29 | Z29: =T29 | AA29: =IF(OR(S29="6C",S29="6B",S29="5X",S29="5Y"),0.08,0.5) | AB29: =$AG$5/$AG$2*Z29 | AC29: =Z29+AA29 | AD29: =IF(COUNTIF(Catégories!A:A,N29)=0,"catégorie inconnue",LOOKUP(N29,Catégories!A:A,Catégories!B:B)) | AE29: =SUM(Z29:AB29)
B30: 13617723 | C30: 0 | D30: 46146 | E30: 21320 | F30: 42651 | G30: FR | H30: DE | I30: Michallek Lars | J30: Laruche | K30: 999999 | L30: XF142220932FR | M30: N | N30: Transport | O30: N | P30: S | Q30: Z1 | R30: 0.748 | S30: 17 | T30: 9.94 | U30: LA RUCHE LOGISTIQUE | W30: =IF(C30<>2,"",IF(S30="5X","5XK",IF(S30="5Y","5YK",IF(S30="6B","6BK",IF(S30="6C","6CK",""))))) | X30: =IF(S30="6B",_xlfn.XLOOKUP(H30,'Zoning 2shop'!A:A,'Zoning 2shop'!B:B),IF(S30="6C",_xlfn.XLOOKUP(G30,'Zoning 2shop'!C:C,'Zoning 2shop'!D:D),"")) | Y30: =AB30/Z30 | Z30: =T30 | AA30: =IF(OR(S30="6C",S30="6B",S30="5X",S30="5Y"),0.08,0.5) | AB30: =$AG$5/$AG$2*Z30 | AC30: =Z30+AA30 | AD30: =IF(COUNTIF(Catégories!A:A,N30)=0,"catégorie inconnue",LOOKUP(N30,Catégories!A:A,Catégories!B:B)) | AE30: =SUM(Z30:AB30)
B31: 13617723 | C31: 0 | D31: 46146 | E31: 21320 | F31: 88279 | G31: FR | H31: DE | I31: Simon Dr Karl | J31: Laruche | K31: 999999 | L31: XF142221116FR | M31: N | N31: Transport | O31: N | P31: S | Q31: Z1 | R31: 0.1 | S31: 17 | T31: 7.86 | U31: LA RUCHE LOGISTIQUE | W31: =IF(C31<>2,"",IF(S31="5X","5XK",IF(S31="5Y","5YK",IF(S31="6B","6BK",IF(S31="6C","6CK",""))))) | X31: =IF(S31="6B",_xlfn.XLOOKUP(H31,'Zoning 2shop'!A:A,'Zoning 2shop'!B:B),IF(S31="6C",_xlfn.XLOOKUP(G31,'Zoning 2shop'!C:C,'Zoning 2shop'!D:D),"")) | Y31: =AB31/Z31 | Z31: =T31 | AA31: =IF(OR(S31="6C",S31="6B",S31="5X",S31="5Y"),0.08,0.5) | AB31: =$AG$5/$AG$2*Z31 | AC31: =Z31+AA31 | AD31: =IF(COUNTIF(Catégories!A:A,N31)=0,"catégorie inconnue",LOOKUP(N31,Catégories!A:A,Catégories!B:B)) | AE31: =SUM(Z31:AB31)
B32: 13617723 | C32: 0 | D32: 46146 | E32: 21320 | F32: 1028 | G32: FR | H32: HU | I32: Moulenes Katalin | J32: Laruche | K32: 999999 | L32: XF142221147FR | M32: N | N32: Transport | O32: N | P32: S | Q32: Z3 | R32: 0.748 | S32: 17 | T32: 13.35 | U32: LA RUCHE LOGISTIQUE | W32: =IF(C32<>2,"",IF(S32="5X","5XK",IF(S32="5Y","5YK",IF(S32="6B","6BK",IF(S32="6C","6CK",""))))) | X32: =IF(S32="6B",_xlfn.XLOOKUP(H32,'Zoning 2shop'!A:A,'Zoning 2shop'!B:B),IF(S32="6C",_xlfn.XLOOKUP(G32,'Zoning 2shop'!C:C,'Zoning 2shop'!D:D),"")) | Y32: =AB32/Z32 | Z32: =T32 | AA32: =IF(OR(S32="6C",S32="6B",S32="5X",S32="5Y"),0.08,0.5) | AB32: =$AG$5/$AG$2*Z32 | AC32: =Z32+AA32 | AD32: =IF(COUNTIF(Catégories!A:A,N32)=0,"catégorie inconnue",LOOKUP(N32,Catégories!A:A,Catégories!B:B)) | AE32: =SUM(Z32:AB32)
B33: 13617723 | C33: 0 | D33: 46146 | E33: 21320 | F33: 17031 | G33: FR | H33: IT | I33: CARTA GIOBERTI Cinzia | J33: Laruche | K33: 999999 | L33: XF142221677FR | M33: N | N33: Transport | O33: N | P33: S | Q33: Z2 | R33: 4.427 | S33: 17 | T33: 18.34 | U33: LA RUCHE LOGISTIQUE | W33: =IF(C33<>2,"",IF(S33="5X","5XK",IF(S33="5Y","5YK",IF(S33="6B","6BK",IF(S33="6C","6CK",""))))) | X33: =IF(S33="6B",_xlfn.XLOOKUP(H33,'Zoning 2shop'!A:A,'Zoning 2shop'!B:B),IF(S33="6C",_xlfn.XLOOKUP(G33,'Zoning 2shop'!C:C,'Zoning 2shop'!D:D),"")) | Y33: =AB33/Z33 | Z33: =T33 | AA33: =IF(OR(S33="6C",S33="6B",S33="5X",S33="5Y"),0.08,0.5) | AB33: =$AG$5/$AG$2*Z33 | AC33: =Z33+AA33 | AD33: =IF(COUNTIF(Catégories!A:A,N33)=0,"catégorie inconnue",LOOKUP(N33,Catégories!A:A,Catégories!B:B)) | AE33: =SUM(Z33:AB33)
B34: 13617723 | C34: 0 | D34: 46146 | E34: 21320 | F34: 97348 | G34: FR | H34: DE | I34: Seel Timea | J34: Laruche | K34: 999999 | L34: XF142221779FR | M34: N | N34: Transport | O34: N | P34: S | Q34: Z1 | R34: 5.773 | S34: 17 | T34: 21.83 | U34: LA RUCHE LOGISTIQUE | W34: =IF(C34<>2,"",IF(S34="5X","5XK",IF(S34="5Y","5YK",IF(S34="6B","6BK",IF(S34="6C","6CK",""))))) | X34: =IF(S34="6B",_xlfn.XLOOKUP(H34,'Zoning 2shop'!A:A,'Zoning 2shop'!B:B),IF(S34="6C",_xlfn.XLOOKUP(G34,'Zoning 2shop'!C:C,'Zoning 2shop'!D:D),"")) | Y34: =AB34/Z34 | Z34: =T34 | AA34: =IF(OR(S34="6C",S34="6B",S34="5X",S34="5Y"),0.08,0.5) | AB34: =$AG$5/$AG$2*Z34 | AC34: =Z34+AA34 | AD34: =IF(COUNTIF(Catégories!A:A,N34)=0,"catégorie inconnue",LOOKUP(N34,Catégories!A:A,Catégories!B:B)) | AE34: =SUM(Z34:AB34)
B35: 13617723 | C35: 0 | D35: 46146 | E35: 21320 | F35: 28280 | G35: FR | H35: ES | I35: Beltran Carmen | J35: Laruche | K35: 999999 | L35: XF142224761FR | M35: N | N35: Transport | O35: N | P35: S | Q35: Z2 | R35: 0.748 | S35: 17 | T35: 9.94 | U35: LA RUCHE LOGISTIQUE | W35: =IF(C35<>2,"",IF(S35="5X","5XK",IF(S35="5Y","5YK",IF(S35="6B","6BK",IF(S35="6C","6CK",""))))) | X35: =IF(S35="6B",_xlfn.XLOOKUP(H35,'Zoning 2shop'!A:A,'Zoning 2shop'!B:B),IF(S35="6C",_xlfn.XLOOKUP(G35,'Zoning 2shop'!C:C,'Zoning 2shop'!D:D),"")) | Y35: =AB35/Z35 | Z35: =T35 | AA35: =IF(OR(S35="6C",S35="6B",S35="5X",S35="5Y"),0.08,0.5) | AB35: =$AG$5/$AG$2*Z35 | AC35: =Z35+AA35 | AD35: =IF(COUNTIF(Catégories!A:A,N35)=0,"catégorie inconnue",LOOKUP(N35,Catégories!A:A,Catégories!B:B)) | AE35: =SUM(Z35:AB35)
B36: 13617723 | C36: 0 | D36: 46146 | E36: 21320 | F36: 94065 | G36: FR | H36: DE | I36: Lutje Maximilian | J36: Laruche | K36: 999999 | L36: XF142225206FR | M36: N | N36: Transport | O36: N | P36: S | Q36: Z1 | R36: 5.76 | S36: 17 | T36: 21.83 | U36: LA RUCHE LOGISTIQUE | W36: =IF(C36<>2,"",IF(S36="5X","5XK",IF(S36="5Y","5YK",IF(S36="6B","6BK",IF(S36="6C","6CK",""))))) | X36: =IF(S36="6B",_xlfn.XLOOKUP(H36,'Zoning 2shop'!A:A,'Zoning 2shop'!B:B),IF(S36="6C",_xlfn.XLOOKUP(G36,'Zoning 2shop'!C:C,'Zoning 2shop'!D:D),"")) | Y36: =AB36/Z36 | Z36: =T36 | AA36: =IF(OR(S36="6C",S36="6B",S36="5X",S36="5Y"),0.08,0.5) | AB36: =$AG$5/$AG$2*Z36 | AC36: =Z36+AA36 | AD36: =IF(COUNTIF(Catégories!A:A,N36)=0,"catégorie inconnue",LOOKUP(N36,Catégories!A:A,Catégories!B:B)) | AE36: =SUM(Z36:AB36)
B37: 13617723 | C37: 0 | D37: 46146 | E37: 21320 | F37: 36329 | G37: FR | H37: DE | I37: Marek Nicole | J37: Laruche | K37: 999999 | L37: XF142225223FR | M37: N | N37: Transport | O37: N | P37: S | Q37: Z1 | R37: 4.266 | S37: 17 | T37: 18.34 | U37: LA RUCHE LOGISTIQUE | W37: =IF(C37<>2,"",IF(S37="5X","5XK",IF(S37="5Y","5YK",IF(S37="6B","6BK",IF(S37="6C","6CK",""))))) | X37: =IF(S37="6B",_xlfn.XLOOKUP(H37,'Zoning 2shop'!A:A,'Zoning 2shop'!B:B),IF(S37="6C",_xlfn.XLOOKUP(G37,'Zoning 2shop'!C:C,'Zoning 2shop'!D:D),"")) | Y37: =AB37/Z37 | Z37: =T37 | AA37: =IF(OR(S37="6C",S37="6B",S37="5X",S37="5Y"),0.08,0.5) | AB37: =$AG$5/$AG$2*Z37 | AC37: =Z37+AA37 | AD37: =IF(COUNTIF(Catégories!A:A,N37)=0,"catégorie inconnue",LOOKUP(N37,Catégories!A:A,Catégories!B:B)) | AE37: =SUM(Z37:AB37)
B38: 13617723 | C38: 0 | D38: 46146 | E38: 21320 | F38: 57074 | G38: FR | H38: DE | I38: Serra Daniela | J38: Laruche | K38: 999999 | L38: XF142225342FR | M38: N | N38: Transport | O38: N | P38: S | Q38: Z1 | R38: 4.266 | S38: 17 | T38: 18.34 | U38: LA RUCHE LOGISTIQUE | W38: =IF(C38<>2,"",IF(S38="5X","5XK",IF(S38="5Y","5YK",IF(S38="6B","6BK",IF(S38="6C","6CK",""))))) | X38: =IF(S38="6B",_xlfn.XLOOKUP(H38,'Zoning 2shop'!A:A,'Zoning 2shop'!B:B),IF(S38="6C",_xlfn.XLOOKUP(G38,'Zoning 2shop'!C:C,'Zoning 2shop'!D:D),"")) | Y38: =AB38/Z38 | Z38: =T38 | AA38: =IF(OR(S38="6C",S38="6B",S38="5X",S38="5Y"),0.08,0.5) | AB38: =$AG$5/$AG$2*Z38 | AC38: =Z38+AA38 | AD38: =IF(COUNTIF(Catégories!A:A,N38)=0,"catégorie inconnue",LOOKUP(N38,Catégories!A:A,Catégories!B:B)) | AE38: =SUM(Z38:AB38)
B39: 13617723 | C39: 0 | D39: 46146 | E39: 21320 | F39: 9991 | G39: FR | H39: BE | I39: Van Robays Steven | J39: Laruche | K39: 999999 | L39: XF142225838FR | M39: N | N39: Transport | O39: N | P39: S | Q39: Z1 | R39: 5.904 | S39: 17 | T39: 21.83 | U39: LA RUCHE LOGISTIQUE | W39: =IF(C39<>2,"",IF(S39="5X","5XK",IF(S39="5Y","5YK",IF(S39="6B","6BK",IF(S39="6C","6CK",""))))) | X39: =IF(S39="6B",_xlfn.XLOOKUP(H39,'Zoning 2shop'!A:A,'Zoning 2shop'!B:B),IF(S39="6C",_xlfn.XLOOKUP(G39,'Zoning 2shop'!C:C,'Zoning 2shop'!D:D),"")) | Y39: =AB39/Z39 | Z39: =T39 | AA39: =IF(OR(S39="6C",S39="6B",S39="5X",S39="5Y"),0.08,0.5) | AB39: =$AG$5/$AG$2*Z39 | AC39: =Z39+AA39 | AD39: =IF(COUNTIF(Catégories!A:A,N39)=0,"catégorie inconnue",LOOKUP(N39,Catégories!A:A,Catégories!B:B)) | AE39: =SUM(Z39:AB39)
... B118: 13617723 | C118: 0 | D118: 46161 | E118: 21320 | F118: 28200 | G118: FR | H118: ES | I118: Aguilera Reija Ersilia | J118: Laruche | K118: 999999 | L118: XF142970539FR | M118: N | N118: Transport | O118: N | P118: S | Q118: Z2 | R118: 0.328 | S118: 17 | T118: 7.86 | U118: LA RUCHE LOGISTIQUE | W118: =IF(C118<>2,"",IF(S118="5X","5XK",IF(S118="5Y","5YK",IF(S118="6B","6BK",IF(S118="6C","6CK",""))))) | X118: =IF(S118="6B",_xlfn.XLOOKUP(H118,'Zoning 2shop'!A:A,'Zoning 2shop'!B:B),IF(S118="6C",_xlfn.XLOOKUP(G118,'Zoning 2shop'!C:C,'Zoning 2shop'!D:D),"")) | Y118: =AB118/Z118 | Z118: =T118 | AA118: =IF(OR(S118="6C",S118="6B",S118="5X",S118="5Y"),0.08,0.5) | AB118: =$AG$5/$AG$2*Z118 | AC118: =Z118+AA118 | AD118: =IF(COUNTIF(Catégories!A:A,N118)=0,"catégorie inconnue",LOOKUP(N118,Catégories!A:A,Catégories!B:B)) | AE118: =SUM(Z118:AB118)
B119: 13617723 | C119: 0 | D119: 46161 | E119: 21320 | F119: 28200 | G119: FR | H119: ES | I119: Aguilera Reija Ersilia | J119: Laruche | K119: 999999 | L119: XF142970539FR | M119: N | N119: Supp Zone Internationale Eloignee | O119: N | Q119: Z2 | R119: 0 | S119: 17 | T119: 17 | U119: LA RUCHE LOGISTIQUE | W119: =IF(C119<>2,"",IF(S119="5X","5XK",IF(S119="5Y","5YK",IF(S119="6B","6BK",IF(S119="6C","6CK",""))))) | X119: =IF(S119="6B",_xlfn.XLOOKUP(H119,'Zoning 2shop'!A:A,'Zoning 2shop'!B:B),IF(S119="6C",_xlfn.XLOOKUP(G119,'Zoning 2shop'!C:C,'Zoning 2shop'!D:D),"")) | Y119: =AB119/Z119 | Z119: =T119 | AA119: =IF(OR(S119="6C",S119="6B",S119="5X",S119="5Y"),0.08,0.5) | AB119: =$AG$5/$AG$2*Z119 | AC119: =Z119+AA119 | AD119: =IF(COUNTIF(Catégories!A:A,N119)=0,"catégorie inconnue",LOOKUP(N119,Catégories!A:A,Catégories!B:B)) | AE119: =SUM(Z119:AB119)
B120: 13617723 | C120: 0 | D120: 46161 | E120: 21320 | F120: 53925 | G120: FR | H120: DE | I120: Schumacher Franca | J120: Laruche | K120: 999999 | L120: XF142970715FR | M120: N | N120: Transport | O120: N | P120: S | Q120: Z1 | R120: 0.738 | S120: 17 | T120: 9.94 | U120: LA RUCHE LOGISTIQUE | W120: =IF(C120<>2,"",IF(S120="5X","5XK",IF(S120="5Y","5YK",IF(S120="6B","6BK",IF(S120="6C","6CK",""))))) | X120: =IF(S120="6B",_xlfn.XLOOKUP(H120,'Zoning 2shop'!A:A,'Zoning 2shop'!B:B),IF(S120="6C",_xlfn.XLOOKUP(G120,'Zoning 2shop'!C:C,'Zoning 2shop'!D:D),"")) | Y120: =AB120/Z120 | Z120: =T120 | AA120: =IF(OR(S120="6C",S120="6B",S120="5X",S120="5Y"),0.08,0.5) | AB120: =$AG$5/$AG$2*Z120 | AC120: =Z120+AA120 | AD120: =IF(COUNTIF(Catégories!A:A,N120)=0,"catégorie inconnue",LOOKUP(N120,Catégories!A:A,Catégories!B:B)) | AE120: =SUM(Z120:AB120)
B121: 13617723 | C121: 0 | D121: 46161 | E121: 21320 | F121: 27356 | G121: FR | H121: DE | I121: Schroeder Torsten | J121: Laruche | K121: 999999 | L121: XF142971004FR | M121: N | N121: Transport | O121: N | P121: S | Q121: Z1 | R121: 4.266 | S121: 17 | T121: 18.34 | U121: LA RUCHE LOGISTIQUE | W121: =IF(C121<>2,"",IF(S121="5X","5XK",IF(S121="5Y","5YK",IF(S121="6B","6BK",IF(S121="6C","6CK",""))))) | X121: =IF(S121="6B",_xlfn.XLOOKUP(H121,'Zoning 2shop'!A:A,'Zoning 2shop'!B:B),IF(S121="6C",_xlfn.XLOOKUP(G121,'Zoning 2shop'!C:C,'Zoning 2shop'!D:D),"")) | Y121: =AB121/Z121 | Z121: =T121 | AA121: =IF(OR(S121="6C",S121="6B",S121="5X",S121="5Y"),0.08,0.5) | AB121: =$AG$5/$AG$2*Z121 | AC121: =Z121+AA121 | AD121: =IF(COUNTIF(Catégories!A:A,N121)=0,"catégorie inconnue",LOOKUP(N121,Catégories!A:A,Catégories!B:B)) | AE121: =SUM(Z121:AB121)
...

Sheet TCD poids
A1: Étiquettes de lignes | B1: Somme de Poids | C1: Poids arrondi
A2: CAPI1 | B2: 0 | C2: =ROUNDUP(B2,1)
A3: CAPI2 | B3: 0 | C3: =ROUNDUP(B3,1)
A4: CAPN1 | B4: 0 | C4: =ROUNDUP(B4,1)
A5: CAPN2 | B5: 0 | C5: =ROUNDUP(B5,1)
A6: CAPO1 | B6: 0 | C6: =ROUNDUP(B6,1)
A7: ECORI | B7: 0 | C7: =ROUNDUP(B7,1)
A8: ECORN | B8: 0 | C8: =ROUNDUP(B8,1)
A9: ECORO | B9: 0 | C9: =ROUNDUP(B9,1)
A10: SURTI | B10: 0 | C10: =ROUNDUP(B10,1)
A11: SURTN | B11: 0 | C11: =ROUNDUP(B11,1)
A12: SURTO | B12: 0 | C12: =ROUNDUP(B12,1)
A13: XF142220606FR | B13: 0.783 | C13: =ROUNDUP(B13,1)
... A2208: XY514004567JB | B2208: 0.2 | C2208: =ROUNDUP(B2208,1)
A2209: (vide) | C2209: =ROUNDUP(B2209,1)

Sheet TCD
A1: Total GO | B1: Total avec CAP + ECO… | C1: Total hors GO | D1: ID client | E1: Somme de Montant HT | I1: Catégories | X1: Gazole + facturation + divers
E2: Numero LT | F2: Produit | G2: TVA | H2: Zone Tarifaire | I2: Adresse | J2: Assurance | K2: Colis volumineux | L2: Corse | M2: Droits et taxes | N2: Frais facturation | O2: Frêt | P2: Gazole | Q2: Zones éloignées | R2: (vide) | S2: Sureté + eco | U2: zone | V2: Transporteur | W2: Frêt + CAP + ECO… (hors gazole) | X2: =SUM(N$3:N$1048576)+SUM(P$3:P$1048576)+SUM(O3:O13) | Y2: Formule Test a vérifier | Z2: Vérif avec ancienne formule
E3: CAPI1 | F3: X | G3: I | H3: XX | P3: 42.11 | S3: =_xlfn.XLOOKUP(E3,'Facture Chronopost'!L:L,'Facture Chronopost'!AA:AA,"") | T3: =IF(COUNTIF('Bibliothèque transporteurs'!C:C,F3)=0,"inconnu",_xlfn.XLOOKUP(F3,'Bibliothèque transporteurs'!C:C,'Bibliothèque transporteurs'!A:A)) | U3: =IF(OR(F3="6C",F3="6B"),_xlfn.XLOOKUP(E3,'Facture Chronopost'!L:L,'Facture Chronopost'!X:X),IF(OR(F3=17,F3=44),F3&"_"&H3,IF(COUNTIF('Bibliothèque transporteurs'!C:C,F3)=0,"inconnu",_xlfn.XLOOKUP(F3,'Bibliothèque transporteurs'!C:C,'Bibliothèque transporteurs'!B:B)))) | V3: =IF(COUNTIF('Bibliothèque transporteurs'!C:C,F3)=0,"inconnu",_xlfn.XLOOKUP(F3,'Bibliothèque transporteurs'!C:C,'Bibliothèque transporteurs'!E:E))
E4: CAPI2 | F4: X | G4: I | H4: XX | P4: 55.57 | S4: =_xlfn.XLOOKUP(E4,'Facture Chronopost'!L:L,'Facture Chronopost'!AA:AA,"") | T4: =IF(COUNTIF('Bibliothèque transporteurs'!C:C,F4)=0,"inconnu",_xlfn.XLOOKUP(F4,'Bibliothèque transporteurs'!C:C,'Bibliothèque transporteurs'!A:A)) | U4: =IF(OR(F4="6C",F4="6B"),_xlfn.XLOOKUP(E4,'Facture Chronopost'!L:L,'Facture Chronopost'!X:X),IF(OR(F4=17,F4=44),F4&"_"&H4,IF(COUNTIF('Bibliothèque transporteurs'!C:C,F4)=0,"inconnu",_xlfn.XLOOKUP(F4,'Bibliothèque transporteurs'!C:C,'Bibliothèque transporteurs'!B:B)))) | V4: =IF(COUNTIF('Bibliothèque transporteurs'!C:C,F4)=0,"inconnu",_xlfn.XLOOKUP(F4,'Bibliothèque transporteurs'!C:C,'Bibliothèque transporteurs'!E:E))
E5: CAPN1 | F5: X | G5: N | H5: XX | P5: 1534.86 | S5: =_xlfn.XLOOKUP(E5,'Facture Chronopost'!L:L,'Facture Chronopost'!AA:AA,"") | T5: =IF(COUNTIF('Bibliothèque transporteurs'!C:C,F5)=0,"inconnu",_xlfn.XLOOKUP(F5,'Bibliothèque transporteurs'!C:C,'Bibliothèque transporteurs'!A:A)) | U5: =IF(OR(F5="6C",F5="6B"),_xlfn.XLOOKUP(E5,'Facture Chronopost'!L:L,'Facture Chronopost'!X:X),IF(OR(F5=17,F5=44),F5&"_"&H5,IF(COUNTIF('Bibliothèque transporteurs'!C:C,F5)=0,"inconnu",_xlfn.XLOOKUP(F5,'Bibliothèque transporteurs'!C:C,'Bibliothèque transporteurs'!B:B)))) | V5: =IF(COUNTIF('Bibliothèque transporteurs'!C:C,F5)=0,"inconnu",_xlfn.XLOOKUP(F5,'Bibliothèque transporteurs'!C:C,'Bibliothèque transporteurs'!E:E))
E6: CAPN2 | F6: X | G6: N | H6: XX | P6: 1025.67 | S6: =_xlfn.XLOOKUP(E6,'Facture Chronopost'!L:L,'Facture Chronopost'!AA:AA,"") | T6: =IF(COUNTIF('Bibliothèque transporteurs'!C:C,F6)=0,"inconnu",_xlfn.XLOOKUP(F6,'Bibliothèque transporteurs'!C:C,'Bibliothèque transporteurs'!A:A)) | U6: =IF(OR(F6="6C",F6="6B"),_xlfn.XLOOKUP(E6,'Facture Chronopost'!L:L,'Facture Chronopost'!X:X),IF(OR(F6=17,F6=44),F6&"_"&H6,IF(COUNTIF('Bibliothèque transporteurs'!C:C,F6)=0,"inconnu",_xlfn.XLOOKUP(F6,'Bibliothèque transporteurs'!C:C,'Bibliothèque transporteurs'!B:B)))) | V6: =IF(COUNTIF('Bibliothèque transporteurs'!C:C,F6)=0,"inconnu",_xlfn.XLOOKUP(F6,'Bibliothèque transporteurs'!C:C,'Bibliothèque transporteurs'!E:E))
E7: CAPO1 | F7: X | G7: O | H7: XX | P7: 18.19 | S7: =_xlfn.XLOOKUP(E7,'Facture Chronopost'!L:L,'Facture Chronopost'!AA:AA,"") | T7: =IF(COUNTIF('Bibliothèque transporteurs'!C:C,F7)=0,"inconnu",_xlfn.XLOOKUP(F7,'Bibliothèque transporteurs'!C:C,'Bibliothèque transporteurs'!A:A)) | U7: =IF(OR(F7="6C",F7="6B"),_xlfn.XLOOKUP(E7,'Facture Chronopost'!L:L,'Facture Chronopost'!X:X),IF(OR(F7=17,F7=44),F7&"_"&H7,IF(COUNTIF('Bibliothèque transporteurs'!C:C,F7)=0,"inconnu",_xlfn.XLOOKUP(F7,'Bibliothèque transporteurs'!C:C,'Bibliothèque transporteurs'!B:B)))) | V7: =IF(COUNTIF('Bibliothèque transporteurs'!C:C,F7)=0,"inconnu",_xlfn.XLOOKUP(F7,'Bibliothèque transporteurs'!C:C,'Bibliothèque transporteurs'!E:E))
E8: ECORI | F8: X | G8: I | H8: XX | O8: 3.7 | S8: =_xlfn.XLOOKUP(E8,'Facture Chronopost'!L:L,'Facture Chronopost'!AA:AA,"") | T8: =IF(COUNTIF('Bibliothèque transporteurs'!C:C,F8)=0,"inconnu",_xlfn.XLOOKUP(F8,'Bibliothèque transporteurs'!C:C,'Bibliothèque transporteurs'!A:A)) | U8: =IF(OR(F8="6C",F8="6B"),_xlfn.XLOOKUP(E8,'Facture Chronopost'!L:L,'Facture Chronopost'!X:X),IF(OR(F8=17,F8=44),F8&"_"&H8,IF(COUNTIF('Bibliothèque transporteurs'!C:C,F8)=0,"inconnu",_xlfn.XLOOKUP(F8,'Bibliothèque transporteurs'!C:C,'Bibliothèque transporteurs'!B:B)))) | V8: =IF(COUNTIF('Bibliothèque transporteurs'!C:C,F8)=0,"inconnu",_xlfn.XLOOKUP(F8,'Bibliothèque transporteurs'!C:C,'Bibliothèque transporteurs'!E:E))
E9: ECORN | F9: X | G9: N | H9: XX | O9: 118.7 | S9: =_xlfn.XLOOKUP(E9,'Facture Chronopost'!L:L,'Facture Chronopost'!AA:AA,"") | T9: =IF(COUNTIF('Bibliothèque transporteurs'!C:C,F9)=0,"inconnu",_xlfn.XLOOKUP(F9,'Bibliothèque transporteurs'!C:C,'Bibliothèque transporteurs'!A:A)) | U9: =IF(OR(F9="6C",F9="6B"),_xlfn.XLOOKUP(E9,'Facture Chronopost'!L:L,'Facture Chronopost'!X:X),IF(OR(F9=17,F9=44),F9&"_"&H9,IF(COUNTIF('Bibliothèque transporteurs'!C:C,F9)=0,"inconnu",_xlfn.XLOOKUP(F9,'Bibliothèque transporteurs'!C:C,'Bibliothèque transporteurs'!B:B)))) | V9: =IF(COUNTIF('Bibliothèque transporteurs'!C:C,F9)=0,"inconnu",_xlfn.XLOOKUP(F9,'Bibliothèque transporteurs'!C:C,'Bibliothèque transporteurs'!E:E))
A10: =C10/SUM(C:C)*(SUM(C:C)+$X$2) | B10: =C10/SUM(C:C)*(SUM(C:C)+SUM($N$3:$O$7))+S10 | C10: =SUM(I10:Q10)-N10-P10 | E10: ECORO | F10: X | G10: O | H10: XX | O10: 0.1 | S10: =_xlfn.XLOOKUP(E10,'Facture Chronopost'!L:L,'Facture Chronopost'!AA:AA,"") | T10: =IF(COUNTIF('Bibliothèque transporteurs'!C:C,F10)=0,"inconnu",_xlfn.XLOOKUP(F10,'Bibliothèque transporteurs'!C:C,'Bibliothèque transporteurs'!A:A)) | U10: =IF(OR(F10="6C",F10="6B"),_xlfn.XLOOKUP(E10,'Facture Chronopost'!L:L,'Facture Chronopost'!X:X),IF(OR(F10=17,F10=44),F10&"_"&H10,IF(COUNTIF('Bibliothèque transporteurs'!C:C,F10)=0,"inconnu",_xlfn.XLOOKUP(F10,'Bibliothèque transporteurs'!C:C,'Bibliothèque transporteurs'!B:B)))) | V10: =IF(COUNTIF('Bibliothèque transporteurs'!C:C,F10)=0,"inconnu",_xlfn.XLOOKUP(F10,'Bibliothèque transporteurs'!C:C,'Bibliothèque transporteurs'!E:E)) | W10: =IF(T10="FR_2SHOP",O10,IF(O10=0,0,ROUNDUP(O10/C10*B10,2))) | Y10: =ROUNDUP(B10,2)-M10-L10-N10-J10-K10-I10-Q10 | Z10: =IF(Y10=W10,"OK","Non")
A11: =C11/SUM(C:C)*(SUM(C:C)+$X$2) | B11: =C11/SUM(C:C)*(SUM(C:C)+SUM($N$3:$O$7))+S11 | C11: =SUM(I11:Q11)-N11-P11 | E11: SURTI | F11: X | G11: I | H11: XX | O11: 14.8 | S11: =_xlfn.XLOOKUP(E11,'Facture Chronopost'!L:L,'Facture Chronopost'!AA:AA,"") | T11: =IF(COUNTIF('Bibliothèque transporteurs'!C:C,F11)=0,"inconnu",_xlfn.XLOOKUP(F11,'Bibliothèque transporteurs'!C:C,'Bibliothèque transporteurs'!A:A)) | U11: =IF(OR(F11="6C",F11="6B"),_xlfn.XLOOKUP(E11,'Facture Chronopost'!L:L,'Facture Chronopost'!X:X),IF(OR(F11=17,F11=44),F11&"_"&H11,IF(COUNTIF('Bibliothèque transporteurs'!C:C,F11)=0,"inconnu",_xlfn.XLOOKUP(F11,'Bibliothèque transporteurs'!C:C,'Bibliothèque transporteurs'!B:B)))) | V11: =IF(COUNTIF('Bibliothèque transporteurs'!C:C,F11)=0,"inconnu",_xlfn.XLOOKUP(F11,'Bibliothèque transporteurs'!C:C,'Bibliothèque transporteurs'!E:E)) | W11: =IF(T11="FR_2SHOP",O11,IF(O11=0,0,ROUNDUP(O11/C11*B11,2))) | Y11: =ROUNDUP(B11,2)-M11-L11-N11-J11-K11-I11-Q11 | Z11: =IF(Y11=W11,"OK","Non")
A12: =C12/SUM(C:C)*(SUM(C:C)+$X$2) | B12: =C12/SUM(C:C)*(SUM(C:C)+SUM($N$3:$O$7))+S12 | C12: =SUM(I12:Q12)-N12-P12 | E12: SURTN | F12: X | G12: N | H12: XX | O12: 378.2 | S12: =_xlfn.XLOOKUP(E12,'Facture Chronopost'!L:L,'Facture Chronopost'!AA:AA,"") | T12: =IF(COUNTIF('Bibliothèque transporteurs'!C:C,F12)=0,"inconnu",_xlfn.XLOOKUP(F12,'Bibliothèque transporteurs'!C:C,'Bibliothèque transporteurs'!A:A)) | U12: =IF(OR(F12="6C",F12="6B"),_xlfn.XLOOKUP(E12,'Facture Chronopost'!L:L,'Facture Chronopost'!X:X),IF(OR(F12=17,F12=44),F12&"_"&H12,IF(COUNTIF('Bibliothèque transporteurs'!C:C,F12)=0,"inconnu",_xlfn.XLOOKUP(F12,'Bibliothèque transporteurs'!C:C,'Bibliothèque transporteurs'!B:B)))) | V12: =IF(COUNTIF('Bibliothèque transporteurs'!C:C,F12)=0,"inconnu",_xlfn.XLOOKUP(F12,'Bibliothèque transporteurs'!C:C,'Bibliothèque transporteurs'!E:E)) | W12: =IF(T12="FR_2SHOP",O12,IF(O12=0,0,ROUNDUP(O12/C12*B12,2))) | Y12: =ROUNDUP(B12,2)-M12-L12-N12-J12-K12-I12-Q12 | Z12: =IF(Y12=W12,"OK","Non")
A13: =C13/SUM(C:C)*(SUM(C:C)+$X$2) | B13: =C13/SUM(C:C)*(SUM(C:C)+SUM($N$3:$O$7))+S13 | C13: =SUM(I13:Q13)-N13-P13 | E13: SURTO | F13: X | G13: O | H13: XX | O13: 0.4 | S13: =_xlfn.XLOOKUP(E13,'Facture Chronopost'!L:L,'Facture Chronopost'!AA:AA,"") | T13: =IF(COUNTIF('Bibliothèque transporteurs'!C:C,F13)=0,"inconnu",_xlfn.XLOOKUP(F13,'Bibliothèque transporteurs'!C:C,'Bibliothèque transporteurs'!A:A)) | U13: =IF(OR(F13="6C",F13="6B"),_xlfn.XLOOKUP(E13,'Facture Chronopost'!L:L,'Facture Chronopost'!X:X),IF(OR(F13=17,F13=44),F13&"_"&H13,IF(COUNTIF('Bibliothèque transporteurs'!C:C,F13)=0,"inconnu",_xlfn.XLOOKUP(F13,'Bibliothèque transporteurs'!C:C,'Bibliothèque transporteurs'!B:B)))) | V13: =IF(COUNTIF('Bibliothèque transporteurs'!C:C,F13)=0,"inconnu",_xlfn.XLOOKUP(F13,'Bibliothèque transporteurs'!C:C,'Bibliothèque transporteurs'!E:E)) | W13: =IF(T13="FR_2SHOP",O13,IF(O13=0,0,ROUNDUP(O13/C13*B13,2))) | Y13: =ROUNDUP(B13,2)-M13-L13-N13-J13-K13-I13-Q13 | Z13: =IF(Y13=W13,"OK","Non")
A14: =C14/SUM(C:C)*(SUM(C:C)+$X$2) | B14: =C14/SUM(C:C)*(SUM(C:C)+SUM($N$3:$O$7))+S14 | C14: =SUM(I14:Q14)-N14-P14 | D14: 6235 | E14: XF142220606FR | F14: 17 | G14: N | H14: Z1 | O14: 9.94 | S14: =_xlfn.XLOOKUP(E14,'Facture Chronopost'!L:L,'Facture Chronopost'!AA:AA,"") | T14: =IF(COUNTIF('Bibliothèque transporteurs'!C:C,F14)=0,"inconnu",_xlfn.XLOOKUP(F14,'Bibliothèque transporteurs'!C:C,'Bibliothèque transporteurs'!A:A)) | U14: =IF(OR(F14="6C",F14="6B"),_xlfn.XLOOKUP(E14,'Facture Chronopost'!L:L,'Facture Chronopost'!X:X),IF(OR(F14=17,F14=44),F14&"_"&H14,IF(COUNTIF('Bibliothèque transporteurs'!C:C,F14)=0,"inconnu",_xlfn.XLOOKUP(F14,'Bibliothèque transporteurs'!C:C,'Bibliothèque transporteurs'!B:B)))) | V14: =IF(COUNTIF('Bibliothèque transporteurs'!C:C,F14)=0,"inconnu",_xlfn.XLOOKUP(F14,'Bibliothèque transporteurs'!C:C,'Bibliothèque transporteurs'!E:E)) | W14: =IF(T14="FR_2SHOP",O14,IF(O14=0,0,ROUNDUP(O14/C14*B14,2))) | Y14: =ROUNDUP(B14,2)-M14-L14-N14-J14-K14-I14-Q14 | Z14: =IF(Y14=W14,"OK","Non")
A15: =C15/SUM(C:C)*(SUM(C:C)+$X$2) | B15: =C15/SUM(C:C)*(SUM(C:C)+SUM($N$3:$O$7))+S15 | C15: =SUM(I15:Q15)-N15-P15 | D15: 6235 | E15: XF142220708FR | F15: 17 | G15: N | H15: Z1 | O15: 19.47 | S15: =_xlfn.XLOOKUP(E15,'Facture Chronopost'!L:L,'Facture Chronopost'!AA:AA,"") | T15: =IF(COUNTIF('Bibliothèque transporteurs'!C:C,F15)=0,"inconnu",_xlfn.XLOOKUP(F15,'Bibliothèque transporteurs'!C:C,'Bibliothèque transporteurs'!A:A)) | U15: =IF(OR(F15="6C",F15="6B"),_xlfn.XLOOKUP(E15,'Facture Chronopost'!L:L,'Facture Chronopost'!X:X),IF(OR(F15=17,F15=44),F15&"_"&H15,IF(COUNTIF('Bibliothèque transporteurs'!C:C,F15)=0,"inconnu",_xlfn.XLOOKUP(F15,'Bibliothèque transporteurs'!C:C,'Bibliothèque transporteurs'!B:B)))) | V15: =IF(COUNTIF('Bibliothèque transporteurs'!C:C,F15)=0,"inconnu",_xlfn.XLOOKUP(F15,'Bibliothèque transporteurs'!C:C,'Bibliothèque transporteurs'!E:E)) | W15: =IF(T15="FR_2SHOP",O15,IF(O15=0,0,ROUNDUP(O15/C15*B15,2))) | Y15: =ROUNDUP(B15,2)-M15-L15-N15-J15-K15-I15-Q15 | Z15: =IF(Y15=W15,"OK","Non")
A16: =C16/SUM(C:C)*(SUM(C:C)+$X$2) | B16: =C16/SUM(C:C)*(SUM(C:C)+SUM($N$3:$O$7))+S16 | C16: =SUM(I16:Q16)-N16-P16 | D16: 6235 | E16: XF142220932FR | F16: 17 | G16: N | H16: Z1 | O16: 9.94 | S16: =_xlfn.XLOOKUP(E16,'Facture Chronopost'!L:L,'Facture Chronopost'!AA:AA,"") | T16: =IF(COUNTIF('Bibliothèque transporteurs'!C:C,F16)=0,"inconnu",_xlfn.XLOOKUP(F16,'Bibliothèque transporteurs'!C:C,'Bibliothèque transporteurs'!A:A)) | U16: =IF(OR(F16="6C",F16="6B"),_xlfn.XLOOKUP(E16,'Facture Chronopost'!L:L,'Facture Chronopost'!X:X),IF(OR(F16=17,F16=44),F16&"_"&H16,IF(COUNTIF('Bibliothèque transporteurs'!C:C,F16)=0,"inconnu",_xlfn.XLOOKUP(F16,'Bibliothèque transporteurs'!C:C,'Bibliothèque transporteurs'!B:B)))) | V16: =IF(COUNTIF('Bibliothèque transporteurs'!C:C,F16)=0,"inconnu",_xlfn.XLOOKUP(F16,'Bibliothèque transporteurs'!C:C,'Bibliothèque transporteurs'!E:E)) | W16: =IF(T16="FR_2SHOP",O16,IF(O16=0,0,ROUNDUP(O16/C16*B16,2))) | Y16: =ROUNDUP(B16,2)-M16-L16-N16-J16-K16-I16-Q16 | Z16: =IF(Y16=W16,"OK","Non")
A17: =C17/SUM(C:C)*(SUM(C:C)+$X$2) | B17: =C17/SUM(C:C)*(SUM(C:C)+SUM($N$3:$O$7))+S17 | C17: =SUM(I17:Q17)-N17-P17 | D17: 6235 | E17: XF142221116FR | F17: 17 | G17: N | H17: Z1 | O17: 7.86 | S17: =_xlfn.XLOOKUP(E17,'Facture Chronopost'!L:L,'Facture Chronopost'!AA:AA,"") | T17: =IF(COUNTIF('Bibliothèque transporteurs'!C:C,F17)=0,"inconnu",_xlfn.XLOOKUP(F17,'Bibliothèque transporteurs'!C:C,'Bibliothèque transporteurs'!A:A)) | U17: =IF(OR(F17="6C",F17="6B"),_xlfn.XLOOKUP(E17,'Facture Chronopost'!L:L,'Facture Chronopost'!X:X),IF(OR(F17=17,F17=44),F17&"_"&H17,IF(COUNTIF('Bibliothèque transporteurs'!C:C,F17)=0,"inconnu",_xlfn.XLOOKUP(F17,'Bibliothèque transporteurs'!C:C,'Bibliothèque transporteurs'!B:B)))) | V17: =IF(COUNTIF('Bibliothèque transporteurs'!C:C,F17)=0,"inconnu",_xlfn.XLOOKUP(F17,'Bibliothèque transporteurs'!C:C,'Bibliothèque transporteurs'!E:E)) | W17: =IF(T17="FR_2SHOP",O17,IF(O17=0,0,ROUNDUP(O17/C17*B17,2))) | Y17: =ROUNDUP(B17,2)-M17-L17-N17-J17-K17-I17-Q17 | Z17: =IF(Y17=W17,"OK","Non")
A18: =C18/SUM(C:C)*(SUM(C:C)+$X$2) | B18: =C18/SUM(C:C)*(SUM(C:C)+SUM($N$3:$O$7))+S18 | C18: =SUM(I18:Q18)-N18-P18 | D18: 6235 | E18: XF142221147FR | F18: 17 | G18: N | H18: Z3 | O18: 13.35 | S18: =_xlfn.XLOOKUP(E18,'Facture Chronopost'!L:L,'Facture Chronopost'!AA:AA,"") | T18: =IF(COUNTIF('Bibliothèque transporteurs'!C:C,F18)=0,"inconnu",_xlfn.XLOOKUP(F18,'Bibliothèque transporteurs'!C:C,'Bibliothèque transporteurs'!A:A)) | U18: =IF(OR(F18="6C",F18="6B"),_xlfn.XLOOKUP(E18,'Facture Chronopost'!L:L,'Facture Chronopost'!X:X),IF(OR(F18=17,F18=44),F18&"_"&H18,IF(COUNTIF('Bibliothèque transporteurs'!C:C,F18)=0,"inconnu",_xlfn.XLOOKUP(F18,'Bibliothèque transporteurs'!C:C,'Bibliothèque transporteurs'!B:B)))) | V18: =IF(COUNTIF('Bibliothèque transporteurs'!C:C,F18)=0,"inconnu",_xlfn.XLOOKUP(F18,'Bibliothèque transporteurs'!C:C,'Bibliothèque transporteurs'!E:E)) | W18: =IF(T18="FR_2SHOP",O18,IF(O18=0,0,ROUNDUP(O18/C18*B18,2))) | Y18: =ROUNDUP(B18,2)-M18-L18-N18-J18-K18-I18-Q18 | Z18: =IF(Y18=W18,"OK","Non")
A19: =C19/SUM(C:C)*(SUM(C:C)+$X$2) | B19: =C19/SUM(C:C)*(SUM(C:C)+SUM($N$3:$O$7))+S19 | C19: =SUM(I19:Q19)-N19-P19 | D19: 6235 | E19: XF142221677FR | F19: 17 | G19: N | H19: Z2 | O19: 18.34 | S19: =_xlfn.XLOOKUP(E19,'Facture Chronopost'!L:L,'Facture Chronopost'!AA:AA,"") | T19: =IF(COUNTIF('Bibliothèque transporteurs'!C:C,F19)=0,"inconnu",_xlfn.XLOOKUP(F19,'Bibliothèque transporteurs'!C:C,'Bibliothèque transporteurs'!A:A)) | U19: =IF(OR(F19="6C",F19="6B"),_xlfn.XLOOKUP(E19,'Facture Chronopost'!L:L,'Facture Chronopost'!X:X),IF(OR(F19=17,F19=44),F19&"_"&H19,IF(COUNTIF('Bibliothèque transporteurs'!C:C,F19)=0,"inconnu",_xlfn.XLOOKUP(F19,'Bibliothèque transporteurs'!C:C,'Bibliothèque transporteurs'!B:B)))) | V19: =IF(COUNTIF('Bibliothèque transporteurs'!C:C,F19)=0,"inconnu",_xlfn.XLOOKUP(F19,'Bibliothèque transporteurs'!C:C,'Bibliothèque transporteurs'!E:E)) | W19: =IF(T19="FR_2SHOP",O19,IF(O19=0,0,ROUNDUP(O19/C19*B19,2))) | Y19: =ROUNDUP(B19,2)-M19-L19-N19-J19-K19-I19-Q19 | Z19: =IF(Y19=W19,"OK","Non")
A20: =C20/SUM(C:C)*(SUM(C:C)+$X$2) | B20: =C20/SUM(C:C)*(SUM(C:C)+SUM($N$3:$O$7))+S20 | C20: =SUM(I20:Q20)-N20-P20 | D20: 6235 | E20: XF142221779FR | F20: 17 | G20: N | H20: Z1 | O20: 21.83 | S20: =_xlfn.XLOOKUP(E20,'Facture Chronopost'!L:L,'Facture Chronopost'!AA:AA,"") | T20: =IF(COUNTIF('Bibliothèque transporteurs'!C:C,F20)=0,"inconnu",_xlfn.XLOOKUP(F20,'Bibliothèque transporteurs'!C:C,'Bibliothèque transporteurs'!A:A)) | U20: =IF(OR(F20="6C",F20="6B"),_xlfn.XLOOKUP(E20,'Facture Chronopost'!L:L,'Facture Chronopost'!X:X),IF(OR(F20=17,F20=44),F20&"_"&H20,IF(COUNTIF('Bibliothèque transporteurs'!C:C,F20)=0,"inconnu",_xlfn.XLOOKUP(F20,'Bibliothèque transporteurs'!C:C,'Bibliothèque transporteurs'!B:B)))) | V20: =IF(COUNTIF('Bibliothèque transporteurs'!C:C,F20)=0,"inconnu",_xlfn.XLOOKUP(F20,'Bibliothèque transporteurs'!C:C,'Bibliothèque transporteurs'!E:E)) | W20: =IF(T20="FR_2SHOP",O20,IF(O20=0,0,ROUNDUP(O20/C20*B20,2))) | Y20: =ROUNDUP(B20,2)-M20-L20-N20-J20-K20-I20-Q20 | Z20: =IF(Y20=W20,"OK","Non")
A21: =C21/SUM(C:C)*(SUM(C:C)+$X$2) | B21: =C21/SUM(C:C)*(SUM(C:C)+SUM($N$3:$O$7))+S21 | C21: =SUM(I21:Q21)-N21-P21 | D21: 6235 | E21: XF142224761FR | F21: 17 | G21: N | H21: Z2 | O21: 9.94 | S21: =_xlfn.XLOOKUP(E21,'Facture Chronopost'!L:L,'Facture Chronopost'!AA:AA,"") | T21: =IF(COUNTIF('Bibliothèque transporteurs'!C:C,F21)=0,"inconnu",_xlfn.XLOOKUP(F21,'Bibliothèque transporteurs'!C:C,'Bibliothèque transporteurs'!A:A)) | U21: =IF(OR(F21="6C",F21="6B"),_xlfn.XLOOKUP(E21,'Facture Chronopost'!L:L,'Facture Chronopost'!X:X),IF(OR(F21=17,F21=44),F21&"_"&H21,IF(COUNTIF('Bibliothèque transporteurs'!C:C,F21)=0,"inconnu",_xlfn.XLOOKUP(F21,'Bibliothèque transporteurs'!C:C,'Bibliothèque transporteurs'!B:B)))) | V21: =IF(COUNTIF('Bibliothèque transporteurs'!C:C,F21)=0,"inconnu",_xlfn.XLOOKUP(F21,'Bibliothèque transporteurs'!C:C,'Bibliothèque transporteurs'!E:E)) | W21: =IF(T21="FR_2SHOP",O21,IF(O21=0,0,ROUNDUP(O21/C21*B21,2))) | Y21: =ROUNDUP(B21,2)-M21-L21-N21-J21-K21-I21-Q21 | Z21: =IF(Y21=W21,"OK","Non")
A22: =C22/SUM(C:C)*(SUM(C:C)+$X$2) | B22: =C22/SUM(C:C)*(SUM(C:C)+SUM($N$3:$O$7))+S22 | C22: =SUM(I22:Q22)-N22-P22 | D22: 6235 | E22: XF142225206FR | F22: 17 | G22: N | H22: Z1 | O22: 21.83 | S22: =_xlfn.XLOOKUP(E22,'Facture Chronopost'!L:L,'Facture Chronopost'!AA:AA,"") | T22: =IF(COUNTIF('Bibliothèque transporteurs'!C:C,F22)=0,"inconnu",_xlfn.XLOOKUP(F22,'Bibliothèque transporteurs'!C:C,'Bibliothèque transporteurs'!A:A)) | U22: =IF(OR(F22="6C",F22="6B"),_xlfn.XLOOKUP(E22,'Facture Chronopost'!L:L,'Facture Chronopost'!X:X),IF(OR(F22=17,F22=44),F22&"_"&H22,IF(COUNTIF('Bibliothèque transporteurs'!C:C,F22)=0,"inconnu",_xlfn.XLOOKUP(F22,'Bibliothèque transporteurs'!C:C,'Bibliothèque transporteurs'!B:B)))) | V22: =IF(COUNTIF('Bibliothèque transporteurs'!C:C,F22)=0,"inconnu",_xlfn.XLOOKUP(F22,'Bibliothèque transporteurs'!C:C,'Bibliothèque transporteurs'!E:E)) | W22: =IF(T22="FR_2SHOP",O22,IF(O22=0,0,ROUNDUP(O22/C22*B22,2))) | Y22: =ROUNDUP(B22,2)-M22-L22-N22-J22-K22-I22-Q22 | Z22: =IF(Y22=W22,"OK","Non")
A23: =C23/SUM(C:C)*(SUM(C:C)+$X$2) | B23: =C23/SUM(C:C)*(SUM(C:C)+SUM($N$3:$O$7))+S23 | C23: =SUM(I23:Q23)-N23-P23 | D23: 6235 | E23: XF142225223FR | F23: 17 | G23: N | H23: Z1 | O23: 18.34 | S23: =_xlfn.XLOOKUP(E23,'Facture Chronopost'!L:L,'Facture Chronopost'!AA:AA,"") | T23: =IF(COUNTIF('Bibliothèque transporteurs'!C:C,F23)=0,"inconnu",_xlfn.XLOOKUP(F23,'Bibliothèque transporteurs'!C:C,'Bibliothèque transporteurs'!A:A)) | U23: =IF(OR(F23="6C",F23="6B"),_xlfn.XLOOKUP(E23,'Facture Chronopost'!L:L,'Facture Chronopost'!X:X),IF(OR(F23=17,F23=44),F23&"_"&H23,IF(COUNTIF('Bibliothèque transporteurs'!C:C,F23)=0,"inconnu",_xlfn.XLOOKUP(F23,'Bibliothèque transporteurs'!C:C,'Bibliothèque transporteurs'!B:B)))) | V23: =IF(COUNTIF('Bibliothèque transporteurs'!C:C,F23)=0,"inconnu",_xlfn.XLOOKUP(F23,'Bibliothèque transporteurs'!C:C,'Bibliothèque transporteurs'!E:E)) | W23: =IF(T23="FR_2SHOP",O23,IF(O23=0,0,ROUNDUP(O23/C23*B23,2))) | Y23: =ROUNDUP(B23,2)-M23-L23-N23-J23-K23-I23-Q23 | Z23: =IF(Y23=W23,"OK","Non")
A24: =C24/SUM(C:C)*(SUM(C:C)+$X$2) | B24: =C24/SUM(C:C)*(SUM(C:C)+SUM($N$3:$O$7))+S24 | C24: =SUM(I24:Q24)-N24-P24 | D24: 6235 | E24: XF142225342FR | F24: 17 | G24: N | H24: Z1 | O24: 18.34 | S24: =_xlfn.XLOOKUP(E24,'Facture Chronopost'!L:L,'Facture Chronopost'!AA:AA,"") | T24: =IF(COUNTIF('Bibliothèque transporteurs'!C:C,F24)=0,"inconnu",_xlfn.XLOOKUP(F24,'Bibliothèque transporteurs'!C:C,'Bibliothèque transporteurs'!A:A)) | U24: =IF(OR(F24="6C",F24="6B"),_xlfn.XLOOKUP(E24,'Facture Chronopost'!L:L,'Facture Chronopost'!X:X),IF(OR(F24=17,F24=44),F24&"_"&H24,IF(COUNTIF('Bibliothèque transporteurs'!C:C,F24)=0,"inconnu",_xlfn.XLOOKUP(F24,'Bibliothèque transporteurs'!C:C,'Bibliothèque transporteurs'!B:B)))) | V24: =IF(COUNTIF('Bibliothèque transporteurs'!C:C,F24)=0,"inconnu",_xlfn.XLOOKUP(F24,'Bibliothèque transporteurs'!C:C,'Bibliothèque transporteurs'!E:E)) | W24: =IF(T24="FR_2SHOP",O24,IF(O24=0,0,ROUNDUP(O24/C24*B24,2))) | Y24: =ROUNDUP(B24,2)-M24-L24-N24-J24-K24-I24-Q24 | Z24: =IF(Y24=W24,"OK","Non")
