Workbook

Sheet Zoning
A1: Pays | B1: Code ISO | C1: FICP | D1: IE | E1: RE | F1: Zone
A2: Andorre | B2: AD | C2: S | D2: T
A3: Émirats arabes unis | B3: AE | C3: C
A4: Afghanistan | B4: AF
A5: Antigua-et-Barbuda | B5: AG
A6: Anguilla | B6: AI | C6: D
A7: Albanie | B7: AL | C7: W
A8: Arménie | B8: AM | C8: C
A9: Angola | B9: AO | C9: E
A10: Argentine | B10: AR | C10: D
A11: Samoa américaines | B11: AS
A12: Autriche | B12: AT | C12: T | F12: Europe
A13: Australie | B13: AU | C13: G
A14: Aruba | B14: AW | C14: D
A15: Azerbaïdjan | B15: AZ | C15: C
A16: Bosnie-Herzégovine | B16: BA | C16: W | F16: Europe
A17: Barbade | B17: BB | C17: D
A18: Bangladesh | B18: BD | C18: C
A19: Belgique | B19: BE | C19: R | F19: Europe
A20: Burkina Faso | B20: BF | C20: E
A21: Bulgarie | B21: BG | C21: U | F21: Europe
A22: Bahreïn | B22: BH | C22: C
A23: Burundi | B23: BI | C23: E
A24: Bénin | B24: BJ | C24: E
A25: Saint-Barthélemy | B25: BL
A26: Bermudes | B26: BM | C26: D
A27: Brunei | B27: BN | C27: C
A28: Bolivie | B28: BO | C28: D
A29: Pays-Bas caribéens | B29: BQ
A30: Brésil | B30: BR | C30: D | F30: International
A31: Bahamas | B31: BS | C31: D
A32: Bhoutan | B32: BT | C32: C
A33: Botswana | B33: BW | C33: E
A34: Biélorussie | B34: BY
A35: Belize | B35: BZ | C35: D
A36: Canada | B36: CA | C36: A | F36: International
A37: République démocratique du Congo | B37: CD | C37: E
A38: République centrafricaine | B38: CF
A39: Congo | B39: CG | C39: E
A40: Suisse | B40: CH | C40: U | F40: International
...

Sheet Bilan factures
A3: Étiquettes de lignes | B3: Frêt HT | C3: Total TTC | D3: PDF | E3: Ecart
A4: 634323394 | B4: 217.91 | C4: 368.95 | D4: 368.95 | E4: =C4-D4 -> 0
A5: 634324015 | B5: 4124.86 | C5: 9093.5 | D5: 9093.5 | E5: =C5-D5 -> -2.0008883e-11
A6: 634333315 | B6: 34.63 | C6: 112.36 | D6: 112.36 | E6: =C6-D6 -> 0
A7: 634333759 | B7: 12657.37 | C7: 36460 | D7: 36460 | E7: =C7-D7 -> 2.6193447e-10
A8: 634343396 | B8: 119.26 | C8: 188.96 | D8: 188.96 | E8: =C8-D8 -> 0
A9: 634343823 | B9: 10563.68 | C9: 28893.06 | D9: 28893.06 | E9: =C9-D9 -> -4.3655746e-11
A10: 634353470 | B10: 117.97 | C10: 196.76 | D10: 196.76 | E10: =C10-D10 -> 0
A11: 634353938 | B11: 8832.41 | C11: 14308.73 | D11: 14308.73 | E11: =C11-D11 -> -6.184564e-11
A12: 634364547 | B12: 8847.74 | C12: 13684.18 | D12: 13684.18 | E12: =C12-D12 -> -4.1836756e-11
A13: (vide) | E13: =C13-D13 -> 0
A14: Total général | B14: 45515.83 | C14: 103306.5

Sheet Shipment Detail
A1: Montant | B1: Clients | C1: Catégorie | D1: E/P | E1: Mode d'envoi | F1: Payer Account | G1: Invoice Month (yyyymm) | H1: OPCO | I1: Service Type | J1: Service Description | K1: Pay Type | L1: Shipment Date (mm/dd/yyyy) | M1: Shipment Delivery Date (mm/dd/yyyy) | N1: Shipment Tracking Number | O1: Postal Identification Number | P1: Shipper Name | Q1: Shipper Company Name | R1: Shipper Address | S1: Shipper City | T1: Shipper State/Province | U1: Shipper Country/Territory | V1: Shipper Postal Code | W1: Shipment Freight Charge Amount USD | X1: Shipment Miscellaneous Charge USD | Y1: Shipment Duty and Tax Charge USD | Z1: Shipment Discount Amount USD | AA1: Net Charge Amount USD | AB1: Pieces In Shipment | AC1: Shipment Rated Weight (Pounds) | AD1: Original Weight (Pounds) | AE1: Proof Of Delivery Recipient | AF1: Recipient Name | AG1: Recipient Company Name | AH1: Recipient Address | AI1: Recipient City | AJ1: Recipient State/Province | AK1: Recipient Country/Territory | AL1: Recipient Postal Code | AM1: Reference Notes Line 1 | AN1: Reference Notes Line 2 | AO1: Reference Notes Line 3 | AP1: Department Number | AQ1: PO Number | AR1: Pricing Zone | AS1: Shipment DIM Flag (Y or N) | AT1: Dimmed Height (cm) | AU1: Dimmed Width (cm) | AV1: Dimmed Length (cm) | AW1: Recipient Original Address | AX1: Recipient Original City | AY1: Recipient Original State/Province | AZ1: Recipient Original Postal Code | BA1: Recipient Original Country/Territory | BB1: Shipment Declared Value Amount | BC1: Customs Value | BD1: Customs Value Currency Code | BE1: Invoice Date (mm/dd/yyyy) | BF1: Invoice Number | BG1: Master Tracking Number | BH1: Domestic/Intl | BI1: Package Type | BJ1: Shipment Delivery Time (12 Hours) | BK1: Shipment Freight Charge Billed Currency | BL1: Shipment Miscellaneous Charge Billed Currency | BM1: Shipment Duty And Tax Charge Billed Currency | BN1: Shipment Discount Billed Currency | BO1: Net Charge Billed Currency | BP1: Billed Currency Code | BQ1: Exchange Rate to USD | BR1: Weight Type Code | BS1: Customer Order Number
A2: =BK2+BN2 -> 13.48 | B2: 3752 | D2: entreprise | E2: =IF(J2="FedEx Priority","ST","FICP") -> ST | F2: 200720433 | G2: 202606 | H2: Express | I2: UO | J2: FedEx Priority | K2: Bill_Sender_Prepaid | L2: 46028 | M2: 46059 | N2: 872386856889 | P2: HYDRATIS B2B | Q2: HYDRATIS B2B | R2: VOIE COMMUNALE 4 | S2: CR?ANCEY | T2: 21 | U2: FR | V2: 21320 | W2: 65.79 | X2: 7.79 | Y2: 0 | Z2: -50.06 | AA2: 23.52 | AB2: 3 | AC2: 59.4 | AD2: 11.88 | AE2: M,AISON BLANCHE | AF2: PHARMACIE AUBIJOUX | AG2: PHARMACIE AUBIJOUX | AH2: 160 AVENUE D'ITALIE | AI2: PARIS 13 | AJ2: 75 | AK2: FR | AL2: 75013 | AS2: N | AT2: 30 | AU2: 31 | AV2: 40 | BB2: 0 | BC2: 0 | BD2: EUR | BE2: 46240 | BF2: 634324015 | BH2: Domestic | BI2: Your Packaging | BJ2: 0.52361111 | BK2: 56.4 | BL2: 6.68 | BM2: 0 | BN2: -42.92 | BO2: 20.16 | BP2: EUR | BQ2: 1.1664392 | BR2: kg
A3: =BK3+BN3 -> 9.8 | B3: 3752 | D3: entreprise | E3: =IF(J3="FedEx Priority","ST","FICP") -> ST | F3: 200720433 | G3: 202606 | H3: Express | I3: UO | J3: FedEx Priority | K3: Bill_Sender_Prepaid | L3: 05/28/2026 | M3: 05/29/2026 | N3: 872328943547 | P3: HYDRATIS B2B | Q3: HYDRATIS B2B | R3: VOIE COMMUNALE 4 | S3: CR?ANCEY | T3: 21 | U3: FR | V3: 21320 | W3: 47.7 | X3: 13.49 | Y3: 0 | Z3: -36.3 | AA3: 24.9 | AB3: 2 | AC3: 35.2 | AD3: 3.96 | AE3: B,AZINET | AF3: PHARMACIE MC PHARMA | AG3: PHARMACIE MC PHARMA | AH3: CCIAL LA GRANDE ROCADE | AI3: PRADES | AJ3: 66 | AK3: FR | AL3: 66500 | AS3: N | AT3: 0 | AU3: 0 | AV3: 0 | BB3: 0 | BC3: 0 | BD3: EUR | BE3: 46240 | BF3: 634324015 | BH3: Domestic | BI3: Your Packaging | BJ3: 0.46111111 | BK3: 41 | BL3: 11.6 | BM3: 0 | BN3: -31.2 | BO3: 21.4 | BP3: EUR | BQ3: 1.1633182 | BR3: kg
A4: =BK4+BN4 -> 12.14 | B4: 3752 | D4: entreprise | E4: =IF(J4="FedEx Priority","ST","FICP") -> ST | F4: 200720433 | G4: 202606 | H4: Express | I4: UO | J4: FedEx Priority | K4: Bill_Sender_Prepaid | L4: 46028 | M4: 46087 | N4: 872391359368 | P4: HYDRATIS B2B | Q4: HYDRATIS B2B | R4: VOIE COMMUNALE 4 | S4: CR?ANCEY | T4: 21 | U4: FR | V4: 21320 | W4: 59.26 | X4: 7.02 | Y4: 0 | Z4: -45.09 | AA4: 21.18 | AB4: 4 | AC4: 48.84 | AD4: 10.56 | AE4: P, CENTRE | AF4: PHARMACIE DU CENTRE | AG4: PHARMACIE DU CENTRE | AH4: 148 AVENUE SAINT ALBERT | AI4: PUGET SUR ARGENS | AJ4: 83 | AK4: FR | AL4: 83480 | AS4: N | AT4: 0 | AU4: 0 | AV4: 0 | BB4: 0 | BC4: 0 | BD4: EUR | BE4: 46240 | BF4: 634324015 | BH4: Domestic | BI4: Your Packaging | BJ4: 0.51875 | BK4: 50.8 | BL4: 6.02 | BM4: 0 | BN4: -38.66 | BO4: 18.16 | BP4: EUR | BQ4: 1.1664392 | BR4: kg
A5: =BK5+BN5 -> 13.48 | B5: 3752 | D5: entreprise | E5: =IF(J5="FedEx Priority","ST","FICP") -> ST | F5: 200720433 | G5: 202606 | H5: Express | I5: UO | J5: FedEx Priority | K5: Bill_Sender_Prepaid | L5: 05/29/2026 | M5: 05/30/2026 | N5: 872337970166 | P5: HYDRATIS B2B | Q5: HYDRATIS B2B | R5: VOIE COMMUNALE 4 | S5: CR?ANCEY | T5: 21 | U5: FR | V5: 21320 | W5: 65.63 | X5: 6.99 | Y5: 0 | Z5: -49.95 | AA5: 22.68 | AB5: 5 | AC5: 58.08 | AD5: 18.7 | AE5: P,ARIS | AF5: PHARMACIE SAINTPOL | AG5: PHARMACIE SAINTPOL | AH5: 12 PLACE DU GENERAL DE SAINT POL | AI5: NOGENT-LE-ROTROU | AJ5: 28 | AK5: FR | AL5: 28400 | AS5: N | AT5: 0 | AU5: 0 | AV5: 0 | BB5: 0 | BC5: 0 | BD5: EUR | BE5: 46240 | BF5: 634324015 | BH5: Domestic | BI5: Your Packaging | BJ5: 0.42291667 | BK5: 56.4 | BL5: 6.01 | BM5: 0 | BN5: -42.92 | BO5: 19.49 | BP5: EUR | BQ5: 1.1637244 | BR5: kg
A6: =BK6+BN6 -> 11.47 | B6: 3752 | D6: entreprise | E6: =IF(J6="FedEx Priority","ST","FICP") -> ST | F6: 200720433 | G6: 202606 | H6: Express | I6: UO | J6: FedEx Priority | K6: Bill_Sender_Prepaid | L6: 05/29/2026 | M6: 05/30/2026 | N6: 872384769195 | P6: HYDRATIS B2B | Q6: HYDRATIS B2B | R6: VOIE COMMUNALE 4 | S6: CR?ANCEY | T6: 21 | U6: FR | V6: 21320 | W6: 55.86 | X6: 5.95 | Y6: 0 | Z6: -42.51 | AA6: 19.29 | AB6: 3 | AC6: 46.2 | AD6: 9.9 | AE6: A,Behue | AF6: PHARMACIE DES VIGNES | AG6: PHARMACIE DES VIGNES | AH6: 1 D RUE D'ALMAS PELLOUAILLES | AI6: VERRIERES-EN-ANJOU | AJ6: 49 | AK6: FR | AL6: 49112 | AS6: N | AT6: 30 | AU6: 31 | AV6: 38 | BB6: 0 | BC6: 0 | BD6: EUR | BE6: 46240 | BF6: 634324015 | BH6: Domestic | BI6: Your Packaging | BJ6: 0.46527778 | BK6: 48 | BL6: 5.11 | BM6: 0 | BN6: -36.53 | BO6: 16.58 | BP6: EUR | BQ6: 1.1637244 | BR6: kg
A7: =BK7+BN7 -> 7.12 | B7: 3752 | D7: entreprise | E7: =IF(J7="FedEx Priority","ST","FICP") -> ST | F7: 200720433 | G7: 202606 | H7: Express | I7: UO | J7: FedEx Priority | K7: Bill_Sender_Prepaid | L7: 46028 | M7: 46059 | N7: 872384622893 | P7: HYDRATIS B2B | Q7: HYDRATIS B2B | R7: VOIE COMMUNALE 4 | S7: CR?ANCEY | T7: 21 | U7: FR | V7: 21320 | W7: 34.76 | X7: 4.13 | Y7: 0 | Z7: -26.45 | AA7: 12.43 | AB7: 1 | AC7: 15.84 | AD7: 1.98 | AE7: F,ABIENNE | AF7: OCP STC BAULE | AG7: OCP STC BAULE | AH7: 600 RUE 1ERE AVENUE | AI7: BAULE | AJ7: 45 | AK7: FR | AL7: 45130 | AS7: Y | AT7: 30 | AU7: 30 | AV7: 40 | BB7: 0 | BC7: 0 | BD7: EUR | BE7: 46240 | BF7: 634324015 | BH7: Domestic | BI7: Your Packaging | BJ7: 0.40486111 | BK7: 29.8 | BL7: 3.54 | BM7: 0 | BN7: -22.68 | BO7: 10.66 | BP7: EUR | BQ7: 1.1664392 | BR7: kg
A8: =BK8+BN8 -> 8.8 | B8: 3752 | D8: entreprise | E8: =IF(J8="FedEx Priority","ST","FICP") -> ST | F8: 200720433 | G8: 202606 | H8: Express | I8: UO | J8: FedEx Priority | K8: Bill_Sender_Prepaid | L8: 05/28/2026 | M8: 05/29/2026 | N8: 872285404035 | P8: HYDRATIS B2B | Q8: HYDRATIS B2B | R8: VOIE COMMUNALE 4 | S8: CR?ANCEY | T8: 21 | U8: FR | V8: 21320 | W8: 42.81 | X8: 4.56 | Y8: 0 | Z8: -32.57 | AA8: 14.8 | AB8: 2 | AC8: 28.6 | AD8: 4.84 | AE8: P,HI ETAIN | AF8: PHARMACIE DU POT D'ETAIN | AG8: PHARMACIE DU POT D'ETAIN | AH8: 11 BIS PLACE DU POT D'ETAIN | AI8: PONT-AUDEMER | AJ8: 27 | AK8: FR | AL8: 27500 | AS8: N | AT8: 0 | AU8: 0 | AV8: 0 | BB8: 0 | BC8: 0 | BD8: EUR | BE8: 46240 | BF8: 634324015 | BH8: Domestic | BI8: Your Packaging | BJ8: 0.49930556 | BK8: 36.8 | BL8: 3.92 | BM8: 0 | BN8: -28 | BO8: 12.72 | BP8: EUR | BQ8: 1.1633182 | BR8: kg
A9: =BK9+BN9 -> 7.79 | B9: 3752 | D9: entreprise | E9: =IF(J9="FedEx Priority","ST","FICP") -> ST | F9: 200720433 | G9: 202606 | H9: Express | I9: UO | J9: FedEx Priority | K9: Bill_Sender_Prepaid | L9: 05/29/2026 | M9: 46059 | N9: 872385135922 | P9: HYDRATIS B2B | Q9: HYDRATIS B2B | R9: VOIE COMMUNALE 4 | S9: CR?ANCEY | T9: 21 | U9: FR | V9: 21320 | W9: 37.94 | X9: 4.04 | Y9: 0 | Z9: -28.87 | AA9: 13.1 | AB9: 2 | AC9: 21.12 | AD9: 2.64 | AE9: M,Marina | AF9: PHARMACIE DES PAGES | AG9: PHARMACIE DES PAGES | AH9: 16/18 ROUTE DE MONTESSON | AI9: LE V?SINET | AJ9: 78 | AK9: FR | AL9: 78110 | AS9: N | AT9: 0 | AU9: 0 | AV9: 0 | BB9: 0 | BC9: 0 | BD9: EUR | BE9: 46240 | BF9: 634324015 | BH9: Domestic | BI9: Your Packaging | BJ9: 0.45069444 | BK9: 32.6 | BL9: 3.47 | BM9: 0 | BN9: -24.81 | BO9: 11.26 | BP9: EUR | BQ9: 1.1637244 | BR9: kg
A10: =BK10+BN10 -> 10.47 | B10: 3752 | D10: entreprise | E10: =IF(J10="FedEx Priority","ST","FICP") -> ST | F10: 200720433 | G10: 202606 | H10: Express | I10: UO | J10: FedEx Priority | K10: Bill_Sender_Prepaid | L10: 46028 | M10: 46059 | N10: 872285149227 | P10: HYDRATIS B2B | Q10: HYDRATIS B2B | R10: VOIE COMMUNALE 4 | S10: CR?ANCEY | T10: 21 | U10: FR | V10: 21320 | W10: 51.09 | X10: 6.05 | Y10: 0 | Z10: -38.88 | AA10: 18.27 | AB10: 3 | AC10: 39.38 | AD10: 5.94 | AE10: R,OSSI | AF10: INTERSPORT DENAIN 04967/000 | AG10: INTERSPORT DENAIN 04967/000 | AH10: SAS AFC SPORTS ST GEOIRS | AI10: SAINT-ETIENNE-DE-SAINT-GEOIRS | AJ10: 38 | AK10: FR | AL10: 38590 | AS10: N | AT10: 30 | AU10: 31 | AV10: 40 | BB10: 0 | BC10: 0 | BD10: EUR | BE10: 46240 | BF10: 634324015 | BH10: Domestic | BI10: Your Packaging | BJ10: 0.38541667 | BK10: 43.8 | BL10: 5.19 | BM10: 0 | BN10: -33.33 | BO10: 15.66 | BP10: EUR | BQ10: 1.1664392 | BR10: kg
A11: =BK11+BN11 -> 6.45 | B11: 3752 | D11: entreprise | E11: =IF(J11="FedEx Priority","ST","FICP") -> ST | F11: 200720433 | G11: 202606 | H11: Express | I11: UO | J11: FedEx Priority | K11: Bill_Sender_Prepaid | L11: 46059 | M11: 46118 | N11: 872389888666 | P11: HYDRATIS B2B | Q11: HYDRATIS B2B | R11: VOIE COMMUNALE 4 | S11: CR?ANCEY | T11: 21 | U11: FR | V11: 21320 | W11: 31.49 | X11: 3.73 | Y11: 0 | Z11: -23.97 | AA11: 11.26 | AB11: 1 | AC11: 13.2 | AD11: 1.1 | AE11: C,YRIL | AF11: SOLIDRO PARAPHARMACIE LECLERC | AG11: SOLIDRO PARAPHARMACIE LECLERC | AH11: BP9 ROUTE DE PERIGUEUX | AI11: RIBERAC | AJ11: 24 | AK11: FR | AL11: 24600 | AS11: N | AT11: 0 | AU11: 0 | AV11: 0 | BB11: 0 | BC11: 0 | BD11: EUR | BE11: 46240 | BF11: 634324015 | BH11: Domestic | BI11: Your Packaging | BJ11: 0.45208333 | BK11: 27 | BL11: 3.2 | BM11: 0 | BN11: -20.55 | BO11: 9.65 | BP11: EUR | BQ11: 1.166344 | BR11: kg
A12: =BK12+BN12 -> 7.79 | B12: 3752 | D12: entreprise | E12: =IF(J12="FedEx Priority","ST","FICP") -> ST | F12: 200720433 | G12: 202606 | H12: Express | I12: UO | J12: FedEx Priority | K12: Bill_Sender_Prepaid | L12: 05/28/2026 | M12: 05/29/2026 | N12: 872328680201 | P12: HYDRATIS B2B | Q12: HYDRATIS B2B | R12: VOIE COMMUNALE 4 | S12: CR?ANCEY | T12: 21 | U12: FR | V12: 21320 | W12: 37.92 | X12: 4.04 | Y12: 0 | Z12: -28.86 | AA12: 13.1 | AB12: 2 | AC12: 21.56 | AD12: 3.52 | AE12: Q,UERE | AF12: PHARMACIE DES GRANDS JARDINS | AG12: PHARMACIE DES GRANDS JARDINS | AH12: 6 PLACE DU MARCHE | AI12: MESLAY-DU-MAINE | AJ12: 53 | AK12: FR | AL12: 53170 | AS12: N | AT12: 0 | AU12: 0 | AV12: 0 | BB12: 0 | BC12: 0 | BD12: EUR | BE12: 46240 | BF12: 634324015 | BH12: Domestic | BI12: Your Packaging | BJ12: 0.39305556 | BK12: 32.6 | BL12: 3.47 | BM12: 0 | BN12: -24.81 | BO12: 11.26 | BP12: EUR | BQ12: 1.1633182 | BR12: kg
A13: =BK13+BN13 -> 10.13 | B13: 3752 | D13: entreprise | E13: =IF(J13="FedEx Priority","ST","FICP") -> ST | F13: 200720433 | G13: 202606 | H13: Express | I13: UO | J13: FedEx Priority | K13: Bill_Sender_Prepaid | L13: 05/29/2026 | M13: 05/30/2026 | N13: 872385768346 | P13: HYDRATIS B2B | Q13: HYDRATIS B2B | R13: VOIE COMMUNALE 4 | S13: CR?ANCEY | T13: 21 | U13: FR | V13: 21320 | W13: 49.34 | X13: 5.25 | Y13: 0 | Z13: -37.55 | AA13: 17.04 | AB13: 3 | AC13: 37.18 | AD13: 4.62 | AE13: L,Delaneau | AF13: PHARMACIE DE LARCAY | AG13: PHARMACIE DE LARCAY | AH13: 1 ALLEE DE LA BERGERIE | AI13: LARCAY | AJ13: 37 | AK13: FR | AL13: 37270 | AS13: N | AT13: 30 | AU13: 31 | AV13: 40 | BB13: 0 | BC13: 0 | BD13: EUR | BE13: 46240 | BF13: 634324015 | BH13: Domestic | BI13: Your Packaging | BJ13: 0.35972222 | BK13: 42.4 | BL13: 4.51 | BM13: 0 | BN13: -32.27 | BO13: 14.64 | BP13: EUR | BQ13: 1.1637244 | BR13: kg
A14: =BK14+BN14 -> 12.14 | B14: 3752 | D14: entreprise | E14: =IF(J14="FedEx Priority","ST","FICP") -> ST | F14: 200720433 | G14: 202606 | H14: Express | I14: UO | J14: FedEx Priority | K14: Bill_Sender_Prepaid | L14: 05/28/2026 | M14: 46028 | N14: 872278253231 | P14: HYDRATIS B2B | Q14: HYDRATIS B2B | R14: VOIE COMMUNALE 4 | S14: CR?ANCEY | T14: 21 | U14: FR | V14: 21320 | W14: 59.1 | X14: 6.28 | Y14: 0 | Z14: -44.97 | AA14: 20.4 | AB14: 3 | AC14: 50.6 | AD14: 8.58 | AE14: N,ICO | AF14: PARAPHARMACIE LECLERC LANDI DIS | AG14: PARAPHARMACIE LECLERC LANDI DI | AH14: 4 BOULEVARD DE LA REPUBLIQUE | AI14: LANDIVISIAU | AJ14: 29 | AK14: FR | AL14: 29403 | AS14: N | AT14: 0 | AU14: 0 | AV14: 0 | BB14: 0 | BC14: 0 | BD14: EUR | BE14: 46240 | BF14: 634324015 | BH14: Domestic | BI14: Your Packaging | BJ14: 0.60138889 | BK14: 50.8 | BL14: 5.4 | BM14: 0 | BN14: -38.66 | BO14: 17.54 | BP14: EUR | BQ14: 1.1633182 | BR14: kg
A15: =BK15+BN15 -> 8.46 | B15: 3752 | E15: =IF(J15="FedEx Priority","ST","FICP") -> ST | F15: 200720433 | G15: 202606 | H15: Express | I15: UO | J15: FedEx Priority | K15: Bill_Sender_Prepaid | L15: 46087 | M15: 46118 | N15: 872530870896 | P15: HYDRATIS B2B | Q15: HYDRATIS B2B | R15: VOIE COMMUNALE 4 | S15: CR?ANCEY | T15: 21 | U15: FR | V15: 21320 | W15: 41.21 | X15: 13.6 | Y15: 0 | Z15: -31.36 | AA15: 23.44 | AB15: 2 | AC15: 26.4 | AD15: 3.08 | AE15: P,EIGNER | AF15: PHARMACIE PEIGNIER | AG15: PHARMACIE PEIGNIER | AH15: 99 GRANDE RUE | AI15: LE VAL D'AJOL | AJ15: 88 | AK15: FR | AL15: 88340 | AS15: N | AT15: 0 | AU15: 0 | AV15: 0 | BB15: 0 | BC15: 0 | BD15: EUR | BE15: 46240 | BF15: 634324015 | BH15: Domestic | BI15: Your Packaging | BJ15: 0.45694444 | BK15: 35.4 | BL15: 11.68 | BM15: 0 | BN15: -26.94 | BO15: 20.14 | BP15: EUR | BQ15: 1.1640901 | BR15: kg
A16: =BK16+BN16 -> 19.84 | B16: 3752 | D16: entreprise | E16: =IF(J16="FedEx Priority","ST","FICP") -> ST | F16: 200720433 | G16: 202606 | H16: Express | I16: UO | J16: FedEx Priority | K16: Bill_Sender_Prepaid | L16: 05/29/2026 | M16: 46028 | N16: 872382473532 | P16: HYDRATIS B2B | Q16: HYDRATIS B2B | R16: VOIE COMMUNALE 4 | S16: CR?ANCEY | T16: 21 | U16: FR | V16: 21320 | W16: 96.59 | X16: 10.29 | Y16: 0 | Z16: -73.5 | AA16: 33.38 | AB16: 5 | AC16: 101.2 | AD16: 25.3 | AE16: A,NNE | AF16: GRANDE PHARMACIE DE CAVIGNAC | AG16: GRANDE PHARMACIE DE CAVIGNAC | AH16: CC SUPER U | AI16: CAVIGNAC | AJ16: 33 | AK16: FR | AL16: 33620 | AS16: N | AT16: 0 | AU16: 0 | AV16: 0 | BB16: 0 | BC16: 0 | BD16: EUR | BE16: 46240 | BF16: 634324015 | BH16: Domestic | BI16: Your Packaging | BJ16: 0.40486111 | BK16: 83 | BL16: 8.84 | BM16: 0 | BN16: -63.16 | BO16: 28.68 | BP16: EUR | BQ16: 1.1637244 | BR16: kg
A17: =BK17+BN17 -> 22.18 | B17: 3752 | D17: entreprise | E17: =IF(J17="FedEx Priority","ST","FICP") -> ST | F17: 200720433 | G17: 202606 | H17: Express | I17: UO | J17: FedEx Priority | K17: Bill_Sender_Prepaid | L17: 46301 | M17: 46332 | N17: 872882388981 | P17: HYDRATIS B2B | Q17: HYDRATIS B2B | R17: VOIE COMMUNALE 4 | S17: CR?ANCEY | T17: 21 | U17: FR | V17: 21320 | W17: 107.01 | X17: 112.32 | Y17: 0 | Z17: -81.44 | AA17: 137.9 | AB17: 10 | AC17: 116.38 | AD17: 116.38 | AE17: M,Melani | AF17: PHARMACIE GAERTNER | AG17: PHARMACIE GAERTNER | AH17: 41 ROUTE DE RHINAU | AI17: BOOFZHEIM | AJ17: 67 | AK17: FR | AL17: 67860 | AS17: N | AT17: 0 | AU17: 0 | AV17: 0 | BB17: 0 | BC17: 0 | BD17: EUR | BE17: 06/15/2026 | BF17: 634333759 | BH17: Domestic | BI17: Your Packaging | BJ17: 0.49236111 | BK17: 92.8 | BL17: 97.4 | BM17: 0 | BN17: -70.62 | BO17: 119.58 | BP17: EUR | BQ17: 1.1531631 | BR17: kg
A18: =BK18+BN18 -> 7.12 | B18: 3752 | D18: entreprise | E18: =IF(J18="FedEx Priority","ST","FICP") -> ST | F18: 200720433 | G18: 202606 | H18: Express | I18: UO | J18: FedEx Priority | K18: Bill_Sender_Prepaid | L18: 05/20/2026 | M18: 1 | N18: 871971966607 | P18: HYDRATIS B2B | Q18: HYDRATIS B2B | R18: VOIE COMMUNALE 4 | S18: CR?ANCEY | T18: 21 | U18: FR | V18: 21320 | W18: 34.69 | X18: 3.7 | Y18: 0 | Z18: -26.4 | AA18: 11.99 | AB18: 1 | AC18: 17.6 | AD18: 1.54 | AF18: INTERSPORT PONTAULT 00670/000 | AG18: INTERSPORT PONTAULT 00670/000 | AH18: PROSPORT XIX SAS | AI18: PONTAULT-COMBAULT | AJ18: 77 | AK18: FR | AL18: 77340 | AS18: N | AT18: 30 | AU18: 31 | AV18: 39 | BB18: 0 | BC18: 0 | BD18: EUR | BE18: 46240 | BF18: 634324015 | BH18: Domestic | BI18: Your Packaging | BJ18: 0 | BK18: 29.8 | BL18: 3.18 | BM18: 0 | BN18: -22.68 | BO18: 10.3 | BP18: EUR | BQ18: 1.1639411 | BR18: kg
A19: =BK19+BN19 -> 11.81 | B19: 3752 | D19: entreprise | E19: =IF(J19="FedEx Priority","ST","FICP") -> ST | F19: 200720433 | G19: 202606 | H19: Express | I19: UO | J19: FedEx Priority | K19: Bill_Sender_Prepaid | L19: 05/29/2026 | M19: 46028 | N19: 872336662060 | P19: HYDRATIS B2B | Q19: HYDRATIS B2B | R19: VOIE COMMUNALE 4 | S19: CR?ANCEY | T19: 21 | U19: FR | V19: 21320 | W19: 57.49 | X19: 6.13 | Y19: 0 | Z19: -43.74 | AA19: 19.88 | AB19: 3 | AC19: 48.4 | AD19: 11.22 | AE19: L,EA | AF19: PHARMACIE DES BANCHAIS | AG19: PHARMACIE DES BANCHAIS | AH19: 360 RUE HAUTE DES BANCHAIS | AI19: SAINT BARTHELEMY D'ANJOU | AJ19: 49 | AK19: FR | AL19: 49124 | AS19: N | AT19: 30 | AU19: 31 | AV19: 39 | BB19: 0 | BC19: 0 | BD19: EUR | BE19: 46240 | BF19: 634324015 | BH19: Domestic | BI19: Your Packaging | BJ19: 0.41666667 | BK19: 49.4 | BL19: 5.27 | BM19: 0 | BN19: -37.59 | BO19: 17.08 | BP19: EUR | BQ19: 1.1637244 | BR19: kg
A20: =BK20+BN20 -> 8.46 | B20: 3752 | D20: entreprise | E20: =IF(J20="FedEx Priority","ST","FICP") -> ST | F20: 200720433 | G20: 202606 | H20: Express | I20: UO | J20: FedEx Priority | K20: Bill_Sender_Prepaid | L20: 05/29/2026 | M20: 46028 | N20: 872334971921 | P20: HYDRATIS B2B | Q20: HYDRATIS B2B | R20: VOIE COMMUNALE 4 | S20: CR?ANCEY | T20: 21 | U20: FR | V20: 21320 | W20: 41.2 | X20: 4.39 | Y20: 0 | Z20: -31.35 | AA20: 14.23 | AB20: 2 | AC20: 26.4 | AD20: 2.64 | AE20: L,E DUFF | AF20: PHARMACIE DU KERVENT | AG20: PHARMACIE DU KERVENT | AH20: CCIAL LECLERC / ZAC KERVENT | AI20: SAINT-POL-DE-L?ON | AJ20: 29 | AK20: FR | AL20: 29250 | AS20: N | AT20: 0 | AU20: 0 | AV20: 0 | BB20: 0 | BC20: 0 | BD20: EUR | BE20: 46240 | BF20: 634324015 | BH20: Domestic | BI20: Your Packaging | BJ20: 0.42777778 | BK20: 35.4 | BL20: 3.77 | BM20: 0 | BN20: -26.94 | BO20: 12.23 | BP20: EUR | BQ20: 1.1637244 | BR20: kg
A21: =BK21+BN21 -> 8.46 | B21: 3752 | D21: entreprise | E21: =IF(J21="FedEx Priority","ST","FICP") -> ST | F21: 200720433 | G21: 202606 | H21: Express | I21: UO | J21: FedEx Priority | K21: Bill_Sender_Prepaid | L21: 05/29/2026 | M21: 46028 | N21: 872382386231 | P21: HYDRATIS B2B | Q21: HYDRATIS B2B | R21: VOIE COMMUNALE 4 | S21: CR?ANCEY | T21: 21 | U21: FR | V21: 21320 | W21: 41.2 | X21: 4.39 | Y21: 0 | Z21: -31.35 | AA21: 14.23 | AB21: 2 | AC21: 26.4 | AD21: 3.08 | AE21: M,Anne | AF21: PHARMACIE DE RICHTER | AG21: PHARMACIE DE RICHTER | AH21: 181 PLACE ERNEST GRANIER | AI21: MONTPELLIER | AJ21: 34 | AK21: FR | AL21: 34000 | AS21: N | AT21: 0 | AU21: 0 | AV21: 0 | BB21: 0 | BC21: 0 | BD21: EUR | BE21: 46240 | BF21: 634324015 | BH21: Domestic | BI21: Your Packaging | BJ21: 0.49930556 | BK21: 35.4 | BL21: 3.77 | BM21: 0 | BN21: -26.94 | BO21: 12.23 | BP21: EUR | BQ21: 1.1637244 | BR21: kg
A22: =BK22+BN22 -> 8.46 | B22: 3752 | E22: =IF(J22="FedEx Priority","ST","FICP") -> ST | F22: 200720433 | G22: 202606 | H22: Express | I22: UO | J22: FedEx Priority | K22: Bill_Sender_Prepaid | L22: 46087 | M22: 46118 | N22: 872531222769 | P22: HYDRATIS B2B | Q22: HYDRATIS B2B | R22: VOIE COMMUNALE 4 | S22: CR?ANCEY | T22: 21 | U22: FR | V22: 21320 | W22: 41.21 | X22: 4.89 | Y22: 0 | Z22: -31.36 | AA22: 14.74 | AB22: 2 | AC22: 26.4 | AD22: 3.96 | AE22: B,ODIN | AF22: PHARMACIE D ANDARD | AG22: PHARMACIE D ANDARD | AH22: 55 B GRANDE RUE | AI22: LOIRE-AUTHION | AJ22: 49 | AK22: FR | AL22: 49800 | AS22: N | AT22: 0 | AU22: 0 | AV22: 0 | BB22: 0 | BC22: 0 | BD22: EUR | BE22: 46240 | BF22: 634324015 | BH22: Domestic | BI22: Your Packaging | BJ22: 0.44027778 | BK22: 35.4 | BL22: 4.2 | BM22: 0 | BN22: -26.94 | BO22: 12.66 | BP22: EUR | BQ22: 1.1640901 | BR22: kg
A23: =BK23+BN23 -> 10.47 | B23: 3752 | D23: entreprise | E23: =IF(J23="FedEx Priority","ST","FICP") -> ST | F23: 200720433 | G23: 202606 | H23: Express | I23: UO | J23: FedEx Priority | K23: Bill_Sender_Prepaid | L23: 05/28/2026 | M23: 05/29/2026 | N23: 872332173220 | P23: HYDRATIS B2B | Q23: HYDRATIS B2B | R23: VOIE COMMUNALE 4 | S23: CR?ANCEY | T23: 21 | U23: FR | V23: 21320 | W23: 50.95 | X23: 5.42 | Y23: 0 | Z23: -38.77 | AA23: 17.6 | AB23: 3 | AC23: 38.06 | AD23: 8.58 | AE23: J,Jeudy | AF23: PHARMACIE SAINT EPAIN | AG23: PHARMACIE SAINT EPAIN | AH23: 6 PLACE DE LA MAIRIE | AI23: SAINT-?PAIN | AJ23: 37 | AK23: FR | AL23: 37800 | AS23: N | AT23: 30 | AU23: 32 | AV23: 39 | BB23: 0 | BC23: 0 | BD23: EUR | BE23: 46240 | BF23: 634324015 | BH23: Domestic | BI23: Your Packaging | BJ23: 0.37708333 | BK23: 43.8 | BL23: 4.66 | BM23: 0 | BN23: -33.33 | BO23: 15.13 | BP23: EUR | BQ23: 1.1633182 | BR23: kg
A24: =BK24+BN24 -> 12.48 | B24: 3752 | D24: entreprise | E24: =IF(J24="FedEx Priority","ST","FICP") -> ST | F24: 200720433 | G24: 202606 | H24: Express | I24: UO | J24: FedEx Priority | K24: Bill_Sender_Prepaid | L24: 05/29/2026 | M24: 46028 | N24: 872385254070 | P24: HYDRATIS B2B | Q24: HYDRATIS B2B | R24: VOIE COMMUNALE 4 | S24: CR?ANCEY | T24: 21 | U24: FR | V24: 21320 | W24: 60.75 | X24: 6.47 | Y24: 0 | Z24: -46.22 | AA24: 20.99 | AB24: 3 | AC24: 52.8 | AD24: 9.24 | AE24: K,IM | AF24: PHARMACIE CAP VALESCURE | AG24: PHARMACIE CAP VALESCURE | AH24: 37 ALLEE DU PARC ARUNDO | AI24: FREJUS | AJ24: 83 | AK24: FR | AL24: 83600 | AS24: N | AT24: 30 | AU24: 30 | AV24: 40 | BB24: 0 | BC24: 0 | BD24: EUR | BE24: 46240 | BF24: 634324015 | BH24: Domestic | BI24: Your Packaging | BJ24: 0.49861111 | BK24: 52.2 | BL24: 5.56 | BM24: 0 | BN24: -39.72 | BO24: 18.04 | BP24: EUR | BQ24: 1.1637244 | BR24: kg
A25: =BK25+BN25 -> 12.14 | B25: 3752 | D25: entreprise | E25: =IF(J25="FedEx Priority","ST","FICP") -> ST | F25: 200720433 | G25: 202606 | H25: Express | I25: UO | J25: FedEx Priority | K25: Bill_Sender_Prepaid | L25: 05/28/2026 | M25: 05/29/2026 | N25: 872331112770 | P25: HYDRATIS B2B | Q25: HYDRATIS B2B | R25: VOIE COMMUNALE 4 | S25: CR?ANCEY | T25: 21 | U25: FR | V25: 21320 | W25: 59.1 | X25: 6.28 | Y25: 0 | Z25: -44.97 | AA25: 20.4 | AB25: 4 | AC25: 50.6 | AD25: 17.6 | AE25: P,HIE ZARROUCK | AF25: PHARMACIE SAINT BLAISE | AG25: PHARMACIE SAINT BLAISE | AH25: 1 RUE STENDHAL | AI25: PARIS 20 | AJ25: 75 | AK25: FR | AL25: 75020 | AS25: N | AT25: 30 | AU25: 31 | AV25: 40 | BB25: 0 | BC25: 0 | BD25: EUR | BE25: 46240 | BF25: 634324015 | BH25: Domestic | BI25: Your Packaging | BJ25: 0.475 | BK25: 50.8 | BL25: 5.4 | BM25: 0 | BN25: -38.66 | BO25: 17.54 | BP25: EUR | BQ25: 1.1633182 | BR25: kg
A26: =BK26+BN26 -> 13.48 | B26: 3752 | D26: entreprise | E26: =IF(J26="FedEx Priority","ST","FICP") -> ST | F26: 200720433 | G26: 202606 | H26: Express | I26: UO | J26: FedEx Priority | K26: Bill_Sender_Prepaid | L26: 46028 | M26: 46059 | N26: 872338229810 | P26: HYDRATIS B2B | Q26: HYDRATIS B2B | R26: VOIE COMMUNALE 4 | S26: CR?ANCEY | T26: 21 | U26: FR | V26: 21320 | W26: 65.79 | X26: 7.79 | Y26: 0 | Z26: -50.06 | AA26: 23.52 | AB26: 5 | AC26: 57.42 | AD26: 12.1 | AE26: A,Arcade | AF26: PHARMACIE DES ARCADES | AG26: PHARMACIE DES ARCADES | AH26: 1 PLACE DE LA BEURRERIE | AI26: NOZAY | AJ26: 44 | AK26: FR | AL26: 44170 | AS26: N | AT26: 0 | AU26: 0 | AV26: 0 | BB26: 0 | BC26: 0 | BD26: EUR | BE26: 46240 | BF26: 634324015 | BH26: Domestic | BI26: Your Packaging | BJ26: 0.45347222 | BK26: 56.4 | BL26: 6.68 | BM26: 0 | BN26: -42.92 | BO26: 20.16 | BP26: EUR | BQ26: 1.1664392 | BR26: kg
A27: =BK27+BN27 -> 8.46 | B27: 3752 | D27: entreprise | E27: =IF(J27="FedEx Priority","ST","FICP") -> ST | F27: 200720433 | G27: 202606 | H27: Express | I27: UO | J27: FedEx Priority | K27: Bill_Sender_Prepaid | L27: 46028 | M27: 46059 | N27: 872386996430 | P27: HYDRATIS B2B | Q27: HYDRATIS B2B | R27: VOIE COMMUNALE 4 | S27: CR?ANCEY | T27: 21 | U27: FR | V27: 21320 | W27: 41.29 | X27: 4.9 | Y27: 0 | Z27: -31.42 | AA27: 14.77 | AB27: 2 | AC27: 25.08 | AD27: 5.72 | AE27: V,Viressel | AF27: DELMONICO DOREL | AG27: DELMONICO DOREL | AH27: RIVE DE GIER | AI27: RIVE-DE-GIER | AJ27: 42 | AK27: FR | AL27: 42800 | AS27: N | AT27: 30 | AU27: 31 | AV27: 40 | BB27: 0 | BC27: 0 | BD27: EUR | BE27: 46240 | BF27: 634324015 | BH27: Domestic | BI27: Your Packaging | BJ27: 0.49097222 | BK27: 35.4 | BL27: 4.2 | BM27: 0 | BN27: -26.94 | BO27: 12.66 | BP27: EUR | BQ27: 1.1664392 | BR27: kg
A28: =BK28+BN28 -> 27.53 | B28: 3752 | D28: entreprise | E28: =IF(J28="FedEx Priority","ST","FICP") -> ST | F28: 200720433 | G28: 202606 | H28: Express | I28: UO | J28: FedEx Priority | K28: Bill_Sender_Prepaid | L28: 46028 | M28: 46059 | N28: 872327509740 | P28: HYDRATIS B2B | Q28: HYDRATIS B2B | R28: VOIE COMMUNALE 4 | S28: CR?ANCEY | T28: 21 | U28: FR | V28: 21320 | W28: 134.37 | X28: 116.7 | Y28: 0 | Z28: -102.26 | AA28: 148.81 | AB28: 10 | AC28: 150.48 | AD28: 70.4 | AE28: J,OUBERT | AF28: GRANDE PHARMACIE JOUBERT | AG28: GRANDE PHARMACIE JOUBERT | AH28: 9 RUE RENE GOSCINNY | AI28: ANGOUL?ME | AJ28: 16 | AK28: FR | AL28: 16006 | AS28: N | AT28: 0 | AU28: 0 | AV28: 0 | BB28: 0 | BC28: 0 | BD28: EUR | BE28: 46240 | BF28: 634324015 | BH28: Domestic | BI28: Your Packaging | BJ28: 0.44375 | BK28: 115.2 | BL28: 100.05 | BM28: 0 | BN28: -87.67 | BO28: 127.58 | BP28: EUR | BQ28: 1.1664392 | BR28: kg
A29: =BK29+BN29 -> 8.8 | B29: 3752 | D29: entreprise | E29: =IF(J29="FedEx Priority","ST","FICP") -> ST | F29: 200720433 | G29: 202606 | H29: Express | I29: UO | J29: FedEx Priority | K29: Bill_Sender_Prepaid | L29: 05/26/2026 | M29: 05/29/2026 | N29: 872124873682 | P29: HYDRATIS B2B | Q29: HYDRATIS B2B | R29: VOIE COMMUNALE 4 | S29: CR?ANCEY | T29: 21 | U29: FR | V29: 21320 | W29: 42.72 | X29: 4.55 | Y29: 0 | Z29: -32.5 | AA29: 14.77 | AB29: 2 | AC29: 28.6 | AD29: 4.4 | AE29: M,AUDE | AF29: PHARMACIE D'ARITXAGUE | AG29: PHARMACIE D'ARITXAGUE | AH29: C,C, D'ARITXAGUE | AI29: ANGLET | AJ29: 64 | AK29: FR | AL29: 64600 | AS29: N | AT29: 30 | AU29: 31 | AV29: 40 | BB29: 0 | BC29: 0 | BD29: EUR | BE29: 46240 | BF29: 634324015 | BH29: Domestic | BI29: Your Packaging | BJ29: 0.39861111 | BK29: 36.8 | BL29: 3.92 | BM29: 0 | BN29: -28 | BO29: 12.72 | BP29: EUR | BQ29: 1.1608335 | BR29: kg
A30: =BK30+BN30 -> 8.13 | B30: 3752 | D30: entreprise | E30: =IF(J30="FedEx Priority","ST","FICP") -> ST | F30: 200720433 | G30: 202606 | H30: Express | I30: UO | J30: FedEx Priority | K30: Bill_Sender_Prepaid | L30: 46059 | M30: 46087 | N30: 872389481693 | P30: HYDRATIS B2B | Q30: HYDRATIS B2B | R30: VOIE COMMUNALE 4 | S30: CR?ANCEY | T30: 21 | U30: FR | V30: 21320 | W30: 39.66 | X30: 4.7 | Y30: 0 | Z30: -30.17 | AA30: 14.18 | AB30: 3 | AC30: 23.54 | AD30: 4.62 | AE30: P,HIE DU PARCS | AF30: PHARMACIE DU PARC | AG30: PHARMACIE DU PARC | AH30: 51 RUE DE PARIS | AI30: TORCY | AJ30: 77 | AK30: FR | AL30: 77200 | AS30: N | AT30: 13 | AU30: 21 | AV30: 29 | BB30: 0 | BC30: 0 | BD30: EUR | BE30: 46240 | BF30: 634324015 | BH30: Domestic | BI30: Your Packaging | BJ30: 0.54097222 | BK30: 34 | BL30: 4.03 | BM30: 0 | BN30: -25.87 | BO30: 12.16 | BP30: EUR | BQ30: 1.166344 | BR30: kg
A31: =BK31+BN31 -> 8.46 | B31: 3752 | D31: entreprise | E31: =IF(J31="FedEx Priority","ST","FICP") -> ST | F31: 200720433 | G31: 202606 | H31: Express | I31: UO | J31: FedEx Priority | K31: Bill_Sender_Prepaid | L31: 05/29/2026 | M31: 46028 | N31: 872385056711 | P31: HYDRATIS B2B | Q31: HYDRATIS B2B | R31: VOIE COMMUNALE 4 | S31: CR?ANCEY | T31: 21 | U31: FR | V31: 21320 | W31: 41.2 | X31: 4.39 | Y31: 0 | Z31: -31.35 | AA31: 14.23 | AB31: 2 | AC31: 26.4 | AD31: 5.28 | AE31: M,OMCELLIER | AF31: PHARMACIE DU TERRE FORT | AG31: PHARMACIE DU TERRE FORT | AH31: 29 AVENUE DU TERRE FORT | AI31: SAINT-HILAIRE-DE-RIEZ | AJ31: 85 | AK31: FR | AL31: 85270 | AS31: N | AT31: 0 | AU31: 0 | AV31: 0 | BB31: 0 | BC31: 0 | BD31: EUR | BE31: 46240 | BF31: 634324015 | BH31: Domestic | BI31: Your Packaging | BJ31: 0.51180556 | BK31: 35.4 | BL31: 3.77 | BM31: 0 | BN31: -26.94 | BO31: 12.23 | BP31: EUR | BQ31: 1.1637244 | BR31: kg
A32: =BK32+BN32 -> 10.13 | B32: 3752 | D32: entreprise | E32: =IF(J32="FedEx Priority","ST","FICP") -> ST | F32: 200720433 | G32: 202606 | H32: Express | I32: UO | J32: FedEx Priority | K32: Bill_Sender_Prepaid | L32: 05/28/2026 | M32: 05/29/2026 | N32: 872333265107 | P32: HYDRATIS B2B | Q32: HYDRATIS B2B | R32: VOIE COMMUNALE 4 | S32: CR?ANCEY | T32: 21 | U32: FR | V32: 21320 | W32: 49.32 | X32: 5.25 | Y32: 0 | Z32: -37.54 | AA32: 17.03 | AB32: 2 | AC32: 35.64 | AD32: 3.08 | AE32: P,HE | AF32: PHARMACIE DE LA FONTAINE | AG32: PHARMACIE DE LA FONTAINE | AH32: 3 PLACE CARNOT | AI32: LILLEBONNE | AJ32: 76 | AK32: FR | AL32: 76170 | AS32: N | AT32: 30 | AU32: 32 | AV32: 39 | BB32: 0 | BC32: 0 | BD32: EUR | BE32: 46240 | BF32: 634324015 | BH32: Domestic | BI32: Your Packaging | BJ32: 0.43680556 | BK32: 42.4 | BL32: 4.51 | BM32: 0 | BN32: -32.27 | BO32: 14.64 | BP32: EUR | BQ32: 1.1633182 | BR32: kg
A33: =BK33+BN33 -> 10.13 | B33: 3752 | D33: entreprise | E33: =IF(J33="FedEx Priority","ST","FICP") -> ST | F33: 200720433 | G33: 202606 | H33: Express | I33: UO | J33: FedEx Priority | K33: Bill_Sender_Prepaid | L33: 46028 | M33: 46059 | N33: 872284412449 | P33: HYDRATIS B2B | Q33: HYDRATIS B2B | R33: VOIE COMMUNALE 4 | S33: CR?ANCEY | T33: 21 | U33: FR | V33: 21320 | W33: 49.46 | X33: 5.87 | Y33: 0 | Z33: -37.64 | AA33: 17.68 | AB33: 2 | AC33: 37.4 | AD33: 4.4 | AE33: R,ECEP | AF33: PARAPHARMACIE AUCHAN BIGANOS | AG33: PARAPHARMACIE AUCHAN BIGANOS | AH33: 71 RUE DES FONDERIES | AI33: BIGANOS | AJ33: 33 | AK33: FR | AL33: 33380 | AS33: N | AT33: 29 | AU33: 30 | AV33: 40 | BB33: 0 | BC33: 0 | BD33: EUR | BE33: 46240 | BF33: 634324015 | BH33: Domestic | BI33: Your Packaging | BJ33: 0.49861111 | BK33: 42.4 | BL33: 5.03 | BM33: 0 | BN33: -32.27 | BO33: 15.16 | BP33: EUR | BQ33: 1.1664392 | BR33: kg
A34: =BK34+BN34 -> 8.46 | B34: 3752 | D34: entreprise | E34: =IF(J34="FedEx Priority","ST","FICP") -> ST | F34: 200720433 | G34: 202606 | H34: Express | I34: UO | J34: FedEx Priority | K34: Bill_Sender_Prepaid | L34: 05/28/2026 | M34: 05/29/2026 | N34: 872331093657 | P34: HYDRATIS B2B | Q34: HYDRATIS B2B | R34: VOIE COMMUNALE 4 | S34: CR?ANCEY | T34: 21 | U34: FR | V34: 21320 | W34: 41.18 | X34: 4.39 | Y34: 0 | Z34: -31.34 | AA34: 14.23 | AB34: 2 | AC34: 26.4 | AD34: 4.4 | AE34: C,OURALET | AF34: PHARMACIE DU MINAGE | AG34: PHARMACIE DU MINAGE | AH34: 1 RUE DU CORDOUAN | AI34: LA ROCHELLE | AJ34: 17 | AK34: FR | AL34: 17000 | AS34: N | AT34: 0 | AU34: 0 | AV34: 0 | BB34: 0 | BC34: 0 | BD34: EUR | BE34: 46240 | BF34: 634324015 | BH34: Domestic | BI34: Your Packaging | BJ34: 0.44513889 | BK34: 35.4 | BL34: 3.77 | BM34: 0 | BN34: -26.94 | BO34: 12.23 | BP34: EUR | BQ34: 1.1633182 | BR34: kg
A35: =BK35+BN35 -> 8.46 | B35: 3752 | D35: entreprise | E35: =IF(J35="FedEx Priority","ST","FICP") -> ST | F35: 200720433 | G35: 202606 | H35: Express | I35: UO | J35: FedEx Priority | K35: Bill_Sender_Prepaid | L35: 05/28/2026 | M35: 46028 | N35: 872329618198 | P35: HYDRATIS B2B | Q35: HYDRATIS B2B | R35: VOIE COMMUNALE 4 | S35: CR?ANCEY | T35: 21 | U35: FR | V35: 21320 | W35: 41.18 | X35: 4.39 | Y35: 0 | Z35: -31.34 | AA35: 14.23 | AB35: 2 | AC35: 26.4 | AD35: 24.2 | AE35: P,HARMACIE DE LA | AF35: PHARMACIE DE LA PLAGE | AG35: PHARMACIE DE LA PLAGE | AH35: 33 PROMENADE DE LA MER | AI35: CAVALAIRE-SUR-MER | AJ35: 83 | AK35: FR | AL35: 83240 | AS35: N | AT35: 20 | AU35: 20 | AV35: 30 | BB35: 0 | BC35: 0 | BD35: EUR | BE35: 46240 | BF35: 634324015 | BH35: Domestic | BI35: Your Packaging | BJ35: 0.44305556 | BK35: 35.4 | BL35: 3.77 | BM35: 0 | BN35: -26.94 | BO35: 12.23 | BP35: EUR | BQ35: 1.1633182 | BR35: kg
A36: =BK36+BN36 -> 9.13 | B36: 3752 | D36: entreprise | E36: =IF(J36="FedEx Priority","ST","FICP") -> ST | F36: 200720433 | G36: 202606 | H36: Express | I36: UO | J36: FedEx Priority | K36: Bill_Sender_Prepaid | L36: 05/28/2026 | M36: 05/29/2026 | N36: 872285381670 | P36: HYDRATIS B2B | Q36: HYDRATIS B2B | R36: VOIE COMMUNALE 4 | S36: CR?ANCEY | T36: 21 | U36: FR | V36: 21320 | W36: 44.44 | X36: 4.73 | Y36: 0 | Z36: -33.82 | AA36: 15.36 | AB36: 2 | AC36: 30.8 | AD36: 3.96 | AE36: M,ARIE | AF36: PHARMACIE DE LA CROIX VALMER | AG36: PHARMACIE DE LA CROIX VALMER | AH36: RUE LOUIS MARTIN | AI36: LA CROIX-VALMER | AJ36: 83 | AK36: FR | AL36: 83420 | AS36: N | AT36: 30 | AU36: 31 | AV36: 39 | BB36: 0 | BC36: 0 | BD36: EUR | BE36: 46240 | BF36: 634324015 | BH36: Domestic | BI36: Your Packaging | BJ36: 0.52222222 | BK36: 38.2 | BL36: 4.07 | BM36: 0 | BN36: -29.07 | BO36: 13.2 | BP36: EUR | BQ36: 1.1633182 | BR36: kg
A37: =BK37+BN37 -> 12.48 | B37: 3752 | D37: entreprise | E37: =IF(J37="FedEx Priority","ST","FICP") -> ST | F37: 200720433 | G37: 202606 | H37: Express | I37: UO | J37: FedEx Priority | K37: Bill_Sender_Prepaid | L37: 46301 | M37: 46332 | N37: 872884057299 | P37: HYDRATIS B2B | Q37: HYDRATIS B2B | R37: VOIE COMMUNALE 4 | S37: CR?ANCEY | T37: 21 | U37: FR | V37: 21320 | W37: 60.2 | X37: 7.14 | Y37: 0 | Z37: -45.8 | AA37: 21.53 | AB37: 3 | AC37: 52.58 | AD37: 52.58 | AE37: P,H | AF37: PHARMACIE DES ARCADES | AG37: PHARMACIE DES ARCADES | AH37: 100 RUE DU 23 AOUT 1944 | AI37: MIONS | AJ37: 69 | AK37: FR | AL37: 69780 | AS37: N | AT37: 4 | AU37: 74 | AV37: 114 | BB37: 0 | BC37: 0 | BD37: EUR | BE37: 06/15/2026 | BF37: 634333759 | BH37: Domestic | BI37: Your Packaging | BJ37: 0.39305556 | BK37: 52.2 | BL37: 6.19 | BM37: 0 | BN37: -39.72 | BO37: 18.67 | BP37: EUR | BQ37: 1.1531631 | BR37: kg
A38: =BK38+BN38 -> 8.13 | B38: 3752 | E38: =IF(J38="FedEx Priority","ST","FICP") -> ST | F38: 200720433 | G38: 202606 | H38: Express | I38: UO | J38: FedEx Priority | K38: Bill_Sender_Prepaid | L38: 46087 | M38: 46118 | N38: 872531520801 | P38: HYDRATIS B2B | Q38: HYDRATIS B2B | R38: VOIE COMMUNALE 4 | S38: CR?ANCEY | T38: 21 | U38: FR | V38: 21320 | W38: 39.58 | X38: 4.69 | Y38: 0 | Z38: -30.12 | AA38: 14.16 | AB38: 2 | AC38: 24.2 | AD38: 3.52 | AE38: A,UBERT | AF38: PHARMACIE DE L'ODON | AG38: PHARMACIE DE L'ODON | AH38: 62 ROUTE DE BRETAGNE | AI38: BRETTEVILLE-SUR-ODON | AJ38: 14 | AK38: FR | AL38: 14760 | AS38: N | AT38: 30 | AU38: 31 | AV38: 40 | BB38: 0 | BC38: 0 | BD38: EUR | BE38: 46240 | BF38: 634324015 | BH38: Domestic | BI38: Your Packaging | BJ38: 0.38611111 | BK38: 34 | BL38: 4.03 | BM38: 0 | BN38: -25.87 | BO38: 12.16 | BP38: EUR | BQ38: 1.1640901 | BR38: kg
A39: =BK39+BN39 -> 10.47 | B39: 3752 | D39: entreprise | E39: =IF(J39="FedEx Priority","ST","FICP") -> ST | F39: 200720433 | G39: 202606 | H39: Express | I39: UO | J39: FedEx Priority | K39: Bill_Sender_Prepaid | L39: 05/29/2026 | M39: 05/30/2026 | N39: 872382459480 | P39: HYDRATIS B2B | Q39: HYDRATIS B2B | R39: VOIE COMMUNALE 4 | S39: CR?ANCEY | T39: 21 | U39: FR | V39: 21320 | W39: 50.97 | X39: 5.42 | Y39: 0 | Z39: -38.79 | AA39: 17.61 | AB39: 2 | AC39: 39.6 | AD39: 3.96 | AE39: P,HARMA PANO | AF39: PHARMACIE DU PANORAMA | AG39: PHARMACIE DU PANORAMA | AH39: 16 PLACE DU PANORAMA | AI39: CLAMART | AJ39: 92 | AK39: FR | AL39: 92140 | AS39: N | AT39: 30 | AU39: 30 | AV39: 38 | BB39: 0 | BC39: 0 | BD39: EUR | BE39: 46240 | BF39: 634324015 | BH39: Domestic | BI39: Your Packaging | BJ39: 0.32986111 | BK39: 43.8 | BL39: 4.66 | BM39: 0 | BN39: -33.33 | BO39: 15.13 | BP39: EUR | BQ39: 1.1637244 | BR39: kg
A40: =BK40+BN40 -> 7.46 | B40: 3752 | D40: entreprise | E40: =IF(J40="FedEx Priority","ST","FICP") -> ST | F40: 200720433 | G40: 202606 | H40: Express | I40: UO | J40: FedEx Priority | K40: Bill_Sender_Prepaid | L40: 05/28/2026 | M40: 05/29/2026 | N40: 872285433650 | P40: HYDRATIS B2B | Q40: HYDRATIS B2B | R40: VOIE COMMUNALE 4 | S40: CR?ANCEY | T40: 21 | U40: FR | V40: 21320 | W40: 36.3 | X40: 3.87 | Y40: 0 | Z40: -27.62 | AA40: 12.55 | AB40: 1 | AC40: 19.8 | AD40: 1.32 | AE40: C,YCL | AF40: RUN ADDICT CUCQ | AG40: RUN ADDICT CUCQ | AH40: E-BIKE SARL | AI40: CUCQ | AJ40: 62 | AK40: FR | AL40: 62780 | AS40: N | AT40: 30 | AU40: 31 | AV40: 40 | BB40: 0 | BC40: 0 | BD40: EUR | BE40: 46240 | BF40: 634324015 | BH40: Domestic | BI40: Your Packaging | BJ40: 0.47222222 | BK40: 31.2 | BL40: 3.33 | BM40: 0 | BN40: -23.74 | BO40: 10.79 | BP40: EUR | BQ40: 1.1633182 | BR40: kg
...

Sheet TCD
A1: Shipment Tracking Number | B1: Recipient Country/Territory | C1: Somme de Montant | D1: Somme de Shipment Rated Weight (Pounds) | E1: Poids arrondis sup (kg) | F1: E/P
A2: 381547998902 | B2: FI | C2: 70.41 | D2: 47.96 | E2: =ROUNDUP(D2*0.453592,1) -> 21.8 | F2: =IF(_xlfn.XLOOKUP(A2,'Shipment Detail'!N:N,'Shipment Detail'!D:D)="entreprise","E","P") -> E
A3: 381571985035 | B3: FI | C3: 58.57 | D3: 37.62 | E3: =ROUNDUP(D3*0.453592,1) -> 17.1 | F3: =IF(_xlfn.XLOOKUP(A3,'Shipment Detail'!N:N,'Shipment Detail'!D:D)="entreprise","E","P") -> E
A4: 381663677033 | B4: FR | C4: 8.8 | D4: 28.6 | E4: =ROUNDUP(D4*0.453592,1) -> 13 | F4: =IF(_xlfn.XLOOKUP(A4,'Shipment Detail'!N:N,'Shipment Detail'!D:D)="entreprise","E","P") -> P
A5: 381707060387 | B5: CH | C5: 15.89 | D5: 0.22 | E5: =ROUNDUP(D5*0.453592,1) -> 0.1 | F5: =IF(_xlfn.XLOOKUP(A5,'Shipment Detail'!N:N,'Shipment Detail'!D:D)="entreprise","E","P") -> P
A6: 381708365556 | B6: FR | C6: 5.45 | D6: 6.6 | E6: =ROUNDUP(D6*0.453592,1) -> 3 | F6: =IF(_xlfn.XLOOKUP(A6,'Shipment Detail'!N:N,'Shipment Detail'!D:D)="entreprise","E","P") -> P
A7: 381770737060 | B7: FR | C7: 4.78 | D7: 1.32 | E7: =ROUNDUP(D7*0.453592,1) -> 0.6 | F7: =IF(_xlfn.XLOOKUP(A7,'Shipment Detail'!N:N,'Shipment Detail'!D:D)="entreprise","E","P") -> P
A8: 381798154893 | B8: FR | C8: 6.45 | D8: 11.22 | E8: =ROUNDUP(D8*0.453592,1) -> 5.1 | F8: =IF(_xlfn.XLOOKUP(A8,'Shipment Detail'!N:N,'Shipment Detail'!D:D)="entreprise","E","P") -> P
A9: 381824285874 | B9: US | C9: 29.87 | D9: 3.74 | E9: =ROUNDUP(D9*0.453592,1) -> 1.7 | F9: =IF(_xlfn.XLOOKUP(A9,'Shipment Detail'!N:N,'Shipment Detail'!D:D)="entreprise","E","P") -> P
A10: 381863886430 | B10: FR | C10: 7.46 | D10: 19.8 | E10: =ROUNDUP(D10*0.453592,1) -> 9 | F10: =IF(_xlfn.XLOOKUP(A10,'Shipment Detail'!N:N,'Shipment Detail'!D:D)="entreprise","E","P") -> P
A11: 381905290506 | B11: FR | C11: 8.46 | D11: 24.64 | E11: =ROUNDUP(D11*0.453592,1) -> 11.2 | F11: =IF(_xlfn.XLOOKUP(A11,'Shipment Detail'!N:N,'Shipment Detail'!D:D)="entreprise","E","P") -> P
A12: 381954329162 | B12: FR | C12: 7.46 | D12: 19.8 | E12: =ROUNDUP(D12*0.453592,1) -> 9 | F12: =IF(_xlfn.XLOOKUP(A12,'Shipment Detail'!N:N,'Shipment Detail'!D:D)="entreprise","E","P") -> P
A13: 381981990415 | B13: FI | C13: 32.37 | D13: 15.84 | E13: =ROUNDUP(D13*0.453592,1) -> 7.2 | F13: =IF(_xlfn.XLOOKUP(A13,'Shipment Detail'!N:N,'Shipment Detail'!D:D)="entreprise","E","P") -> E
... A3608: 873819757072 | B3608: FR | C3608: 14.82 | D3608: 68.2 | E3608: =ROUNDUP(D3608*0.453592,1) -> 31 | F3608: =IF(_xlfn.XLOOKUP(A3608,'Shipment Detail'!N:N,'Shipment Detail'!D:D)="entreprise","E","P") -> P
A3609: (vide) | B3609: (vide) | E3609: =ROUNDUP(D3609*0.453592,1) -> 0 | F3609: =IF(_xlfn.XLOOKUP(A3609,'Shipment Detail'!N:N,'Shipment Detail'!D:D)="entreprise","E","P") -> #N/A

Sheet Bilan clients
A3: Étiquettes de lignes | B3: Somme de Montant
A4: 3752 | B4: 45112.65
A5: 6085 | B5: 58.07
A6: 7515 | B6: 34.63
A7: 8640 | B7: 67.5
A8: 8656 | B8: 242.98
A9: (vide)
A10: Total général | B10: 45515.83

Sheet Import ERP
A1: Transporteur | B1: Date validité tarif | C1: Réf.1 | D1: Réf. 2 | E1: Id client | F1: N° Tracking | G1: Nom | H1: E / P | I1: Pays | J1: Zone | K1: Nbr Colis | L1: Poids | M1: mode envoi | N1: TVA | O1: Droits et taxes | P1: Assurance | Q1: Zones éloignées | R1: Colis volumineux | S1: Adresses | T1: Frêt | U1: plus-value BtoC | V1: Gazole | W1: Nb colis
A2: =IF(OR(M2="FICP",M2="IE", M2="RE", M2="International", M2="Europe"),"FEDEX INTERNATIONAL","FEDEX FRANCE") -> FEDEX INTERNATIONAL | B2: 46174 | F2: =TCD!A2 -> 381547998902 | H2: =TCD!F2 -> E | I2: =TCD!B2 -> FI | J2: =IF(COUNTIF(Zoning!B:B,I2)=0,"inconnu",_xlfn.XLOOKUP(I2,Zoning!B:B,Zoning!C:C)) -> T | K2: =_xlfn.XLOOKUP(F2,'Shipment Detail'!N:N,'Shipment Detail'!AB:AB) -> 1 | L2: =TCD!E2 -> 21.8 | M2: =IF(J2="France","ST",_xlfn.XLOOKUP(F2,'Shipment Detail'!N:N,'Shipment Detail'!E:E,"")) -> FICP | N2: =IF(OR(I2="FR",I2="DE",I2="IT",I2="ES",I2="BE",I2="NL",I2="LU",I2="PT",I2="AT",I2="IE",I2="FI",I2="SE",I2="DK",I2="PL",I2="CZ",I2="SK",I2="HU",I2="RO",I2="BG",I2="HR",I2="SI",I2="EE",I2="LV",I2="LT",I2="GR",I2="CY",I2="MT"),0.2,0) -> 0.2 | O2: =IF(_xlfn.XLOOKUP(F2,'Shipment Detail'!N:N,'Shipment Detail'!BM:BM)=0,"",_xlfn.XLOOKUP(F2,'Shipment Detail'!N:N,'Shipment Detail'!BM:BM)) | R2: =IF(_xlfn.XLOOKUP(F2,'Shipment Detail'!N:N,'Shipment Detail'!AV:AV)>60,10,"") -> 10 | T2: =TCD!C2 -> 70.41
A3: =IF(OR(M3="FICP",M3="IE", M3="RE", M3="International", M3="Europe"),"FEDEX INTERNATIONAL","FEDEX FRANCE") -> FEDEX INTERNATIONAL | B3: =B2 -> 46174 | F3: =TCD!A3 -> 381571985035 | H3: =TCD!F3 -> E | I3: =TCD!B3 -> FI | J3: =IF(COUNTIF(Zoning!B:B,I3)=0,"inconnu",_xlfn.XLOOKUP(I3,Zoning!B:B,Zoning!C:C)) -> T | K3: =_xlfn.XLOOKUP(F3,'Shipment Detail'!N:N,'Shipment Detail'!AB:AB) -> 1 | L3: =TCD!E3 -> 17.1 | M3: =IF(J3="France","ST",_xlfn.XLOOKUP(F3,'Shipment Detail'!N:N,'Shipment Detail'!E:E,"")) -> FICP | N3: =IF(OR(I3="FR",I3="DE",I3="IT",I3="ES",I3="BE",I3="NL",I3="LU",I3="PT",I3="AT",I3="IE",I3="FI",I3="SE",I3="DK",I3="PL",I3="CZ",I3="SK",I3="HU",I3="RO",I3="BG",I3="HR",I3="SI",I3="EE",I3="LV",I3="LT",I3="GR",I3="CY",I3="MT"),0.2,0) -> 0.2 | O3: =IF(_xlfn.XLOOKUP(F3,'Shipment Detail'!N:N,'Shipment Detail'!BM:BM)=0,"",_xlfn.XLOOKUP(F3,'Shipment Detail'!N:N,'Shipment Detail'!BM:BM)) | R3: =IF(_xlfn.XLOOKUP(F3,'Shipment Detail'!N:N,'Shipment Detail'!AV:AV)>60,10,"") | T3: =TCD!C3 -> 58.57
A4: =IF(OR(M4="FICP",M4="IE", M4="RE", M4="International", M4="Europe"),"FEDEX INTERNATIONAL","FEDEX FRANCE") -> FEDEX FRANCE | B4: =B3 -> 46174 | F4: =TCD!A4 -> 381663677033 | H4: =TCD!F4 -> P | I4: =TCD!B4 -> FR | J4: =IF(COUNTIF(Zoning!B:B,I4)=0,"inconnu",_xlfn.XLOOKUP(I4,Zoning!B:B,Zoning!C:C)) -> France | K4: =_xlfn.XLOOKUP(F4,'Shipment Detail'!N:N,'Shipment Detail'!AB:AB) -> 2 | L4: =TCD!E4 -> 13 | M4: =IF(J4="France","ST",_xlfn.XLOOKUP(F4,'Shipment Detail'!N:N,'Shipment Detail'!E:E,"")) -> ST | N4: =IF(OR(I4="FR",I4="DE",I4="IT",I4="ES",I4="BE",I4="NL",I4="LU",I4="PT",I4="AT",I4="IE",I4="FI",I4="SE",I4="DK",I4="PL",I4="CZ",I4="SK",I4="HU",I4="RO",I4="BG",I4="HR",I4="SI",I4="EE",I4="LV",I4="LT",I4="GR",I4="CY",I4="MT"),0.2,0) -> 0.2 | O4: =IF(_xlfn.XLOOKUP(F4,'Shipment Detail'!N:N,'Shipment Detail'!BM:BM)=0,"",_xlfn.XLOOKUP(F4,'Shipment Detail'!N:N,'Shipment Detail'!BM:BM)) | R4: =IF(_xlfn.XLOOKUP(F4,'Shipment Detail'!N:N,'Shipment Detail'!AV:AV)>60,10,"") | T4: =TCD!C4 -> 8.8
A5: =IF(OR(M5="FICP",M5="IE", M5="RE", M5="International", M5="Europe"),"FEDEX INTERNATIONAL","FEDEX FRANCE") -> FEDEX INTERNATIONAL | B5: =B4 -> 46174 | F5: =TCD!A5 -> 381707060387 | H5: =TCD!F5 -> P | I5: =TCD!B5 -> CH | J5: =IF(COUNTIF(Zoning!B:B,I5)=0,"inconnu",_xlfn.XLOOKUP(I5,Zoning!B:B,Zoning!C:C)) -> U | K5: =_xlfn.XLOOKUP(F5,'Shipment Detail'!N:N,'Shipment Detail'!AB:AB) -> 1 | L5: =TCD!E5 -> 0.1 | M5: =IF(J5="France","ST",_xlfn.XLOOKUP(F5,'Shipment Detail'!N:N,'Shipment Detail'!E:E,"")) -> FICP | N5: =IF(OR(I5="FR",I5="DE",I5="IT",I5="ES",I5="BE",I5="NL",I5="LU",I5="PT",I5="AT",I5="IE",I5="FI",I5="SE",I5="DK",I5="PL",I5="CZ",I5="SK",I5="HU",I5="RO",I5="BG",I5="HR",I5="SI",I5="EE",I5="LV",I5="LT",I5="GR",I5="CY",I5="MT"),0.2,0) -> 0 | O5: =IF(_xlfn.XLOOKUP(F5,'Shipment Detail'!N:N,'Shipment Detail'!BM:BM)=0,"",_xlfn.XLOOKUP(F5,'Shipment Detail'!N:N,'Shipment Detail'!BM:BM)) | R5: =IF(_xlfn.XLOOKUP(F5,'Shipment Detail'!N:N,'Shipment Detail'!AV:AV)>60,10,"") | T5: =TCD!C5 -> 15.89
A6: =IF(OR(M6="FICP",M6="IE", M6="RE", M6="International", M6="Europe"),"FEDEX INTERNATIONAL","FEDEX FRANCE") -> FEDEX FRANCE | B6: =B5 -> 46174 | F6: =TCD!A6 -> 381708365556 | H6: =TCD!F6 -> P | I6: =TCD!B6 -> FR | J6: =IF(COUNTIF(Zoning!B:B,I6)=0,"inconnu",_xlfn.XLOOKUP(I6,Zoning!B:B,Zoning!C:C)) -> France | K6: =_xlfn.XLOOKUP(F6,'Shipment Detail'!N:N,'Shipment Detail'!AB:AB) -> 1 | L6: =TCD!E6 -> 3 | M6: =IF(J6="France","ST",_xlfn.XLOOKUP(F6,'Shipment Detail'!N:N,'Shipment Detail'!E:E,"")) -> ST | N6: =IF(OR(I6="FR",I6="DE",I6="IT",I6="ES",I6="BE",I6="NL",I6="LU",I6="PT",I6="AT",I6="IE",I6="FI",I6="SE",I6="DK",I6="PL",I6="CZ",I6="SK",I6="HU",I6="RO",I6="BG",I6="HR",I6="SI",I6="EE",I6="LV",I6="LT",I6="GR",I6="CY",I6="MT"),0.2,0) -> 0.2 | O6: =IF(_xlfn.XLOOKUP(F6,'Shipment Detail'!N:N,'Shipment Detail'!BM:BM)=0,"",_xlfn.XLOOKUP(F6,'Shipment Detail'!N:N,'Shipment Detail'!BM:BM)) | R6: =IF(_xlfn.XLOOKUP(F6,'Shipment Detail'!N:N,'Shipment Detail'!AV:AV)>60,10,"") | T6: =TCD!C6 -> 5.45
A7: =IF(OR(M7="FICP",M7="IE", M7="RE", M7="International", M7="Europe"),"FEDEX INTERNATIONAL","FEDEX FRANCE") -> FEDEX FRANCE | B7: =B6 -> 46174 | F7: =TCD!A7 -> 381770737060 | H7: =TCD!F7 -> P | I7: =TCD!B7 -> FR | J7: =IF(COUNTIF(Zoning!B:B,I7)=0,"inconnu",_xlfn.XLOOKUP(I7,Zoning!B:B,Zoning!C:C)) -> France | K7: =_xlfn.XLOOKUP(F7,'Shipment Detail'!N:N,'Shipment Detail'!AB:AB) -> 1 | L7: =TCD!E7 -> 0.6 | M7: =IF(J7="France","ST",_xlfn.XLOOKUP(F7,'Shipment Detail'!N:N,'Shipment Detail'!E:E,"")) -> ST | N7: =IF(OR(I7="FR",I7="DE",I7="IT",I7="ES",I7="BE",I7="NL",I7="LU",I7="PT",I7="AT",I7="IE",I7="FI",I7="SE",I7="DK",I7="PL",I7="CZ",I7="SK",I7="HU",I7="RO",I7="BG",I7="HR",I7="SI",I7="EE",I7="LV",I7="LT",I7="GR",I7="CY",I7="MT"),0.2,0) -> 0.2 | O7: =IF(_xlfn.XLOOKUP(F7,'Shipment Detail'!N:N,'Shipment Detail'!BM:BM)=0,"",_xlfn.XLOOKUP(F7,'Shipment Detail'!N:N,'Shipment Detail'!BM:BM)) | R7: =IF(_xlfn.XLOOKUP(F7,'Shipment Detail'!N:N,'Shipment Detail'!AV:AV)>60,10,"") | T7: =TCD!C7 -> 4.78
A8: =IF(OR(M8="FICP",M8="IE", M8="RE", M8="International", M8="Europe"),"FEDEX INTERNATIONAL","FEDEX FRANCE") -> FEDEX FRANCE | B8: =B7 -> 46174 | F8: =TCD!A8 -> 381798154893 | H8: =TCD!F8 -> P | I8: =TCD!B8 -> FR | J8: =IF(COUNTIF(Zoning!B:B,I8)=0,"inconnu",_xlfn.XLOOKUP(I8,Zoning!B:B,Zoning!C:C)) -> France | K8: =_xlfn.XLOOKUP(F8,'Shipment Detail'!N:N,'Shipment Detail'!AB:AB) -> 3 | L8: =TCD!E8 -> 5.1 | M8: =IF(J8="France","ST",_xlfn.XLOOKUP(F8,'Shipment Detail'!N:N,'Shipment Detail'!E:E,"")) -> ST | N8: =IF(OR(I8="FR",I8="DE",I8="IT",I8="ES",I8="BE",I8="NL",I8="LU",I8="PT",I8="AT",I8="IE",I8="FI",I8="SE",I8="DK",I8="PL",I8="CZ",I8="SK",I8="HU",I8="RO",I8="BG",I8="HR",I8="SI",I8="EE",I8="LV",I8="LT",I8="GR",I8="CY",I8="MT"),0.2,0) -> 0.2 | O8: =IF(_xlfn.XLOOKUP(F8,'Shipment Detail'!N:N,'Shipment Detail'!BM:BM)=0,"",_xlfn.XLOOKUP(F8,'Shipment Detail'!N:N,'Shipment Detail'!BM:BM)) | R8: =IF(_xlfn.XLOOKUP(F8,'Shipment Detail'!N:N,'Shipment Detail'!AV:AV)>60,10,"") | T8: =TCD!C8 -> 6.45
A9: =IF(OR(M9="FICP",M9="IE", M9="RE", M9="International", M9="Europe"),"FEDEX INTERNATIONAL","FEDEX FRANCE") -> FEDEX INTERNATIONAL | B9: =B8 -> 46174 | F9: =TCD!A9 -> 381824285874 | H9: =TCD!F9 -> P | I9: =TCD!B9 -> US | J9: =IF(COUNTIF(Zoning!B:B,I9)=0,"inconnu",_xlfn.XLOOKUP(I9,Zoning!B:B,Zoning!C:C)) -> H | K9: =_xlfn.XLOOKUP(F9,'Shipment Detail'!N:N,'Shipment Detail'!AB:AB) -> 1 | L9: =TCD!E9 -> 1.7 | M9: =IF(J9="France","ST",_xlfn.XLOOKUP(F9,'Shipment Detail'!N:N,'Shipment Detail'!E:E,"")) -> FICP | N9: =IF(OR(I9="FR",I9="DE",I9="IT",I9="ES",I9="BE",I9="NL",I9="LU",I9="PT",I9="AT",I9="IE",I9="FI",I9="SE",I9="DK",I9="PL",I9="CZ",I9="SK",I9="HU",I9="RO",I9="BG",I9="HR",I9="SI",I9="EE",I9="LV",I9="LT",I9="GR",I9="CY",I9="MT"),0.2,0) -> 0 | O9: =IF(_xlfn.XLOOKUP(F9,'Shipment Detail'!N:N,'Shipment Detail'!BM:BM)=0,"",_xlfn.XLOOKUP(F9,'Shipment Detail'!N:N,'Shipment Detail'!BM:BM)) | R9: =IF(_xlfn.XLOOKUP(F9,'Shipment Detail'!N:N,'Shipment Detail'!AV:AV)>60,10,"") | T9: =TCD!C9 -> 29.87
A10: =IF(OR(M10="FICP",M10="IE", M10="RE", M10="International", M10="Europe"),"FEDEX INTERNATIONAL","FEDEX FRANCE") -> FEDEX FRANCE | B10: =B9 -> 46174 | F10: =TCD!A10 -> 381863886430 | H10: =TCD!F10 -> P | I10: =TCD!B10 -> FR | J10: =IF(COUNTIF(Zoning!B:B,I10)=0,"inconnu",_xlfn.XLOOKUP(I10,Zoning!B:B,Zoning!C:C)) -> France | K10: =_xlfn.XLOOKUP(F10,'Shipment Detail'!N:N,'Shipment Detail'!AB:AB) -> 1 | L10: =TCD!E10 -> 9 | M10: =IF(J10="France","ST",_xlfn.XLOOKUP(F10,'Shipment Detail'!N:N,'Shipment Detail'!E:E,"")) -> ST | N10: =IF(OR(I10="FR",I10="DE",I10="IT",I10="ES",I10="BE",I10="NL",I10="LU",I10="PT",I10="AT",I10="IE",I10="FI",I10="SE",I10="DK",I10="PL",I10="CZ",I10="SK",I10="HU",I10="RO",I10="BG",I10="HR",I10="SI",I10="EE",I10="LV",I10="LT",I10="GR",I10="CY",I10="MT"),0.2,0) -> 0.2 | O10: =IF(_xlfn.XLOOKUP(F10,'Shipment Detail'!N:N,'Shipment Detail'!BM:BM)=0,"",_xlfn.XLOOKUP(F10,'Shipment Detail'!N:N,'Shipment Detail'!BM:BM)) | R10: =IF(_xlfn.XLOOKUP(F10,'Shipment Detail'!N:N,'Shipment Detail'!AV:AV)>60,10,"") | T10: =TCD!C10 -> 7.46
A11: =IF(OR(M11="FICP",M11="IE", M11="RE", M11="International", M11="Europe"),"FEDEX INTERNATIONAL","FEDEX FRANCE") -> FEDEX FRANCE | B11: =B10 -> 46174 | F11: =TCD!A11 -> 381905290506 | H11: =TCD!F11 -> P | I11: =TCD!B11 -> FR | J11: =IF(COUNTIF(Zoning!B:B,I11)=0,"inconnu",_xlfn.XLOOKUP(I11,Zoning!B:B,Zoning!C:C)) -> France | K11: =_xlfn.XLOOKUP(F11,'Shipment Detail'!N:N,'Shipment Detail'!AB:AB) -> 3 | L11: =TCD!E11 -> 11.2 | M11: =IF(J11="France","ST",_xlfn.XLOOKUP(F11,'Shipment Detail'!N:N,'Shipment Detail'!E:E,"")) -> ST | N11: =IF(OR(I11="FR",I11="DE",I11="IT",I11="ES",I11="BE",I11="NL",I11="LU",I11="PT",I11="AT",I11="IE",I11="FI",I11="SE",I11="DK",I11="PL",I11="CZ",I11="SK",I11="HU",I11="RO",I11="BG",I11="HR",I11="SI",I11="EE",I11="LV",I11="LT",I11="GR",I11="CY",I11="MT"),0.2,0) -> 0.2 | O11: =IF(_xlfn.XLOOKUP(F11,'Shipment Detail'!N:N,'Shipment Detail'!BM:BM)=0,"",_xlfn.XLOOKUP(F11,'Shipment Detail'!N:N,'Shipment Detail'!BM:BM)) | R11: =IF(_xlfn.XLOOKUP(F11,'Shipment Detail'!N:N,'Shipment Detail'!AV:AV)>60,10,"") | T11: =TCD!C11 -> 8.46
A12: =IF(OR(M12="FICP",M12="IE", M12="RE", M12="International", M12="Europe"),"FEDEX INTERNATIONAL","FEDEX FRANCE") -> FEDEX FRANCE | B12: =B11 -> 46174 | F12: =TCD!A12 -> 381954329162 | H12: =TCD!F12 -> P | I12: =TCD!B12 -> FR | J12: =IF(COUNTIF(Zoning!B:B,I12)=0,"inconnu",_xlfn.XLOOKUP(I12,Zoning!B:B,Zoning!C:C)) -> France | K12: =_xlfn.XLOOKUP(F12,'Shipment Detail'!N:N,'Shipment Detail'!AB:AB) -> 1 | L12: =TCD!E12 -> 9 | M12: =IF(J12="France","ST",_xlfn.XLOOKUP(F12,'Shipment Detail'!N:N,'Shipment Detail'!E:E,"")) -> ST | N12: =IF(OR(I12="FR",I12="DE",I12="IT",I12="ES",I12="BE",I12="NL",I12="LU",I12="PT",I12="AT",I12="IE",I12="FI",I12="SE",I12="DK",I12="PL",I12="CZ",I12="SK",I12="HU",I12="RO",I12="BG",I12="HR",I12="SI",I12="EE",I12="LV",I12="LT",I12="GR",I12="CY",I12="MT"),0.2,0) -> 0.2 | O12: =IF(_xlfn.XLOOKUP(F12,'Shipment Detail'!N:N,'Shipment Detail'!BM:BM)=0,"",_xlfn.XLOOKUP(F12,'Shipment Detail'!N:N,'Shipment Detail'!BM:BM)) | R12: =IF(_xlfn.XLOOKUP(F12,'Shipment Detail'!N:N,'Shipment Detail'!AV:AV)>60,10,"") | T12: =TCD!C12 -> 7.46
A13: =IF(OR(M13="FICP",M13="IE", M13="RE", M13="International", M13="Europe"),"FEDEX INTERNATIONAL","FEDEX FRANCE") -> FEDEX INTERNATIONAL | B13: =B12 -> 46174 | F13: =TCD!A13 -> 381981990415 | H13: =TCD!F13 -> E | I13: =TCD!B13 -> FI | J13: =IF(COUNTIF(Zoning!B:B,I13)=0,"inconnu",_xlfn.XLOOKUP(I13,Zoning!B:B,Zoning!C:C)) -> T | K13: =_xlfn.XLOOKUP(F13,'Shipment Detail'!N:N,'Shipment Detail'!AB:AB) -> 1 | L13: =TCD!E13 -> 7.2 | M13: =IF(J13="France","ST",_xlfn.XLOOKUP(F13,'Shipment Detail'!N:N,'Shipment Detail'!E:E,"")) -> FICP | N13: =IF(OR(I13="FR",I13="DE",I13="IT",I13="ES",I13="BE",I13="NL",I13="LU",I13="PT",I13="AT",I13="IE",I13="FI",I13="SE",I13="DK",I13="PL",I13="CZ",I13="SK",I13="HU",I13="RO",I13="BG",I13="HR",I13="SI",I13="EE",I13="LV",I13="LT",I13="GR",I13="CY",I13="MT"),0.2,0) -> 0.2 | O13: =IF(_xlfn.XLOOKUP(F13,'Shipment Detail'!N:N,'Shipment Detail'!BM:BM)=0,"",_xlfn.XLOOKUP(F13,'Shipment Detail'!N:N,'Shipment Detail'!BM:BM)) | R13: =IF(_xlfn.XLOOKUP(F13,'Shipment Detail'!N:N,'Shipment Detail'!AV:AV)>60,10,"") | T13: =TCD!C13 -> 32.37
A14: =IF(OR(M14="FICP",M14="IE", M14="RE", M14="International", M14="Europe"),"FEDEX INTERNATIONAL","FEDEX FRANCE") -> FEDEX INTERNATIONAL | B14: =B13 -> 46174 | F14: =TCD!A14 -> 382050598017 | H14: =TCD!F14 -> E | I14: =TCD!B14 -> SE | J14: =IF(COUNTIF(Zoning!B:B,I14)=0,"inconnu",_xlfn.XLOOKUP(I14,Zoning!B:B,Zoning!C:C)) -> T | K14: =_xlfn.XLOOKUP(F14,'Shipment Detail'!N:N,'Shipment Detail'!AB:AB) -> 1 | L14: =TCD!E14 -> 13.8 | M14: =IF(J14="France","ST",_xlfn.XLOOKUP(F14,'Shipment Detail'!N:N,'Shipment Detail'!E:E,"")) -> FICP | N14: =IF(OR(I14="FR",I14="DE",I14="IT",I14="ES",I14="BE",I14="NL",I14="LU",I14="PT",I14="AT",I14="IE",I14="FI",I14="SE",I14="DK",I14="PL",I14="CZ",I14="SK",I14="HU",I14="RO",I14="BG",I14="HR",I14="SI",I14="EE",I14="LV",I14="LT",I14="GR",I14="CY",I14="MT"),0.2,0) -> 0.2 | O14: =IF(_xlfn.XLOOKUP(F14,'Shipment Detail'!N:N,'Shipment Detail'!BM:BM)=0,"",_xlfn.XLOOKUP(F14,'Shipment Detail'!N:N,'Shipment Detail'!BM:BM)) | R14: =IF(_xlfn.XLOOKUP(F14,'Shipment Detail'!N:N,'Shipment Detail'!AV:AV)>60,10,"") | T14: =TCD!C14 -> 49.88
... A3608: =IF(OR(M3608="FICP",M3608="IE", M3608="RE", M3608="International", M3608="Europe"),"FEDEX INTERNATIONAL","FEDEX FRANCE") -> FEDEX FRANCE | B3608: =B3607 -> 46174 | F3608: =TCD!A3608 -> 873819757072 | H3608: =TCD!F3608 -> P | I3608: =TCD!B3608 -> FR | J3608: =IF(COUNTIF(Zoning!B:B,I3608)=0,"inconnu",_xlfn.XLOOKUP(I3608,Zoning!B:B,Zoning!C:C)) -> France | K3608: =_xlfn.XLOOKUP(F3608,'Shipment Detail'!N:N,'Shipment Detail'!AB:AB) -> 7 | L3608: =TCD!E3608 -> 31 | M3608: =IF(J3608="France","ST",_xlfn.XLOOKUP(F3608,'Shipment Detail'!N:N,'Shipment Detail'!E:E,"")) -> ST | N3608: =IF(OR(I3608="FR",I3608="DE",I3608="IT",I3608="ES",I3608="BE",I3608="NL",I3608="LU",I3608="PT",I3608="AT",I3608="IE",I3608="FI",I3608="SE",I3608="DK",I3608="PL",I3608="CZ",I3608="SK",I3608="HU",I3608="RO",I3608="BG",I3608="HR",I3608="SI",I3608="EE",I3608="LV",I3608="LT",I3608="GR",I3608="CY",I3608="MT"),0.2,0) -> 0.2 | O3608: =IF(_xlfn.XLOOKUP(F3608,'Shipment Detail'!N:N,'Shipment Detail'!BM:BM)=0,"",_xlfn.XLOOKUP(F3608,'Shipment Detail'!N:N,'Shipment Detail'!BM:BM)) | R3608: =IF(_xlfn.XLOOKUP(F3608,'Shipment Detail'!N:N,'Shipment Detail'!AV:AV)>60,10,"") | T3608: =TCD!C3608 -> 14.82
