Workbook

Sheet Catégories
A1: CNM | B1: Colis volumineux
A2: AS_AD_VAL | B2: Assurance
A3: DR | B3: Frêt
A4: FACTOR_FOR | B4: Frêt
A5: LS | B5: Frêt
A6: RS | B6: Frêt
A7: SURCH_CARB | B7: Gazole
A8: TMC | B8: Frêt
A9: Z | B9: Frêt
A10: ZEL | B10: Zones éloignées
A11: SURCH_CARB | B11: Gazole
A12: AS_AD_VAL | B12: Assurance
... A26: FACTOR_FOR | B26: Frêt
B27: Frêt

Sheet Recherche tracking
A1: numero envoi | B1: id colis
A2: E00000000000000 | B2: '
A3: E20260601123351 | B3: '
A4: E20260601123351 | B4: '6343814314751131
A5: E20260601123351 | B5: '6343814314751148
A6: E20260601123352 | B6: '
A7: E20260601123352 | B7: '6543814314751205
A8: E20260601123353 | B8: '
A9: E20260601123353 | B9: '7443814314751128
A10: E20260601123355 | B10: '
A11: E20260601123355 | B11: '5643814314751081
A12: E20260601123356 | B12: '
... A1202: (vide) | B1202: (vide)

Sheet Nb colis et poids
A1: code complement | B1: TMC | E1: Étiquettes de lignes | F1: Max. de poids colis
F2: 0
A3: Étiquettes de lignes | B3: Somme de montant HT | E3: 0143814314751704 | F3: 1.34
A4: 0143814314754170 | B4: 1 | E4: 0143814314752278 | F4: 0.8
A5: 0643814314752665 | B5: 1 | E5: 0143814314752704 | F5: 3.84
A6: 0643814314754648 | B6: 8 | E6: 0143814314754170 | F6: 12.61
A7: 0743814314753622 | B7: 1 | E7: 0143814314756819 | F7: 11.69
A8: 1143814314757169 | B8: 1 | E8: 0243814314752776 | F8: 4.01
A9: 1343814314754157 | B9: 2 | E9: 0343814314755970 | F9: 0.8
A10: 1343814314756278 | B10: 2 | E10: 0443814314751303 | F10: 1.6
A11: 1443814314751684 | B11: 1 | E11: 0543814314752536 | F11: 2.9
A12: 1443814314752131 | B12: 1 | E12: 0643814314751591 | F12: 2.9
A13: 1443814314752190 | B13: 2 | E13: 0643814314752078 | F13: 9.2
A14: 1743814314752225 | B14: 2 | E14: 0643814314752665 | F14: 11.8
A15: 1743814314753657 | B15: 1 | E15: 0643814314752717 | F15: 2.9
... A104: 9543814314757247 | B104: 4 | E104: 2543814314752930 | F104: 24.04
E105: 2543814314754952 | F105: 6.01
E106: 2543814314757693 | F106: 3.5
E107: 2643814314752908 | F107: 10.8
E108: 2643814314754839 | F108: 3.5
E109: 2643814314757125 | F109: 2.6
E110: 2743814314752617 | F110: 3.6
E111: 2743814314754992 | F111: 3.9
E112: 2943814314753670 | F112: 26.3
E113: 2943814314754006 | F113: 2.9
E114: 2943814314754686 | F114: 3.2
E115: 2943814314756795 | F115: 3.8
E116: 3043814314752882 | F116: 1
... E515: 9543814314757247 | F515: 76.9
E516: (vide)

Sheet Facture TNT
A1: Problème | B1: Catégorie | C1: Tracking | D1: Mois de Facturation | E1: Indicatif Facture | F1: Numero de Facture | G1: Compte Expediteur | H1: Client Facturé | I1: Ligne Facture | J1: id colis | K1: date Expedition | L1: numero envoi | M1: code Produit | N1: poids colis | O1: code complement | P1: montant HT | Q1: raison sociale expéditeur | R1: adresse 1 | S1: adresse 2 | T1: pays | U1: departement | V1: code postal | W1: ville | X1: raison sociale destinataire | Y1: adresse 1 | Z1: adresse 2 | AA1: pays | AB1: departement | AC1: code postal | AD1: ville
B2: =IF(O2="","Frêt",_xlfn.XLOOKUP(O2,Catégories!A:A,Catégories!B:B,"inconnu")) -> Gazole | C2: =RIGHT(LOOKUP(L2,'Recherche tracking'!A:A,'Recherche tracking'!B:B),16) | D2: 202606 | E2: 51 | F2: 1085442 | G2: '03814314 | H2: '03814314 | I2: EXP | J2: ' | K2: 0 | L2: E00000000000000 | N2: 0 | O2: SURCH_CARB | P2: 422.52 | U2: ' | V2: ' | AB2: ' | AC2: '
B3: =IF(O3="","Frêt",_xlfn.XLOOKUP(O3,Catégories!A:A,Catégories!B:B,"inconnu")) -> Frêt | C3: =RIGHT(LOOKUP(L3,'Recherche tracking'!A:A,'Recherche tracking'!B:B),16) -> 6343814314751148 | D3: 202606 | E3: 51 | F3: 1085442 | G3: '03814314 | H3: '03814314 | I3: ENV | J3: ' | K3: 20260601 | L3: E20260601123351 | M3: J18 | N3: 12.7 | P3: 7.27 | Q3: LARUCHE | R3: VOIE COMMUNALE 4 | T3: FR | U3: '21 | V3: '21320 | W3: CREANCEY | X3: ARNAUD PHILIPPE | Y3: 97 AVENUE JOSEPH CLAUSSAT | AA3: FR | AB3: '63 | AC3: '63400 | AD3: CHAMALIERES
B4: =IF(O4="","Frêt",_xlfn.XLOOKUP(O4,Catégories!A:A,Catégories!B:B,"inconnu")) -> Frêt | C4: =RIGHT(LOOKUP(L4,'Recherche tracking'!A:A,'Recherche tracking'!B:B),16) -> 6343814314751148 | D4: 202606 | E4: 51 | F4: 1085442 | G4: '03814314 | H4: '03814314 | I4: COL | J4: '6343814314751131 | K4: 20260601 | L4: E20260601123351 | M4: J18 | N4: 5.4 | P4: 0 | Q4: LARUCHE | R4: VOIE COMMUNALE 4 | T4: FR | U4: '21 | V4: '21320 | W4: CREANCEY | X4: ARNAUD PHILIPPE | Y4: 97 AVENUE JOSEPH CLAUSSAT | AA4: FR | AB4: '63 | AC4: '63400 | AD4: CHAMALIERES
B5: =IF(O5="","Frêt",_xlfn.XLOOKUP(O5,Catégories!A:A,Catégories!B:B,"inconnu")) -> Frêt | C5: =RIGHT(LOOKUP(L5,'Recherche tracking'!A:A,'Recherche tracking'!B:B),16) -> 6343814314751148 | D5: 202606 | E5: 51 | F5: 1085442 | G5: '03814314 | H5: '03814314 | I5: CPC | J5: '6343814314751131 | K5: 20260601 | L5: E20260601123351 | N5: 5.4 | O5: RS | P5: 0 | Q5: LARUCHE | R5: VOIE COMMUNALE 4 | T5: FR | U5: '21 | V5: '21320 | W5: CREANCEY | X5: ARNAUD PHILIPPE | Y5: 97 AVENUE JOSEPH CLAUSSAT | AA5: FR | AB5: '63 | AC5: '63400 | AD5: CHAMALIERES
B6: =IF(O6="","Frêt",_xlfn.XLOOKUP(O6,Catégories!A:A,Catégories!B:B,"inconnu")) -> Frêt | C6: =RIGHT(LOOKUP(L6,'Recherche tracking'!A:A,'Recherche tracking'!B:B),16) -> 6343814314751148 | D6: 202606 | E6: 51 | F6: 1085442 | G6: '03814314 | H6: '03814314 | I6: COL | J6: '6343814314751148 | K6: 20260601 | L6: E20260601123351 | M6: J18 | N6: 7.3 | P6: 0 | Q6: LARUCHE | R6: VOIE COMMUNALE 4 | T6: FR | U6: '21 | V6: '21320 | W6: CREANCEY | X6: ARNAUD PHILIPPE | Y6: 97 AVENUE JOSEPH CLAUSSAT | AA6: FR | AB6: '63 | AC6: '63400 | AD6: CHAMALIERES
B7: =IF(O7="","Frêt",_xlfn.XLOOKUP(O7,Catégories!A:A,Catégories!B:B,"inconnu")) -> Frêt | C7: =RIGHT(LOOKUP(L7,'Recherche tracking'!A:A,'Recherche tracking'!B:B),16) -> 6343814314751148 | D7: 202606 | E7: 51 | F7: 1085442 | G7: '03814314 | H7: '03814314 | I7: CPC | J7: '6343814314751148 | K7: 20260601 | L7: E20260601123351 | N7: 7.3 | O7: RS | P7: 0 | Q7: LARUCHE | R7: VOIE COMMUNALE 4 | T7: FR | U7: '21 | V7: '21320 | W7: CREANCEY | X7: ARNAUD PHILIPPE | Y7: 97 AVENUE JOSEPH CLAUSSAT | AA7: FR | AB7: '63 | AC7: '63400 | AD7: CHAMALIERES
B8: =IF(O8="","Frêt",_xlfn.XLOOKUP(O8,Catégories!A:A,Catégories!B:B,"inconnu")) -> Frêt | C8: =RIGHT(LOOKUP(L8,'Recherche tracking'!A:A,'Recherche tracking'!B:B),16) -> 6343814314751148 | D8: 202606 | E8: 51 | F8: 1085442 | G8: '03814314 | H8: '03814314 | I8: CPC | J8: '6343814314751148 | K8: 20260601 | L8: E20260601123351 | N8: 7.3 | O8: TMC | P8: 1 | Q8: LARUCHE | R8: VOIE COMMUNALE 4 | T8: FR | U8: '21 | V8: '21320 | W8: CREANCEY | X8: ARNAUD PHILIPPE | Y8: 97 AVENUE JOSEPH CLAUSSAT | AA8: FR | AB8: '63 | AC8: '63400 | AD8: CHAMALIERES
B9: =IF(O9="","Frêt",_xlfn.XLOOKUP(O9,Catégories!A:A,Catégories!B:B,"inconnu")) -> Frêt | C9: =RIGHT(LOOKUP(L9,'Recherche tracking'!A:A,'Recherche tracking'!B:B),16) -> 6543814314751205 | D9: 202606 | E9: 51 | F9: 1085442 | G9: '03814314 | H9: '03814314 | I9: ENV | J9: ' | K9: 20260601 | L9: E20260601123352 | M9: J18 | N9: 2.9 | P9: 4.67 | Q9: LARUCHE | R9: VOIE COMMUNALE 4 | T9: FR | U9: '21 | V9: '21320 | W9: CREANCEY | X9: BACHA LOLA | Y9: 82 RUE THIERS | AA9: FR | AB9: '65 | AC9: '65300 | AD9: LANNEMEZAN
B10: =IF(O10="","Frêt",_xlfn.XLOOKUP(O10,Catégories!A:A,Catégories!B:B,"inconnu")) -> Frêt | C10: =RIGHT(LOOKUP(L10,'Recherche tracking'!A:A,'Recherche tracking'!B:B),16) -> 6543814314751205 | D10: 202606 | E10: 51 | F10: 1085442 | G10: '03814314 | H10: '03814314 | I10: COL | J10: '6543814314751205 | K10: 20260601 | L10: E20260601123352 | M10: J18 | N10: 2.9 | P10: 0 | Q10: LARUCHE | R10: VOIE COMMUNALE 4 | T10: FR | U10: '21 | V10: '21320 | W10: CREANCEY | X10: BACHA LOLA | Y10: 82 RUE THIERS | AA10: FR | AB10: '65 | AC10: '65300 | AD10: LANNEMEZAN
B11: =IF(O11="","Frêt",_xlfn.XLOOKUP(O11,Catégories!A:A,Catégories!B:B,"inconnu")) -> Frêt | C11: =RIGHT(LOOKUP(L11,'Recherche tracking'!A:A,'Recherche tracking'!B:B),16) -> 6543814314751205 | D11: 202606 | E11: 51 | F11: 1085442 | G11: '03814314 | H11: '03814314 | I11: CPC | J11: '6543814314751205 | K11: 20260601 | L11: E20260601123352 | N11: 2.9 | O11: RS | P11: 0 | Q11: LARUCHE | R11: VOIE COMMUNALE 4 | T11: FR | U11: '21 | V11: '21320 | W11: CREANCEY | X11: BACHA LOLA | Y11: 82 RUE THIERS | AA11: FR | AB11: '65 | AC11: '65300 | AD11: LANNEMEZAN
B12: =IF(O12="","Frêt",_xlfn.XLOOKUP(O12,Catégories!A:A,Catégories!B:B,"inconnu")) -> Frêt | C12: =RIGHT(LOOKUP(L12,'Recherche tracking'!A:A,'Recherche tracking'!B:B),16) -> 7443814314751128 | D12: 202606 | E12: 51 | F12: 1085442 | G12: '03814314 | H12: '03814314 | I12: ENV | J12: ' | K12: 20260601 | L12: E20260601123353 | M12: J18 | N12: 22.1 | P12: 9.87 | Q12: LARUCHE | R12: VOIE COMMUNALE 4 | T12: FR | U12: '21 | V12: '21320 | W12: CREANCEY | X12: BALLET THEO | Y12: 21 PLACE BALMAT | AA12: FR | AB12: '74 | AC12: '74400 | AD12: CHAMONIX-MONT-BLANC
B13: =IF(O13="","Frêt",_xlfn.XLOOKUP(O13,Catégories!A:A,Catégories!B:B,"inconnu")) -> Frêt | C13: =RIGHT(LOOKUP(L13,'Recherche tracking'!A:A,'Recherche tracking'!B:B),16) -> 7443814314751128 | D13: 202606 | E13: 51 | F13: 1085442 | G13: '03814314 | H13: '03814314 | I13: COL | J13: '7443814314751128 | K13: 20260601 | L13: E20260601123353 | M13: J18 | N13: 22.1 | P13: 0 | Q13: LARUCHE | R13: VOIE COMMUNALE 4 | T13: FR | U13: '21 | V13: '21320 | W13: CREANCEY | X13: BALLET THEO | Y13: 21 PLACE BALMAT | AA13: FR | AB13: '74 | AC13: '74400 | AD13: CHAMONIX-MONT-BLANC
B14: =IF(O14="","Frêt",_xlfn.XLOOKUP(O14,Catégories!A:A,Catégories!B:B,"inconnu")) -> Frêt | C14: =RIGHT(LOOKUP(L14,'Recherche tracking'!A:A,'Recherche tracking'!B:B),16) -> 7443814314751128 | D14: 202606 | E14: 51 | F14: 1085442 | G14: '03814314 | H14: '03814314 | I14: CPC | J14: '7443814314751128 | K14: 20260601 | L14: E20260601123353 | N14: 22.1 | O14: RS | P14: 0 | Q14: LARUCHE | R14: VOIE COMMUNALE 4 | T14: FR | U14: '21 | V14: '21320 | W14: CREANCEY | X14: BALLET THEO | Y14: 21 PLACE BALMAT | AA14: FR | AB14: '74 | AC14: '74400 | AD14: CHAMONIX-MONT-BLANC
B15: =IF(O15="","Frêt",_xlfn.XLOOKUP(O15,Catégories!A:A,Catégories!B:B,"inconnu")) -> Zones éloignées | C15: =RIGHT(LOOKUP(L15,'Recherche tracking'!A:A,'Recherche tracking'!B:B),16) -> 7443814314751128 | D15: 202606 | E15: 51 | F15: 1085442 | G15: '03814314 | H15: '03814314 | I15: CPC | J15: '7443814314751128 | K15: 20260601 | L15: E20260601123353 | N15: 22.1 | O15: ZEL | P15: 5 | Q15: LARUCHE | R15: VOIE COMMUNALE 4 | T15: FR | U15: '21 | V15: '21320 | W15: CREANCEY | X15: BALLET THEO | Y15: 21 PLACE BALMAT | AA15: FR | AB15: '74 | AC15: '74400 | AD15: CHAMONIX-MONT-BLANC
B16: =IF(O16="","Frêt",_xlfn.XLOOKUP(O16,Catégories!A:A,Catégories!B:B,"inconnu")) -> Frêt | C16: =RIGHT(LOOKUP(L16,'Recherche tracking'!A:A,'Recherche tracking'!B:B),16) -> 5643814314751081 | D16: 202606 | E16: 51 | F16: 1085442 | G16: '03814314 | H16: '03814314 | I16: ENV | J16: ' | K16: 20260601 | L16: E20260601123355 | M16: J18 | N16: 10.4 | P16: 6.75 | Q16: LARUCHE | R16: VOIE COMMUNALE 4 | T16: FR | U16: '21 | V16: '21320 | W16: CREANCEY | X16: BATEJAT VICTOR | Y16: 19 RUE DES VIERGES | AA16: FR | AB16: '56 | AC16: '56000 | AD16: VANNES
B17: =IF(O17="","Frêt",_xlfn.XLOOKUP(O17,Catégories!A:A,Catégories!B:B,"inconnu")) -> Frêt | C17: =RIGHT(LOOKUP(L17,'Recherche tracking'!A:A,'Recherche tracking'!B:B),16) -> 5643814314751081 | D17: 202606 | E17: 51 | F17: 1085442 | G17: '03814314 | H17: '03814314 | I17: COL | J17: '5643814314751081 | K17: 20260601 | L17: E20260601123355 | M17: J18 | N17: 10.4 | P17: 0 | Q17: LARUCHE | R17: VOIE COMMUNALE 4 | T17: FR | U17: '21 | V17: '21320 | W17: CREANCEY | X17: BATEJAT VICTOR | Y17: 19 RUE DES VIERGES | AA17: FR | AB17: '56 | AC17: '56000 | AD17: VANNES
B18: =IF(O18="","Frêt",_xlfn.XLOOKUP(O18,Catégories!A:A,Catégories!B:B,"inconnu")) -> Frêt | C18: =RIGHT(LOOKUP(L18,'Recherche tracking'!A:A,'Recherche tracking'!B:B),16) -> 5643814314751081 | D18: 202606 | E18: 51 | F18: 1085442 | G18: '03814314 | H18: '03814314 | I18: CPC | J18: '5643814314751081 | K18: 20260601 | L18: E20260601123355 | N18: 10.4 | O18: RS | P18: 0 | Q18: LARUCHE | R18: VOIE COMMUNALE 4 | T18: FR | U18: '21 | V18: '21320 | W18: CREANCEY | X18: BATEJAT VICTOR | Y18: 19 RUE DES VIERGES | AA18: FR | AB18: '56 | AC18: '56000 | AD18: VANNES
B19: =IF(O19="","Frêt",_xlfn.XLOOKUP(O19,Catégories!A:A,Catégories!B:B,"inconnu")) -> Frêt | C19: =RIGHT(LOOKUP(L19,'Recherche tracking'!A:A,'Recherche tracking'!B:B),16) -> 9343814314751052 | D19: 202606 | E19: 51 | F19: 1085442 | G19: '03814314 | H19: '03814314 | I19: ENV | J19: ' | K19: 20260601 | L19: E20260601123356 | M19: J18 | N19: 2.84 | P19: 4.67 | Q19: LARUCHE | R19: VOIE COMMUNALE 4 | T19: FR | U19: '21 | V19: '21320 | W19: CREANCEY | X19: BERRIAS HOUDA | Y19: 16 PLACE DU GENERAL DE GAULLE | AA19: FR | AB19: '93 | AC19: '93220 | AD19: GAGNY
B20: =IF(O20="","Frêt",_xlfn.XLOOKUP(O20,Catégories!A:A,Catégories!B:B,"inconnu")) -> Frêt | C20: =RIGHT(LOOKUP(L20,'Recherche tracking'!A:A,'Recherche tracking'!B:B),16) -> 9343814314751052 | D20: 202606 | E20: 51 | F20: 1085442 | G20: '03814314 | H20: '03814314 | I20: COL | J20: '9343814314751052 | K20: 20260601 | L20: E20260601123356 | M20: J18 | N20: 2.84 | P20: 0 | Q20: LARUCHE | R20: VOIE COMMUNALE 4 | T20: FR | U20: '21 | V20: '21320 | W20: CREANCEY | X20: BERRIAS HOUDA | Y20: 16 PLACE DU GENERAL DE GAULLE | AA20: FR | AB20: '93 | AC20: '93220 | AD20: GAGNY
B21: =IF(O21="","Frêt",_xlfn.XLOOKUP(O21,Catégories!A:A,Catégories!B:B,"inconnu")) -> Frêt | C21: =RIGHT(LOOKUP(L21,'Recherche tracking'!A:A,'Recherche tracking'!B:B),16) -> 9343814314751052 | D21: 202606 | E21: 51 | F21: 1085442 | G21: '03814314 | H21: '03814314 | I21: CPC | J21: '9343814314751052 | K21: 20260601 | L21: E20260601123356 | N21: 2.84 | O21: RS | P21: 0 | Q21: LARUCHE | R21: VOIE COMMUNALE 4 | T21: FR | U21: '21 | V21: '21320 | W21: CREANCEY | X21: BERRIAS HOUDA | Y21: 16 PLACE DU GENERAL DE GAULLE | AA21: FR | AB21: '93 | AC21: '93220 | AD21: GAGNY
B22: =IF(O22="","Frêt",_xlfn.XLOOKUP(O22,Catégories!A:A,Catégories!B:B,"inconnu")) -> Frêt | C22: =RIGHT(LOOKUP(L22,'Recherche tracking'!A:A,'Recherche tracking'!B:B),16) -> 7543814314751091 | D22: 202606 | E22: 51 | F22: 1085442 | G22: '03814314 | H22: '03814314 | I22: ENV | J22: ' | K22: 20260601 | L22: E20260601123357 | M22: J18 | N22: 3.2 | P22: 4.93 | Q22: LARUCHE | R22: VOIE COMMUNALE 4 | T22: FR | U22: '21 | V22: '21320 | W22: CREANCEY | X22: BOURGUIBA CHEYMA | Y22: 42 RUE DU CHEMIN VERT | AA22: FR | AB22: '75 | AC22: '75011 | AD22: PARIS
B23: =IF(O23="","Frêt",_xlfn.XLOOKUP(O23,Catégories!A:A,Catégories!B:B,"inconnu")) -> Frêt | C23: =RIGHT(LOOKUP(L23,'Recherche tracking'!A:A,'Recherche tracking'!B:B),16) -> 7543814314751091 | D23: 202606 | E23: 51 | F23: 1085442 | G23: '03814314 | H23: '03814314 | I23: COL | J23: '7543814314751091 | K23: 20260601 | L23: E20260601123357 | M23: J18 | N23: 3.2 | P23: 0 | Q23: LARUCHE | R23: VOIE COMMUNALE 4 | T23: FR | U23: '21 | V23: '21320 | W23: CREANCEY | X23: BOURGUIBA CHEYMA | Y23: 42 RUE DU CHEMIN VERT | AA23: FR | AB23: '75 | AC23: '75011 | AD23: PARIS
B24: =IF(O24="","Frêt",_xlfn.XLOOKUP(O24,Catégories!A:A,Catégories!B:B,"inconnu")) -> Frêt | C24: =RIGHT(LOOKUP(L24,'Recherche tracking'!A:A,'Recherche tracking'!B:B),16) -> 7543814314751091 | D24: 202606 | E24: 51 | F24: 1085442 | G24: '03814314 | H24: '03814314 | I24: CPC | J24: '7543814314751091 | K24: 20260601 | L24: E20260601123357 | N24: 3.2 | O24: RS | P24: 0 | Q24: LARUCHE | R24: VOIE COMMUNALE 4 | T24: FR | U24: '21 | V24: '21320 | W24: CREANCEY | X24: BOURGUIBA CHEYMA | Y24: 42 RUE DU CHEMIN VERT | AA24: FR | AB24: '75 | AC24: '75011 | AD24: PARIS
B25: =IF(O25="","Frêt",_xlfn.XLOOKUP(O25,Catégories!A:A,Catégories!B:B,"inconnu")) -> Frêt | C25: =RIGHT(LOOKUP(L25,'Recherche tracking'!A:A,'Recherche tracking'!B:B),16) -> 9443814314751187 | D25: 202606 | E25: 51 | F25: 1085442 | G25: '03814314 | H25: '03814314 | I25: ENV | J25: ' | K25: 20260601 | L25: E20260601123358 | M25: J18 | N25: 10 | P25: 6.49 | Q25: LARUCHE | R25: VOIE COMMUNALE 4 | T25: FR | U25: '21 | V25: '21320 | W25: CREANCEY | X25: CASSE LIONEL | Y25: 12 AVENUE DE VERDUN | AA25: FR | AB25: '94 | AC25: '94410 | AD25: SAINT MAURICE
B26: =IF(O26="","Frêt",_xlfn.XLOOKUP(O26,Catégories!A:A,Catégories!B:B,"inconnu")) -> Frêt | C26: =RIGHT(LOOKUP(L26,'Recherche tracking'!A:A,'Recherche tracking'!B:B),16) -> 9443814314751187 | D26: 202606 | E26: 51 | F26: 1085442 | G26: '03814314 | H26: '03814314 | I26: COL | J26: '9443814314751175 | K26: 20260601 | L26: E20260601123358 | M26: J18 | N26: 5.3 | P26: 0 | Q26: LARUCHE | R26: VOIE COMMUNALE 4 | T26: FR | U26: '21 | V26: '21320 | W26: CREANCEY | X26: CASSE LIONEL | Y26: 12 AVENUE DE VERDUN | AA26: FR | AB26: '94 | AC26: '94410 | AD26: SAINT MAURICE
B27: =IF(O27="","Frêt",_xlfn.XLOOKUP(O27,Catégories!A:A,Catégories!B:B,"inconnu")) -> Frêt | C27: =RIGHT(LOOKUP(L27,'Recherche tracking'!A:A,'Recherche tracking'!B:B),16) -> 9443814314751187 | D27: 202606 | E27: 51 | F27: 1085442 | G27: '03814314 | H27: '03814314 | I27: CPC | J27: '9443814314751175 | K27: 20260601 | L27: E20260601123358 | N27: 5.3 | O27: RS | P27: 0 | Q27: LARUCHE | R27: VOIE COMMUNALE 4 | T27: FR | U27: '21 | V27: '21320 | W27: CREANCEY | X27: CASSE LIONEL | Y27: 12 AVENUE DE VERDUN | AA27: FR | AB27: '94 | AC27: '94410 | AD27: SAINT MAURICE
B28: =IF(O28="","Frêt",_xlfn.XLOOKUP(O28,Catégories!A:A,Catégories!B:B,"inconnu")) -> Frêt | C28: =RIGHT(LOOKUP(L28,'Recherche tracking'!A:A,'Recherche tracking'!B:B),16) -> 9443814314751187 | D28: 202606 | E28: 51 | F28: 1085442 | G28: '03814314 | H28: '03814314 | I28: COL | J28: '9443814314751187 | K28: 20260601 | L28: E20260601123358 | M28: J18 | N28: 4.7 | P28: 0 | Q28: LARUCHE | R28: VOIE COMMUNALE 4 | T28: FR | U28: '21 | V28: '21320 | W28: CREANCEY | X28: CASSE LIONEL | Y28: 12 AVENUE DE VERDUN | AA28: FR | AB28: '94 | AC28: '94410 | AD28: SAINT MAURICE
B29: =IF(O29="","Frêt",_xlfn.XLOOKUP(O29,Catégories!A:A,Catégories!B:B,"inconnu")) -> Frêt | C29: =RIGHT(LOOKUP(L29,'Recherche tracking'!A:A,'Recherche tracking'!B:B),16) -> 9443814314751187 | D29: 202606 | E29: 51 | F29: 1085442 | G29: '03814314 | H29: '03814314 | I29: CPC | J29: '9443814314751187 | K29: 20260601 | L29: E20260601123358 | N29: 4.7 | O29: RS | P29: 0 | Q29: LARUCHE | R29: VOIE COMMUNALE 4 | T29: FR | U29: '21 | V29: '21320 | W29: CREANCEY | X29: CASSE LIONEL | Y29: 12 AVENUE DE VERDUN | AA29: FR | AB29: '94 | AC29: '94410 | AD29: SAINT MAURICE
B30: =IF(O30="","Frêt",_xlfn.XLOOKUP(O30,Catégories!A:A,Catégories!B:B,"inconnu")) -> Frêt | C30: =RIGHT(LOOKUP(L30,'Recherche tracking'!A:A,'Recherche tracking'!B:B),16) -> 9443814314751187 | D30: 202606 | E30: 51 | F30: 1085442 | G30: '03814314 | H30: '03814314 | I30: CPC | J30: '9443814314751187 | K30: 20260601 | L30: E20260601123358 | N30: 4.7 | O30: TMC | P30: 1 | Q30: LARUCHE | R30: VOIE COMMUNALE 4 | T30: FR | U30: '21 | V30: '21320 | W30: CREANCEY | X30: CASSE LIONEL | Y30: 12 AVENUE DE VERDUN | AA30: FR | AB30: '94 | AC30: '94410 | AD30: SAINT MAURICE
B31: =IF(O31="","Frêt",_xlfn.XLOOKUP(O31,Catégories!A:A,Catégories!B:B,"inconnu")) -> Frêt | C31: =RIGHT(LOOKUP(L31,'Recherche tracking'!A:A,'Recherche tracking'!B:B),16) -> 2543814314751261 | D31: 202606 | E31: 51 | F31: 1085442 | G31: '03814314 | H31: '03814314 | I31: ENV | J31: ' | K31: 20260601 | L31: E20260601123359 | M31: J18 | N31: 6.8 | P31: 5.71 | Q31: LARUCHE | R31: VOIE COMMUNALE 4 | T31: FR | U31: '21 | V31: '21320 | W31: CREANCEY | X31: CHRISTOPHE DENNIEL | Y31: 87 GRANDE RUE | AA31: FR | AB31: '25 | AC31: '25000 | AD31: BESANCON
B32: =IF(O32="","Frêt",_xlfn.XLOOKUP(O32,Catégories!A:A,Catégories!B:B,"inconnu")) -> Frêt | C32: =RIGHT(LOOKUP(L32,'Recherche tracking'!A:A,'Recherche tracking'!B:B),16) -> 2543814314751261 | D32: 202606 | E32: 51 | F32: 1085442 | G32: '03814314 | H32: '03814314 | I32: COL | J32: '2543814314751261 | K32: 20260601 | L32: E20260601123359 | M32: J18 | N32: 6.8 | P32: 0 | Q32: LARUCHE | R32: VOIE COMMUNALE 4 | T32: FR | U32: '21 | V32: '21320 | W32: CREANCEY | X32: CHRISTOPHE DENNIEL | Y32: 87 GRANDE RUE | AA32: FR | AB32: '25 | AC32: '25000 | AD32: BESANCON
B33: =IF(O33="","Frêt",_xlfn.XLOOKUP(O33,Catégories!A:A,Catégories!B:B,"inconnu")) -> Frêt | C33: =RIGHT(LOOKUP(L33,'Recherche tracking'!A:A,'Recherche tracking'!B:B),16) -> 2543814314751261 | D33: 202606 | E33: 51 | F33: 1085442 | G33: '03814314 | H33: '03814314 | I33: CPC | J33: '2543814314751261 | K33: 20260601 | L33: E20260601123359 | N33: 6.8 | O33: RS | P33: 0 | Q33: LARUCHE | R33: VOIE COMMUNALE 4 | T33: FR | U33: '21 | V33: '21320 | W33: CREANCEY | X33: CHRISTOPHE DENNIEL | Y33: 87 GRANDE RUE | AA33: FR | AB33: '25 | AC33: '25000 | AD33: BESANCON
B34: =IF(O34="","Frêt",_xlfn.XLOOKUP(O34,Catégories!A:A,Catégories!B:B,"inconnu")) -> Frêt | C34: =RIGHT(LOOKUP(L34,'Recherche tracking'!A:A,'Recherche tracking'!B:B),16) -> 8043814314751285 | D34: 202606 | E34: 51 | F34: 1085442 | G34: '03814314 | H34: '03814314 | I34: ENV | J34: ' | K34: 20260601 | L34: E20260601123361 | M34: J18 | N34: 6.8 | P34: 5.71 | Q34: LARUCHE | R34: VOIE COMMUNALE 4 | T34: FR | U34: '21 | V34: '21320 | W34: CREANCEY | X34: DELABYE VIRGINIE | Y34: 14 RUE DES VERGEAUX | AA34: FR | AB34: '80 | AC34: '80000 | AD34: AMIENS
B35: =IF(O35="","Frêt",_xlfn.XLOOKUP(O35,Catégories!A:A,Catégories!B:B,"inconnu")) -> Frêt | C35: =RIGHT(LOOKUP(L35,'Recherche tracking'!A:A,'Recherche tracking'!B:B),16) -> 8043814314751285 | D35: 202606 | E35: 51 | F35: 1085442 | G35: '03814314 | H35: '03814314 | I35: COL | J35: '8043814314751285 | K35: 20260601 | L35: E20260601123361 | M35: J18 | N35: 6.8 | P35: 0 | Q35: LARUCHE | R35: VOIE COMMUNALE 4 | T35: FR | U35: '21 | V35: '21320 | W35: CREANCEY | X35: DELABYE VIRGINIE | Y35: 14 RUE DES VERGEAUX | AA35: FR | AB35: '80 | AC35: '80000 | AD35: AMIENS
B36: =IF(O36="","Frêt",_xlfn.XLOOKUP(O36,Catégories!A:A,Catégories!B:B,"inconnu")) -> Frêt | C36: =RIGHT(LOOKUP(L36,'Recherche tracking'!A:A,'Recherche tracking'!B:B),16) -> 8043814314751285 | D36: 202606 | E36: 51 | F36: 1085442 | G36: '03814314 | H36: '03814314 | I36: CPC | J36: '8043814314751285 | K36: 20260601 | L36: E20260601123361 | N36: 6.8 | O36: RS | P36: 0 | Q36: LARUCHE | R36: VOIE COMMUNALE 4 | T36: FR | U36: '21 | V36: '21320 | W36: CREANCEY | X36: DELABYE VIRGINIE | Y36: 14 RUE DES VERGEAUX | AA36: FR | AB36: '80 | AC36: '80000 | AD36: AMIENS
B37: =IF(O37="","Frêt",_xlfn.XLOOKUP(O37,Catégories!A:A,Catégories!B:B,"inconnu")) -> Frêt | C37: =RIGHT(LOOKUP(L37,'Recherche tracking'!A:A,'Recherche tracking'!B:B),16) -> 7143814314751103 | D37: 202606 | E37: 51 | F37: 1085442 | G37: '03814314 | H37: '03814314 | I37: ENV | J37: ' | K37: 20260601 | L37: E20260601123362 | M37: J18 | N37: 2.9 | P37: 4.67 | Q37: LARUCHE | R37: VOIE COMMUNALE 4 | T37: FR | U37: '21 | V37: '21320 | W37: CREANCEY | X37: DELFORGE STEPHANIE | Y37: 43 RUE SIGORGNE | AA37: FR | AB37: '71 | AC37: '71000 | AD37: MACON
B38: =IF(O38="","Frêt",_xlfn.XLOOKUP(O38,Catégories!A:A,Catégories!B:B,"inconnu")) -> Frêt | C38: =RIGHT(LOOKUP(L38,'Recherche tracking'!A:A,'Recherche tracking'!B:B),16) -> 7143814314751103 | D38: 202606 | E38: 51 | F38: 1085442 | G38: '03814314 | H38: '03814314 | I38: COL | J38: '7143814314751103 | K38: 20260601 | L38: E20260601123362 | M38: J18 | N38: 2.9 | P38: 0 | Q38: LARUCHE | R38: VOIE COMMUNALE 4 | T38: FR | U38: '21 | V38: '21320 | W38: CREANCEY | X38: DELFORGE STEPHANIE | Y38: 43 RUE SIGORGNE | AA38: FR | AB38: '71 | AC38: '71000 | AD38: MACON
B39: =IF(O39="","Frêt",_xlfn.XLOOKUP(O39,Catégories!A:A,Catégories!B:B,"inconnu")) -> Frêt | C39: =RIGHT(LOOKUP(L39,'Recherche tracking'!A:A,'Recherche tracking'!B:B),16) -> 7143814314751103 | D39: 202606 | E39: 51 | F39: 1085442 | G39: '03814314 | H39: '03814314 | I39: CPC | J39: '7143814314751103 | K39: 20260601 | L39: E20260601123362 | N39: 2.9 | O39: RS | P39: 0 | Q39: LARUCHE | R39: VOIE COMMUNALE 4 | T39: FR | U39: '21 | V39: '21320 | W39: CREANCEY | X39: DELFORGE STEPHANIE | Y39: 43 RUE SIGORGNE | AA39: FR | AB39: '71 | AC39: '71000 | AD39: MACON
B40: =IF(O40="","Frêt",_xlfn.XLOOKUP(O40,Catégories!A:A,Catégories!B:B,"inconnu")) -> Frêt | C40: =RIGHT(LOOKUP(L40,'Recherche tracking'!A:A,'Recherche tracking'!B:B),16) -> 6343814314751230 | D40: 202606 | E40: 51 | F40: 1085442 | G40: '03814314 | H40: '03814314 | I40: ENV | J40: ' | K40: 20260601 | L40: E20260601123364 | M40: J18 | N40: 2.9 | P40: 4.67 | Q40: LARUCHE | R40: VOIE COMMUNALE 4 | T40: FR | U40: '21 | V40: '21320 | W40: CREANCEY | X40: GUBERT PAULINE | Y40: 7 RUE DES TROENES | AA40: FR | AB40: '63 | AC40: '63500 | AD40: ISSOIRE
...

Sheet TCD
A1: Total | B1: Total | C1: ID | F1: Somme de montant HT | G1: Étiquettes de colonnes | Q1: Poids | R1: Étiquettes de lignes | S1: Colis volumineux | T1: Frêt | U1: Gazole | V1: Zones éloignées | Y1: Étiquettes de lignes | Z1: Moyenne de Frêt
A2: avec GO | B2: hors GO | C2: client | D2: Tracking | E2: Poids | F2: Étiquettes de lignes | G2: Colis volumineux | H2: Frêt | I2: Gazole | J2: Zones éloignées | K2: (vide) | Q2: 0 | U2: 185.85 | Y2: 0
B3: =SUM(G3:H3) -> 0 | E3: =_xlfn.XLOOKUP(F3,'Nb colis et poids'!E:E,'Nb colis et poids'!F:F) -> 0 | F3: (vide) | Q3: 0 | Y3: 0.1 | Z3: 5.11
A4: =ROUND(B4/(SUM(G:H)+SUM(J:J))*SUM(G:J),2) -> 31.17 | B4: =SUM(G4:J4) -> 27.91 | C4: 8640 | D4: =RIGHT(_xlfn.XLOOKUP(F4,'Recherche tracking'!A:A,'Recherche tracking'!B:B),16) -> #N/A | E4: =_xlfn.XLOOKUP(F4,'Nb colis et poids'!E:E,'Nb colis et poids'!F:F) -> 76.9 | F4: 9543814314757247 | H4: 27.91 | M4: 9.5438143e+15 | N4: =LEFT(F4,15)&"0" -> 9543814314757240 | Q4: 33.9 | R4: 117777519613379 | T4: 16.32 | Y4: 0.2 | Z4: 6.11
A5: =ROUND(B5/(SUM(G:H)+SUM(J:J))*SUM(G:J),2) -> 9.57 | B5: =SUM(G5:J5) -> 8.57 | C5: 8640 | D5: =RIGHT(_xlfn.XLOOKUP(F5,'Recherche tracking'!A:A,'Recherche tracking'!B:B),16) -> #N/A | E5: =_xlfn.XLOOKUP(F5,'Nb colis et poids'!E:E,'Nb colis et poids'!F:F) -> 18 | F5: 9543814314756996 | H5: 8.57 | M5: 9.5438143e+15 | N5: =LEFT(F5,15)&"0" -> 9543814314756990 | Q5: 14.9 | R5: 143814314728836 | T5: 8.57 | Y5: 1 | Z5: 4.7633333
A6: =ROUND(B6/(SUM(G:H)+SUM(J:J))*SUM(G:J),2) -> 5.51 | B6: =SUM(G6:J6) -> 4.93 | C6: 3752 | D6: =RIGHT(_xlfn.XLOOKUP(F6,'Recherche tracking'!A:A,'Recherche tracking'!B:B),16) -> #N/A | E6: =_xlfn.XLOOKUP(F6,'Nb colis et poids'!E:E,'Nb colis et poids'!F:F) -> 3.01 | F6: 9543814314755656 | H6: 4.93 | M6: 9.5438143e+15 | N6: =LEFT(F6,15)&"0" -> 9543814314755650 | Q6: 24.5 | R6: 143814314730487 | T6: 11.07 | Y6: 3.7 | Z6: 4.82
A7: =ROUND(B7/(SUM(G:H)+SUM(J:J))*SUM(G:J),2) -> 4.64 | B7: =SUM(G7:J7) -> 4.15 | C7: 9294 | D7: =RIGHT(_xlfn.XLOOKUP(F7,'Recherche tracking'!A:A,'Recherche tracking'!B:B),16) -> #N/A | E7: =_xlfn.XLOOKUP(F7,'Nb colis et poids'!E:E,'Nb colis et poids'!F:F) -> 0.8 | F7: 9543814314754754 | H7: 4.15 | M7: 9.5438143e+15 | N7: =LEFT(F7,15)&"0" -> 9543814314754750 | Q7: 15.6 | R7: 243814314733363 | T7: 8.82 | Y7: 4 | Z7: 4.82
A8: =ROUND(B8/(SUM(G:H)+SUM(J:J))*SUM(G:J),2) -> 4.64 | B8: =SUM(G8:J8) -> 4.15 | C8: 9294 | D8: =RIGHT(_xlfn.XLOOKUP(F8,'Recherche tracking'!A:A,'Recherche tracking'!B:B),16) -> #N/A | E8: =_xlfn.XLOOKUP(F8,'Nb colis et poids'!E:E,'Nb colis et poids'!F:F) -> 0.8 | F8: 9524024014087290 | H8: 4.15 | M8: 9.524024e+15 | N8: =LEFT(F8,15)&"0" -> 9524024014087290 | Q8: 32 | R8: 343814314731826 | T8: 14.82 | Y8: 6.5 | Z8: 5.57
A9: =ROUND(B9/(SUM(G:H)+SUM(J:J))*SUM(G:J),2) -> 15.33 | B9: =SUM(G9:J9) -> 13.73 | C9: 8640 | D9: =RIGHT(_xlfn.XLOOKUP(F9,'Recherche tracking'!A:A,'Recherche tracking'!B:B),16) -> #N/A | E9: =_xlfn.XLOOKUP(F9,'Nb colis et poids'!E:E,'Nb colis et poids'!F:F) -> 33.9 | F9: 9443814314757475 | H9: 13.73 | M9: 9.4438143e+15 | N9: =LEFT(F9,15)&"0" -> 9443814314757470 | Q9: 16.2 | R9: 643814314730212 | T9: 9.07 | Y9: 7.1 | Z9: 6.82
A10: =ROUND(B10/(SUM(G:H)+SUM(J:J))*SUM(G:J),2) -> 4.64 | B10: =SUM(G10:J10) -> 4.15 | C10: 3752 | D10: =RIGHT(_xlfn.XLOOKUP(F10,'Recherche tracking'!A:A,'Recherche tracking'!B:B),16) -> #N/A | E10: =_xlfn.XLOOKUP(F10,'Nb colis et poids'!E:E,'Nb colis et poids'!F:F) -> 0.8 | F10: 9443814314756452 | H10: 4.15 | M10: 9.4438143e+15 | N10: =LEFT(F10,15)&"0" -> 9443814314756450 | Q10: 15 | R10: 643814314731340 | T10: 8.57 | Y10: 7.2 | Z10: 6.82
A11: =ROUND(B11/(SUM(G:H)+SUM(J:J))*SUM(G:J),2) -> 4.64 | B11: =SUM(G11:J11) -> 4.15 | C11: 3752 | D11: =RIGHT(_xlfn.XLOOKUP(F11,'Recherche tracking'!A:A,'Recherche tracking'!B:B),16) -> #N/A | E11: =_xlfn.XLOOKUP(F11,'Nb colis et poids'!E:E,'Nb colis et poids'!F:F) -> 0.8 | F11: 9443814314756240 | H11: 4.15 | M11: 9.4438143e+15 | N11: =LEFT(F11,15)&"0" -> 9443814314756240 | Q11: 16.4 | R11: 643814314733638 | T11: 9.07 | Y11: 7.9 | Z11: 5.82
A12: =ROUND(B12/(SUM(G:H)+SUM(J:J))*SUM(G:J),2) -> 4.64 | B12: =SUM(G12:J12) -> 4.15 | C12: 3752 | D12: =RIGHT(_xlfn.XLOOKUP(F12,'Recherche tracking'!A:A,'Recherche tracking'!B:B),16) -> #N/A | E12: =_xlfn.XLOOKUP(F12,'Nb colis et poids'!E:E,'Nb colis et poids'!F:F) -> 0.8 | F12: 9443814314756072 | H12: 4.15 | M12: 9.4438143e+15 | N12: =LEFT(F12,15)&"0" -> 9443814314756070 | Q12: 13.2 | R12: 843814314728653 | T12: 7.32 | Y12: 8.2 | Z12: 6.07
A13: =ROUND(B13/(SUM(G:H)+SUM(J:J))*SUM(G:J),2) -> 5.22 | B13: =SUM(G13:J13) -> 4.67 | C13: 3752 | D13: =RIGHT(_xlfn.XLOOKUP(F13,'Recherche tracking'!A:A,'Recherche tracking'!B:B),16) -> #N/A | E13: =_xlfn.XLOOKUP(F13,'Nb colis et poids'!E:E,'Nb colis et poids'!F:F) -> 2.84 | F13: 9443814314755728 | H13: 4.67 | M13: 9.4438143e+15 | N13: =LEFT(F13,15)&"0" -> 9443814314755720 | Q13: 26.5 | R13: 843814314729019 | T13: 13.57 | Y13: 8.6 | Z13: 7.75
A14: =ROUND(B14/(SUM(G:H)+SUM(J:J))*SUM(G:J),2) -> 5.51 | B14: =SUM(G14:J14) -> 4.93 | C14: 9351 | D14: =RIGHT(_xlfn.XLOOKUP(F14,'Recherche tracking'!A:A,'Recherche tracking'!B:B),16) -> #N/A | E14: =_xlfn.XLOOKUP(F14,'Nb colis et poids'!E:E,'Nb colis et poids'!F:F) -> 3.2 | F14: 9443814314754803 | H14: 4.93 | M14: 9.4438143e+15 | N14: =LEFT(F14,15)&"0" -> 9443814314754800 | Q14: 34 | R14: 943814314731934 | T14: 25.32 | Y14: 8.7 | Z14: 6.07
A15: =ROUND(B15/(SUM(G:H)+SUM(J:J))*SUM(G:J),2) -> 5.51 | B15: =SUM(G15:J15) -> 4.93 | C15: 9351 | D15: =RIGHT(_xlfn.XLOOKUP(F15,'Recherche tracking'!A:A,'Recherche tracking'!B:B),16) -> #N/A | E15: =_xlfn.XLOOKUP(F15,'Nb colis et poids'!E:E,'Nb colis et poids'!F:F) -> 3.6 | F15: 9443814314754050 | H15: 4.93 | M15: 9.4438143e+15 | N15: =LEFT(F15,15)&"0" -> 9443814314754050 | Q15: 25.5 | R15: 943814314732630 | T15: 13.32 | Y15: 9.9 | Z15: 9.08
... A48: =ROUND(B48/(SUM(G:H)+SUM(J:J))*SUM(G:J),2) -> 7.83 | B48: =SUM(G48:J48) -> 7.01 | C48: 8656 | D48: =RIGHT(_xlfn.XLOOKUP(F48,'Recherche tracking'!A:A,'Recherche tracking'!B:B),16) -> #N/A | E48: =_xlfn.XLOOKUP(F48,'Nb colis et poids'!E:E,'Nb colis et poids'!F:F) -> 11.52 | F48: 9243814314751971 | H48: 7.01 | M48: 9.2438143e+15 | N48: =LEFT(F48,15)&"0" -> 9243814314751970 | Q48: 8.6 | R48: 2.1838143e+15 | T48: 7.75 | Y48: 38.7 | Z48: 15.57
A49: =ROUND(B49/(SUM(G:H)+SUM(J:J))*SUM(G:J),2) -> 6.09 | B49: =SUM(G49:J49) -> 5.45 | C49: 9351 | D49: =RIGHT(_xlfn.XLOOKUP(F49,'Recherche tracking'!A:A,'Recherche tracking'!B:B),16) -> #N/A | E49: =_xlfn.XLOOKUP(F49,'Nb colis et poids'!E:E,'Nb colis et poids'!F:F) -> 5.68 | F49: 9243814314751959 | H49: 5.45 | M49: 9.2438143e+15 | N49: =LEFT(F49,15)&"0" -> 9243814314751950 | Q49: 0.2 | R49: 2.1838143e+15 | T49: 6.11 | Y49: (vide)
A50: =ROUND(B50/(SUM(G:H)+SUM(J:J))*SUM(G:J),2) -> 6.38 | B50: =SUM(G50:J50) -> 5.71 | C50: 8041 | D50: =RIGHT(_xlfn.XLOOKUP(F50,'Recherche tracking'!A:A,'Recherche tracking'!B:B),16) -> #N/A | E50: =_xlfn.XLOOKUP(F50,'Nb colis et poids'!E:E,'Nb colis et poids'!F:F) -> 6.8 | F50: 9243814314751395 | H50: 5.71 | M50: 9.2438143e+15 | N50: =LEFT(F50,15)&"0" -> 9243814314751390 | Q50: 9.9 | R50: 2.1838143e+15 | T50: 9.08 | Y50: 5.7 | Z50: 6.32
A51: =ROUND(B51/(SUM(G:H)+SUM(J:J))*SUM(G:J),2) -> 5.8 | B51: =SUM(G51:J51) -> 5.19 | C51: 9351 | D51: =RIGHT(_xlfn.XLOOKUP(F51,'Recherche tracking'!A:A,'Recherche tracking'!B:B),16) -> #N/A | E51: =_xlfn.XLOOKUP(F51,'Nb colis et poids'!E:E,'Nb colis et poids'!F:F) -> 4.01 | F51: 9143814314754974 | H51: 5.19 | M51: 9.1438143e+15 | N51: =LEFT(F51,15)&"0" -> 9143814314754970 | Q51: 5 | R51: 2.2438143e+15 | T51: 6.43 | Y51: 1.9 | Z51: 4.32
A52: =ROUND(B52/(SUM(G:H)+SUM(J:J))*SUM(G:J),2) -> 7.83 | B52: =SUM(G52:J52) -> 7.01 | C52: 8640 | D52: =RIGHT(_xlfn.XLOOKUP(F52,'Recherche tracking'!A:A,'Recherche tracking'!B:B),16) -> #N/A | E52: =_xlfn.XLOOKUP(F52,'Nb colis et poids'!E:E,'Nb colis et poids'!F:F) -> 11.69 | F52: 9143814314754330 | H52: 7.01 | M52: 9.1438143e+15 | N52: =LEFT(F52,15)&"0" -> 9143814314754330 | Q52: 14.4 | R52: 2.2438143e+15 | T52: 8.57 | Y52: 24.3 | Z52: 12.07
A53: =ROUND(B53/(SUM(G:H)+SUM(J:J))*SUM(G:J),2) -> 12.43 | B53: =SUM(G53:J53) -> 11.13 | C53: 8640 | D53: =RIGHT(_xlfn.XLOOKUP(F53,'Recherche tracking'!A:A,'Recherche tracking'!B:B),16) -> #N/A | E53: =_xlfn.XLOOKUP(F53,'Nb colis et poids'!E:E,'Nb colis et poids'!F:F) -> 23.72 | F53: 9143814314754323 | H53: 11.13 | M53: 9.1438143e+15 | N53: =LEFT(F53,15)&"0" -> 9143814314754320 | Q53: 14 | R53: 2.3438143e+15 | T53: 7.32 | Y53: 35.2 | Z53: 14.82
A54: =ROUND(B54/(SUM(G:H)+SUM(J:J))*SUM(G:J),2) -> 15.33 | B54: =SUM(G54:J54) -> 13.73 | C54: 8041 | D54: =RIGHT(_xlfn.XLOOKUP(F54,'Recherche tracking'!A:A,'Recherche tracking'!B:B),16) -> #N/A | E54: =_xlfn.XLOOKUP(F54,'Nb colis et poids'!E:E,'Nb colis et poids'!F:F) -> 33.9 | F54: 9143814314752795 | H54: 13.73 | M54: 9.1438143e+15 | N54: =LEFT(F54,15)&"0" -> 9143814314752790 | Q54: 15.4 | R54: 2.4438143e+15 | T54: 8.82 | Y54: 5 | Z54: 6.43
A55: =ROUND(B55/(SUM(G:H)+SUM(J:J))*SUM(G:J),2) -> 5.22 | B55: =SUM(G55:J55) -> 4.67 | C55: 9351 | D55: =RIGHT(_xlfn.XLOOKUP(F55,'Recherche tracking'!A:A,'Recherche tracking'!B:B),16) -> #N/A | E55: =_xlfn.XLOOKUP(F55,'Nb colis et poids'!E:E,'Nb colis et poids'!F:F) -> 2.9 | F55: 9143814314751645 | H55: 4.67 | M55: 9.1438143e+15 | N55: =LEFT(F55,15)&"0" -> 9143814314751640 | Q55: 15.5 | R55: 2.4438143e+15 | T55: 8.82 | Y55: 43.8 | Z55: 15.82
A56: =ROUND(B56/(SUM(G:H)+SUM(J:J))*SUM(G:J),2) -> 4.64 | B56: =SUM(G56:J56) -> 4.15 | C56: 3752 | D56: =RIGHT(_xlfn.XLOOKUP(F56,'Recherche tracking'!A:A,'Recherche tracking'!B:B),16) -> #N/A | E56: =_xlfn.XLOOKUP(F56,'Nb colis et poids'!E:E,'Nb colis et poids'!F:F) -> 0.8 | F56: 8843814314756440 | H56: 4.15 | M56: 8.8438143e+15 | N56: =LEFT(F56,15)&"0" -> 8843814314756440 | Q56: 33.7 | R56: 2.5438143e+15 | T56: 14.32 | Y56: 11.6 | Z56: 7.82
A57: =ROUND(B57/(SUM(G:H)+SUM(J:J))*SUM(G:J),2) -> 4.64 | B57: =SUM(G57:J57) -> 4.15 | C57: 3752 | D57: =RIGHT(_xlfn.XLOOKUP(F57,'Recherche tracking'!A:A,'Recherche tracking'!B:B),16) -> #N/A | E57: =_xlfn.XLOOKUP(F57,'Nb colis et poids'!E:E,'Nb colis et poids'!F:F) -> 0.8 | F57: 8743814314756165 | H57: 4.15 | M57: 8.7438143e+15 | N57: =LEFT(F57,15)&"0" -> 8743814314756160 | Q57: 11 | R57: 2.7438143e+15 | T57: 7.57 | Y57: Total général | Z57: 9.0404167
A58: =ROUND(B58/(SUM(G:H)+SUM(J:J))*SUM(G:J),2) -> 4.64 | B58: =SUM(G58:J58) -> 4.15 | C58: 3752 | D58: =RIGHT(_xlfn.XLOOKUP(F58,'Recherche tracking'!A:A,'Recherche tracking'!B:B),16) -> #N/A | E58: =_xlfn.XLOOKUP(F58,'Nb colis et poids'!E:E,'Nb colis et poids'!F:F) -> 0.8 | F58: 8643814314755525 | H58: 4.15 | M58: 8.6438143e+15 | N58: =LEFT(F58,15)&"0" -> 8643814314755520 | Q58: 15.9 | R58: 2.824264e+15 | T58: 8.82
A59: =ROUND(B59/(SUM(G:H)+SUM(J:J))*SUM(G:J),2) -> 5.51 | B59: =SUM(G59:J59) -> 4.93 | C59: 9351 | D59: =RIGHT(_xlfn.XLOOKUP(F59,'Recherche tracking'!A:A,'Recherche tracking'!B:B),16) -> #N/A | E59: =_xlfn.XLOOKUP(F59,'Nb colis et poids'!E:E,'Nb colis et poids'!F:F) -> 3.6 | F59: 8643814314754877 | H59: 4.93 | M59: 8.6438143e+15 | N59: =LEFT(F59,15)&"0" -> 8643814314754870 | Q59: 15.5 | R59: 2.8438143e+15 | T59: 8.82
A60: =ROUND(B60/(SUM(G:H)+SUM(J:J))*SUM(G:J),2) -> 5.8 | B60: =SUM(G60:J60) -> 5.19 | C60: 7254 | D60: =RIGHT(_xlfn.XLOOKUP(F60,'Recherche tracking'!A:A,'Recherche tracking'!B:B),16) -> #N/A | E60: =_xlfn.XLOOKUP(F60,'Nb colis et poids'!E:E,'Nb colis et poids'!F:F) -> 4.4 | F60: 8643814314752353 | H60: 5.19 | M60: 8.6438143e+15 | N60: =LEFT(F60,15)&"0" -> 8643814314752350 | Q60: 10.6 | R60: 2.8438143e+15 | T60: 7.57
A61: =ROUND(B61/(SUM(G:H)+SUM(J:J))*SUM(G:J),2) -> 11.27 | B61: =SUM(G61:J61) -> 10.09 | C61: 7254 | D61: =RIGHT(_xlfn.XLOOKUP(F61,'Recherche tracking'!A:A,'Recherche tracking'!B:B),16) -> #N/A | E61: =_xlfn.XLOOKUP(F61,'Nb colis et poids'!E:E,'Nb colis et poids'!F:F) -> 19.3 | F61: 8643814314752042 | H61: 10.09 | M61: 8.6438143e+15 | N61: =LEFT(F61,15)&"0" -> 8643814314752040 | Q61: 15.6 | R61: 2.8438143e+15 | T61: 8.82
A62: =ROUND(B62/(SUM(G:H)+SUM(J:J))*SUM(G:J),2) -> 5.22 | B62: =SUM(G62:J62) -> 4.67 | C62: 9351 | D62: =RIGHT(_xlfn.XLOOKUP(F62,'Recherche tracking'!A:A,'Recherche tracking'!B:B),16) -> #N/A | E62: =_xlfn.XLOOKUP(F62,'Nb colis et poids'!E:E,'Nb colis et poids'!F:F) -> 2.9 | F62: 8543814314754765 | H62: 4.67 | M62: 8.5438143e+15 | N62: =LEFT(F62,15)&"0" -> 8543814314754760 | Q62: 1 | R62: 2.9438143e+15 | T62: 4.07
A63: =ROUND(B63/(SUM(G:H)+SUM(J:J))*SUM(G:J),2) -> 12.14 | B63: =SUM(G63:J63) -> 10.87 | C63: 7254 | D63: =RIGHT(_xlfn.XLOOKUP(F63,'Recherche tracking'!A:A,'Recherche tracking'!B:B),16) -> #N/A | E63: =_xlfn.XLOOKUP(F63,'Nb colis et poids'!E:E,'Nb colis et poids'!F:F) -> 22.9 | F63: 8543814314754362 | H63: 10.87 | M63: 8.5438143e+15 | N63: =LEFT(F63,15)&"0" -> 8543814314754360 | Q63: 3.7 | R63: 2.9438143e+15 | T63: 4.82
A64: =ROUND(B64/(SUM(G:H)+SUM(J:J))*SUM(G:J),2) -> 4.64 | B64: =SUM(G64:J64) -> 4.15 | C64: 9294 | D64: =RIGHT(_xlfn.XLOOKUP(F64,'Recherche tracking'!A:A,'Recherche tracking'!B:B),16) -> #N/A | E64: =_xlfn.XLOOKUP(F64,'Nb colis et poids'!E:E,'Nb colis et poids'!F:F) -> 0.5 | F64: 8543814314753978 | H64: 4.15 | M64: 8.5438143e+15 | N64: =LEFT(F64,15)&"0" -> 8543814314753970 | Q64: 13 | R64: 2.9438143e+15 | T64: 8.07
A65: =ROUND(B65/(SUM(G:H)+SUM(J:J))*SUM(G:J),2) -> 19.07 | B65: =SUM(G65:J65) -> 17.07 | C65: 7254 | D65: =RIGHT(_xlfn.XLOOKUP(F65,'Recherche tracking'!A:A,'Recherche tracking'!B:B),16) -> #N/A | E65: =_xlfn.XLOOKUP(F65,'Nb colis et poids'!E:E,'Nb colis et poids'!F:F) -> 42.4 | F65: 8543814314753828 | H65: 17.07 | M65: 8.5438143e+15 | N65: =LEFT(F65,15)&"0" -> 8543814314753820 | Q65: 4 | R65: 2.9438143e+15 | T65: 4.82
A66: =ROUND(B66/(SUM(G:H)+SUM(J:J))*SUM(G:J),2) -> 5.51 | B66: =SUM(G66:J66) -> 4.93 | C66: 9351 | D66: =RIGHT(_xlfn.XLOOKUP(F66,'Recherche tracking'!A:A,'Recherche tracking'!B:B),16) -> #N/A | E66: =_xlfn.XLOOKUP(F66,'Nb colis et poids'!E:E,'Nb colis et poids'!F:F) -> 3.2 | F66: 8543814314751258 | H66: 4.93 | M66: 8.5438143e+15 | N66: =LEFT(F66,15)&"0" -> 8543814314751250 | Q66: 15.4 | R66: 2.9438143e+15 | T66: 8.82
A67: =ROUND(B67/(SUM(G:H)+SUM(J:J))*SUM(G:J),2) -> 5.51 | B67: =SUM(G67:J67) -> 4.93 | C67: 7254 | D67: =RIGHT(_xlfn.XLOOKUP(F67,'Recherche tracking'!A:A,'Recherche tracking'!B:B),16) -> #N/A | E67: =_xlfn.XLOOKUP(F67,'Nb colis et poids'!E:E,'Nb colis et poids'!F:F) -> 3.01 | F67: 8443814314756019 | H67: 4.93 | M67: 8.4438143e+15 | N67: =LEFT(F67,15)&"0" -> 8443814314756010 | Q67: 14.5 | R67: 2.9438143e+15 | T67: 8.57
A68: =ROUND(B68/(SUM(G:H)+SUM(J:J))*SUM(G:J),2) -> 5.51 | B68: =SUM(G68:J68) -> 4.93 | C68: 3752 | D68: =RIGHT(_xlfn.XLOOKUP(F68,'Recherche tracking'!A:A,'Recherche tracking'!B:B),16) -> #N/A | E68: =_xlfn.XLOOKUP(F68,'Nb colis et poids'!E:E,'Nb colis et poids'!F:F) -> 3.01 | F68: 8443814314755660 | H68: 4.93 | M68: 8.4438143e+15 | N68: =LEFT(F68,15)&"0" -> 8443814314755660 | Q68: 43.8 | R68: 2.9438143e+15 | T68: 15.82
A69: =ROUND(B69/(SUM(G:H)+SUM(J:J))*SUM(G:J),2) -> 5.51 | B69: =SUM(G69:J69) -> 4.93 | C69: 9351 | D69: =RIGHT(_xlfn.XLOOKUP(F69,'Recherche tracking'!A:A,'Recherche tracking'!B:B),16) -> #N/A | E69: =_xlfn.XLOOKUP(F69,'Nb colis et poids'!E:E,'Nb colis et poids'!F:F) -> 3.84 | F69: 8443814314754797 | H69: 4.93 | M69: 8.4438143e+15 | N69: =LEFT(F69,15)&"0" -> 8443814314754790 | Q69: 11.3 | R69: 3.0438143e+15 | T69: 7.82
... A75: =ROUND(B75/(SUM(G:H)+SUM(J:J))*SUM(G:J),2) -> 8.7 | B75: =SUM(G75:J75) -> 7.79 | C75: 8656 | D75: =RIGHT(_xlfn.XLOOKUP(F75,'Recherche tracking'!A:A,'Recherche tracking'!B:B),16) -> #N/A | E75: =_xlfn.XLOOKUP(F75,'Nb colis et poids'!E:E,'Nb colis et poids'!F:F) -> 14.5 | F75: 8343814314753224 | H75: 7.79 | M75: 8.3438143e+15 | N75: =LEFT(F75,15)&"0" -> 8343814314753220 | Q75: 14.4 | R75: 3.1438143e+15 | T75: 7.57
A76: =ROUND(B76/(SUM(G:H)+SUM(J:J))*SUM(G:J),2) -> 6.09 | B76: =SUM(G76:J76) -> 5.45 | C76: 7254 | D76: =RIGHT(_xlfn.XLOOKUP(F76,'Recherche tracking'!A:A,'Recherche tracking'!B:B),16) -> #N/A | E76: =_xlfn.XLOOKUP(F76,'Nb colis et poids'!E:E,'Nb colis et poids'!F:F) -> 5.1 | F76: 8343814314752086 | H76: 5.45 | M76: 8.3438143e+15 | N76: =LEFT(F76,15)&"0" -> 8343814314752080
A77: =ROUND(B77/(SUM(G:H)+SUM(J:J))*SUM(G:J),2) -> 6.38 | B77: =SUM(G77:J77) -> 5.71 | C77: 9351 | D77: =RIGHT(_xlfn.XLOOKUP(F77,'Recherche tracking'!A:A,'Recherche tracking'!B:B),16) -> #N/A | E77: =_xlfn.XLOOKUP(F77,'Nb colis et poids'!E:E,'Nb colis et poids'!F:F) -> 6.2 | F77: 8243814314753215 | H77: 5.71 | M77: 8.2438143e+15 | N77: =LEFT(F77,15)&"0" -> 8243814314753210
...

Sheet Bilan clients
A3: Étiquettes de lignes | B3: Somme de Total
A4: 3752 | B4: 768.62
A5: 4565 | B5: 243.27
A6: 6930 | B6: 28.09
A7: 7027 | B7: 18.27
A8: 7254 | B8: 926.09
A9: 8041 | B9: 347.3
A10: 8640 | B10: 204.83
A11: 8656 | B11: 131.75
A12: 9169 | B12: 6.96
A13: 9294 | B13: 141.81
A14: 9351 | B14: 1155.62
A15: Avoir | B15: 65.98
A16: client | B16: 0
A17: (vide) | B17: 471.91
A18: Total général | B18: 4510.5

Sheet Import csv
A1: Transporteur | B1: Date validité tarif | C1: Réf.1 | D1: Réf. 2 | E1: Id client | F1: N° Tracking | G1: Nom | H1: E / P | I1: Pays | J1: Zone | K1: Nbr Colis | L1: Poids | M1: mode envoi | N1: TVA | O1: Droits et taxes | P1: Assurance | Q1: Zones éloignées | R1: Colis volumineux | S1: Adresses | T1: Frêt | U1: plus-value BtoC | V1: Gazole | W1: Nb Colis | Y1: Attention aux poids sup > 15 kg avec nb colis = 1
A2: TNT | B2: 46174 | F2: =TCD!F3 -> (vide) | H2: E | I2: FR | J2: France | K2: {=IF(COUNTIF('Nb colis et poids'!A:A,F2)=0,1,LOOKUP(F2,'Nb colis et poids'!A:A,'Nb colis et poids'!B:B+1))} -> 1 | L2: =TCD!E3 -> 0 | M2: ST | N2: 0.2 | Q2: =IF(TCD!J3="","",TCD!J3) | R2: =IF(TCD!G3="","",TCD!G3) | T2: =TCD!H3 -> 0
A3: =A2 -> TNT | B3: =B2 -> 46174 | F3: =TCD!F4 -> 9543814314757247 | H3: =H2 -> E | I3: =I2 -> FR | J3: =J2 -> France | K3: {=IF(COUNTIF('Nb colis et poids'!A:A,F3)=0,1,LOOKUP(F3,'Nb colis et poids'!A:A,'Nb colis et poids'!B:B+1))} -> 5 | L3: =TCD!E4 -> 76.9 | M3: =M2 -> ST | N3: =N2 -> 0.2 | Q3: =IF(TCD!J4="","",TCD!J4) | R3: =IF(TCD!G4="","",TCD!G4) | T3: =TCD!H4 -> 27.91
A4: =A3 -> TNT | B4: =B3 -> 46174 | F4: =TCD!F5 -> 9543814314756996 | H4: =H3 -> E | I4: =I3 -> FR | J4: =J3 -> France | K4: {=IF(COUNTIF('Nb colis et poids'!A:A,F4)=0,1,LOOKUP(F4,'Nb colis et poids'!A:A,'Nb colis et poids'!B:B+1))} -> 1 | L4: =TCD!E5 -> 18 | M4: =M3 -> ST | N4: =N3 -> 0.2 | Q4: =IF(TCD!J5="","",TCD!J5) | R4: =IF(TCD!G5="","",TCD!G5) | T4: =TCD!H5 -> 8.57
A5: =A4 -> TNT | B5: =B4 -> 46174 | F5: =TCD!F6 -> 9543814314755656 | H5: =H4 -> E | I5: =I4 -> FR | J5: =J4 -> France | K5: {=IF(COUNTIF('Nb colis et poids'!A:A,F5)=0,1,LOOKUP(F5,'Nb colis et poids'!A:A,'Nb colis et poids'!B:B+1))} -> 1 | L5: =TCD!E6 -> 3.01 | M5: =M4 -> ST | N5: =N4 -> 0.2 | Q5: =IF(TCD!J6="","",TCD!J6) | R5: =IF(TCD!G6="","",TCD!G6) | T5: =TCD!H6 -> 4.93
A6: =A5 -> TNT | B6: =B5 -> 46174 | F6: =TCD!F7 -> 9543814314754754 | H6: =H5 -> E | I6: =I5 -> FR | J6: =J5 -> France | K6: {=IF(COUNTIF('Nb colis et poids'!A:A,F6)=0,1,LOOKUP(F6,'Nb colis et poids'!A:A,'Nb colis et poids'!B:B+1))} -> 1 | L6: =TCD!E7 -> 0.8 | M6: =M5 -> ST | N6: =N5 -> 0.2 | Q6: =IF(TCD!J7="","",TCD!J7) | R6: =IF(TCD!G7="","",TCD!G7) | T6: =TCD!H7 -> 4.15
A7: =A6 -> TNT | B7: =B6 -> 46174 | F7: =TCD!F8 -> 9524024014087290 | H7: =H6 -> E | I7: =I6 -> FR | J7: =J6 -> France | K7: {=IF(COUNTIF('Nb colis et poids'!A:A,F7)=0,1,LOOKUP(F7,'Nb colis et poids'!A:A,'Nb colis et poids'!B:B+1))} -> 1 | L7: =TCD!E8 -> 0.8 | M7: =M6 -> ST | N7: =N6 -> 0.2 | Q7: =IF(TCD!J8="","",TCD!J8) | R7: =IF(TCD!G8="","",TCD!G8) | T7: =TCD!H8 -> 4.15
A8: =A7 -> TNT | B8: =B7 -> 46174 | F8: =TCD!F9 -> 9443814314757475 | H8: =H7 -> E | I8: =I7 -> FR | J8: =J7 -> France | K8: {=IF(COUNTIF('Nb colis et poids'!A:A,F8)=0,1,LOOKUP(F8,'Nb colis et poids'!A:A,'Nb colis et poids'!B:B+1))} -> 2 | L8: =TCD!E9 -> 33.9 | M8: =M7 -> ST | N8: =N7 -> 0.2 | Q8: =IF(TCD!J9="","",TCD!J9) | R8: =IF(TCD!G9="","",TCD!G9) | T8: =TCD!H9 -> 13.73
A9: =A8 -> TNT | B9: =B8 -> 46174 | F9: =TCD!F10 -> 9443814314756452 | H9: =H8 -> E | I9: =I8 -> FR | J9: =J8 -> France | K9: {=IF(COUNTIF('Nb colis et poids'!A:A,F9)=0,1,LOOKUP(F9,'Nb colis et poids'!A:A,'Nb colis et poids'!B:B+1))} -> 1 | L9: =TCD!E10 -> 0.8 | M9: =M8 -> ST | N9: =N8 -> 0.2 | Q9: =IF(TCD!J10="","",TCD!J10) | R9: =IF(TCD!G10="","",TCD!G10) | T9: =TCD!H10 -> 4.15
A10: =A9 -> TNT | B10: =B9 -> 46174 | F10: =TCD!F11 -> 9443814314756240 | H10: =H9 -> E | I10: =I9 -> FR | J10: =J9 -> France | K10: {=IF(COUNTIF('Nb colis et poids'!A:A,F10)=0,1,LOOKUP(F10,'Nb colis et poids'!A:A,'Nb colis et poids'!B:B+1))} -> 1 | L10: =TCD!E11 -> 0.8 | M10: =M9 -> ST | N10: =N9 -> 0.2 | Q10: =IF(TCD!J11="","",TCD!J11) | R10: =IF(TCD!G11="","",TCD!G11) | T10: =TCD!H11 -> 4.15
A11: =A10 -> TNT | B11: =B10 -> 46174 | F11: =TCD!F12 -> 9443814314756072 | H11: =H10 -> E | I11: =I10 -> FR | J11: =J10 -> France | K11: {=IF(COUNTIF('Nb colis et poids'!A:A,F11)=0,1,LOOKUP(F11,'Nb colis et poids'!A:A,'Nb colis et poids'!B:B+1))} -> 1 | L11: =TCD!E12 -> 0.8 | M11: =M10 -> ST | N11: =N10 -> 0.2 | Q11: =IF(TCD!J12="","",TCD!J12) | R11: =IF(TCD!G12="","",TCD!G12) | T11: =TCD!H12 -> 4.15
A12: =A11 -> TNT | B12: =B11 -> 46174 | F12: =TCD!F13 -> 9443814314755728 | H12: =H11 -> E | I12: =I11 -> FR | J12: =J11 -> France | K12: {=IF(COUNTIF('Nb colis et poids'!A:A,F12)=0,1,LOOKUP(F12,'Nb colis et poids'!A:A,'Nb colis et poids'!B:B+1))} -> 1 | L12: =TCD!E13 -> 2.84 | M12: =M11 -> ST | N12: =N11 -> 0.2 | Q12: =IF(TCD!J13="","",TCD!J13) | R12: =IF(TCD!G13="","",TCD!G13) | T12: =TCD!H13 -> 4.67
A13: =A12 -> TNT | B13: =B12 -> 46174 | F13: =TCD!F14 -> 9443814314754803 | H13: =H12 -> E | I13: =I12 -> FR | J13: =J12 -> France | K13: {=IF(COUNTIF('Nb colis et poids'!A:A,F13)=0,1,LOOKUP(F13,'Nb colis et poids'!A:A,'Nb colis et poids'!B:B+1))} -> 1 | L13: =TCD!E14 -> 3.2 | M13: =M12 -> ST | N13: =N12 -> 0.2 | Q13: =IF(TCD!J14="","",TCD!J14) | R13: =IF(TCD!G14="","",TCD!G14) | T13: =TCD!H14 -> 4.93
A14: =A13 -> TNT | B14: =B13 -> 46174 | F14: =TCD!F15 -> 9443814314754050 | H14: =H13 -> E | I14: =I13 -> FR | J14: =J13 -> France | K14: {=IF(COUNTIF('Nb colis et poids'!A:A,F14)=0,1,LOOKUP(F14,'Nb colis et poids'!A:A,'Nb colis et poids'!B:B+1))} -> 1 | L14: =TCD!E15 -> 3.6 | M14: =M13 -> ST | N14: =N13 -> 0.2 | Q14: =IF(TCD!J15="","",TCD!J15) | R14: =IF(TCD!G15="","",TCD!G15) | T14: =TCD!H15 -> 4.93
... A515: =A514 -> TNT | B515: =B514 -> 46174 | F515: =TCD!F516 -> 0143814314751704 | H515: =H514 -> E | I515: =I514 -> FR | J515: =J514 -> France | K515: {=IF(COUNTIF('Nb colis et poids'!A:A,F515)=0,1,LOOKUP(F515,'Nb colis et poids'!A:A,'Nb colis et poids'!B:B+1))} -> 1 | L515: =TCD!E516 -> 1.34 | M515: =M514 -> ST | N515: =N514 -> 0.2 | Q515: =IF(TCD!J516="","",TCD!J516) | R515: =IF(TCD!G516="","",TCD!G516) | T515: =TCD!H516 -> 4.41

Sheet Demande d'avoir
A1: Trackings | B1: Raison | C1: Montant | D1: Suivi
A2: 2183814314002910 | B2: impossible d'identifier le client | C2: 4.15
A3: 2183814314003016 | B3: impossible d'identifier le client | C3: 4.15
A4: 2183814314003000 | B4: impossible d'identifier le client | C4: 4.15
A5: 2183814314002995 | B5: impossible d'identifier le client | C5: 4.15
A6: 1424014009525861. | B6: impossible d'identifier le client aucun suivis | C6: 14.25
A7: 2183814314003195 | B7: impossible d'identifier le client | C7: 14.13
A8: 2183814314003143. | B8: impossible d'identifier le client | C8: 4.41
A9: 2183814314003137. | B9: impossible d'identifier le client | C9: 4.15
A10: 2183814314003125. | B10: impossible d'identifier le client | C10: 8.53
A11: 2183814314003108. | B11: impossible d'identifier le client | C11: 4.15
A12: 2183814314003097 | B12: impossible d'identifier le client | C12: 11.31
A13: 2183814314003051. | B13: impossible d'identifier le client | C13: 6.15
A14: 2183814314003022 | B14: impossible d'identifier le client | C14: 6.23
