Workbook

Sheet PA GLS
A1: 0.5 | B1: 3.77
A2: 1 | B2: 4.1
A3: 2 | B3: 4.42
A4: 3 | B4: 4.74
A5: 4 | B5: 5.3
A6: 5 | B6: 5.86
A7: 6 | B7: 6.42
A8: 7 | B8: 6.98
A9: 8 | B9: 7.61
A10: 9 | B10: 8.26
A11: 10 | B11: 8.89
A12: 11 | B12: 9.53
... A31: 30 | B31: 28.59

Sheet Zoning
A1: Pays | B1: Zone | C1: TVA
A2: AD | B2: 2 | C2: 0.2
A3: AT | B3: 3 | C3: 0.2
A4: BE | B4: 1 | C4: 0.2
A5: BG | B5: 4 | C5: 0.2
A6: CH | B6: 3 | C6: 0
A7: CY | B7: 5 | C7: 0.2
A8: CZ | B8: 2 | C8: 0.2
A9: DE | B9: 1 | C9: 0.2
A10: DK | B10: 2 | C10: 0.2
A11: EE | B11: 4 | C11: 0.2
A12: ES | B12: 2 | C12: 0.2
A13: FI | B13: 4 | C13: 0.2
A14: FR | B14: France | C14: 0.2
A15: GB | B15: 3 | C15: 0.2
A16: GI | B16: 2 | C16: 0.2
A17: GR | B17: 5 | C17: 0.2
A18: HR | B18: 4 | C18: 0.2
A19: HU | B19: 2 | C19: 0.2
A20: IE | B20: 4 | C20: 0.2
A21: IT | B21: 2 | C21: 0.2
A22: LI | B22: 3 | C22: 0.2
A23: LU | B23: 1 | C23: 0.2
A24: LT | B24: 4 | C24: 0.2
A25: LV | B25: 4 | C25: 0.2
A26: MT | B26: 5 | C26: 0.2
... A38: VA | B38: 2 | C38: 0.2

Sheet Poids
A1: Étiquettes de lignes | B1: Max. de Poids pour le traitement commande vente | C1: poids | D1: poids < 500 g | E1: poids > 500 g | G1: poids < 500 g | H1: =SUM(D:D) -> 113 | I1: =H1/SUM(H1:H2) -> 0.26650943
A2: 00KUR5TU | B2: 0 | C2: =ROUNDUP(B2,1) -> 0 | D2: =IF(C2=0,0,IF(C2<=0.5,1,0)) -> 0 | E2: =IF(C2=0,0,1-D2) -> 0 | G2: poids > 500 g | H2: =SUM(E:E) -> 311
A3: 00KUR5TX | B3: 0.25 | C3: =ROUNDUP(B3,1) -> 0.3 | D3: =IF(C3=0,0,IF(C3<=0.5,1,0)) -> 1 | E3: =IF(C3=0,0,1-D3) -> 0
A4: 00KUR5TY | B4: 0.28 | C4: =ROUNDUP(B4,1) -> 0.3 | D4: =IF(C4=0,0,IF(C4<=0.5,1,0)) -> 1 | E4: =IF(C4=0,0,1-D4) -> 0
A5: 00KUR5TZ | B5: 0.26 | C5: =ROUNDUP(B5,1) -> 0.3 | D5: =IF(C5=0,0,IF(C5<=0.5,1,0)) -> 1 | E5: =IF(C5=0,0,1-D5) -> 0
A6: 00KUR5U0 | B6: 0.28 | C6: =ROUNDUP(B6,1) -> 0.3 | D6: =IF(C6=0,0,IF(C6<=0.5,1,0)) -> 1 | E6: =IF(C6=0,0,1-D6) -> 0
A7: 00KUR5U1 | B7: 0.54 | C7: =ROUNDUP(B7,1) -> 0.6 | D7: =IF(C7=0,0,IF(C7<=0.5,1,0)) -> 0 | E7: =IF(C7=0,0,1-D7) -> 1
A8: 00KUR5U2 | B8: 0.28 | C8: =ROUNDUP(B8,1) -> 0.3 | D8: =IF(C8=0,0,IF(C8<=0.5,1,0)) -> 1 | E8: =IF(C8=0,0,1-D8) -> 0
A9: 00KUR5U3 | B9: 0.3 | C9: =ROUNDUP(B9,1) -> 0.3 | D9: =IF(C9=0,0,IF(C9<=0.5,1,0)) -> 1 | E9: =IF(C9=0,0,1-D9) -> 0
A10: 00KUR5U4 | B10: 0.54 | C10: =ROUNDUP(B10,1) -> 0.6 | D10: =IF(C10=0,0,IF(C10<=0.5,1,0)) -> 0 | E10: =IF(C10=0,0,1-D10) -> 1
A11: 00KUR5U5 | B11: 0.56 | C11: =ROUNDUP(B11,1) -> 0.6 | D11: =IF(C11=0,0,IF(C11<=0.5,1,0)) -> 0 | E11: =IF(C11=0,0,1-D11) -> 1
A12: 00KUR5U6 | B12: 0.72 | C12: =ROUNDUP(B12,1) -> 0.8 | D12: =IF(C12=0,0,IF(C12<=0.5,1,0)) -> 0 | E12: =IF(C12=0,0,1-D12) -> 1
A13: 00KUR5U7 | B13: 0.48 | C13: =ROUNDUP(B13,1) -> 0.5 | D13: =IF(C13=0,0,IF(C13<=0.5,1,0)) -> 1 | E13: =IF(C13=0,0,1-D13) -> 0
A14: 00KUR5U8 | B14: 0.58 | C14: =ROUNDUP(B14,1) -> 0.6 | D14: =IF(C14=0,0,IF(C14<=0.5,1,0)) -> 0 | E14: =IF(C14=0,0,1-D14) -> 1
... A428: (vide) | B428: 0 | C428: =ROUNDUP(B428,1) -> 0 | D428: =IF(C428=0,0,IF(C428<=0.5,1,0)) -> 0 | E428: =IF(C428=0,0,1-D428) -> 0
A1348: zz

Sheet Comptes GLS
A1: Présence | B1: NÂ° compte exploit. | C1: Nom compte exploit. | E1: NÂ° compte exploit. | F1: Nom compte exploit. | G1: ID
A2: =COUNTIF(E:E,B2) -> 1 | B2: 9000037814 | C2: LA RUCHE | E2: 9000037814 | F2: LA RUCHE
A3: =COUNTIF(E:E,B3) -> 1 | B3: 9000079829 | C3: ANOTHER WAY | E3: 9000079828 | F3: ALL MY KETO | G3: 6259
A4: =COUNTIF(E:E,B4) -> 1 | B4: 9000079830 | C4: BY FOUTAS | E4: 9000079829 | F4: ANOTHER WAY | G4: 4565
A5: =COUNTIF(E:E,B5) -> 1 | B5: 9000082822 | C5: Laboratoires Christian Roche | E5: 9000079830 | F5: BY FOUTAS | G5: 3888
A6: =COUNTIF(E:E,B6) -> 1 | B6: 9000084612 | C6: EQUILIBRE CBD | E6: 9000079831 | F6: Prairymood | G6: 6210
A7: =COUNTIF(E:E,B7) -> 0 | B7: (vide) | C7: (vide) | E7: 9000079832 | F7: Le vapoteur tranquille | G7: 3997
E8: 9000079833 | F8: Atomic soda | G8: 6294
A9: 1 | E9: 9000081899 | F9: AÃ„SGARD | G9: 6262
E10: 9000082004 | F10: MOWLY | G10: 6516
E11: 9000082421 | F11: DRUYDES | G11: 6652
E12: 9000082422 | F12: HYDRATIS | G12: 3752
E13: 9000082423 | F13: NOSC | G13: 6665
E14: 9000082814 | F14: EDRA | G14: 6685
E15: 9000082815 | F15: DÃ©couvre Bitcoin | G15: 6705
E16: 9000082821 | F16: KERBI | G16: 6741
E17: 9000082822 | F17: Laboratoires Christian Roche | G17: 6739
E18: 9000083106 | F18: Par un Curieux Hasard | G18: 6814
E19: 9000083593 | F19: SpineFootwear | G19: 6639
E20: 9000083758 | F20: WISE | G20: 6851
E21: 9000083759 | F21: ADOPTE UN BRASSEUR | G21: 6910
... E25: 9000152816 | F25: ONEGUM | G25: 7494

Sheet Catégories
A1: Catégorie GLS | B1: Catégorie ERP | C1: Désignation article
A2: EXPREDOMESSTANDARD | B2: Frêt
A3: PARCEDOMESFDS | B3: Frêt | C3: BP FlexDelivery - Dis. 01 - Size 01
A4: PARCEDOMESPRTN | B4: Frêt - retour
A5: PARCEDOMESPSHP | B5: Frêt
A6: PARCEDOMESSHDS | B6: Frêt
A7: PARCEDOMESSTANDARD | B7: Frêt | C7: Business Parcel - Dis. 01 - Size 01
A8: PARCEEUROPFDS | B8: Frêt | C8: Euro FlexDelivery - Dis. 11 - Size 01
A9: PARCEEUROPSTANDARD | B9: Frêt | C9: EuroBusiness Parcel - Dis. 12 - S. 13
A10: PARCEGLOBASTANDARD | B10: Frêt
A11: SERVIALL FDS | B11: Frêt | C11: Service - FDS - Remise
A12: SURCHALL | B12: Frêt - avisé | C12: AvisÃ© FDS
A13: SURCHALL ADM | B13: Frais de gestion | C13: Frais de Gestion
A14: SURCHALL BPTOC | B14: Frêt
A15: SURCHALL GEO | B15: Zone éloignée
A16: SURCHALL NC | B16: Colis volumineux
A17: SURCHALL NTFCNCRD | B17: Adresse | C17: Majoration AvisÃ© sans TÃ©l ou mail
A18: SURCHALL PCKNOPAR | B18: Adresse
A19: SURCHALL RETURN | B19: Frêt - retour | C19: Retour Colis BUP - Classe 01
A20: SURCHALL SNGLPRCL | B20: ZZ_Ramasse unicolis | C20: Ramassage Uni - Colis - Type 01

Sheet Facture GLS
A1: Catégorie | B1: Total HT | C1: Gazole | D1: Total HT (hors gazole) | E1: Poids | F1: Facture | G1: Document de vente | H1: Date de la facture | I1: nÂ° client | J1: raison sociale | K1: nÂ° chargeur | L1: chargeur Alpha | M1: Nom chargeur | N1: NÂ° compte exploit. | O1: Nom compte exploit. | P1: Nom 2 | Q1: Nom 3 | R1: Nom 4 | S1: nÂ° payer | T1: Nom payer | U1: Groupe d'articles | V1: Article | W1: DÃ©signation article | X1: HiÃ©rarchie produits | Y1: PRICING_COND | Z1: Poste | AA1: Date jour | AB1: NumÃ©ro de colis | AC1: Numero Colis interne | AD1: Consignation ID | AE1: nombre de points | AF1: QuantitÃ© facturÃ©e | AG1: Nombre de colis | AH1: Poids pour le traitement commande vente | AI1: UnitÃ© de qtÃ© base | AJ1: Valeur de Base | AK1: CSR | AL1: PER | AM1: Taux SGO % | AN1: SGO | AO1: prix kilos additionnel | AP1: Saisie manuelle | AQ1: Monnaie ADV | AR1: Client RÃ©fÃ©rence | AS1: Client RÃ©fÃ©rence 1 | AT1: Client RÃ©fÃ©rence 2 | AU1: Client RÃ©fÃ©rence 3 | AV1: adresse de destination NOM | AW1: adresse de dest. ADR1 | AX1: adresse de destination ADR2 | AY1: adresse de destination ADR3 | AZ1: adresse de destination CP | BA1: adresse de destination VILLE | BB1: Code Pays | BC1: Pays | BD1: DSV_TRANSITNO
A2: =IF(COUNTIF(Catégories!A:A,X2)=0,"catégorie inconnue",_xlfn.XLOOKUP(X2,Catégories!A:A,Catégories!B:B)) -> Frêt | B2: =SUM(AJ2:AL2)+SUM(AN2:AP2) -> 7.43 | C2: =AN2 -> 1.64 | D2: =B2-C2 -> 5.79 | E2: =IF(AH2<>0,ROUNDUP(AH2,0),IF(BB2<>"FR","hors France",IF(AH2<>0,ROUNDUP(AH2,0),_xlfn.XLOOKUP(AJ2,'PA GLS'!B:B,'PA GLS'!A:A)))) -> 3 | F2: 2501382993 | G2: 1030231978 | H2: 30.06.2026 | I2: 2500034092 | J2: LA RUCHE LOGISTIQUE | K2: 9000009190 | L2: 46946 | M2: LA RUCHE | N2: 9000079830 | O2: BY FOUTAS | S2: 2507012387 | T2: LA RUCHE LOGISTIQUE | U2: FDS | V2: PARCEL_D01_S07 | W2: Business Parcel - Dis. 01 - Size 07 | X2: PARCEDOMESSTANDARD | Z2: 143 | AA2: 01.06.2026 | AB2: 00KZZJTF | AC2: 2604000030 | AE2: 0 | AF2: 0 | AG2: 0 | AH2: 0 | AI2: KG | AJ2: 4.74 | AK2: 0.9 | AL2: 0.15 | AM2: 29.1 | AN2: 1.64 | AO2: 0 | AP2: 0 | AQ2: EUR | AS2: EXP20260530-2770811- | AT2: EXP20260530-2770811- | AU2: 00KZZJTF | AV2: BERIOT LOUISE | AW2: 119 RUE DE LEGLISE | AZ2: 60140 | BA2: LABRUYERE | BB2: FR | BC2: France
A3: =IF(COUNTIF(Catégories!A:A,X3)=0,"catégorie inconnue",_xlfn.XLOOKUP(X3,Catégories!A:A,Catégories!B:B)) -> Frêt | B3: =SUM(AJ3:AL3)+SUM(AN3:AP3) -> 7.43 | C3: =AN3 -> 1.64 | D3: =B3-C3 -> 5.79 | E3: =IF(AH3<>0,ROUNDUP(AH3,0),IF(BB3<>"FR","hors France",IF(AH3<>0,ROUNDUP(AH3,0),_xlfn.XLOOKUP(AJ3,'PA GLS'!B:B,'PA GLS'!A:A)))) -> 3 | F3: 2501382993 | G3: 1030231978 | H3: 30.06.2026 | I3: 2500034092 | J3: LA RUCHE LOGISTIQUE | K3: 9000009190 | L3: 46946 | M3: LA RUCHE | N3: 9000079830 | O3: BY FOUTAS | S3: 2507012387 | T3: LA RUCHE LOGISTIQUE | U3: FDS | V3: PARCEL_D01_S07 | W3: Business Parcel - Dis. 01 - Size 07 | X3: PARCEDOMESSTANDARD | Z3: 143 | AA3: 01.06.2026 | AB3: 00KZZJTD | AC3: 2604000028 | AE3: 0 | AF3: 0 | AG3: 0 | AH3: 0 | AI3: KG | AJ3: 4.74 | AK3: 0.9 | AL3: 0.15 | AM3: 29.1 | AN3: 1.64 | AO3: 0 | AP3: 0 | AQ3: EUR | AS3: EXP20260529-2769727- | AT3: EXP20260529-2769727- | AU3: 00KZZJTD | AV3: GENDRON CARINE | AW3: 4 LOTISSEMENT PARK KOZH | AZ3: 29590 | BA3: SAINT-SEGAL | BB3: FR | BC3: France
A4: =IF(COUNTIF(Catégories!A:A,X4)=0,"catégorie inconnue",_xlfn.XLOOKUP(X4,Catégories!A:A,Catégories!B:B)) -> Frêt | B4: =SUM(AJ4:AL4)+SUM(AN4:AP4) -> 7.01 | C4: =AN4 -> 1.54 | D4: =B4-C4 -> 5.47 | E4: =IF(AH4<>0,ROUNDUP(AH4,0),IF(BB4<>"FR","hors France",IF(AH4<>0,ROUNDUP(AH4,0),_xlfn.XLOOKUP(AJ4,'PA GLS'!B:B,'PA GLS'!A:A)))) -> 2 | F4: 2501382993 | G4: 1030231978 | H4: 30.06.2026 | I4: 2500034092 | J4: LA RUCHE LOGISTIQUE | K4: 9000009190 | L4: 46946 | M4: LA RUCHE | N4: 9000079830 | O4: BY FOUTAS | S4: 2507012387 | T4: LA RUCHE LOGISTIQUE | U4: FDS | V4: PARCEL_D01_S06 | W4: Business Parcel - Dis. 01 - Size 06 | X4: PARCEDOMESSTANDARD | Z4: 142 | AA4: 01.06.2026 | AB4: 00KZZJTH | AC4: 2604000032 | AE4: 0 | AF4: 0 | AG4: 0 | AH4: 0 | AI4: KG | AJ4: 4.42 | AK4: 0.9 | AL4: 0.15 | AM4: 29.1 | AN4: 1.54 | AO4: 0 | AP4: 0 | AQ4: EUR | AS4: EXP20260529-2770182- | AT4: EXP20260529-2770182- | AU4: 00KZZJTH | AV4: KORMAS CELINE | AW4: 110 ROUTE DE THONES | AZ4: 74940 | BA4: ANNECY | BB4: FR | BC4: France
A5: =IF(COUNTIF(Catégories!A:A,X5)=0,"catégorie inconnue",_xlfn.XLOOKUP(X5,Catégories!A:A,Catégories!B:B)) -> Frêt | B5: =SUM(AJ5:AL5)+SUM(AN5:AP5) -> 7.01 | C5: =AN5 -> 1.54 | D5: =B5-C5 -> 5.47 | E5: =IF(AH5<>0,ROUNDUP(AH5,0),IF(BB5<>"FR","hors France",IF(AH5<>0,ROUNDUP(AH5,0),_xlfn.XLOOKUP(AJ5,'PA GLS'!B:B,'PA GLS'!A:A)))) -> 2 | F5: 2501382993 | G5: 1030231978 | H5: 30.06.2026 | I5: 2500034092 | J5: LA RUCHE LOGISTIQUE | K5: 9000009190 | L5: 46946 | M5: LA RUCHE | N5: 9000079830 | O5: BY FOUTAS | S5: 2507012387 | T5: LA RUCHE LOGISTIQUE | U5: FDS | V5: PARCEL_D01_S06 | W5: Business Parcel - Dis. 01 - Size 06 | X5: PARCEDOMESSTANDARD | Z5: 142 | AA5: 01.06.2026 | AB5: 00KZZJT9 | AC5: 2604000024 | AE5: 0 | AF5: 0 | AG5: 0 | AH5: 0 | AI5: KG | AJ5: 4.42 | AK5: 0.9 | AL5: 0.15 | AM5: 29.1 | AN5: 1.54 | AO5: 0 | AP5: 0 | AQ5: EUR | AS5: EXP20260529-2769320- | AT5: EXP20260529-2769320- | AU5: 00KZZJT9 | AV5: COSTE DE BAGNEAUX JUSTINE | AW5: 46 RUE LOUIS PETRI | AZ5: 35200 | BA5: RENNES | BB5: FR | BC5: France
A6: =IF(COUNTIF(Catégories!A:A,X6)=0,"catégorie inconnue",_xlfn.XLOOKUP(X6,Catégories!A:A,Catégories!B:B)) -> Frêt | B6: =SUM(AJ6:AL6)+SUM(AN6:AP6) -> 7.01 | C6: =AN6 -> 1.54 | D6: =B6-C6 -> 5.47 | E6: =IF(AH6<>0,ROUNDUP(AH6,0),IF(BB6<>"FR","hors France",IF(AH6<>0,ROUNDUP(AH6,0),_xlfn.XLOOKUP(AJ6,'PA GLS'!B:B,'PA GLS'!A:A)))) -> 2 | F6: 2501382993 | G6: 1030231978 | H6: 30.06.2026 | I6: 2500034092 | J6: LA RUCHE LOGISTIQUE | K6: 9000009190 | L6: 46946 | M6: LA RUCHE | N6: 9000079830 | O6: BY FOUTAS | S6: 2507012387 | T6: LA RUCHE LOGISTIQUE | U6: FDS | V6: PARCEL_D01_S05 | W6: Business Parcel - Dis. 01 - Size 05 | X6: PARCEDOMESSTANDARD | Z6: 141 | AA6: 01.06.2026 | AB6: 00KZZJTG | AC6: 2604000031 | AE6: 0 | AF6: 0 | AG6: 0 | AH6: 0 | AI6: KG | AJ6: 4.42 | AK6: 0.9 | AL6: 0.15 | AM6: 29.1 | AN6: 1.54 | AO6: 0 | AP6: 0 | AQ6: EUR | AS6: EXP20260530-2770970- | AT6: EXP20260530-2770970- | AU6: 00KZZJTG | AV6: REAL CHARLES | AW6: 8 RUE RUHMKORFF | AZ6: 75017 | BA6: PARIS | BB6: FR | BC6: France
A7: =IF(COUNTIF(Catégories!A:A,X7)=0,"catégorie inconnue",_xlfn.XLOOKUP(X7,Catégories!A:A,Catégories!B:B)) -> Frêt | B7: =SUM(AJ7:AL7)+SUM(AN7:AP7) -> 7.01 | C7: =AN7 -> 1.54 | D7: =B7-C7 -> 5.47 | E7: =IF(AH7<>0,ROUNDUP(AH7,0),IF(BB7<>"FR","hors France",IF(AH7<>0,ROUNDUP(AH7,0),_xlfn.XLOOKUP(AJ7,'PA GLS'!B:B,'PA GLS'!A:A)))) -> 2 | F7: 2501382993 | G7: 1030231978 | H7: 30.06.2026 | I7: 2500034092 | J7: LA RUCHE LOGISTIQUE | K7: 9000009190 | L7: 46946 | M7: LA RUCHE | N7: 9000079830 | O7: BY FOUTAS | S7: 2507012387 | T7: LA RUCHE LOGISTIQUE | U7: FDS | V7: PARCEL_D01_S05 | W7: Business Parcel - Dis. 01 - Size 05 | X7: PARCEDOMESSTANDARD | Z7: 141 | AA7: 01.06.2026 | AB7: 00KZZJTA | AC7: 2604000025 | AE7: 0 | AF7: 0 | AG7: 0 | AH7: 0 | AI7: KG | AJ7: 4.42 | AK7: 0.9 | AL7: 0.15 | AM7: 29.1 | AN7: 1.54 | AO7: 0 | AP7: 0 | AQ7: EUR | AS7: EXP20260529-2769726- | AT7: EXP20260529-2769726- | AU7: 00KZZJTA | AV7: GABORIT CLARISSE | AW7: 15 RUE DE LA LIBERTE | AZ7: 92150 | BA7: SURESNES | BB7: FR | BC7: France
A8: =IF(COUNTIF(Catégories!A:A,X8)=0,"catégorie inconnue",_xlfn.XLOOKUP(X8,Catégories!A:A,Catégories!B:B)) -> Frêt | B8: =SUM(AJ8:AL8)+SUM(AN8:AP8) -> 6.6 | C8: =AN8 -> 1.45 | D8: =B8-C8 -> 5.15 | E8: =IF(AH8<>0,ROUNDUP(AH8,0),IF(BB8<>"FR","hors France",IF(AH8<>0,ROUNDUP(AH8,0),_xlfn.XLOOKUP(AJ8,'PA GLS'!B:B,'PA GLS'!A:A)))) -> 1 | F8: 2501382993 | G8: 1030231978 | H8: 30.06.2026 | I8: 2500034092 | J8: LA RUCHE LOGISTIQUE | K8: 9000009190 | L8: 46946 | M8: LA RUCHE | N8: 9000079830 | O8: BY FOUTAS | S8: 2507012387 | T8: LA RUCHE LOGISTIQUE | U8: FDS | V8: PARCEL_D01_S04 | W8: Business Parcel - Dis. 01 - Size 04 | X8: PARCEDOMESSTANDARD | Z8: 140 | AA8: 01.06.2026 | AB8: 00KZZJTC | AC8: 2604000027 | AE8: 0 | AF8: 0 | AG8: 0 | AH8: 0 | AI8: KG | AJ8: 4.1 | AK8: 0.9 | AL8: 0.15 | AM8: 29.1 | AN8: 1.45 | AO8: 0 | AP8: 0 | AQ8: EUR | AS8: EXP20260529-2769287- | AT8: EXP20260529-2769287- | AU8: 00KZZJTC | AV8: HEUBES CAROLINE | AW8: 29 AVENUE FELIX FAURE | AZ8: 75015 | BA8: PARIS | BB8: FR | BC8: France
A9: =IF(COUNTIF(Catégories!A:A,X9)=0,"catégorie inconnue",_xlfn.XLOOKUP(X9,Catégories!A:A,Catégories!B:B)) -> Frêt | B9: =SUM(AJ9:AL9)+SUM(AN9:AP9) -> 6.6 | C9: =AN9 -> 1.45 | D9: =B9-C9 -> 5.15 | E9: =IF(AH9<>0,ROUNDUP(AH9,0),IF(BB9<>"FR","hors France",IF(AH9<>0,ROUNDUP(AH9,0),_xlfn.XLOOKUP(AJ9,'PA GLS'!B:B,'PA GLS'!A:A)))) -> 1 | F9: 2501382993 | G9: 1030231978 | H9: 30.06.2026 | I9: 2500034092 | J9: LA RUCHE LOGISTIQUE | K9: 9000009190 | L9: 46946 | M9: LA RUCHE | N9: 9000079830 | O9: BY FOUTAS | S9: 2507012387 | T9: LA RUCHE LOGISTIQUE | U9: FDS | V9: PARCEL_D01_S04 | W9: Business Parcel - Dis. 01 - Size 04 | X9: PARCEDOMESSTANDARD | Z9: 140 | AA9: 01.06.2026 | AB9: 00KZZJTB | AC9: 2604000026 | AE9: 0 | AF9: 0 | AG9: 0 | AH9: 0 | AI9: KG | AJ9: 4.1 | AK9: 0.9 | AL9: 0.15 | AM9: 29.1 | AN9: 1.45 | AO9: 0 | AP9: 0 | AQ9: EUR | AS9: EXP20260529-2769423- | AT9: EXP20260529-2769423- | AU9: 00KZZJTB | AV9: HERVOUET DOMINIQUE | AW9: 10 IMPASSE DE LA DOUETTEE | AZ9: 44120 | BA9: VERTOU | BB9: FR | BC9: France
A10: =IF(COUNTIF(Catégories!A:A,X10)=0,"catégorie inconnue",_xlfn.XLOOKUP(X10,Catégories!A:A,Catégories!B:B)) -> Frêt | B10: =SUM(AJ10:AL10)+SUM(AN10:AP10) -> 6.17 | C10: =AN10 -> 1.35 | D10: =B10-C10 -> 4.82 | E10: =IF(AH10<>0,ROUNDUP(AH10,0),IF(BB10<>"FR","hors France",IF(AH10<>0,ROUNDUP(AH10,0),_xlfn.XLOOKUP(AJ10,'PA GLS'!B:B,'PA GLS'!A:A)))) -> 0.5 | F10: 2501382993 | G10: 1030231978 | H10: 30.06.2026 | I10: 2500034092 | J10: LA RUCHE LOGISTIQUE | K10: 9000009190 | L10: 46946 | M10: LA RUCHE | N10: 9000079830 | O10: BY FOUTAS | S10: 2507012387 | T10: LA RUCHE LOGISTIQUE | U10: FDS | V10: PARCEL_D01_S02 | W10: Business Parcel - Dis. 01 - Size 02 | X10: PARCEDOMESSTANDARD | Z10: 139 | AA10: 01.06.2026 | AB10: 00KZZJTE | AC10: 2604000029 | AE10: 0 | AF10: 0 | AG10: 0 | AH10: 0 | AI10: KG | AJ10: 3.77 | AK10: 0.9 | AL10: 0.15 | AM10: 29.1 | AN10: 1.35 | AO10: 0 | AP10: 0 | AQ10: EUR | AS10: EXP20260529-2770183- | AT10: EXP20260529-2770183- | AU10: 00KZZJTE | AV10: CALLENDRET TIFFANY | AW10: 206 CHEMIN DE NARBAN | AZ10: 38510 | BA10: ST VICTOR DE MORESTEL | BB10: FR | BC10: France
A11: =IF(COUNTIF(Catégories!A:A,X11)=0,"catégorie inconnue",_xlfn.XLOOKUP(X11,Catégories!A:A,Catégories!B:B)) -> Frêt | B11: =SUM(AJ11:AL11)+SUM(AN11:AP11) -> 0 | C11: =AN11 -> 0 | D11: =B11-C11 -> 0 | E11: =IF(AH11<>0,ROUNDUP(AH11,0),IF(BB11<>"FR","hors France",IF(AH11<>0,ROUNDUP(AH11,0),_xlfn.XLOOKUP(AJ11,'PA GLS'!B:B,'PA GLS'!A:A)))) -> 2 | F11: 2501382993 | G11: 1030231978 | H11: 30.06.2026 | I11: 2500034092 | J11: LA RUCHE LOGISTIQUE | K11: 9000009190 | L11: 46946 | M11: LA RUCHE | N11: 9000079830 | O11: BY FOUTAS | S11: 2507012387 | T11: LA RUCHE LOGISTIQUE | U11: FDS | V11: FDS_D01_S01 | W11: BP FlexDelivery - Dis. 01 - Size 01 | X11: PARCEDOMESFDS | Z11: 138 | AA11: 01.06.2026 | AB11: 00KZZJTH | AC11: 2604000032 | AE11: 0 | AF11: 1 | AG11: 0 | AH11: 1.7 | AI11: KG | AJ11: 0 | AK11: 0 | AL11: 0 | AM11: 0 | AN11: 0 | AO11: 0 | AP11: 0 | AQ11: EUR | AS11: EXP20260529-2770182- | AT11: EXP20260529-2770182- | AU11: 00KZZJTH | AV11: KORMAS CELINE | AW11: 110 ROUTE DE THONES | AZ11: 74940 | BA11: ANNECY | BB11: FR | BC11: France
A12: =IF(COUNTIF(Catégories!A:A,X12)=0,"catégorie inconnue",_xlfn.XLOOKUP(X12,Catégories!A:A,Catégories!B:B)) -> Frêt | B12: =SUM(AJ12:AL12)+SUM(AN12:AP12) -> 0 | C12: =AN12 -> 0 | D12: =B12-C12 -> 0 | E12: =IF(AH12<>0,ROUNDUP(AH12,0),IF(BB12<>"FR","hors France",IF(AH12<>0,ROUNDUP(AH12,0),_xlfn.XLOOKUP(AJ12,'PA GLS'!B:B,'PA GLS'!A:A)))) -> 2 | F12: 2501382993 | G12: 1030231978 | H12: 30.06.2026 | I12: 2500034092 | J12: LA RUCHE LOGISTIQUE | K12: 9000009190 | L12: 46946 | M12: LA RUCHE | N12: 9000079830 | O12: BY FOUTAS | S12: 2507012387 | T12: LA RUCHE LOGISTIQUE | U12: FDS | V12: FDS_D01_S01 | W12: BP FlexDelivery - Dis. 01 - Size 01 | X12: PARCEDOMESFDS | Z12: 138 | AA12: 01.06.2026 | AB12: 00KZZJTG | AC12: 2604000031 | AE12: 0 | AF12: 1 | AG12: 0 | AH12: 1.15 | AI12: KG | AJ12: 0 | AK12: 0 | AL12: 0 | AM12: 0 | AN12: 0 | AO12: 0 | AP12: 0 | AQ12: EUR | AS12: EXP20260530-2770970- | AT12: EXP20260530-2770970- | AU12: 00KZZJTG | AV12: REAL CHARLES | AW12: 8 RUE RUHMKORFF | AZ12: 75017 | BA12: PARIS | BB12: FR | BC12: France
A13: =IF(COUNTIF(Catégories!A:A,X13)=0,"catégorie inconnue",_xlfn.XLOOKUP(X13,Catégories!A:A,Catégories!B:B)) -> Frêt | B13: =SUM(AJ13:AL13)+SUM(AN13:AP13) -> 0 | C13: =AN13 -> 0 | D13: =B13-C13 -> 0 | E13: =IF(AH13<>0,ROUNDUP(AH13,0),IF(BB13<>"FR","hors France",IF(AH13<>0,ROUNDUP(AH13,0),_xlfn.XLOOKUP(AJ13,'PA GLS'!B:B,'PA GLS'!A:A)))) -> 3 | F13: 2501382993 | G13: 1030231978 | H13: 30.06.2026 | I13: 2500034092 | J13: LA RUCHE LOGISTIQUE | K13: 9000009190 | L13: 46946 | M13: LA RUCHE | N13: 9000079830 | O13: BY FOUTAS | S13: 2507012387 | T13: LA RUCHE LOGISTIQUE | U13: FDS | V13: FDS_D01_S01 | W13: BP FlexDelivery - Dis. 01 - Size 01 | X13: PARCEDOMESFDS | Z13: 138 | AA13: 01.06.2026 | AB13: 00KZZJTF | AC13: 2604000030 | AE13: 0 | AF13: 1 | AG13: 0 | AH13: 2.42 | AI13: KG | AJ13: 0 | AK13: 0 | AL13: 0 | AM13: 0 | AN13: 0 | AO13: 0 | AP13: 0 | AQ13: EUR | AS13: EXP20260530-2770811- | AT13: EXP20260530-2770811- | AU13: 00KZZJTF | AV13: BERIOT LOUISE | AW13: 119 RUE DE LEGLISE | AZ13: 60140 | BA13: LABRUYERE | BB13: FR | BC13: France
... A26: =IF(COUNTIF(Catégories!A:A,X26)=0,"catégorie inconnue",_xlfn.XLOOKUP(X26,Catégories!A:A,Catégories!B:B)) -> Frêt - avisé | B26: =SUM(AJ26:AL26)+SUM(AN26:AP26) -> 0 | C26: =AN26 -> 0 | D26: =B26-C26 -> 0 | E26: =IF(AH26<>0,ROUNDUP(AH26,0),IF(BB26<>"FR","hors France",IF(AH26<>0,ROUNDUP(AH26,0),_xlfn.XLOOKUP(AJ26,'PA GLS'!B:B,'PA GLS'!A:A)))) -> #N/A | F26: 2501382993 | G26: 1030228091 | H26: 30.06.2026 | I26: 2500034092 | J26: LA RUCHE LOGISTIQUE | K26: 9000009190 | L26: 46946 | M26: LA RUCHE | N26: 9000037814 | O26: LA RUCHE | S26: 2507012387 | T26: LA RUCHE LOGISTIQUE | U26: FDS | V26: SUR_FS_AVIS_01 | W26: AvisÃ© FDS | X26: SURCHALL | Z26: 104 | AA26: 01.06.2026 | AB26: 00KUR5TU | AC26: 2604000012 | AE26: 0 | AF26: 0 | AG26: 0 | AH26: 0 | AI26: KG | AJ26: 0 | AK26: 0 | AL26: 0 | AM26: 0 | AN26: 0 | AO26: 0 | AP26: 0 | AQ26: EUR | AS26: EXP20260528-2768458- | AT26: EXP20260528-2768458- | AU26: 00KUR5TU | AV26: CARBALLEDA ELENA | AW26: 8 RUE ALFRED DE MUSSET | AZ26: 78330 | BA26: FONTENAY-LE-FLEURY | BB26: FR | BC26: France
A27: =IF(COUNTIF(Catégories!A:A,X27)=0,"catégorie inconnue",_xlfn.XLOOKUP(X27,Catégories!A:A,Catégories!B:B)) -> Frêt | B27: =SUM(AJ27:AL27)+SUM(AN27:AP27) -> 6.17 | C27: =AN27 -> 1.35 | D27: =B27-C27 -> 4.82 | E27: =IF(AH27<>0,ROUNDUP(AH27,0),IF(BB27<>"FR","hors France",IF(AH27<>0,ROUNDUP(AH27,0),_xlfn.XLOOKUP(AJ27,'PA GLS'!B:B,'PA GLS'!A:A)))) -> 0.5 | F27: 2501382993 | G27: 1030230689 | H27: 30.06.2026 | I27: 2500034092 | J27: LA RUCHE LOGISTIQUE | K27: 9000009190 | L27: 46946 | M27: LA RUCHE | N27: 9000079829 | O27: ANOTHER WAY | S27: 2507012387 | T27: LA RUCHE LOGISTIQUE | U27: FDS | V27: PARCEL_D01_S02 | W27: Business Parcel - Dis. 01 - Size 02 | X27: PARCEDOMESSTANDARD | Z27: 110 | AA27: 02.06.2026 | AB27: 00L0EX46 | AC27: 6699599 | AE27: 0 | AF27: 0 | AG27: 0 | AH27: 0 | AI27: KG | AJ27: 3.77 | AK27: 0.9 | AL27: 0.15 | AM27: 29.1 | AN27: 1.35 | AO27: 0 | AP27: 0 | AQ27: EUR | AS27: EXP20260601-2774736 | AU27: 00L0EX46 | AV27: LEROY FANNY | AW27: 9 RUE EMILE DUBOIS | AZ27: 75014 | BA27: PARIS | BB27: FR | BC27: France
A28: =IF(COUNTIF(Catégories!A:A,X28)=0,"catégorie inconnue",_xlfn.XLOOKUP(X28,Catégories!A:A,Catégories!B:B)) -> Frêt | B28: =SUM(AJ28:AL28)+SUM(AN28:AP28) -> 0 | C28: =AN28 -> 0 | D28: =B28-C28 -> 0 | E28: =IF(AH28<>0,ROUNDUP(AH28,0),IF(BB28<>"FR","hors France",IF(AH28<>0,ROUNDUP(AH28,0),_xlfn.XLOOKUP(AJ28,'PA GLS'!B:B,'PA GLS'!A:A)))) -> 1 | F28: 2501382993 | G28: 1030230689 | H28: 30.06.2026 | I28: 2500034092 | J28: LA RUCHE LOGISTIQUE | K28: 9000009190 | L28: 46946 | M28: LA RUCHE | N28: 9000079829 | O28: ANOTHER WAY | S28: 2507012387 | T28: LA RUCHE LOGISTIQUE | U28: FDS | V28: FDS_D01_S01 | W28: BP FlexDelivery - Dis. 01 - Size 01 | X28: PARCEDOMESFDS | Z28: 109 | AA28: 02.06.2026 | AB28: 00L0EXC0 | AC28: 6699902 | AE28: 0 | AF28: 1 | AG28: 0 | AH28: 0.4 | AI28: KG | AJ28: 0 | AK28: 0 | AL28: 0 | AM28: 0 | AN28: 0 | AO28: 0 | AP28: 0 | AQ28: EUR | AS28: EXP20260601-2772297 | AU28: 00L0EXC0 | AV28: GROSSEMY MARIE-LAURE | AW28: 24, RUE DES ERABLES | AZ28: 71640 | BA28: GIVRY | BB28: FR | BC28: France
A29: =IF(COUNTIF(Catégories!A:A,X29)=0,"catégorie inconnue",_xlfn.XLOOKUP(X29,Catégories!A:A,Catégories!B:B)) -> Frêt | B29: =SUM(AJ29:AL29)+SUM(AN29:AP29) -> 0 | C29: =AN29 -> 0 | D29: =B29-C29 -> 0 | E29: =IF(AH29<>0,ROUNDUP(AH29,0),IF(BB29<>"FR","hors France",IF(AH29<>0,ROUNDUP(AH29,0),_xlfn.XLOOKUP(AJ29,'PA GLS'!B:B,'PA GLS'!A:A)))) -> 1 | F29: 2501382993 | G29: 1030230689 | H29: 30.06.2026 | I29: 2500034092 | J29: LA RUCHE LOGISTIQUE | K29: 9000009190 | L29: 46946 | M29: LA RUCHE | N29: 9000079829 | O29: ANOTHER WAY | S29: 2507012387 | T29: LA RUCHE LOGISTIQUE | U29: FDS | V29: FDS_D01_S01 | W29: BP FlexDelivery - Dis. 01 - Size 01 | X29: PARCEDOMESFDS | Z29: 109 | AA29: 02.06.2026 | AB29: 00L0EX46 | AC29: 6699599 | AE29: 0 | AF29: 1 | AG29: 0 | AH29: 0.38 | AI29: KG | AJ29: 0 | AK29: 0 | AL29: 0 | AM29: 0 | AN29: 0 | AO29: 0 | AP29: 0 | AQ29: EUR | AS29: EXP20260601-2774736 | AU29: 00L0EX46 | AV29: LEROY FANNY | AW29: 9 RUE EMILE DUBOIS | AZ29: 75014 | BA29: PARIS | BB29: FR | BC29: France
A30: =IF(COUNTIF(Catégories!A:A,X30)=0,"catégorie inconnue",_xlfn.XLOOKUP(X30,Catégories!A:A,Catégories!B:B)) -> Frêt | B30: =SUM(AJ30:AL30)+SUM(AN30:AP30) -> 7.01 | C30: =AN30 -> 1.54 | D30: =B30-C30 -> 5.47 | E30: =IF(AH30<>0,ROUNDUP(AH30,0),IF(BB30<>"FR","hors France",IF(AH30<>0,ROUNDUP(AH30,0),_xlfn.XLOOKUP(AJ30,'PA GLS'!B:B,'PA GLS'!A:A)))) -> 2 | F30: 2501382993 | G30: 1030219781 | H30: 30.06.2026 | I30: 2500034092 | J30: LA RUCHE LOGISTIQUE | K30: 9000009190 | L30: 46946 | M30: LA RUCHE | N30: 9000079830 | O30: BY FOUTAS | S30: 2507012387 | T30: LA RUCHE LOGISTIQUE | U30: FDS | V30: PARCEL_D01_S05 | W30: Business Parcel - Dis. 01 - Size 05 | X30: PARCEDOMESSTANDARD | Z30: 44 | AA30: 02.06.2026 | AB30: 00KZZJTK | AC30: 2604000035 | AE30: 0 | AF30: 0 | AG30: 0 | AH30: 0 | AI30: KG | AJ30: 4.42 | AK30: 0.9 | AL30: 0.15 | AM30: 29.1 | AN30: 1.54 | AO30: 0 | AP30: 0 | AQ30: EUR | AS30: EXP20260530-2771113- | AT30: EXP20260530-2771113- | AU30: 00KZZJTK | AV30: BRAIZE FREDERIC | AW30: 420 AVENUE DE LA FRUITIERE | AZ30: 74140 | BA30: SCIEZ | BB30: FR | BC30: France
A31: =IF(COUNTIF(Catégories!A:A,X31)=0,"catégorie inconnue",_xlfn.XLOOKUP(X31,Catégories!A:A,Catégories!B:B)) -> Frêt | B31: =SUM(AJ31:AL31)+SUM(AN31:AP31) -> 7.01 | C31: =AN31 -> 1.54 | D31: =B31-C31 -> 5.47 | E31: =IF(AH31<>0,ROUNDUP(AH31,0),IF(BB31<>"FR","hors France",IF(AH31<>0,ROUNDUP(AH31,0),_xlfn.XLOOKUP(AJ31,'PA GLS'!B:B,'PA GLS'!A:A)))) -> 2 | F31: 2501382993 | G31: 1030219781 | H31: 30.06.2026 | I31: 2500034092 | J31: LA RUCHE LOGISTIQUE | K31: 9000009190 | L31: 46946 | M31: LA RUCHE | N31: 9000079830 | O31: BY FOUTAS | S31: 2507012387 | T31: LA RUCHE LOGISTIQUE | U31: FDS | V31: PARCEL_D01_S05 | W31: Business Parcel - Dis. 01 - Size 05 | X31: PARCEDOMESSTANDARD | Z31: 44 | AA31: 02.06.2026 | AB31: 00KZZJTI | AC31: 2604000033 | AE31: 0 | AF31: 0 | AG31: 0 | AH31: 0 | AI31: KG | AJ31: 4.42 | AK31: 0.9 | AL31: 0.15 | AM31: 29.1 | AN31: 1.54 | AO31: 0 | AP31: 0 | AQ31: EUR | AS31: EXP20260529-2769965- | AT31: EXP20260529-2769965- | AU31: 00KZZJTI | AV31: FICHET MORGAN | AW31: 9 RUE DU DOUET | AZ31: 35510 | BA31: CESSON-SEVIGNE | BB31: FR | BC31: France
A32: =IF(COUNTIF(Catégories!A:A,X32)=0,"catégorie inconnue",_xlfn.XLOOKUP(X32,Catégories!A:A,Catégories!B:B)) -> Frêt | B32: =SUM(AJ32:AL32)+SUM(AN32:AP32) -> 6.6 | C32: =AN32 -> 1.45 | D32: =B32-C32 -> 5.15 | E32: =IF(AH32<>0,ROUNDUP(AH32,0),IF(BB32<>"FR","hors France",IF(AH32<>0,ROUNDUP(AH32,0),_xlfn.XLOOKUP(AJ32,'PA GLS'!B:B,'PA GLS'!A:A)))) -> 1 | F32: 2501382993 | G32: 1030219781 | H32: 30.06.2026 | I32: 2500034092 | J32: LA RUCHE LOGISTIQUE | K32: 9000009190 | L32: 46946 | M32: LA RUCHE | N32: 9000079830 | O32: BY FOUTAS | S32: 2507012387 | T32: LA RUCHE LOGISTIQUE | U32: FDS | V32: PARCEL_D01_S04 | W32: Business Parcel - Dis. 01 - Size 04 | X32: PARCEDOMESSTANDARD | Z32: 43 | AA32: 02.06.2026 | AB32: 00KZZJU2 | AC32: 2604000053 | AE32: 0 | AF32: 0 | AG32: 0 | AH32: 0 | AI32: KG | AJ32: 4.1 | AK32: 0.9 | AL32: 0.15 | AM32: 29.1 | AN32: 1.45 | AO32: 0 | AP32: 0 | AQ32: EUR | AS32: EXP20260601-2774808- | AT32: EXP20260601-2774808- | AU32: 00KZZJU2 | AV32: AUDRAIN ESTELLE | AW32: 305 RUE JEAN DAUSSET | AZ32: 13090 | BA32: AIX-EN-PROVENCE | BB32: FR | BC32: France
A33: =IF(COUNTIF(Catégories!A:A,X33)=0,"catégorie inconnue",_xlfn.XLOOKUP(X33,Catégories!A:A,Catégories!B:B)) -> Frêt | B33: =SUM(AJ33:AL33)+SUM(AN33:AP33) -> 6.6 | C33: =AN33 -> 1.45 | D33: =B33-C33 -> 5.15 | E33: =IF(AH33<>0,ROUNDUP(AH33,0),IF(BB33<>"FR","hors France",IF(AH33<>0,ROUNDUP(AH33,0),_xlfn.XLOOKUP(AJ33,'PA GLS'!B:B,'PA GLS'!A:A)))) -> 1 | F33: 2501382993 | G33: 1030219781 | H33: 30.06.2026 | I33: 2500034092 | J33: LA RUCHE LOGISTIQUE | K33: 9000009190 | L33: 46946 | M33: LA RUCHE | N33: 9000079830 | O33: BY FOUTAS | S33: 2507012387 | T33: LA RUCHE LOGISTIQUE | U33: FDS | V33: PARCEL_D01_S04 | W33: Business Parcel - Dis. 01 - Size 04 | X33: PARCEDOMESSTANDARD | Z33: 43 | AA33: 02.06.2026 | AB33: 00KZZJTP | AC33: 2604000040 | AE33: 0 | AF33: 0 | AG33: 0 | AH33: 0 | AI33: KG | AJ33: 4.1 | AK33: 0.9 | AL33: 0.15 | AM33: 29.1 | AN33: 1.45 | AO33: 0 | AP33: 0 | AQ33: EUR | AS33: EXP20260530-2771224- | AT33: EXP20260530-2771224- | AU33: 00KZZJTP | AV33: LAMY MEGANE | AW33: 24 RUE DU CLOCHER | AZ33: 83990 | BA33: SAINT-TROPEZ | BB33: FR | BC33: France
A34: =IF(COUNTIF(Catégories!A:A,X34)=0,"catégorie inconnue",_xlfn.XLOOKUP(X34,Catégories!A:A,Catégories!B:B)) -> Frêt | B34: =SUM(AJ34:AL34)+SUM(AN34:AP34) -> 6.17 | C34: =AN34 -> 1.35 | D34: =B34-C34 -> 4.82 | E34: =IF(AH34<>0,ROUNDUP(AH34,0),IF(BB34<>"FR","hors France",IF(AH34<>0,ROUNDUP(AH34,0),_xlfn.XLOOKUP(AJ34,'PA GLS'!B:B,'PA GLS'!A:A)))) -> 0.5 | F34: 2501382993 | G34: 1030219781 | H34: 30.06.2026 | I34: 2500034092 | J34: LA RUCHE LOGISTIQUE | K34: 9000009190 | L34: 46946 | M34: LA RUCHE | N34: 9000079830 | O34: BY FOUTAS | S34: 2507012387 | T34: LA RUCHE LOGISTIQUE | U34: FDS | V34: PARCEL_D01_S02 | W34: Business Parcel - Dis. 01 - Size 02 | X34: PARCEDOMESSTANDARD | Z34: 42 | AA34: 02.06.2026 | AB34: 00KZZJTY | AC34: 2604000049 | AE34: 0 | AF34: 0 | AG34: 0 | AH34: 0 | AI34: KG | AJ34: 3.77 | AK34: 0.9 | AL34: 0.15 | AM34: 29.1 | AN34: 1.35 | AO34: 0 | AP34: 0 | AQ34: EUR | AS34: EXP20260601-2772286- | AT34: EXP20260601-2772286- | AU34: 00KZZJTY | AV34: ROBION MAEVA | AW34: 140 IMPASSE DES CHARMES | AZ34: 85220 | BA34: COMMEQUIERS | BB34: FR | BC34: France
A35: =IF(COUNTIF(Catégories!A:A,X35)=0,"catégorie inconnue",_xlfn.XLOOKUP(X35,Catégories!A:A,Catégories!B:B)) -> Frêt | B35: =SUM(AJ35:AL35)+SUM(AN35:AP35) -> 6.17 | C35: =AN35 -> 1.35 | D35: =B35-C35 -> 4.82 | E35: =IF(AH35<>0,ROUNDUP(AH35,0),IF(BB35<>"FR","hors France",IF(AH35<>0,ROUNDUP(AH35,0),_xlfn.XLOOKUP(AJ35,'PA GLS'!B:B,'PA GLS'!A:A)))) -> 0.5 | F35: 2501382993 | G35: 1030219781 | H35: 30.06.2026 | I35: 2500034092 | J35: LA RUCHE LOGISTIQUE | K35: 9000009190 | L35: 46946 | M35: LA RUCHE | N35: 9000079830 | O35: BY FOUTAS | S35: 2507012387 | T35: LA RUCHE LOGISTIQUE | U35: FDS | V35: PARCEL_D01_S02 | W35: Business Parcel - Dis. 01 - Size 02 | X35: PARCEDOMESSTANDARD | Z35: 42 | AA35: 02.06.2026 | AB35: 00KZZJTX | AC35: 2604000048 | AE35: 0 | AF35: 0 | AG35: 0 | AH35: 0 | AI35: KG | AJ35: 3.77 | AK35: 0.9 | AL35: 0.15 | AM35: 29.1 | AN35: 1.35 | AO35: 0 | AP35: 0 | AQ35: EUR | AS35: EXP20260601-2772275- | AT35: EXP20260601-2772275- | AU35: 00KZZJTX | AV35: PERSICO CELINE | AW35: 20 RUE DES MARES BATIMENT K AP | AZ35: 93230 | BA35: ROMAINVILLE | BB35: FR | BC35: France
A36: =IF(COUNTIF(Catégories!A:A,X36)=0,"catégorie inconnue",_xlfn.XLOOKUP(X36,Catégories!A:A,Catégories!B:B)) -> Frêt | B36: =SUM(AJ36:AL36)+SUM(AN36:AP36) -> 6.17 | C36: =AN36 -> 1.35 | D36: =B36-C36 -> 4.82 | E36: =IF(AH36<>0,ROUNDUP(AH36,0),IF(BB36<>"FR","hors France",IF(AH36<>0,ROUNDUP(AH36,0),_xlfn.XLOOKUP(AJ36,'PA GLS'!B:B,'PA GLS'!A:A)))) -> 0.5 | F36: 2501382993 | G36: 1030219781 | H36: 30.06.2026 | I36: 2500034092 | J36: LA RUCHE LOGISTIQUE | K36: 9000009190 | L36: 46946 | M36: LA RUCHE | N36: 9000079830 | O36: BY FOUTAS | S36: 2507012387 | T36: LA RUCHE LOGISTIQUE | U36: FDS | V36: PARCEL_D01_S02 | W36: Business Parcel - Dis. 01 - Size 02 | X36: PARCEDOMESSTANDARD | Z36: 42 | AA36: 02.06.2026 | AB36: 00KZZJTS | AC36: 2604000043 | AE36: 0 | AF36: 0 | AG36: 0 | AH36: 0 | AI36: KG | AJ36: 3.77 | AK36: 0.9 | AL36: 0.15 | AM36: 29.1 | AN36: 1.35 | AO36: 0 | AP36: 0 | AQ36: EUR | AS36: EXP20260601-2772276- | AT36: EXP20260601-2772276- | AU36: 00KZZJTS | AV36: PARIS VIRGINIE | AW36: 12 RUE DES CERISIERS | AZ36: 8090 | BA36: CLIRON | BB36: FR | BC36: France
A37: =IF(COUNTIF(Catégories!A:A,X37)=0,"catégorie inconnue",_xlfn.XLOOKUP(X37,Catégories!A:A,Catégories!B:B)) -> Frêt | B37: =SUM(AJ37:AL37)+SUM(AN37:AP37) -> 8.87 | C37: =AN37 -> 1.96 | D37: =B37-C37 -> 6.91 | E37: =IF(AH37<>0,ROUNDUP(AH37,0),IF(BB37<>"FR","hors France",IF(AH37<>0,ROUNDUP(AH37,0),_xlfn.XLOOKUP(AJ37,'PA GLS'!B:B,'PA GLS'!A:A)))) -> 5 | F37: 2501382993 | G37: 1030219781 | H37: 30.06.2026 | I37: 2500034092 | J37: LA RUCHE LOGISTIQUE | K37: 9000009190 | L37: 46946 | M37: LA RUCHE | N37: 9000079830 | O37: BY FOUTAS | S37: 2507012387 | T37: LA RUCHE LOGISTIQUE | U37: FDS | V37: PARCEL_D01_S09 | W37: Business Parcel - Dis. 01 - Size 09 | X37: PARCEDOMESSTANDARD | Z37: 47 | AA37: 02.06.2026 | AB37: 00KZZJU0 | AC37: 2604000051 | AE37: 0 | AF37: 0 | AG37: 0 | AH37: 0 | AI37: KG | AJ37: 5.86 | AK37: 0.9 | AL37: 0.15 | AM37: 29.1 | AN37: 1.96 | AO37: 0 | AP37: 0 | AQ37: EUR | AS37: EXP20260601-2772284- | AT37: EXP20260601-2772284- | AU37: 00KZZJU0 | AV37: MILVILLE JUSTINE | AW37: 7 TER IMPASSE DE LA PAIX | AZ37: 51370 | BA37: SAINT-BRICE-COURCELLES | BB37: FR | BC37: France
A38: =IF(COUNTIF(Catégories!A:A,X38)=0,"catégorie inconnue",_xlfn.XLOOKUP(X38,Catégories!A:A,Catégories!B:B)) -> Frêt | B38: =SUM(AJ38:AL38)+SUM(AN38:AP38) -> 7.43 | C38: =AN38 -> 1.64 | D38: =B38-C38 -> 5.79 | E38: =IF(AH38<>0,ROUNDUP(AH38,0),IF(BB38<>"FR","hors France",IF(AH38<>0,ROUNDUP(AH38,0),_xlfn.XLOOKUP(AJ38,'PA GLS'!B:B,'PA GLS'!A:A)))) -> 3 | F38: 2501382993 | G38: 1030219781 | H38: 30.06.2026 | I38: 2500034092 | J38: LA RUCHE LOGISTIQUE | K38: 9000009190 | L38: 46946 | M38: LA RUCHE | N38: 9000079830 | O38: BY FOUTAS | S38: 2507012387 | T38: LA RUCHE LOGISTIQUE | U38: FDS | V38: PARCEL_D01_S07 | W38: Business Parcel - Dis. 01 - Size 07 | X38: PARCEDOMESSTANDARD | Z38: 46 | AA38: 02.06.2026 | AB38: 00KZZJTV | AC38: 2604000046 | AE38: 0 | AF38: 0 | AG38: 0 | AH38: 0 | AI38: KG | AJ38: 4.74 | AK38: 0.9 | AL38: 0.15 | AM38: 29.1 | AN38: 1.64 | AO38: 0 | AP38: 0 | AQ38: EUR | AS38: EXP20260601-2772288- | AT38: EXP20260601-2772288- | AU38: 00KZZJTV | AV38: JURET NOLWEN | AW38: 19 PLACE DE L'HOTEL DE VILLE | AZ38: 49190 | BA38: ROCHEFORT-SUR-LOIRE | BB38: FR | BC38: France
A39: =IF(COUNTIF(Catégories!A:A,X39)=0,"catégorie inconnue",_xlfn.XLOOKUP(X39,Catégories!A:A,Catégories!B:B)) -> Frêt | B39: =SUM(AJ39:AL39)+SUM(AN39:AP39) -> 0 | C39: =AN39 -> 0 | D39: =B39-C39 -> 0 | E39: =IF(AH39<>0,ROUNDUP(AH39,0),IF(BB39<>"FR","hors France",IF(AH39<>0,ROUNDUP(AH39,0),_xlfn.XLOOKUP(AJ39,'PA GLS'!B:B,'PA GLS'!A:A)))) -> 2 | F39: 2501382993 | G39: 1030219781 | H39: 30.06.2026 | I39: 2500034092 | J39: LA RUCHE LOGISTIQUE | K39: 9000009190 | L39: 46946 | M39: LA RUCHE | N39: 9000079830 | O39: BY FOUTAS | S39: 2507012387 | T39: LA RUCHE LOGISTIQUE | U39: FDS | V39: FDS_D01_S01 | W39: BP FlexDelivery - Dis. 01 - Size 01 | X39: PARCEDOMESFDS | Z39: 41 | AA39: 02.06.2026 | AB39: 00KZZJTI | AC39: 2604000033 | AE39: 0 | AF39: 1 | AG39: 0 | AH39: 1.11 | AI39: KG | AJ39: 0 | AK39: 0 | AL39: 0 | AM39: 0 | AN39: 0 | AO39: 0 | AP39: 0 | AQ39: EUR | AS39: EXP20260529-2769965- | AT39: EXP20260529-2769965- | AU39: 00KZZJTI | AV39: FICHET MORGAN | AW39: 9 RUE DU DOUET | AZ39: 35510 | BA39: CESSON-SEVIGNE | BB39: FR | BC39: France
A40: =IF(COUNTIF(Catégories!A:A,X40)=0,"catégorie inconnue",_xlfn.XLOOKUP(X40,Catégories!A:A,Catégories!B:B)) -> Frêt | B40: =SUM(AJ40:AL40)+SUM(AN40:AP40) -> 0 | C40: =AN40 -> 0 | D40: =B40-C40 -> 0 | E40: =IF(AH40<>0,ROUNDUP(AH40,0),IF(BB40<>"FR","hors France",IF(AH40<>0,ROUNDUP(AH40,0),_xlfn.XLOOKUP(AJ40,'PA GLS'!B:B,'PA GLS'!A:A)))) -> 3 | F40: 2501382993 | G40: 1030219781 | H40: 30.06.2026 | I40: 2500034092 | J40: LA RUCHE LOGISTIQUE | K40: 9000009190 | L40: 46946 | M40: LA RUCHE | N40: 9000079830 | O40: BY FOUTAS | S40: 2507012387 | T40: LA RUCHE LOGISTIQUE | U40: FDS | V40: FDS_D01_S01 | W40: BP FlexDelivery - Dis. 01 - Size 01 | X40: PARCEDOMESFDS | Z40: 41 | AA40: 02.06.2026 | AB40: 00KZZJTJ | AC40: 2604000034 | AE40: 0 | AF40: 1 | AG40: 0 | AH40: 2.06 | AI40: KG | AJ40: 0 | AK40: 0 | AL40: 0 | AM40: 0 | AN40: 0 | AO40: 0 | AP40: 0 | AQ40: EUR | AS40: EXP20260529-2769861- | AT40: EXP20260529-2769861- | AU40: 00KZZJTJ | AV40: FLAMMEN AURELIE | AW40: LE GRAND BOISSIGNAN | AZ40: 56190 | BA40: NOYAL-MUZILLAC | BB40: FR | BC40: France
A41: =IF(COUNTIF(Catégories!A:A,X41)=0,"catégorie inconnue",_xlfn.XLOOKUP(X41,Catégories!A:A,Catégories!B:B)) -> Frêt | B41: =SUM(AJ41:AL41)+SUM(AN41:AP41) -> 0 | C41: =AN41 -> 0 | D41: =B41-C41 -> 0 | E41: =IF(AH41<>0,ROUNDUP(AH41,0),IF(BB41<>"FR","hors France",IF(AH41<>0,ROUNDUP(AH41,0),_xlfn.XLOOKUP(AJ41,'PA GLS'!B:B,'PA GLS'!A:A)))) -> 2 | F41: 2501382993 | G41: 1030219781 | H41: 30.06.2026 | I41: 2500034092 | J41: LA RUCHE LOGISTIQUE | K41: 9000009190 | L41: 46946 | M41: LA RUCHE | N41: 9000079830 | O41: BY FOUTAS | S41: 2507012387 | T41: LA RUCHE LOGISTIQUE | U41: FDS | V41: FDS_D01_S01 | W41: BP FlexDelivery - Dis. 01 - Size 01 | X41: PARCEDOMESFDS | Z41: 41 | AA41: 02.06.2026 | AB41: 00KZZJTK | AC41: 2604000035 | AE41: 0 | AF41: 1 | AG41: 0 | AH41: 1.18 | AI41: KG | AJ41: 0 | AK41: 0 | AL41: 0 | AM41: 0 | AN41: 0 | AO41: 0 | AP41: 0 | AQ41: EUR | AS41: EXP20260530-2771113- | AT41: EXP20260530-2771113- | AU41: 00KZZJTK | AV41: BRAIZE FREDERIC | AW41: 420 AVENUE DE LA FRUITIERE | AZ41: 74140 | BA41: SCIEZ | BB41: FR | BC41: France
... A80: =IF(COUNTIF(Catégories!A:A,X80)=0,"catégorie inconnue",_xlfn.XLOOKUP(X80,Catégories!A:A,Catégories!B:B)) -> Frêt | B80: =SUM(AJ80:AL80)+SUM(AN80:AP80) -> 6.6 | C80: =AN80 -> 1.45 | D80: =B80-C80 -> 5.15 | E80: =IF(AH80<>0,ROUNDUP(AH80,0),IF(BB80<>"FR","hors France",IF(AH80<>0,ROUNDUP(AH80,0),_xlfn.XLOOKUP(AJ80,'PA GLS'!B:B,'PA GLS'!A:A)))) -> 1 | F80: 2501382993 | G80: 1030212005 | H80: 30.06.2026 | I80: 2500034092 | J80: LA RUCHE LOGISTIQUE | K80: 9000009190 | L80: 46946 | M80: LA RUCHE | N80: 9000037814 | O80: LA RUCHE | S80: 2507012387 | T80: LA RUCHE LOGISTIQUE | U80: FDS | V80: PARCEL_D01_S03 | W80: Business Parcel - Dis. 01 - Size 03 | X80: PARCEDOMESSTANDARD | Z80: 30 | AA80: 02.06.2026 | AB80: 00KUR5U6 | AC80: 2604000024 | AE80: 0 | AF80: 0 | AG80: 0 | AH80: 0 | AI80: KG | AJ80: 4.1 | AK80: 0.9 | AL80: 0.15 | AM80: 29.1 | AN80: 1.45 | AO80: 0 | AP80: 0 | AQ80: EUR | AS80: EXP20260602-2775672- | AT80: EXP20260602-2775672- | AU80: 00KUR5U6 | AV80: LEVEQUE GUILLAUME | AW80: 1251 ROUTE DE LA TELECABINE | AZ80: 1170 | BA80: CROZET | BB80: FR | BC80: France
A81: =IF(COUNTIF(Catégories!A:A,X81)=0,"catégorie inconnue",_xlfn.XLOOKUP(X81,Catégories!A:A,Catégories!B:B)) -> Frêt | B81: =SUM(AJ81:AL81)+SUM(AN81:AP81) -> 0 | C81: =AN81 -> 0 | D81: =B81-C81 -> 0 | E81: =IF(AH81<>0,ROUNDUP(AH81,0),IF(BB81<>"FR","hors France",IF(AH81<>0,ROUNDUP(AH81,0),_xlfn.XLOOKUP(AJ81,'PA GLS'!B:B,'PA GLS'!A:A)))) -> 1 | F81: 2501382993 | G81: 1030216444 | H81: 30.06.2026 | I81: 2500034092 | J81: LA RUCHE LOGISTIQUE | K81: 9000009190 | L81: 46946 | M81: LA RUCHE | N81: 9000082822 | O81: Laboratoires Christian Roche | S81: 2507012387 | T81: LA RUCHE LOGISTIQUE | U81: FDS | V81: FDS_D01_S01 | W81: BP FlexDelivery - Dis. 01 - Size 01 | X81: PARCEDOMESFDS | Z81: 31 | AA81: 02.06.2026 | AB81: 00L0DR8P | AC81: 6694240 | AE81: 0 | AF81: 1 | AG81: 0 | AH81: 0.2 | AI81: KG | AJ81: 0 | AK81: 0 | AL81: 0 | AM81: 0 | AN81: 0 | AO81: 0 | AP81: 0 | AQ81: EUR | AS81: EXP20260601-2774231 | AU81: 00L0DR8P | AV81: AXEL TELECOM | AW81: 64 RUE DE LA REPUBLIQUE | AX81: KRIMOVICH FABIENNE | AZ81: 76000 | BA81: ROUEN | BB81: FR | BC81: France
A82: =IF(COUNTIF(Catégories!A:A,X82)=0,"catégorie inconnue",_xlfn.XLOOKUP(X82,Catégories!A:A,Catégories!B:B)) -> Frêt | B82: =SUM(AJ82:AL82)+SUM(AN82:AP82) -> 0 | C82: =AN82 -> 0 | D82: =B82-C82 -> 0 | E82: =IF(AH82<>0,ROUNDUP(AH82,0),IF(BB82<>"FR","hors France",IF(AH82<>0,ROUNDUP(AH82,0),_xlfn.XLOOKUP(AJ82,'PA GLS'!B:B,'PA GLS'!A:A)))) -> 3 | F82: 2501382993 | G82: 1030216444 | H82: 30.06.2026 | I82: 2500034092 | J82: LA RUCHE LOGISTIQUE | K82: 9000009190 | L82: 46946 | M82: LA RUCHE | N82: 9000082822 | O82: Laboratoires Christian Roche | S82: 2507012387 | T82: LA RUCHE LOGISTIQUE | U82: FDS | V82: FDS_D01_S01 | W82: BP FlexDelivery - Dis. 01 - Size 01 | X82: PARCEDOMESFDS | Z82: 31 | AA82: 02.06.2026 | AB82: 00L0DT0Y | AC82: 6694523 | AE82: 0 | AF82: 1 | AG82: 0 | AH82: 2.7 | AI82: KG | AJ82: 0 | AK82: 0 | AL82: 0 | AM82: 0 | AN82: 0 | AO82: 0 | AP82: 0 | AQ82: EUR | AS82: EXP20260601-2774558 | AU82: 00L0DT0Y | AV82: PHARMACIE TALENSAC | AW82: 19 RUE BEL AIR | AX82: DENYS HELENE | AZ82: 44000 | BA82: NANTES | BB82: FR | BC82: France
A83: =IF(COUNTIF(Catégories!A:A,X83)=0,"catégorie inconnue",_xlfn.XLOOKUP(X83,Catégories!A:A,Catégories!B:B)) -> Frêt | B83: =SUM(AJ83:AL83)+SUM(AN83:AP83) -> 0 | C83: =AN83 -> 0 | D83: =B83-C83 -> 0 | E83: =IF(AH83<>0,ROUNDUP(AH83,0),IF(BB83<>"FR","hors France",IF(AH83<>0,ROUNDUP(AH83,0),_xlfn.XLOOKUP(AJ83,'PA GLS'!B:B,'PA GLS'!A:A)))) -> 1 | F83: 2501382993 | G83: 1030216444 | H83: 30.06.2026 | I83: 2500034092 | J83: LA RUCHE LOGISTIQUE | K83: 9000009190 | L83: 46946 | M83: LA RUCHE | N83: 9000082822 | O83: Laboratoires Christian Roche | S83: 2507012387 | T83: LA RUCHE LOGISTIQUE | U83: FDS | V83: FDS_D01_S01 | W83: BP FlexDelivery - Dis. 01 - Size 01 | X83: PARCEDOMESFDS | Z83: 31 | AA83: 02.06.2026 | AB83: 00L0DT2S | AC83: 6694589 | AE83: 0 | AF83: 1 | AG83: 0 | AH83: 0.77 | AI83: KG | AJ83: 0 | AK83: 0 | AL83: 0 | AM83: 0 | AN83: 0 | AO83: 0 | AP83: 0 | AQ83: EUR | AS83: EXP20260601-2774236 | AU83: 00L0DT2S | AV83: LES PLOMBIERS DU VERCORS | AW83: 25 ALLEE DU LYONNAIS ZI NORD | AX83: RONDEL CATHERINE | AZ83: 26300 | BA83: BOURG DE PEAGE | BB83: FR | BC83: France
A84: =IF(COUNTIF(Catégories!A:A,X84)=0,"catégorie inconnue",_xlfn.XLOOKUP(X84,Catégories!A:A,Catégories!B:B)) -> Frêt | B84: =SUM(AJ84:AL84)+SUM(AN84:AP84) -> 6.17 | C84: =AN84 -> 1.35 | D84: =B84-C84 -> 4.82 | E84: =IF(AH84<>0,ROUNDUP(AH84,0),IF(BB84<>"FR","hors France",IF(AH84<>0,ROUNDUP(AH84,0),_xlfn.XLOOKUP(AJ84,'PA GLS'!B:B,'PA GLS'!A:A)))) -> 0.5 | F84: 2501382993 | G84: 1030216444 | H84: 30.06.2026 | I84: 2500034092 | J84: LA RUCHE LOGISTIQUE | K84: 9000009190 | L84: 46946 | M84: LA RUCHE | N84: 9000082822 | O84: Laboratoires Christian Roche | S84: 2507012387 | T84: LA RUCHE LOGISTIQUE | U84: FDS | V84: PARCEL_D01_S01 | W84: Business Parcel - Dis. 01 - Size 01 | X84: PARCEDOMESSTANDARD | Z84: 32 | AA84: 02.06.2026 | AB84: 00L0DR8P | AC84: 6694240 | AE84: 0 | AF84: 0 | AG84: 0 | AH84: 0 | AI84: KG | AJ84: 3.77 | AK84: 0.9 | AL84: 0.15 | AM84: 29.1 | AN84: 1.35 | AO84: 0 | AP84: 0 | AQ84: EUR | AS84: EXP20260601-2774231 | AU84: 00L0DR8P | AV84: AXEL TELECOM | AW84: 64 RUE DE LA REPUBLIQUE | AX84: KRIMOVICH FABIENNE | AZ84: 76000 | BA84: ROUEN | BB84: FR | BC84: France
A85: =IF(COUNTIF(Catégories!A:A,X85)=0,"catégorie inconnue",_xlfn.XLOOKUP(X85,Catégories!A:A,Catégories!B:B)) -> Frêt | B85: =SUM(AJ85:AL85)+SUM(AN85:AP85) -> 6.6 | C85: =AN85 -> 1.45 | D85: =B85-C85 -> 5.15 | E85: =IF(AH85<>0,ROUNDUP(AH85,0),IF(BB85<>"FR","hors France",IF(AH85<>0,ROUNDUP(AH85,0),_xlfn.XLOOKUP(AJ85,'PA GLS'!B:B,'PA GLS'!A:A)))) -> 1 | F85: 2501382993 | G85: 1030216444 | H85: 30.06.2026 | I85: 2500034092 | J85: LA RUCHE LOGISTIQUE | K85: 9000009190 | L85: 46946 | M85: LA RUCHE | N85: 9000082822 | O85: Laboratoires Christian Roche | S85: 2507012387 | T85: LA RUCHE LOGISTIQUE | U85: FDS | V85: PARCEL_D01_S04 | W85: Business Parcel - Dis. 01 - Size 04 | X85: PARCEDOMESSTANDARD | Z85: 33 | AA85: 02.06.2026 | AB85: 00L0DT2S | AC85: 6694589 | AE85: 0 | AF85: 0 | AG85: 0 | AH85: 0 | AI85: KG | AJ85: 4.1 | AK85: 0.9 | AL85: 0.15 | AM85: 29.1 | AN85: 1.45 | AO85: 0 | AP85: 0 | AQ85: EUR | AS85: EXP20260601-2774236 | AU85: 00L0DT2S | AV85: LES PLOMBIERS DU VERCORS | AW85: 25 ALLEE DU LYONNAIS ZI NORD | AX85: RONDEL CATHERINE | AZ85: 26300 | BA85: BOURG DE PEAGE | BB85: FR | BC85: France
A86: =IF(COUNTIF(Catégories!A:A,X86)=0,"catégorie inconnue",_xlfn.XLOOKUP(X86,Catégories!A:A,Catégories!B:B)) -> Frêt | B86: =SUM(AJ86:AL86)+SUM(AN86:AP86) -> 7.43 | C86: =AN86 -> 1.64 | D86: =B86-C86 -> 5.79 | E86: =IF(AH86<>0,ROUNDUP(AH86,0),IF(BB86<>"FR","hors France",IF(AH86<>0,ROUNDUP(AH86,0),_xlfn.XLOOKUP(AJ86,'PA GLS'!B:B,'PA GLS'!A:A)))) -> 3 | F86: 2501382993 | G86: 1030216444 | H86: 30.06.2026 | I86: 2500034092 | J86: LA RUCHE LOGISTIQUE | K86: 9000009190 | L86: 46946 | M86: LA RUCHE | N86: 9000082822 | O86: Laboratoires Christian Roche | S86: 2507012387 | T86: LA RUCHE LOGISTIQUE | U86: FDS | V86: PARCEL_D01_S07 | W86: Business Parcel - Dis. 01 - Size 07 | X86: PARCEDOMESSTANDARD | Z86: 34 | AA86: 02.06.2026 | AB86: 00L0DT0Y | AC86: 6694523 | AE86: 0 | AF86: 0 | AG86: 0 | AH86: 0 | AI86: KG | AJ86: 4.74 | AK86: 0.9 | AL86: 0.15 | AM86: 29.1 | AN86: 1.64 | AO86: 0 | AP86: 0 | AQ86: EUR | AS86: EXP20260601-2774558 | AU86: 00L0DT0Y | AV86: PHARMACIE TALENSAC | AW86: 19 RUE BEL AIR | AX86: DENYS HELENE | AZ86: 44000 | BA86: NANTES | BB86: FR | BC86: France
A87: =IF(COUNTIF(Catégories!A:A,X87)=0,"catégorie inconnue",_xlfn.XLOOKUP(X87,Catégories!A:A,Catégories!B:B)) -> Frêt | B87: =SUM(AJ87:AL87)+SUM(AN87:AP87) -> 7.01 | C87: =AN87 -> 1.54 | D87: =B87-C87 -> 5.47 | E87: =IF(AH87<>0,ROUNDUP(AH87,0),IF(BB87<>"FR","hors France",IF(AH87<>0,ROUNDUP(AH87,0),_xlfn.XLOOKUP(AJ87,'PA GLS'!B:B,'PA GLS'!A:A)))) -> 2 | F87: 2501382993 | G87: 1030219781 | H87: 30.06.2026 | I87: 2500034092 | J87: LA RUCHE LOGISTIQUE | K87: 9000009190 | L87: 46946 | M87: LA RUCHE | N87: 9000079830 | O87: BY FOUTAS | S87: 2507012387 | T87: LA RUCHE LOGISTIQUE | U87: FDS | V87: PARCEL_D01_S06 | W87: Business Parcel - Dis. 01 - Size 06 | X87: PARCEDOMESSTANDARD | Z87: 45 | AA87: 02.06.2026 | AB87: 00KZZJTM | AC87: 2604000037 | AE87: 0 | AF87: 0 | AG87: 0 | AH87: 0 | AI87: KG | AJ87: 4.42 | AK87: 0.9 | AL87: 0.15 | AM87: 29.1 | AN87: 1.54 | AO87: 0 | AP87: 0 | AQ87: EUR | AS87: EXP20260530-2771657- | AT87: EXP20260530-2771657- | AU87: 00KZZJTM | AV87: HARTMANN CHARLOTTE | AW87: 222 CHEMIN DENTABOR | AZ87: 31450 | BA87: BAZIEGE | BB87: FR | BC87: France
A88: =IF(COUNTIF(Catégories!A:A,X88)=0,"catégorie inconnue",_xlfn.XLOOKUP(X88,Catégories!A:A,Catégories!B:B)) -> Frêt | B88: =SUM(AJ88:AL88)+SUM(AN88:AP88) -> 7.01 | C88: =AN88 -> 1.54 | D88: =B88-C88 -> 5.47 | E88: =IF(AH88<>0,ROUNDUP(AH88,0),IF(BB88<>"FR","hors France",IF(AH88<>0,ROUNDUP(AH88,0),_xlfn.XLOOKUP(AJ88,'PA GLS'!B:B,'PA GLS'!A:A)))) -> 2 | F88: 2501382993 | G88: 1030219781 | H88: 30.06.2026 | I88: 2500034092 | J88: LA RUCHE LOGISTIQUE | K88: 9000009190 | L88: 46946 | M88: LA RUCHE | N88: 9000079830 | O88: BY FOUTAS | S88: 2507012387 | T88: LA RUCHE LOGISTIQUE | U88: FDS | V88: PARCEL_D01_S05 | W88: Business Parcel - Dis. 01 - Size 05 | X88: PARCEDOMESSTANDARD | Z88: 44 | AA88: 02.06.2026 | AB88: 00KZZJU1 | AC88: 2604000052 | AE88: 0 | AF88: 0 | AG88: 0 | AH88: 0 | AI88: KG | AJ88: 4.42 | AK88: 0.9 | AL88: 0.15 | AM88: 29.1 | AN88: 1.54 | AO88: 0 | AP88: 0 | AQ88: EUR | AS88: EXP20260601-2774809- | AT88: EXP20260601-2774809- | AU88: 00KZZJU1 | AV88: ROSET SOPHIE | AW88: 10 RUE DU MOULIN | AZ88: 92170 | BA88: VANVES | BB88: FR | BC88: France
A89: =IF(COUNTIF(Catégories!A:A,X89)=0,"catégorie inconnue",_xlfn.XLOOKUP(X89,Catégories!A:A,Catégories!B:B)) -> Frêt | B89: =SUM(AJ89:AL89)+SUM(AN89:AP89) -> 7.01 | C89: =AN89 -> 1.54 | D89: =B89-C89 -> 5.47 | E89: =IF(AH89<>0,ROUNDUP(AH89,0),IF(BB89<>"FR","hors France",IF(AH89<>0,ROUNDUP(AH89,0),_xlfn.XLOOKUP(AJ89,'PA GLS'!B:B,'PA GLS'!A:A)))) -> 2 | F89: 2501382993 | G89: 1030219781 | H89: 30.06.2026 | I89: 2500034092 | J89: LA RUCHE LOGISTIQUE | K89: 9000009190 | L89: 46946 | M89: LA RUCHE | N89: 9000079830 | O89: BY FOUTAS | S89: 2507012387 | T89: LA RUCHE LOGISTIQUE | U89: FDS | V89: PARCEL_D01_S05 | W89: Business Parcel - Dis. 01 - Size 05 | X89: PARCEDOMESSTANDARD | Z89: 44 | AA89: 02.06.2026 | AB89: 00KZZJTZ | AC89: 2604000050 | AE89: 0 | AF89: 0 | AG89: 0 | AH89: 0 | AI89: KG | AJ89: 4.42 | AK89: 0.9 | AL89: 0.15 | AM89: 29.1 | AN89: 1.54 | AO89: 0 | AP89: 0 | AQ89: EUR | AS89: EXP20260531-2771802- | AT89: EXP20260531-2771802- | AU89: 00KZZJTZ | AV89: ROBINSON THOMAS | AW89: 4 BOULEVARD GRIFFOUL DORVAL | AZ89: 31400 | BA89: TOULOUSE | BB89: FR | BC89: France
A90: =IF(COUNTIF(Catégories!A:A,X90)=0,"catégorie inconnue",_xlfn.XLOOKUP(X90,Catégories!A:A,Catégories!B:B)) -> Frêt | B90: =SUM(AJ90:AL90)+SUM(AN90:AP90) -> 7.01 | C90: =AN90 -> 1.54 | D90: =B90-C90 -> 5.47 | E90: =IF(AH90<>0,ROUNDUP(AH90,0),IF(BB90<>"FR","hors France",IF(AH90<>0,ROUNDUP(AH90,0),_xlfn.XLOOKUP(AJ90,'PA GLS'!B:B,'PA GLS'!A:A)))) -> 2 | F90: 2501382993 | G90: 1030219781 | H90: 30.06.2026 | I90: 2500034092 | J90: LA RUCHE LOGISTIQUE | K90: 9000009190 | L90: 46946 | M90: LA RUCHE | N90: 9000079830 | O90: BY FOUTAS | S90: 2507012387 | T90: LA RUCHE LOGISTIQUE | U90: FDS | V90: PARCEL_D01_S05 | W90: Business Parcel - Dis. 01 - Size 05 | X90: PARCEDOMESSTANDARD | Z90: 44 | AA90: 02.06.2026 | AB90: 00KZZJTW | AC90: 2604000047 | AE90: 0 | AF90: 0 | AG90: 0 | AH90: 0 | AI90: KG | AJ90: 4.42 | AK90: 0.9 | AL90: 0.15 | AM90: 29.1 | AN90: 1.54 | AO90: 0 | AP90: 0 | AQ90: EUR | AS90: EXP20260601-2772291- | AT90: EXP20260601-2772291- | AU90: 00KZZJTW | AV90: BUISSON JESSICA | AW90: 11 RUE DE L'ANCIEN LAVOIR | AZ90: 90110 | BA90: ROUGEMONT-LE-CHATEAU | BB90: FR | BC90: France
...

Sheet TCD
D1: Nom compte exploit. | E1: (Tous) | P1: Total | Q1: =SUM('Facture GLS'!B:B) -> 3069.2 | R1: HT | S1: =Q1*1.2 -> 3683.04 | T1: TTC
A2: Total GO | B2: Total | C2: ID clients | O2: tracking | P2: Gazole | Q2: =SUM('Facture GLS'!AN:AN) -> 669.88 | R2: =Q2/Q3 -> 0.27919577
A3: =B3*(1+$R$2) -> 0 | B3: =SUM(E3:L3) -> 0 | D3: Somme de Total HT (hors gazole) | E3: Catégorie | P3: Hors gazole | Q3: =Q1-Q2 -> 2399.32
A4: =B4*(1+$R$2) -> 0 | B4: =SUM(E4:L4) -> 0 | D4: NumÃ©ro de colis | E4: Adresse | F4: Colis volumineux | G4: Frais de gestion | H4: Frêt | I4: Frêt - avisé | J4: Frêt - retour | K4: Zone éloignée | L4: ZZ_Ramasse unicolis | M4: (vide)
A5: =B5*(1+$R$2) -> 0 | B5: =SUM(E5:L5) -> 0 | D5: 00KUR5TU | I5: 0 | N5: =D5&"R" -> 00KUR5TUR | P5: Taux gazole | Q5: 45689 | R5: 0.309
A6: =B6*(1+$R$2) -> 6.1657236 | B6: =SUM(E6:L6) -> 4.82 | D6: 00KUR5TX | H6: 4.82 | N6: =D6&"R" -> 00KUR5TXR
A7: =B7*(1+$R$2) -> 6.1657236 | B7: =SUM(E7:L7) -> 4.82 | D7: 00KUR5TY | H7: 4.82 | N7: =D7&"R" -> 00KUR5TYR | P7: Fichier import | Q7: =SUM('Import csv'!P:V) -> 2365.61
A8: =B8*(1+$R$2) -> 6.1657236 | B8: =SUM(E8:L8) -> 4.82 | D8: 00KUR5TZ | H8: 4.82 | N8: =D8&"R" -> 00KUR5TZR | P8: Ecart | Q8: =Q3-Q7 -> 33.71 | R8: Frais de gestion ok | T8: 45992
A9: =B9*(1+$R$2) -> 6.1657236 | B9: =SUM(E9:L9) -> 4.82 | D9: 00KUR5U0 | H9: 4.82 | N9: =D9&"R" -> 00KUR5U0R
A10: =B10*(1+$R$2) -> 11.832561 | B10: =SUM(E10:L10) -> 9.25 | D10: 00KUR5U1 | H10: 5.15 | J10: 4.1 | N10: =D10&"R" -> 00KUR5U1R
A11: =B11*(1+$R$2) -> 10.988292 | B11: =SUM(E11:L11) -> 8.59 | D11: 00KUR5U2 | H11: 4.82 | I11: 0 | J11: 3.77 | N11: =D11&"R" -> 00KUR5U2R
A12: =B12*(1+$R$2) -> 6.1657236 | B12: =SUM(E12:L12) -> 4.82 | D12: 00KUR5U3 | H12: 4.82 | N12: =D12&"R" -> 00KUR5U3R
A13: =B13*(1+$R$2) -> 6.5878582 | B13: =SUM(E13:L13) -> 5.15 | D13: 00KUR5U4 | H13: 5.15 | N13: =D13&"R" -> 00KUR5U4R
A14: =B14*(1+$R$2) -> 6.5878582 | B14: =SUM(E14:L14) -> 5.15 | D14: 00KUR5U5 | H14: 5.15 | N14: =D14&"R" -> 00KUR5U5R
A15: =B15*(1+$R$2) -> 6.5878582 | B15: =SUM(E15:L15) -> 5.15 | D15: 00KUR5U6 | H15: 5.15 | N15: =D15&"R" -> 00KUR5U6R
A16: =B16*(1+$R$2) -> 6.1657236 | B16: =SUM(E16:L16) -> 4.82 | D16: 00KUR5U7 | H16: 4.82 | N16: =D16&"R" -> 00KUR5U7R
A17: =B17*(1+$R$2) -> 6.5878582 | B17: =SUM(E17:L17) -> 5.15 | D17: 00KUR5U8 | H17: 5.15 | N17: =D17&"R" -> 00KUR5U8R
A18: =B18*(1+$R$2) -> 6.1657236 | B18: =SUM(E18:L18) -> 4.82 | D18: 00KUR5U9 | H18: 4.82 | N18: =D18&"R" -> 00KUR5U9R
A19: =B19*(1+$R$2) -> 6.5878582 | B19: =SUM(E19:L19) -> 5.15 | D19: 00KUR5UA | H19: 5.15 | N19: =D19&"R" -> 00KUR5UAR
A20: =B20*(1+$R$2) -> 6.5878582 | B20: =SUM(E20:L20) -> 5.15 | D20: 00KUR5UB | H20: 5.15 | N20: =D20&"R" -> 00KUR5UBR
A21: =B21*(1+$R$2) -> 6.1657236 | B21: =SUM(E21:L21) -> 4.82 | D21: 00KUR5UC | H21: 4.82 | N21: =D21&"R" -> 00KUR5UCR
A22: =B22*(1+$R$2) -> 6.1657236 | B22: =SUM(E22:L22) -> 4.82 | D22: 00KUR5UD | H22: 4.82 | N22: =D22&"R" -> 00KUR5UDR
A23: =B23*(1+$R$2) -> 7.4065435 | B23: =SUM(E23:L23) -> 5.79 | D23: 00KUR5UE | H23: 5.79 | N23: =D23&"R" -> 00KUR5UER
... A37: =B37*(1+$R$2) -> 6.1657236 | B37: =SUM(E37:L37) -> 4.82 | D37: 00KUR5US | H37: 4.82 | N37: =D37&"R" -> 00KUR5USR
A38: =B38*(1+$R$2) -> 12.651246 | B38: =SUM(E38:L38) -> 9.89 | D38: 00KUR5UT | H38: 5.47 | J38: 4.42 | N38: =D38&"R" -> 00KUR5UTR
A39: =B39*(1+$R$2) -> 6.5878582 | B39: =SUM(E39:L39) -> 5.15 | D39: 00KUR5UU | H39: 5.15 | N39: =D39&"R" -> 00KUR5UUR
A40: =B40*(1+$R$2) -> 8.8392428 | B40: =SUM(E40:L40) -> 6.91 | D40: 00KUR5UV | H40: 6.91 | N40: =D40&"R" -> 00KUR5UVR
A41: =B41*(1+$R$2) -> 6.1657236 | B41: =SUM(E41:L41) -> 4.82 | D41: 00KUR5UW | H41: 4.82 | N41: =D41&"R" -> 00KUR5UWR
A42: =B42*(1+$R$2) -> 6.9972009 | B42: =SUM(E42:L42) -> 5.47 | D42: 00KUR5UX | H42: 5.47 | N42: =D42&"R" -> 00KUR5UXR
A43: =B43*(1+$R$2) -> 6.5878582 | B43: =SUM(E43:L43) -> 5.15 | D43: 00KUR5UY | H43: 5.15 | N43: =D43&"R" -> 00KUR5UYR
A44: =B44*(1+$R$2) -> 6.1657236 | B44: =SUM(E44:L44) -> 4.82 | D44: 00KUR5UZ | H44: 4.82 | N44: =D44&"R" -> 00KUR5UZR
A45: =B45*(1+$R$2) -> 6.5878582 | B45: =SUM(E45:L45) -> 5.15 | D45: 00KUR5V0 | H45: 5.15 | N45: =D45&"R" -> 00KUR5V0R
A46: =B46*(1+$R$2) -> 6.1657236 | B46: =SUM(E46:L46) -> 4.82 | D46: 00KUR5V1 | H46: 4.82 | N46: =D46&"R" -> 00KUR5V1R
A47: =B47*(1+$R$2) -> 6.1657236 | B47: =SUM(E47:L47) -> 4.82 | D47: 00KUR5V2 | H47: 4.82 | N47: =D47&"R" -> 00KUR5V2R
A48: =B48*(1+$R$2) -> 8.1228932 | B48: =SUM(E48:L48) -> 6.35 | D48: 00KUR5V3 | H48: 6.35 | N48: =D48&"R" -> 00KUR5V3R
A49: =B49*(1+$R$2) -> 6.5878582 | B49: =SUM(E49:L49) -> 5.15 | D49: 00KUR5V4 | H49: 5.15 | N49: =D49&"R" -> 00KUR5V4R
A50: =B50*(1+$R$2) -> 6.5878582 | B50: =SUM(E50:L50) -> 5.15 | D50: 00KUR5V5 | H50: 5.15 | N50: =D50&"R" -> 00KUR5V5R
A51: =B51*(1+$R$2) -> 6.1657236 | B51: =SUM(E51:L51) -> 4.82 | D51: 00KUR5V6 | H51: 4.82 | N51: =D51&"R" -> 00KUR5V6R
A52: =B52*(1+$R$2) -> 10.016103 | B52: =SUM(E52:L52) -> 7.83 | D52: 00KUR5V7 | E52: 2.36 | H52: 5.47 | I52: 0 | N52: =D52&"R" -> 00KUR5V7R
A53: =B53*(1+$R$2) -> 6.5878582 | B53: =SUM(E53:L53) -> 5.15 | D53: 00KUR5V8 | H53: 5.15 | N53: =D53&"R" -> 00KUR5V8R
...

Sheet Import csv
A1: SENEA | B1: Transporteur | C1: Date validité tarif | D1: Réf.1 | E1: Réf. 2 | F1: Id client | G1: N° Tracking | H1: Nom | I1: E / P | J1: Pays | K1: Zone | L1: Nbr Colis | M1: Poids | N1: mode envoi | O1: TVA | P1: Droits et taxes | Q1: Assurance | R1: Zones éloignées | S1: Colis volumineux | T1: Adresses | U1: Frêt | V1: plus-value BtoC | W1: Gazole
A2: =_xlfn.XLOOKUP(G2,'Facture GLS'!AB:AB,'Facture GLS'!O:O) -> #N/A | B2: GLS | C2: 46174 | G2: =TCD!D3 -> Somme de Total HT (hors gazole) | I2: P | J2: =_xlfn.XLOOKUP(G2,'Facture GLS'!AB:AB,'Facture GLS'!BB:BB) -> #N/A | K2: =IF(COUNTIF(Zoning!A:A,J2)=0,"pays inconnu",LOOKUP(J2,Zoning!A:A,Zoning!B:B)) -> pays inconnu | L2: 1 | M2: =_xlfn.XLOOKUP(G2,Poids!A:A,Poids!C:C) -> #N/A | N2: =IF(COUNTIF(Zoning!A:A,J2)=0,"zone inconnue","France") -> zone inconnue | O2: =IF(COUNTIF(Zoning!A:A,J2)=0,"taux inconnu",_xlfn.XLOOKUP(J2,Zoning!A:A,Zoning!C:C)) -> taux inconnu | R2: =IF(TCD!K3="","",TCD!K3) | S2: =IF(TCD!F3="","",TCD!F3) | T2: =IF(TCD!E3="","",TCD!E3) -> Catégorie | U2: =SUM(TCD!H3:J3) -> 0
A3: =_xlfn.XLOOKUP(G3,'Facture GLS'!AB:AB,'Facture GLS'!O:O) -> Nom compte exploit. | B3: =B2 -> GLS | C3: =C2 -> 46174 | G3: =TCD!D4 -> NumÃ©ro de colis | I3: P | J3: =_xlfn.XLOOKUP(G3,'Facture GLS'!AB:AB,'Facture GLS'!BB:BB) -> Code Pays | K3: =IF(COUNTIF(Zoning!A:A,J3)=0,"pays inconnu",LOOKUP(J3,Zoning!A:A,Zoning!B:B)) -> pays inconnu | L3: =L2 -> 1 | M3: =_xlfn.XLOOKUP(G3,Poids!A:A,Poids!C:C) -> #N/A | N3: =IF(COUNTIF(Zoning!A:A,J3)=0,"zone inconnue","France") -> zone inconnue | O3: =IF(COUNTIF(Zoning!A:A,J3)=0,"taux inconnu",_xlfn.XLOOKUP(J3,Zoning!A:A,Zoning!C:C)) -> taux inconnu | R3: =IF(TCD!K4="","",TCD!K4) -> Zone éloignée | S3: =IF(TCD!F4="","",TCD!F4) -> Colis volumineux | T3: =IF(TCD!E4="","",TCD!E4) -> Adresse | U3: =SUM(TCD!H4:J4) -> 0 | W3: RENSEIGNER LES POIDS
A4: =_xlfn.XLOOKUP(G4,'Facture GLS'!AB:AB,'Facture GLS'!O:O) -> LA RUCHE | B4: =B3 -> GLS | C4: =C3 -> 46174 | G4: =TCD!D5 -> 00KUR5TU | I4: P | J4: =_xlfn.XLOOKUP(G4,'Facture GLS'!AB:AB,'Facture GLS'!BB:BB) -> FR | K4: =IF(COUNTIF(Zoning!A:A,J4)=0,"pays inconnu",LOOKUP(J4,Zoning!A:A,Zoning!B:B)) -> France | L4: =L3 -> 1 | M4: =_xlfn.XLOOKUP(G4,Poids!A:A,Poids!C:C) -> 0 | N4: =IF(COUNTIF(Zoning!A:A,J4)=0,"zone inconnue","France") -> France | O4: =IF(COUNTIF(Zoning!A:A,J4)=0,"taux inconnu",_xlfn.XLOOKUP(J4,Zoning!A:A,Zoning!C:C)) -> 0.2 | R4: =IF(TCD!K5="","",TCD!K5) | S4: =IF(TCD!F5="","",TCD!F5) | T4: =IF(TCD!E5="","",TCD!E5) | U4: =SUM(TCD!H5:J5) -> 0
A5: =_xlfn.XLOOKUP(G5,'Facture GLS'!AB:AB,'Facture GLS'!O:O) -> LA RUCHE | B5: =B4 -> GLS | C5: =C4 -> 46174 | G5: =TCD!D6 -> 00KUR5TX | I5: P | J5: =_xlfn.XLOOKUP(G5,'Facture GLS'!AB:AB,'Facture GLS'!BB:BB) -> FR | K5: =IF(COUNTIF(Zoning!A:A,J5)=0,"pays inconnu",LOOKUP(J5,Zoning!A:A,Zoning!B:B)) -> France | L5: =L4 -> 1 | M5: =_xlfn.XLOOKUP(G5,Poids!A:A,Poids!C:C) -> 0.3 | N5: =IF(COUNTIF(Zoning!A:A,J5)=0,"zone inconnue","France") -> France | O5: =IF(COUNTIF(Zoning!A:A,J5)=0,"taux inconnu",_xlfn.XLOOKUP(J5,Zoning!A:A,Zoning!C:C)) -> 0.2 | R5: =IF(TCD!K6="","",TCD!K6) | S5: =IF(TCD!F6="","",TCD!F6) | T5: =IF(TCD!E6="","",TCD!E6) | U5: =SUM(TCD!H6:J6) -> 4.82
A6: =_xlfn.XLOOKUP(G6,'Facture GLS'!AB:AB,'Facture GLS'!O:O) -> LA RUCHE | B6: =B5 -> GLS | C6: =C5 -> 46174 | G6: =TCD!D7 -> 00KUR5TY | I6: P | J6: =_xlfn.XLOOKUP(G6,'Facture GLS'!AB:AB,'Facture GLS'!BB:BB) -> FR | K6: =IF(COUNTIF(Zoning!A:A,J6)=0,"pays inconnu",LOOKUP(J6,Zoning!A:A,Zoning!B:B)) -> France | L6: =L5 -> 1 | M6: =_xlfn.XLOOKUP(G6,Poids!A:A,Poids!C:C) -> 0.3 | N6: =IF(COUNTIF(Zoning!A:A,J6)=0,"zone inconnue","France") -> France | O6: =IF(COUNTIF(Zoning!A:A,J6)=0,"taux inconnu",_xlfn.XLOOKUP(J6,Zoning!A:A,Zoning!C:C)) -> 0.2 | R6: =IF(TCD!K7="","",TCD!K7) | S6: =IF(TCD!F7="","",TCD!F7) | T6: =IF(TCD!E7="","",TCD!E7) | U6: =SUM(TCD!H7:J7) -> 4.82
A7: =_xlfn.XLOOKUP(G7,'Facture GLS'!AB:AB,'Facture GLS'!O:O) -> LA RUCHE | B7: =B6 -> GLS | C7: =C6 -> 46174 | G7: =TCD!D8 -> 00KUR5TZ | I7: P | J7: =_xlfn.XLOOKUP(G7,'Facture GLS'!AB:AB,'Facture GLS'!BB:BB) -> FR | K7: =IF(COUNTIF(Zoning!A:A,J7)=0,"pays inconnu",LOOKUP(J7,Zoning!A:A,Zoning!B:B)) -> France | L7: =L6 -> 1 | M7: =_xlfn.XLOOKUP(G7,Poids!A:A,Poids!C:C) -> 0.3 | N7: =IF(COUNTIF(Zoning!A:A,J7)=0,"zone inconnue","France") -> France | O7: =IF(COUNTIF(Zoning!A:A,J7)=0,"taux inconnu",_xlfn.XLOOKUP(J7,Zoning!A:A,Zoning!C:C)) -> 0.2 | R7: =IF(TCD!K8="","",TCD!K8) | S7: =IF(TCD!F8="","",TCD!F8) | T7: =IF(TCD!E8="","",TCD!E8) | U7: =SUM(TCD!H8:J8) -> 4.82
A8: =_xlfn.XLOOKUP(G8,'Facture GLS'!AB:AB,'Facture GLS'!O:O) -> LA RUCHE | B8: =B7 -> GLS | C8: =C7 -> 46174 | G8: =TCD!D9 -> 00KUR5U0 | I8: P | J8: =_xlfn.XLOOKUP(G8,'Facture GLS'!AB:AB,'Facture GLS'!BB:BB) -> FR | K8: =IF(COUNTIF(Zoning!A:A,J8)=0,"pays inconnu",LOOKUP(J8,Zoning!A:A,Zoning!B:B)) -> France | L8: =L7 -> 1 | M8: =_xlfn.XLOOKUP(G8,Poids!A:A,Poids!C:C) -> 0.3 | N8: =IF(COUNTIF(Zoning!A:A,J8)=0,"zone inconnue","France") -> France | O8: =IF(COUNTIF(Zoning!A:A,J8)=0,"taux inconnu",_xlfn.XLOOKUP(J8,Zoning!A:A,Zoning!C:C)) -> 0.2 | R8: =IF(TCD!K9="","",TCD!K9) | S8: =IF(TCD!F9="","",TCD!F9) | T8: =IF(TCD!E9="","",TCD!E9) | U8: =SUM(TCD!H9:J9) -> 4.82
A9: =_xlfn.XLOOKUP(G9,'Facture GLS'!AB:AB,'Facture GLS'!O:O) -> LA RUCHE | B9: =B8 -> GLS | C9: =C8 -> 46174 | G9: =TCD!D10 -> 00KUR5U1 | I9: P | J9: =_xlfn.XLOOKUP(G9,'Facture GLS'!AB:AB,'Facture GLS'!BB:BB) -> FR | K9: =IF(COUNTIF(Zoning!A:A,J9)=0,"pays inconnu",LOOKUP(J9,Zoning!A:A,Zoning!B:B)) -> France | L9: =L8 -> 1 | M9: =_xlfn.XLOOKUP(G9,Poids!A:A,Poids!C:C) -> 0.6 | N9: =IF(COUNTIF(Zoning!A:A,J9)=0,"zone inconnue","France") -> France | O9: =IF(COUNTIF(Zoning!A:A,J9)=0,"taux inconnu",_xlfn.XLOOKUP(J9,Zoning!A:A,Zoning!C:C)) -> 0.2 | R9: =IF(TCD!K10="","",TCD!K10) | S9: =IF(TCD!F10="","",TCD!F10) | T9: =IF(TCD!E10="","",TCD!E10) | U9: =SUM(TCD!H10:J10) -> 9.25
A10: =_xlfn.XLOOKUP(G10,'Facture GLS'!AB:AB,'Facture GLS'!O:O) -> LA RUCHE | B10: =B9 -> GLS | C10: =C9 -> 46174 | G10: =TCD!D11 -> 00KUR5U2 | I10: P | J10: =_xlfn.XLOOKUP(G10,'Facture GLS'!AB:AB,'Facture GLS'!BB:BB) -> FR | K10: =IF(COUNTIF(Zoning!A:A,J10)=0,"pays inconnu",LOOKUP(J10,Zoning!A:A,Zoning!B:B)) -> France | L10: =L9 -> 1 | M10: =_xlfn.XLOOKUP(G10,Poids!A:A,Poids!C:C) -> 0.3 | N10: =IF(COUNTIF(Zoning!A:A,J10)=0,"zone inconnue","France") -> France | O10: =IF(COUNTIF(Zoning!A:A,J10)=0,"taux inconnu",_xlfn.XLOOKUP(J10,Zoning!A:A,Zoning!C:C)) -> 0.2 | R10: =IF(TCD!K11="","",TCD!K11) | S10: =IF(TCD!F11="","",TCD!F11) | T10: =IF(TCD!E11="","",TCD!E11) | U10: =SUM(TCD!H11:J11) -> 8.59
